Workbook
Name CalendarQ: [11]RTG!$B$36

Sheet SAM TO DO
B4: Clean up Tabcorp Model | G4: FY COMPS
G5: QUARTERLY COMPS
B6: Fill out VC margins
B7: Get bet365/entain data
B8: Look Through Sacha old Notes
B9: Look at industry reports
B10: Look at Rival Investor Days
B11: Compare all state retail licences
B12: Read demerger Docs
B13: Look at Total Wagering Revenue
B16: Look at state lottery revenue budgets
B20: Look Into
B21: Racing NSW Country | C21: http://racingnswcountry.com.au/wp-content/uploads/2016/09/RacingNSWCountry_Annual-Report_2020_final-PDF-2.pdf
B22: Racing Clubs | C22: https://cdn.australianturfclub.com.au/app/uploads/2019/10/2019_WEB_Download_ATC-Annual-Report_2018.pdf
B23: Racing vs World | C23: https://www.ifhaonline.org/resources/Annual_Report_2019.pdf
B24: RacinigCorp ATO | C24: https://connectonline.asic.gov.au/RegistrySearch/faces/landing/panelSearch.jspx?searchText=080959495&searchType=OrgAndBusNm&_adf.ctrl-state=javmibtd9_30
B25: Tabcorp vs Entain Racing Case | C25: https://www.austlii.edu.au/cgi-bin/viewdoc/au/cases/nsw/NSWSC/2023/220.html?context=1;query=entain;mask_path=#fn9
B26: Racing NSW race field fees Case | C26: https://www.troa.com.au/news/racing-nsw-wins-both-race-fields-legislation-cases
B27: Tax comparison | C27: https://www.treasury.nsw.gov.au/sites/default/files/2023-06/trp23-15_interstate-comparison-of-taxes_2022-23.pdf
B28: 1997 NSW Tote Act Notes | C28: https://www.austlii.edu.au/cgi-bin/viewdoc/au/legis/nsw/consol_act/ta1997167/notes.html
B29: NSW Wagering | C29: https://www.liquorandgaming.nsw.gov.au/operating-a-business/gaming-licences/gaming-licences-permits/sports-wagering-in-nsw
B30: POCT example | C30: https://www.treasury.tas.gov.au/liquor-and-gaming/fees/wagering-point-of-consumption-tax
B33: US Sports Betting Revenue
B34: https://sportsbetting.legal/revenue-tracking/
B37: https://h2gc.com/site/assets/News%20Stories/IBIA-Report-2024_FINAL-TEXT_SINGLE_AW.pdf
B44: https://treasury.nt.gov.au/publications/annual-reports
B45: https://industry.nt.gov.au/publications/corporate/annual-reports

Sheet COMPS

Sheet QTR
D3: =IF(MONTH(D11)>6,RIGHT(YEAR(D11),2)+1,RIGHT(YEAR(D11),2)) -> 17 | E3: =IF(MONTH(E11)>6,RIGHT(YEAR(E11),2)+1,RIGHT(YEAR(E11),2)) -> 18 | F3: =IF(MONTH(F11)>6,RIGHT(YEAR(F11),2)+1,RIGHT(YEAR(F11),2)) -> 18 | G3: =IF(MONTH(G11)>6,RIGHT(YEAR(G11),2)+1,RIGHT(YEAR(G11),2)) -> 18 | H3: =IF(MONTH(H11)>6,RIGHT(YEAR(H11),2)+1,RIGHT(YEAR(H11),2)) -> 18 | I3: =IF(MONTH(I11)>6,RIGHT(YEAR(I11),2)+1,RIGHT(YEAR(I11),2)) -> 19 | J3: =IF(MONTH(J11)>6,RIGHT(YEAR(J11),2)+1,RIGHT(YEAR(J11),2)) -> 19 | K3: =IF(MONTH(K11)>6,RIGHT(YEAR(K11),2)+1,RIGHT(YEAR(K11),2)) -> 19 | ... AN3: =IF(MONTH(AN11)>6,RIGHT(YEAR(AN11),2)+1,RIGHT(YEAR(AN11),2)) -> 26
D4: =RIGHT(YEAR(D$11),2) -> 17 | E4: =RIGHT(YEAR(E$11),2) -> 17 | F4: =RIGHT(YEAR(F$11),2) -> 17 | G4: =RIGHT(YEAR(G$11),2) -> 18 | H4: =RIGHT(YEAR(H$11),2) -> 18 | I4: =RIGHT(YEAR(I$11),2) -> 18 | J4: =RIGHT(YEAR(J$11),2) -> 18 | K4: =RIGHT(YEAR(K$11),2) -> 19 | ... AN4: =RIGHT(YEAR(AN$11),2) -> 26
D5: ="FY"&TEXT(D$3,"00") -> FY17 | E5: ="FY"&TEXT(E$3,"00") -> FY18 | F5: ="FY"&TEXT(F$3,"00") -> FY18 | G5: ="FY"&TEXT(G$3,"00") -> FY18 | H5: ="FY"&TEXT(H$3,"00") -> FY18 | I5: ="FY"&TEXT(I$3,"00") -> FY19 | J5: ="FY"&TEXT(J$3,"00") -> FY19 | K5: ="FY"&TEXT(K$3,"00") -> FY19 | ... AN5: ="FY"&TEXT(AN$3,"00") -> FY26
D6: ="CY"&TEXT(D$4,"00") -> CY17 | E6: ="CY"&TEXT(E$4,"00") -> CY17 | F6: ="CY"&TEXT(F$4,"00") -> CY17 | G6: ="CY"&TEXT(G$4,"00") -> CY18 | H6: ="CY"&TEXT(H$4,"00") -> CY18 | I6: ="CY"&TEXT(I$4,"00") -> CY18 | J6: ="CY"&TEXT(J$4,"00") -> CY18 | K6: ="CY"&TEXT(K$4,"00") -> CY19 | ... AN6: ="CY"&TEXT(AN$4,"00") -> CY26
D7: =D11-EOMONTH(D11,-3) -> 91 | E7: =E11-EOMONTH(E11,-3) -> 92 | F7: =F11-EOMONTH(F11,-3) -> 92 | G7: =G11-EOMONTH(G11,-3) -> 90 | H7: =H11-EOMONTH(H11,-3) -> 91 | I7: =I11-EOMONTH(I11,-3) -> 92 | J7: =J11-EOMONTH(J11,-3) -> 92 | K7: =K11-EOMONTH(K11,-3) -> 90 | ... AN7: =AN11-EOMONTH(AN11,-3) -> 91
E9: 1H18 | F9: 1H18 | G9: 2H18 | H9: 2H18 | I9: 1H19 | J9: 1H19 | K9: 2H19 | L9: 2H19 | M9: 1H20 | N9: 1H20 | O9: 2H20 | P9: 2H20 | Q9: 1H21 | R9: 1H21 | S9: 2H21 | T9: 2H21 | U9: 1H22 | V9: 1H22 | W9: 2H22 | X9: 2H22 | Y9: 1H23 | Z9: 1H23 | AA9: 2H23 | AB9: 2H23 | AC9: 1H24 | AD9: 1H24 | AE9: 2H24 | AF9: 2H24 | AG9: 1H25 | AH9: 1H25 | AI9: 2H25 | AJ9: 2H25 | AK9: 1H26 | AL9: 1H26 | AM9: 2H26 | AN9: 2H26 | AP9: YoY | AQ9: QoQ
D10: 4Q17 | E10: 1Q18 | F10: 2Q18 | G10: 3Q18 | H10: 4Q18 | I10: 1Q19 | J10: 2Q19 | K10: 3Q19 | L10: 4Q19 | M10: 1Q20 | N10: 2Q20 | O10: 3Q20 | P10: 4Q20 | Q10: 1Q21 | R10: 2Q21 | S10: 3Q21 | T10: 4Q21 | U10: 1Q22 | V10: 2Q22 | W10: 3Q22 | X10: 4Q22 | Y10: 1Q23 | Z10: 2Q23 | AA10: 3Q23 | AB10: 4Q23 | AC10: 1Q24 | AD10: 2Q24 | AE10: 3Q24 | AF10: 4Q24 | AG10: 1Q25 | AH10: 2Q25 | AI10: 3Q25 | AJ10: 4Q25 | AK10: 1Q26 | AL10: 2Q26 | AM10: 3Q26 | AN10: 4Q26 | AP10: 3Q24 | AQ10: 3Q24
D11: 42916 | E11: =EOMONTH( D11, 3) -> 43008 | F11: =EOMONTH( E11, 3) -> 43100 | G11: =EOMONTH( F11, 3) -> 43190 | H11: =EOMONTH( G11, 3) -> 43281 | I11: =EOMONTH( H11, 3) -> 43373 | J11: =EOMONTH( I11, 3) -> 43465 | K11: =EOMONTH( J11, 3) -> 43555 | L11: =EOMONTH( K11, 3) -> 43646 | ... AN11: =EOMONTH( AM11, 3) -> 46203
B14: Turnover
B15: SportsBet | C15: A$m | O15: ='SBET QTR'!O56 -> 3005.7916 | P15: ='SBET QTR'!P56 -> 4110.3288 | Q15: ='SBET QTR'!Q56 -> 5423.9746 | R15: ='SBET QTR'!R56 -> 5396.7741 | S15: ='SBET QTR'!S56 -> 4373.3237 | T15: ='SBET QTR'!T56 -> 4625.8092 | U15: ='SBET QTR'!U56 -> 6235.0564 | V15: ='SBET QTR'!V56 -> 6261.5594 | ... AH15: ='SBET QTR'!AH56 -> 4379.4949 | AP15: =$AE15/AA15-1 -> -0.15797019 | AQ15: =$AE15/AD15-1 -> -0.16534921
B16: PointsBet | C16: A$m | O16: =PBH!N12 -> 178.4 | P16: =PBH!O12 -> 302.9 | Q16: =PBH!P12 -> 527.7 | R16: =PBH!Q12 -> 543.3 | S16: =PBH!R12 -> 423.2 | T16: =PBH!S12 -> 494.8 | U16: =PBH!T12 -> 631.4 | V16: =PBH!U12 -> 727 | ... AH16: =PBH!AG12 -> 591.5 | AP16: =$AE16/AA16-1 -> 0.04432563 | AQ16: =$AE16/AD16-1 -> -0.32841615
B17: BlueBet | C17: A$m | Q17: ='BBET + BetR'!P12 -> 75.2 | R17: ='BBET + BetR'!Q12 -> 89.5 | S17: ='BBET + BetR'!R12 -> 83.5 | T17: ='BBET + BetR'!S12 -> 96.5 | U17: ='BBET + BetR'!T12 -> 125.9 | V17: ='BBET + BetR'!U12 -> 138.6 | W17: ='BBET + BetR'!V12 -> 120.7 | X17: ='BBET + BetR'!W12 -> 126.7 | ... AH17: ='BBET + BetR'!AG12 -> 0 | AP17: =$AE17/AA17-1 -> 0.17212427 | AQ17: =$AE17/AD17-1 -> -0.098191214
B18: BetR | C18: A$m | AA18: =BETR!Z12 -> 354.2 | AE18: =BETR!AD12 -> 273.1 | AF18: =BETR!AE12 -> 0 | AG18: =BETR!AF12 -> 0 | AH18: =BETR!AG12 -> 0 | AP18: =$AE18/AA18-1 -> -0.22896669
B19: Gross Win
B20: SportsBet | C20: A$m
B21: PointsBet | C21: A$m | O21: =PBH!N14 -> 21.2 | P21: =PBH!O14 -> 41.6 | Q21: =PBH!P14 -> 60.5 | R21: =PBH!Q14 -> 75.5 | S21: =PBH!R14 -> 54.8 | T21: =PBH!S14 -> 66.4 | U21: =PBH!T14 -> 87.9 | V21: =PBH!U14 -> 92.2 | ... AH21: =PBH!AG14 -> 80.5 | AP21: =$AE21/AA21-1 -> 0.093883357 | AQ21: =$AE21/AD21-1 -> -0.12712826
B22: BlueBet | C22: A$m | Q22: ='BBET + BetR'!P14 -> 9.6 | R22: ='BBET + BetR'!Q14 -> 11.5 | S22: ='BBET + BetR'!R14 -> 10.4 | T22: ='BBET + BetR'!S14 -> 12.7 | U22: ='BBET + BetR'!T14 -> 18.1 | V22: ='BBET + BetR'!U14 -> 18.4 | W22: ='BBET + BetR'!V14 -> 17 | X22: ='BBET + BetR'!W14 -> 17 | ... AH22: ='BBET + BetR'!AG14 -> 0 | AP22: =$AE22/AA22-1 -> 0.1835443 | AQ22: =$AE22/AD22-1 -> 0.78095238
B23: BetR | C23: A$m | AA23: =BETR!Z14 -> 37.6 | AE23: =BETR!AD14 -> 37.1 | AF23: =BETR!AE14 -> 0 | AG23: =BETR!AF14 -> 0 | AH23: =BETR!AG14 -> 0 | AP23: =$AE23/AA23-1 -> -0.013297872
B24: Net Win
B25: SportsBet | C25: A$m | O25: ='SBET QTR'!O59 -> 313.22488 | P25: ='SBET QTR'!P59 -> 517.09371 | Q25: ='SBET QTR'!Q59 -> 577.97932 | R25: ='SBET QTR'!R59 -> 578.16127 | S25: ='SBET QTR'!S59 -> 497.98966 | T25: ='SBET QTR'!T59 -> 557.18708 | U25: ='SBET QTR'!U59 -> 698.74904 | V25: ='SBET QTR'!V59 -> 623.82185 | ... AH25: ='SBET QTR'!AH59 -> 530.38335 | AP25: =$AE25/AA25-1 -> -0.024942934 | AQ25: =$AE25/AD25-1 -> -0.13164329
B26: PointsBet | C26: A$m | O26: =PBH!N19 -> 15.5 | P26: =PBH!O19 -> 32.4 | Q26: =PBH!P19 -> 35.1 | R26: =PBH!Q19 -> 49.8 | S26: =PBH!R19 -> 38.2 | T26: =PBH!S19 -> 43.1 | U26: =PBH!T19 -> 54.8 | V26: =PBH!U19 -> 53.1 | ... AH26: =PBH!AG19 -> 60.5 | AP26: =$AE26/AA26-1 -> 0.19921105 | AQ26: =$AE26/AD26-1 -> 0.021848739
B27: BlueBet | C27: A$m | Q27: ='BBET + BetR'!P17 -> 7.9 | R27: ='BBET + BetR'!Q17 -> 9.1 | S27: ='BBET + BetR'!R17 -> 8.5 | T27: ='BBET + BetR'!S17 -> 10.1 | U27: ='BBET + BetR'!T17 -> 14.8 | V27: ='BBET + BetR'!U17 -> 13.8 | W27: ='BBET + BetR'!V17 -> 13.2 | X27: ='BBET + BetR'!W17 -> 12.8 | ... AH27: ='BBET + BetR'!AG17 -> 0 | AP27: =$AE27/AA27-1 -> 0.325 | AQ27: =$AE27/AD27-1 -> -0.018518519
B28: BetR | C28: A$m | AA28: =BETR!Z17 -> 15 | AE28: =BETR!AD17 -> 23.3 | AF28: =BETR!AE17 -> 0 | AG28: =BETR!AF17 -> 0 | AH28: =BETR!AG17 -> 0 | AP28: =$AE28/AA28-1 -> 0.55333333
B29: Active Customers (LTM)
B30: SportsBet | C30: #
B31: PointsBet | C31: # | O31: =PBH!N22 -> 83330 | P31: =PBH!O22 -> 90422 | Q31: =PBH!P22 -> 124715 | R31: =PBH!Q22 -> 142992 | S31: =PBH!R22 -> 158041 | T31: =PBH!S22 -> 196585 | U31: =PBH!T22 -> 222662 | V31: =PBH!U22 -> 232875 | ... AH31: =PBH!AG22 -> 235100 | AP31: =$AE31/AA31-1 -> -0.071639208 | AQ31: =$AE31/AD31-1 -> 0.012423954
B32: BlueBet | C32: # | O32: ='BBET + BetR'!N20 -> 20217 | P32: ='BBET + BetR'!O20 -> 22289 | Q32: ='BBET + BetR'!P20 -> 23927 | R32: ='BBET + BetR'!Q20 -> 25540 | S32: ='BBET + BetR'!R20 -> 26824 | T32: ='BBET + BetR'!S20 -> 32472 | U32: ='BBET + BetR'!T20 -> 39195 | V32: ='BBET + BetR'!U20 -> 45087 | ... AH32: ='BBET + BetR'!AG20 -> 0 | AP32: =$AE32/AA32-1 -> 0.073101176 | AQ32: =$AE32/AD32-1 -> 0.0050600229
B33: BetR | C33: #
B34: Gross Win Margin
B35: SportsBet | C35: %
B36: PointsBet | C36: % | O36: =O21/O16 -> 0.11883408 | P36: =P21/P16 -> 0.13733906 | Q36: =Q21/Q16 -> 0.11464847 | R36: =R21/R16 -> 0.13896558 | S36: =S21/S16 -> 0.1294896 | T36: =T21/T16 -> 0.13419563 | U36: =U21/U16 -> 0.13921444 | V36: =V21/V16 -> 0.12682256 | ... AH36: =AH21/AH16 -> 0.13609467 | AP36: =($AE36-AA36)*100 -> 0.57537708 | AQ36: =($AE36-AD36)*100 -> 2.9287304
B37: BlueBet | C37: % | Q37: =Q22/Q17 -> 0.12765957 | R37: =R22/R17 -> 0.12849162 | S37: =S22/S17 -> 0.1245509 | T37: =T22/T17 -> 0.13160622 | U37: =U22/U17 -> 0.14376489 | V37: =V22/V17 -> 0.13275613 | W37: =W22/W17 -> 0.14084507 | X37: =X22/X17 -> 0.13417522 | ... AH37: =AH22/AH17 -> #DIV/0! | AP37: =($AE37-AA37)*100 -> 0.12925258 | AQ37: =($AE37-AD37)*100 -> 6.6124697
B38: BetR | C38: % | AA38: =AA23/AA18 -> 0.10615471 | AE38: =AE23/AE18 -> 0.13584767 | AF38: =AF23/AF18 -> #DIV/0! | AG38: =AG23/AG18 -> #DIV/0! | AH38: =AH23/AH18 -> #DIV/0! | AP38: =($AE38-AA38)*100 -> 2.969296
B39: Net Win Margin
B40: SportsBet | C40: % | O40: =O25/O15 -> 0.10420712 | P40: =P25/P15 -> 0.12580349 | Q40: =Q25/Q15 -> 0.10656011 | R40: =R25/R15 -> 0.1071309 | S40: =S25/S15 -> 0.11386984 | T40: =T25/T15 -> 0.12045181 | U40: =U25/U15 -> 0.1120678 | V40: =V25/V15 -> 0.099627235 | ... AH40: =AH25/AH15 -> 0.12110606 | AP40: =($AE40-AA40)*100 -> 1.7619132 | AQ40: =($AE40-AD40)*100 -> 0.50128189
B41: PointsBet | C41: % | O41: =O26/O16 -> 0.086883408 | P41: =P26/P16 -> 0.106966 | Q41: =Q26/Q16 -> 0.066515065 | R41: =R26/R16 -> 0.091662065 | S41: =S26/S16 -> 0.09026465 | T41: =T26/T16 -> 0.087105901 | U41: =U26/U16 -> 0.086791258 | V41: =V26/V16 -> 0.07303989 | ... AH41: =AH26/AH16 -> 0.10228233 | AP41: =($AE41-AA41)*100 -> 1.2968936 | AQ41: =($AE41-AD41)*100 -> 3.4419093
B42: BlueBet | C42: % | Q42: =Q27/Q17 -> 0.10505319 | R42: =R27/R17 -> 0.10167598 | S42: =S27/S17 -> 0.10179641 | T42: =T27/T17 -> 0.10466321 | U42: =U27/U17 -> 0.11755361 | V42: =V27/V17 -> 0.0995671 | W42: =W27/W17 -> 0.10936205 | X42: =X27/X17 -> 0.10102605 | ... AH42: =AH27/AH17 -> #DIV/0! | AP42: =($AE42-AA42)*100 -> 1.3141181 | AQ42: =($AE42-AD42)*100 -> 0.92456853
B43: BetR | C43: % | AA43: =AA28/AA18 -> 0.042348955 | AE43: =AE28/AE18 -> 0.085316734 | AF43: =AF28/AF18 -> #DIV/0! | AG43: =AG28/AG18 -> #DIV/0! | AH43: =AH28/AH18 -> #DIV/0! | AP43: =($AE43-AA43)*100 -> 4.2967778
B44: Marketing as a % of Net Win
B45: SportsBet | S45: ='SBET QTR'!S41 -> 0.10731699 | T45: ='SBET QTR'!T41 -> 0.15982187 | U45: ='SBET QTR'!U41 -> 0.1274918 | V45: ='SBET QTR'!V41 -> 0.1243399 | W45: ='SBET QTR'!W41 -> 0.11873294 | X45: ='SBET QTR'!X41 -> 0.13270822 | Y45: ='SBET QTR'!Y41 -> 0.16729703 | Z45: ='SBET QTR'!Z41 -> 0.17042412 | ... AH45: ='SBET QTR'!AH41 -> 0.1734104
...

Sheet HY
A2: X | D2: =D7&D9 -> 1H18A | E2: =E7&E9 -> 2H18A | F2: =F7&F9 -> 1H19A | G2: =G7&G9 -> 2H19A | H2: =H7&H9 -> 1H20A | I2: =I7&I9 -> 2H20A | J2: =J7&J9 -> 1H21A | K2: =K7&K9 -> 2H21A | ... AK2: =AK7&AK9 -> 2H34E
B3: Period End | D3: 43100 | E3: =EOMONTH(D3,6) -> 43281 | F3: =EOMONTH(E3,6) -> 43465 | G3: =EOMONTH(F3,6) -> 43646 | H3: =EOMONTH(G3,6) -> 43830 | I3: =EOMONTH(H3,6) -> 44012 | J3: =EOMONTH(I3,6) -> 44196 | K3: =EOMONTH(J3,6) -> 44377 | L3: =EOMONTH(K3,6) -> 44561 | ... AK3: =EOMONTH(AJ3,6) -> 49125
B5: Half | D5: {=_xlfn.IFS(AND(MONTH(D$3)>=7,MONTH(D$3)<=12),"1H",AND(MONTH(D$3)>=1,MONTH(D$3)<=6),"2H")} -> 1H | E5: {=_xlfn.IFS(AND(MONTH(E$3)>=7,MONTH(E$3)<=12),"1H",AND(MONTH(E$3)>=1,MONTH(E$3)<=6),"2H")} -> 2H | F5: {=_xlfn.IFS(AND(MONTH(F$3)>=7,MONTH(F$3)<=12),"1H",AND(MONTH(F$3)>=1,MONTH(F$3)<=6),"2H")} -> 1H | G5: {=_xlfn.IFS(AND(MONTH(G$3)>=7,MONTH(G$3)<=12),"1H",AND(MONTH(G$3)>=1,MONTH(G$3)<=6),"2H")} -> 2H | H5: {=_xlfn.IFS(AND(MONTH(H$3)>=7,MONTH(H$3)<=12),"1H",AND(MONTH(H$3)>=1,MONTH(H$3)<=6),"2H")} -> 1H | I5: {=_xlfn.IFS(AND(MONTH(I$3)>=7,MONTH(I$3)<=12),"1H",AND(MONTH(I$3)>=1,MONTH(I$3)<=6),"2H")} -> 2H | J5: {=_xlfn.IFS(AND(MONTH(J$3)>=7,MONTH(J$3)<=12),"1H",AND(MONTH(J$3)>=1,MONTH(J$3)<=6),"2H")} -> 1H | K5: {=_xlfn.IFS(AND(MONTH(K$3)>=7,MONTH(K$3)<=12),"1H",AND(MONTH(K$3)>=1,MONTH(K$3)<=6),"2H")} -> 2H | ... AK5: {=_xlfn.IFS(AND(MONTH(AK$3)>=7,MONTH(AK$3)<=12),"1H",AND(MONTH(AK$3)>=1,MONTH(AK$3)<=6),"2H")} -> 2H
B6: FY | D6: =IF(MONTH(D3)>6,RIGHT(YEAR(D3),2)+1,RIGHT(YEAR(D3),2)) -> 18 | E6: =IF(MONTH(E3)>6,RIGHT(YEAR(E3),2)+1,RIGHT(YEAR(E3),2)) -> 18 | F6: =IF(MONTH(F3)>6,RIGHT(YEAR(F3),2)+1,RIGHT(YEAR(F3),2)) -> 19 | G6: =IF(MONTH(G3)>6,RIGHT(YEAR(G3),2)+1,RIGHT(YEAR(G3),2)) -> 19 | H6: =IF(MONTH(H3)>6,RIGHT(YEAR(H3),2)+1,RIGHT(YEAR(H3),2)) -> 20 | I6: =IF(MONTH(I3)>6,RIGHT(YEAR(I3),2)+1,RIGHT(YEAR(I3),2)) -> 20 | J6: =IF(MONTH(J3)>6,RIGHT(YEAR(J3),2)+1,RIGHT(YEAR(J3),2)) -> 21 | K6: =IF(MONTH(K3)>6,RIGHT(YEAR(K3),2)+1,RIGHT(YEAR(K3),2)) -> 21 | ... AK6: =IF(MONTH(AK3)>6,RIGHT(YEAR(AK3),2)+1,RIGHT(YEAR(AK3),2)) -> 34
B7: FY Year | D7: =D$5&TEXT(D$6,"00") -> 1H18 | E7: =E$5&TEXT(E$6,"00") -> 2H18 | F7: =F$5&TEXT(F$6,"00") -> 1H19 | G7: =G$5&TEXT(G$6,"00") -> 2H19 | H7: =H$5&TEXT(H$6,"00") -> 1H20 | I7: =I$5&TEXT(I$6,"00") -> 2H20 | J7: =J$5&TEXT(J$6,"00") -> 1H21 | K7: =K$5&TEXT(K$6,"00") -> 2H21 | ... AK7: =AK$5&TEXT(AK$6,"00") -> 2H34
B8: Financial Year | D8: {=_xlfn.IFS(MONTH(D$3)=12,YEAR(D$3)+1,MONTH(D$3)=6,YEAR(D$3))} -> 2018 | E8: {=_xlfn.IFS(MONTH(E$3)=12,YEAR(E$3)+1,MONTH(E$3)=6,YEAR(E$3))} -> 2018 | F8: {=_xlfn.IFS(MONTH(F$3)=12,YEAR(F$3)+1,MONTH(F$3)=6,YEAR(F$3))} -> 2019 | G8: {=_xlfn.IFS(MONTH(G$3)=12,YEAR(G$3)+1,MONTH(G$3)=6,YEAR(G$3))} -> 2019 | H8: {=_xlfn.IFS(MONTH(H$3)=12,YEAR(H$3)+1,MONTH(H$3)=6,YEAR(H$3))} -> 2020 | I8: {=_xlfn.IFS(MONTH(I$3)=12,YEAR(I$3)+1,MONTH(I$3)=6,YEAR(I$3))} -> 2020 | J8: {=_xlfn.IFS(MONTH(J$3)=12,YEAR(J$3)+1,MONTH(J$3)=6,YEAR(J$3))} -> 2021 | K8: {=_xlfn.IFS(MONTH(K$3)=12,YEAR(K$3)+1,MONTH(K$3)=6,YEAR(K$3))} -> 2021 | ... AK8: {=_xlfn.IFS(MONTH(AK$3)=12,YEAR(AK$3)+1,MONTH(AK$3)=6,YEAR(AK$3))} -> 2034
B9: Actual/Estimate | D9: =IF(ISNUMBER(D$14),"A","E") -> A | E9: =IF(ISNUMBER(E$14),"A","E") -> A | F9: =IF(ISNUMBER(F$14),"A","E") -> A | G9: =IF(ISNUMBER(G$14),"A","E") -> A | H9: =IF(ISNUMBER(H$14),"A","E") -> A | I9: =IF(ISNUMBER(I$14),"A","E") -> A | J9: =IF(ISNUMBER(J$14),"A","E") -> A | K9: =IF(ISNUMBER(K$14),"A","E") -> A | ... AK9: =IF(ISNUMBER(AK$14),"A","E") -> E
B10: Days in period | D10: =D3-EOMONTH(D3,-6) -> 184 | E10: =E3-D3 -> 181 | F10: =F3-E3 -> 184 | G10: =G3-F3 -> 181 | H10: =H3-G3 -> 184 | I10: =I3-H3 -> 182 | J10: =J3-I3 -> 184 | K10: =K3-J3 -> 181 | L10: =L3-K3 -> 184 | ... AK10: =AK3-AJ3 -> 181
B12: SEGMENTS
B13: Turnover
B14: Tabcorp - Retail | D14: 4254 | E14: 3765.4 | F14: 3969.7 | G14: 3458.8 | H14: 3612 | I14: 1742 | J14: 2595 | K14: 2710 | L14: 1720.5 | M14: 2476.2 | N14: 2839 | O14: 2445.1 | P14: 2732.4
B15: Tabcorp - Digital | D15: 3491.4 | E15: 3360.2 | F15: 3821.9 | G15: 3446.8 | H15: 3616 | I15: 3842 | J15: 5167 | K15: 4314 | L15: 5259 | M15: 4438 | N15: 4920.5 | O15: 4346.2 | P15: 4731.2
B16: SportsBet | D16: =_xlfn.XLOOKUP(D$7,SBET!$18:$18,SBET!$94:$94) -> 2998.4194 | E16: =_xlfn.XLOOKUP(E$7,SBET!$18:$18,SBET!$94:$94) -> 3770.1165 | F16: =_xlfn.XLOOKUP(F$7,SBET!$18:$18,SBET!$94:$94) -> 3921.6312 | G16: =_xlfn.XLOOKUP(G$7,SBET!$18:$18,SBET!$94:$94) -> 6066.1924 | H16: =_xlfn.XLOOKUP(H$7,SBET!$18:$18,SBET!$94:$94) -> 6326.0608 | I16: =_xlfn.XLOOKUP(I$7,SBET!$18:$18,SBET!$94:$94) -> 7132.9197 | J16: =_xlfn.XLOOKUP(J$7,SBET!$18:$18,SBET!$94:$94) -> 10820.753 | K16: =_xlfn.XLOOKUP(K$7,SBET!$18:$18,SBET!$94:$94) -> 9001.6287 | ... P16: =_xlfn.XLOOKUP(P$7,SBET!$18:$18,SBET!$94:$94) -> 8171.3795
B17: LadBrokes
B18: Bet365
B19: PointsBet | F19: =SUMIF(PBH!$9:$9,HY!F$7,PBH!$12:$12) -> 209.6 | G19: =SUMIF(PBH!$9:$9,HY!G$7,PBH!$12:$12) -> 280.5 | H19: =SUMIF(PBH!$9:$9,HY!H$7,PBH!$12:$12) -> 349.2 | I19: =SUMIF(PBH!$9:$9,HY!I$7,PBH!$12:$12) -> 481.3 | J19: =SUMIF(PBH!$9:$9,HY!J$7,PBH!$12:$12) -> 1071 | K19: =SUMIF(PBH!$9:$9,HY!K$7,PBH!$12:$12) -> 918 | L19: =SUMIF(PBH!$9:$9,HY!L$7,PBH!$12:$12) -> 1358.4 | M19: =SUMIF(PBH!$9:$9,HY!M$7,PBH!$12:$12) -> 1178 | ... P19: =SUMIF(PBH!$9:$9,HY!P$7,PBH!$12:$12) -> 1468.5
B20: BlueBet | J20: =SUMIF('BBET + BetR'!$9:$9,HY!J$7,'BBET + BetR'!$12:$12) -> 164.7 | K20: =SUMIF('BBET + BetR'!$9:$9,HY!K$7,'BBET + BetR'!$12:$12) -> 180 | L20: =SUMIF('BBET + BetR'!$9:$9,HY!L$7,'BBET + BetR'!$12:$12) -> 264.5 | M20: =SUMIF('BBET + BetR'!$9:$9,HY!M$7,'BBET + BetR'!$12:$12) -> 247.4 | N20: =SUMIF('BBET + BetR'!$9:$9,HY!N$7,'BBET + BetR'!$12:$12) -> 279.1 | O20: =SUMIF('BBET + BetR'!$9:$9,HY!O$7,'BBET + BetR'!$12:$12) -> 250.7 | P20: =SUMIF('BBET + BetR'!$9:$9,HY!P$7,'BBET + BetR'!$12:$12) -> 298.7
B21: BetR | P21: =SUMIF(BETR!$10:$10,HY!P$7,BETR!$12:$12) -> 673.2
B23: Gross Revenue
B24: Tabcorp - Retail | L24: 288.1 | M24: 410.7 | N24: 471.9 | O24: 410.1 | P24: 458.1
B25: Tabcorp - Digital | L25: 894.03 | M25: 744.763 | N25: 806.962 | O25: 712.7768 | P25: 780.648
B26: SportsBet
B27: LadBrokes
B28: Bet365
B29: PointsBet | F29: =SUMIF(PBH!$9:$9,HY!F$7,PBH!$14:$14) -> 21.8 | G29: =SUMIF(PBH!$9:$9,HY!G$7,PBH!$14:$14) -> 28.7 | H29: =SUMIF(PBH!$9:$9,HY!H$7,PBH!$14:$14) -> 38 | I29: =SUMIF(PBH!$9:$9,HY!I$7,PBH!$14:$14) -> 62.8 | J29: =SUMIF(PBH!$9:$9,HY!J$7,PBH!$14:$14) -> 136 | K29: =SUMIF(PBH!$9:$9,HY!K$7,PBH!$14:$14) -> 121.2 | L29: =SUMIF(PBH!$9:$9,HY!L$7,PBH!$14:$14) -> 180.1 | M29: =SUMIF(PBH!$9:$9,HY!M$7,PBH!$14:$14) -> 158.3 | ... P29: =SUMIF(PBH!$9:$9,HY!P$7,PBH!$14:$14) -> 159.7
B30: BlueBet | J30: =SUMIF('BBET + BetR'!$9:$9,HY!J$7,'BBET + BetR'!$14:$14) -> 21.1 | K30: =SUMIF('BBET + BetR'!$9:$9,HY!K$7,'BBET + BetR'!$14:$14) -> 23.1 | L30: =SUMIF('BBET + BetR'!$9:$9,HY!L$7,'BBET + BetR'!$14:$14) -> 36.5 | M30: =SUMIF('BBET + BetR'!$9:$9,HY!M$7,'BBET + BetR'!$14:$14) -> 34 | N30: =SUMIF('BBET + BetR'!$9:$9,HY!N$7,'BBET + BetR'!$14:$14) -> 36 | O30: =SUMIF('BBET + BetR'!$9:$9,HY!O$7,'BBET + BetR'!$14:$14) -> 34.9 | P30: =SUMIF('BBET + BetR'!$9:$9,HY!P$7,'BBET + BetR'!$14:$14) -> 29.3
B31: BetR | P31: =SUMIF(BETR!$10:$10,HY!P$7,BETR!$14:$14) -> 79.8
B33: Net Revenue
B34: Tabcorp - Retail | L34: 288.1 | M34: 410.7 | N34: 471.9 | O34: 410.1 | P34: 458.1 | T34: =SUM(N34:O35)/SUM(L34:M35)-1 -> 0.011594782
B35: Tabcorp - Digital | L35: 702.3 | M35: 599.8 | N35: 599.2 | O35: 542.9 | P35: 572.9
B36: SportsBet | D36: =_xlfn.XLOOKUP(D$7,SBET!$18:$18,SBET!$96:$96) -> 375.43661 | E36: =_xlfn.XLOOKUP(E$7,SBET!$18:$18,SBET!$96:$96) -> 369.16467 | F36: =_xlfn.XLOOKUP(F$7,SBET!$18:$18,SBET!$96:$96) -> 350.33716 | G36: =_xlfn.XLOOKUP(G$7,SBET!$18:$18,SBET!$96:$96) -> 575.11607 | H36: =_xlfn.XLOOKUP(H$7,SBET!$18:$18,SBET!$96:$96) -> 675.09866 | I36: =_xlfn.XLOOKUP(I$7,SBET!$18:$18,SBET!$96:$96) -> 833.4193 | J36: =_xlfn.XLOOKUP(J$7,SBET!$18:$18,SBET!$96:$96) -> 1156.1406 | K36: =_xlfn.XLOOKUP(K$7,SBET!$18:$18,SBET!$96:$96) -> 1053.1906 | ... P36: =_xlfn.XLOOKUP(P$7,SBET!$18:$18,SBET!$96:$96) -> 969.78114 | R36: =SUM(L36:M36)/SUM(J36:K36)-1 -> 0.097209867 | T36: =SUM(N36:O36)/SUM(L36:M36)-1 -> -0.076750483
B37: LadBrokes | E37: =_xlfn.XLOOKUP(E$7,ENT!$17:$17,ENT!$28:$28) -> 157.12085 | F37: =_xlfn.XLOOKUP(F$7,ENT!$17:$17,ENT!$28:$28) -> 204.83165 | G37: =_xlfn.XLOOKUP(G$7,ENT!$17:$17,ENT!$28:$28) -> 206.54747 | H37: =_xlfn.XLOOKUP(H$7,ENT!$17:$17,ENT!$28:$28) -> 247.45072 | I37: =_xlfn.XLOOKUP(I$7,ENT!$17:$17,ENT!$28:$28) -> 308.96149 | J37: =_xlfn.XLOOKUP(J$7,ENT!$17:$17,ENT!$28:$28) -> 401.10624 | K37: =_xlfn.XLOOKUP(K$7,ENT!$17:$17,ENT!$28:$28) -> 322.25831 | L37: =_xlfn.XLOOKUP(L$7,ENT!$17:$17,ENT!$28:$28) -> 442.75863 | ... P37: =_xlfn.XLOOKUP(P$7,ENT!$17:$17,ENT!$28:$28) -> 587.66523 | R37: =SUM(L37:M37)/SUM(J37:K37)-1 -> 0.14474571 | T37: =SUM(N37:O37)/SUM(L37:M37)-1 -> -0.011385251
B38: Bet365
B39: PointsBet | F39: =SUMIF(PBH!$9:$9,HY!F$7,PBH!$19:$19) -> 13.3 | G39: =SUMIF(PBH!$9:$9,HY!G$7,PBH!$19:$19) -> 15.7 | H39: =SUMIF(PBH!$9:$9,HY!H$7,PBH!$19:$19) -> 27.2 | I39: =SUMIF(PBH!$9:$9,HY!I$7,PBH!$19:$19) -> 47.9 | J39: =SUMIF(PBH!$9:$9,HY!J$7,PBH!$19:$19) -> 84.9 | K39: =SUMIF(PBH!$9:$9,HY!K$7,PBH!$19:$19) -> 81.3 | L39: =SUMIF(PBH!$9:$9,HY!L$7,PBH!$19:$19) -> 107.9 | M39: =SUMIF(PBH!$9:$9,HY!M$7,PBH!$19:$19) -> 107.5 | ... P39: =SUMIF(PBH!$9:$9,HY!P$7,PBH!$19:$19) -> 112.3 | R39: =SUM(L39:M39)/SUM(J39:K39)-1 -> 0.29602888 | T39: =SUM(N39:O39)/SUM(L39:M39)-1 -> -0.01810585
B40: BlueBet | J40: =SUMIF('BBET + BetR'!$9:$9,HY!J$7,'BBET + BetR'!$17:$17) -> 17 | K40: =SUMIF('BBET + BetR'!$9:$9,HY!K$7,'BBET + BetR'!$17:$17) -> 18.6 | L40: =SUMIF('BBET + BetR'!$9:$9,HY!L$7,'BBET + BetR'!$17:$17) -> 28.6 | M40: =SUMIF('BBET + BetR'!$9:$9,HY!M$7,'BBET + BetR'!$17:$17) -> 26 | N40: =SUMIF('BBET + BetR'!$9:$9,HY!N$7,'BBET + BetR'!$17:$17) -> 27.2 | O40: =SUMIF('BBET + BetR'!$9:$9,HY!O$7,'BBET + BetR'!$17:$17) -> 26.9 | P40: =SUMIF('BBET + BetR'!$9:$9,HY!P$7,'BBET + BetR'!$17:$17) -> 30.7 | R40: =SUM(L40:M40)/SUM(J40:K40)-1 -> 0.53370787 | T40: =SUM(N40:O40)/SUM(L40:M40)-1 -> -0.0091575092
B41: BetR | P41: =SUMIF(BETR!$10:$10,HY!P$7,BETR!$17:$17) -> 49.8
B43: Gross Profit
B44: Tabcorp - Retail
B45: Tabcorp - Digital
B46: SportsBet | D46: =_xlfn.XLOOKUP(D$7,SBET!$18:$18,SBET!$99:$99) -> 272.2761 | E46: =_xlfn.XLOOKUP(E$7,SBET!$18:$18,SBET!$99:$99) -> 221.14212 | F46: =_xlfn.XLOOKUP(F$7,SBET!$18:$18,SBET!$99:$99) -> 282.41465 | G46: =_xlfn.XLOOKUP(G$7,SBET!$18:$18,SBET!$99:$99) -> 318.69489 | H46: =_xlfn.XLOOKUP(H$7,SBET!$18:$18,SBET!$99:$99) -> 382.61723 | I46: =_xlfn.XLOOKUP(I$7,SBET!$18:$18,SBET!$99:$99) -> 450.23801 | J46: =_xlfn.XLOOKUP(J$7,SBET!$18:$18,SBET!$99:$99) -> 578.07028 | K46: =_xlfn.XLOOKUP(K$7,SBET!$18:$18,SBET!$99:$99) -> 558.10098 | ... O46: =_xlfn.XLOOKUP(O$7,SBET!$18:$18,SBET!$99:$99) -> 518.27
...

Sheet Market Size Summary
B2: Revenue
C4: FY18 | D4: FY19 | E4: FY20 | F4: FY21 | G4: FY22 | H4: FY23 | I4: FY24 | J4: FY25 | K4: FY26 | L4: FY27 | M4: FY28 | N4: FY29 | O4: FY30
B6: Digitlal Market
B7: Digital Revenue Market Share - Tabcorp per VRI | G7: 5229.3173 | H7: 4661.6327
B9: Total Market (incl Retail)
B10: Total Revenue Market Share - Tabcorp per VRI | G10: 5955.0595 | H10: 5850
B11: Australian Gambling Stats - Total Gambling | C11: 4946.739 | D11: 5030.124 | E11: 4567.098 | F11: 5815.092
C13: CY18 | D13: CY19 | E13: CY20 | F13: CY21 | G13: CY22 | H13: CY23 | I13: CY24 | J13: CY25 | K13: CY26 | L13: CY27 | M13: CY28 | N13: CY29 | O13: CY30
B15: Digitlal Market
B16: Digital Revenue Market Share - SB Investor Day | C16: 2588.1361 | D16: 4126.1212 | E16: 4936.8731
B17: Digital Revenue Market Share - SB Annual Reports | D17: 2907.4761 | E17: 4325.1301 | F17: 4747.6589 | G17: 4676.5595 | H17: 4839.9147
B18: Digital Market - SB Annual Reports | C18: 3417 | D18: 3834 | E18: 5934 | F18: 6873 | G18: 6972
B19: Responsible Wagering Australia - Apr 2023 | C19: 3348 | D19: 3608 | E19: 4584 | F19: 6033 | G19: 6585
B20: Responsible Wagering Australia - Nov 2025 | D20: 3818 | E20: 5161 | F20: 6970 | G20: 7430 | H20: 7066 | I20: 7037 | J20: 6982 | K20: 7204 | L20: 7375 | M20: 7544 | N20: 7714
B22: OffShore Betting | D22: 1465 | E22: 2082 | F22: 2413 | G22: 2682 | H22: 4052 | I22: 3893 | J22: 3929 | K22: 4209 | L22: 4467 | M22: 4729 | N22: 4997
B23: OffShore Betting & Casino | D23: 693 | E23: 911 | F23: 1090 | G23: 1086 | H23: 1359 | I23: 1237 | J23: 1228 | K23: 1294 | L23: 1351 | M23: 1407 | N23: 1463
B25: Total Market (incl Retail)
B26: Total Market - SB Annual Reports | C26: 5100 | D26: 5400 | E26: 6900 | F26: 7900 | G26: 8400
B27: Responsible Wagering Australia | C27: 5682 | D27: 5635 | E27: 6234 | F27: 7487 | G27: 7792
B29: TURNOVER
C31: FY18 | D31: FY19 | E31: FY20 | F31: FY21 | G31: FY22 | H31: FY23 | I31: FY24 | J31: FY25 | K31: FY26 | L31: FY27 | M31: FY28 | N31: FY29 | O31: FY30
B33: Digitlal Market
B34: Digital Revenue Market Share - Tabcorp | G34: 49223.35 | H34: 46102.985
B35: NT Licenced Turnover | C35: 24800 | D35: 27900 | E35: 29100 | F35: 42400 | G35: 50000
B37: Total Market (incl Retail)
B38: Racing Australia Annual Report | C38: 39318.91 | D38: 42282.33 | E38: 41693.57 | F38: 59905.07

Sheet FY - Market Shares
C2: FY18 | D2: FY19 | E2: FY20 | F2: FY21 | G2: FY22 | H2: FY23 | I2: FY24 | J2: FY25 | M2: CY18 | N2: CY19 | O2: CY20 | P2: CY21 | Q2: CY22 | R2: CY23 | S2: CY24 | T2: CY25
C3: 43281 | D3: =EOMONTH(C3,12) -> 43646 | E3: =EOMONTH(D3,12) -> 44012 | F3: =EOMONTH(E3,12) -> 44377 | G3: =EOMONTH(F3,12) -> 44742 | H3: =EOMONTH(G3,12) -> 45107 | I3: =EOMONTH(H3,12) -> 45473 | J3: =EOMONTH(I3,12) -> 45838 | M3: 43465 | N3: =EOMONTH(M3,12) -> 43830 | O3: =EOMONTH(N3,12) -> 44196 | P3: =EOMONTH(O3,12) -> 44561 | Q3: =EOMONTH(P3,12) -> 44926 | R3: =EOMONTH(Q3,12) -> 45291 | S3: =EOMONTH(R3,12) -> 45657 | T3: =EOMONTH(S3,12) -> 46022
B5: MARKET SHARE ESTIMATES - NET REVENUE
B7: Net Revenue - Tabcorp | L7: Net Revenue - Tabcorp
B8: Tabcorp - Retail - per VRI Share | G8: 698.8 | H8: 882 | L8: Tabcorp - Retail - per VRI Share | Q8: 882.6 | R8: 868.2 | S8: 918.8 | T8: 916.2
B9: Tabcorp - Digital - per VRI Share | G9: 1302.1 | H9: 1142.1 | L9: Tabcorp - Digital - per VRI Share | Q9: 1199 | R9: 1115.8 | S9: 1101.4 | T9: 1056.2
B10: Tabcorp - Retail | G10: 654 | H10: 818.4 | L10: Tabcorp - Retail | Q10: 814.8 | R10: 801.6
B11: Tabcorp - Digital | G11: 1073.5 | H11: 942.7 | L11: Tabcorp - Digital | Q11: 986.6 | R11: 923.1
B13: Market Share - reported | L13: Market Share - reported
B14: Digital Revenue Market Share - Tabcorp | G14: 0.249 | H14: 0.245 | L14: SportsBet Share - Investor Day | M14: 0.278 | N14: 0.303 | O14: 0.403
B15: Total Revenue Market Share - Tabcorp | G15: 0.336 | H15: 0.346 | L15: SportsBet Share - Annual Reports | N15: 0.43 | O15: 0.46 | P15: 0.5 | Q15: 0.48 | R15: 0.45
B17: Grossed Up Market Size | L17: Grossed Up Market Size
B18: Digital Revenue Market Share - Tabcorp per VRI | G18: =G9/G14 -> 5229.3173 | H18: =H9/H14 -> 4661.6327 | L18: Digital Revenue Market Share - SB Investor Day | M18: =M25/M14 -> 2579.4065 | N18: =N25/N14 -> 2707.9472 | O18: =O25/O14 -> 4101.8263
B19: Total Revenue Market Share - Tabcorp per VRI | G19: =SUM(G8:G9)/G15 -> 5955.0595 | H19: =SUM(H8:H9)/H15 -> 5850 | L19: Digital Revenue Market Share - SB Annual Reports | N19: =N25/N15 -> 1908.1581 | O19: =O25/O15 -> 3593.5565 | P19: =P25/P15 -> 4764.476 | Q19: =Q25/Q15 -> 4677.7354 | R19: =R25/R15 -> 4864.1311
B20: Digital Revenue Market Share - Tabcorp | G20: =G11/G14 -> 4311.245 | H20: =H11/H14 -> 3847.7551
B21: Total Revenue Market Share - Tabcorp | G21: =SUM(G10:G11)/G15 -> 5141.369 | H21: =SUM(H10:H11)/H15 -> 5089.8844 | L21: WA RETAIL? | T21: 300
B23: Digital Net Revenue | L23: Digital Net Revenue - Pre GST
B24: Tabcorp - Digital | G24: =G9 -> 1302.1 | H24: =H9 -> 1142.1 | L24: Tabcorp - Digital | Q24: =Q9 -> 1199 | R24: =R9 -> 1115.8 | S24: =S9 -> 1101.4 | T24: =T9 -> 1056.2 | V24: =S24/R24-1 -> -0.012905539 | W24: =T24/S24-1 -> -0.041038678
B25: SportsBet | C25: =SUMIF(SBET!$5:$5,C$2,SBET!$96:$96) -> 744.60128 | D25: =SUMIF(SBET!$5:$5,D$2,SBET!$96:$96) -> 925.45323 | E25: =SUMIF(SBET!$5:$5,E$2,SBET!$96:$96) -> 1508.518 | F25: =SUMIF(SBET!$5:$5,F$2,SBET!$96:$96) -> 2209.3311 | G25: =SUMIF(SBET!$5:$5,G$2,SBET!$96:$96) -> 2424.0999 | H25: =SUMIF(SBET!$5:$5,H$2,SBET!$96:$96) -> 2238.0491 | I25: =SUMIF(SBET!$5:$5,I$2,SBET!$96:$96) -> 969.78114 | L25: SportsBet | M25: ='SportsBet ASIC'!D5/1000 -> 717.075 | N25: ='SportsBet ASIC'!E5/1000 -> 820.508 | O25: ='SportsBet ASIC'!F5/1000 -> 1653.036 | P25: ='SportsBet ASIC'!G5/1000 -> 2382.238 | Q25: ='SportsBet ASIC'!H5/1000 -> 2245.313 | R25: ='SportsBet ASIC'!I5/1000 -> 2188.859 | S25: ='SportsBet ASIC'!J5/1000 -> 2114.311 | T25: ='SportsBet ASIC'!K5/1000 -> 2038.378 | V25: =S25/R25-1 -> -0.034057927 | W25: =T25/S25-1 -> -0.035913827
B26: LadBrokes | C26: =SUMIF(ENT!$5:$5,C$2,ENT!$28:$28) -> 157.12085 | D26: =SUMIF(ENT!$5:$5,D$2,ENT!$28:$28) -> 411.37912 | E26: =SUMIF(ENT!$5:$5,E$2,ENT!$28:$28) -> 556.41221 | F26: =SUMIF(ENT!$5:$5,F$2,ENT!$28:$28) -> 723.36454 | G26: =SUMIF(ENT!$5:$5,G$2,ENT!$28:$28) -> 828.06846 | H26: =SUMIF(ENT!$5:$5,H$2,ENT!$28:$28) -> 818.64069 | L26: LadBrokes | M26: ='Entain ASIC'!D15/1000 -> 323.279 | N26: ='Entain ASIC'!E15/1000 -> 461.9714 | O26: ='Entain ASIC'!F15/1000 -> 715.1353 | P26: ='Entain ASIC'!G15/1000 -> 841.8366 | Q26: ='Entain ASIC'!H15/1000 -> 915.1868 | R26: ='Entain ASIC'!I15/1000 -> 839.6883 | S26: ='Entain ASIC'!J15/1000 -> 848.9437 | T26: ='Entain ASIC'!K15/1000 -> 797.4901 | V26: =S26/R26-1 -> 0.011022423 | W26: =T26/S26-1 -> -0.060608966
B27: Bet365 | C27: =SUMIF('B365'!$5:$5,C$2,'B365'!$15:$15) -> 114.999 | D27: =SUMIF('B365'!$5:$5,D$2,'B365'!$15:$15) -> 120.914 | E27: =SUMIF('B365'!$5:$5,E$2,'B365'!$15:$15) -> 147.173 | F27: =SUMIF('B365'!$5:$5,F$2,'B365'!$15:$15) -> 190.321 | G27: =SUMIF('B365'!$5:$5,G$2,'B365'!$15:$15) -> 200.429 | H27: =SUMIF('B365'!$5:$5,H$2,'B365'!$15:$15) -> 201.286 | L27: Bet365 | M27: ='Bet365 ASIC'!E8/1000 -> 120.914 | N27: ='Bet365 ASIC'!F8/1000 -> 147.173 | O27: ='Bet365 ASIC'!G8/1000 -> 190.321 | P27: ='Bet365 ASIC'!H8/1000 -> 200.429 | Q27: ='Bet365 ASIC'!I8/1000 -> 201.286 | R27: ='Bet365 ASIC'!J8/1000 -> 261.002 | S27: ='Bet365 ASIC'!K8/1000 -> 292.645 | T27: 285
B28: PointsBet | E28: =SUMIF(PBH!$5:$5,E$2,PBH!$19:$19) -> 75.1 | F28: =SUMIF(PBH!$5:$5,F$2,PBH!$19:$19) -> 166.2 | G28: =SUMIF(PBH!$5:$5,G$2,PBH!$19:$19) -> 215.4 | H28: =SUMIF(PBH!$5:$5,H$2,PBH!$19:$19) -> 211.5 | L28: PointsBet | N28: =PBH!BG19 -> 42.9 | O28: =PBH!BH19 -> 132.8 | P28: =PBH!BI19 -> 189.2 | Q28: =PBH!BJ19 -> 212.7 | R28: =PBH!BK19 -> 218.6 | S28: =PBH!BL19 -> 238 | T28: =PBH!BM19 -> 238.6
B29: BlueBet | F29: =SUMIF('BBET + BetR'!$5:$5,F$2,'BBET + BetR'!$17:$17) -> 35.6 | G29: =SUMIF('BBET + BetR'!$5:$5,G$2,'BBET + BetR'!$17:$17) -> 54.6 | H29: =SUMIF('BBET + BetR'!$5:$5,H$2,'BBET + BetR'!$17:$17) -> 54.1 | L29: BlueBet | P29: =SUMIF('BBET + BetR'!$6:$6,P$2,'BBET + BetR'!$17:$17) -> 47.2 | Q29: =SUMIF('BBET + BetR'!$6:$6,Q$2,'BBET + BetR'!$17:$17) -> 53.2 | R29: =SUMIF('BBET + BetR'!$6:$6,R$2,'BBET + BetR'!$17:$17) -> 57.6 | S29: =SUMIF('BBET + BetR'!$6:$6,S$2,'BBET + BetR'!$17:$17) -> 33.2 | T29: 0
L30: BetR | Q30: 85 | R30: 85 | S30: 118 | T30: =SUMIF('BBET + BetR'!$6:$6,T$2,'BBET + BetR'!$30:$30) -> 153.9
L31: Dabble | Q31: 0 | R31: ='Dabble ASIC'!I14/1000000 -> 0 | S31: ='Dabble ASIC'!J14/1000000 -> 81.884418 | T31: ='Dabble ASIC'!K14/1000000 -> 146.93183
B32: Other - Balancing | G32: =G33-SUM(G24:G29) -> 204.61991 | H32: =H33-SUM(H24:H29) -> -4.0430973 | L32: Other - Balancing | Q32: 150 | R32: 150 | S32: 150 | T32: 150
B33: Digital Market | G33: =G18 -> 5229.3173 | H33: =H18 -> 4661.6327 | L33: Digital Market | O33: =O19 -> 3593.5565 | P33: =P19 -> 4764.476 | Q33: =SUM(Q24:Q32) -> 5061.6858 | R33: =SUM(R24:R32) -> 4916.5493 | S33: =SUM(S24:S32) -> 4978.3841 | T33: =SUM(T24:T32) -> 4866.4999
B35: Share | L35: Share
B36: Tabcorp - Digital | G36: =G24/G$33 -> 0.249 | H36: =H24/H$33 -> 0.245 | L36: Tabcorp | Q36: =Q24/Q$33 -> 0.2368776 | R36: =R24/R$33 -> 0.22694779 | S36: =S24/S$33 -> 0.22123644 | T36: =T24/T$33 -> 0.21703483
B37: SportsBet | G37: =G25/G$33 -> 0.46355954 | H37: =H25/H$33 -> 0.48009983 | L37: SportsBet | O37: =O25/O$33 -> 0.46 | P37: =P25/P$33 -> 0.5 | Q37: =Q25/Q$33 -> 0.44358996 | R37: =R25/R$33 -> 0.44520229 | S37: =S25/S$33 -> 0.42469825 | T37: =T25/T$33 -> 0.41885915
B38: LadBrokes | G38: =G26/G$33 -> 0.15835116 | H38: =H26/H$33 -> 0.17561244 | L38: LadBrokes | O38: =O26/O$33 -> 0.19900488 | P38: =P26/P$33 -> 0.17669028 | Q38: =Q26/Q$33 -> 0.18080672 | R38: =R26/R$33 -> 0.17078814 | S38: =S26/S$33 -> 0.17052595 | T38: =T26/T$33 -> 0.16387344
B39: Bet365 | G39: =G27/G$33 -> 0.038327948 | H39: =H27/H$33 -> 0.043179293 | L39: Bet365 | O39: =O27/O$33 -> 0.052961738 | P39: =P27/P$33 -> 0.042067375 | Q39: =Q27/Q$33 -> 0.039766593 | R39: =R27/R$33 -> 0.05308642 | S39: =S27/S$33 -> 0.05878313 | T39: =T27/T$33 -> 0.05856365
B40: PointsBet | G40: =G28/G$33 -> 0.041190846 | H40: =H28/H$33 -> 0.04537037 | L40: PointsBet | O40: =O28/O$33 -> 0.036955033 | P40: =P28/P$33 -> 0.039710558 | Q40: =Q28/Q$33 -> 0.042021573 | R40: =R28/R$33 -> 0.044462078 | S40: =S28/S$33 -> 0.047806677 | T40: =T28/T$33 -> 0.049029077
B41: BlueBet | G41: =G29/G$33 -> 0.010441134 | H41: =H29/H$33 -> 0.011605376 | L41: BlueBet | P41: =P29/P$33 -> 0.0099066508 | Q41: =Q29/Q$33 -> 0.010510332 | R41: =R29/R$33 -> 0.011715534 | S41: =S29/S$33 -> 0.0066688305 | T41: =T29/T$33 -> 0
B42: Other - Balancing | G42: =G32/G$33 -> 0.039129375 | H42: =H32/H$33 -> -0.00086731357 | L42: BetR | P42: =P30/P$33 -> 0 | Q42: =Q30/Q$33 -> 0.016792824 | R42: =R30/R$33 -> 0.017288548 | S42: =S30/S$33 -> 0.02370247 | T42: =T30/T$33 -> 0.031624371
L43: Dabble | P43: =P31/P$33 -> 0 | Q43: =Q31/Q$33 -> 0 | R43: =R31/R$33 -> 0 | S43: =S31/S$33 -> 0.016447991 | T43: =T31/T$33 -> 0.030192505
B44: Total Net Revenue (ex WA retail) | L44: Other | T44: =T32/T$33 -> 0.030822974
B45: Tabcorp - Total | G45: =G8+G9 -> 2000.9 | H45: =H8+H9 -> 2024.1
B46: SportsBet | C46: =SUMIF(SBET!$5:$5,C$2,SBET!$96:$96) -> 744.60128 | D46: =SUMIF(SBET!$5:$5,D$2,SBET!$96:$96) -> 925.45323 | E46: =SUMIF(SBET!$5:$5,E$2,SBET!$96:$96) -> 1508.518 | F46: =SUMIF(SBET!$5:$5,F$2,SBET!$96:$96) -> 2209.3311 | G46: =SUMIF(SBET!$5:$5,G$2,SBET!$96:$96) -> 2424.0999 | H46: =SUMIF(SBET!$5:$5,H$2,SBET!$96:$96) -> 2238.0491
B47: LadBrokes | C47: =SUMIF(ENT!$5:$5,C$2,ENT!$28:$28) -> 157.12085 | D47: =SUMIF(ENT!$5:$5,D$2,ENT!$28:$28) -> 411.37912 | E47: =SUMIF(ENT!$5:$5,E$2,ENT!$28:$28) -> 556.41221 | F47: =SUMIF(ENT!$5:$5,F$2,ENT!$28:$28) -> 723.36454 | G47: =SUMIF(ENT!$5:$5,G$2,ENT!$28:$28) -> 828.06846 | H47: =SUMIF(ENT!$5:$5,H$2,ENT!$28:$28) -> 818.64069
...

Sheet MS
D3: CY18 | E3: CY19 | F3: CY20 | G3: CY21 | H3: CY22 | I3: CY23 | J3: CY24 | K3: CY25
C4: Tabcorp | H4: 0.25632061 | I4: 0.23408968 | J4: 0.22810944 | K4: 0.21703483
C5: SportsBet | F5: 0.46 | G5: 0.5 | H5: 0.48 | I5: 0.4592125 | J5: 0.43789205 | K5: 0.41885915
C6: LadBrokes | F6: 0.19900488 | G6: 0.17669028 | H6: 0.19564741 | I6: 0.17616272 | J6: 0.17582356 | K6: 0.16387344
C7: Bet365 | F7: 0.052961738 | G7: 0.042067375 | H7: 0.043030651 | I7: 0.054757013 | J7: 0.060609304 | K7: 0.05856365
C8: PointsBet | F8: 0.036955033 | G8: 0.039710558 | H8: 0.045470721 | I8: 0.045861269 | J8: 0.049291853 | K8: 0.049029077
C9: BlueBet | G9: 0.0099066508 | H9: 0.011373025 | I9: 0.012084214 | J9: 0.0068760064 | K9: 0
C10: BetR | G10: 0 | H10: 0 | I10: 0.017832607 | J10: 0.024438818 | K10: 0.031624371
C11: Dabble | G11: 0 | H11: 0 | I11: 0 | J11: 0.016958969 | K11: 0.030192505
C12: Other | K12: 0.030822974
C17: Other | D17: 0.030192505
C18: Dabble | D18: 0.030192505
C19: betr | D19: 0.031624371
C20: PointsBet | D20: 0.049029077
C21: bet365 | D21: 0.05856365
C22: Entain | D22: 0.16387344
C23: Tabcorp | D23: 0.21703483
C24: Sportsbet | D24: 0.41885915
H38: ~

Sheet SBET QTR
AN2: X
D3: =IF(MONTH(D13)>6,RIGHT(YEAR(D13),2)+1,RIGHT(YEAR(D13),2)) -> 17 | E3: =IF(MONTH(E13)>6,RIGHT(YEAR(E13),2)+1,RIGHT(YEAR(E13),2)) -> 18 | F3: =IF(MONTH(F13)>6,RIGHT(YEAR(F13),2)+1,RIGHT(YEAR(F13),2)) -> 18 | G3: =IF(MONTH(G13)>6,RIGHT(YEAR(G13),2)+1,RIGHT(YEAR(G13),2)) -> 18 | H3: =IF(MONTH(H13)>6,RIGHT(YEAR(H13),2)+1,RIGHT(YEAR(H13),2)) -> 18 | I3: =IF(MONTH(I13)>6,RIGHT(YEAR(I13),2)+1,RIGHT(YEAR(I13),2)) -> 19 | J3: =IF(MONTH(J13)>6,RIGHT(YEAR(J13),2)+1,RIGHT(YEAR(J13),2)) -> 19 | K3: =IF(MONTH(K13)>6,RIGHT(YEAR(K13),2)+1,RIGHT(YEAR(K13),2)) -> 19 | ... AN3: =IF(MONTH(AN13)>6,RIGHT(YEAR(AN13),2)+1,RIGHT(YEAR(AN13),2)) -> 26
D4: =RIGHT(YEAR(D$13),2) -> 17 | E4: =RIGHT(YEAR(E$13),2) -> 17 | F4: =RIGHT(YEAR(F$13),2) -> 17 | G4: =RIGHT(YEAR(G$13),2) -> 18 | H4: =RIGHT(YEAR(H$13),2) -> 18 | I4: =RIGHT(YEAR(I$13),2) -> 18 | J4: =RIGHT(YEAR(J$13),2) -> 18 | K4: =RIGHT(YEAR(K$13),2) -> 19 | ... AN4: =RIGHT(YEAR(AN$13),2) -> 26
D5: ="FY"&TEXT(D$3,"00") -> FY17 | E5: ="FY"&TEXT(E$3,"00") -> FY18 | F5: ="FY"&TEXT(F$3,"00") -> FY18 | G5: ="FY"&TEXT(G$3,"00") -> FY18 | H5: ="FY"&TEXT(H$3,"00") -> FY18 | I5: ="FY"&TEXT(I$3,"00") -> FY19 | J5: ="FY"&TEXT(J$3,"00") -> FY19 | K5: ="FY"&TEXT(K$3,"00") -> FY19 | ... AN5: ="FY"&TEXT(AN$3,"00") -> FY26
D6: ="CY"&TEXT(D$4,"00") -> CY17 | E6: ="CY"&TEXT(E$4,"00") -> CY17 | F6: ="CY"&TEXT(F$4,"00") -> CY17 | G6: ="CY"&TEXT(G$4,"00") -> CY18 | H6: ="CY"&TEXT(H$4,"00") -> CY18 | I6: ="CY"&TEXT(I$4,"00") -> CY18 | J6: ="CY"&TEXT(J$4,"00") -> CY18 | K6: ="CY"&TEXT(K$4,"00") -> CY19 | ... AN6: ="CY"&TEXT(AN$4,"00") -> CY26
D7: =D13-EOMONTH(D13,-3) -> 91 | E7: =E13-EOMONTH(E13,-3) -> 92 | F7: =F13-EOMONTH(F13,-3) -> 92 | G7: =G13-EOMONTH(G13,-3) -> 90 | H7: =H13-EOMONTH(H13,-3) -> 91 | I7: =I13-EOMONTH(I13,-3) -> 92 | J7: =J13-EOMONTH(J13,-3) -> 92 | K7: =K13-EOMONTH(K13,-3) -> 90 | ... AN7: =AN13-EOMONTH(AN13,-3) -> 91
B9: SPORTSBET FY | D9: ="FY"&D4 -> FY17 | E9: ="FY"&E4 -> FY17 | F9: ="FY"&F4 -> FY17 | G9: ="FY"&G4 -> FY18 | H9: ="FY"&H4 -> FY18 | I9: ="FY"&I4 -> FY18 | J9: ="FY"&J4 -> FY18 | K9: ="FY"&K4 -> FY19 | ... AN9: ="FY"&AN4 -> FY26
E11: 1H18 | F11: 1H18 | G11: 2H18 | H11: 2H18 | I11: 1H19 | J11: 1H19 | K11: 2H19 | L11: 2H19 | M11: 1H20 | N11: 1H20 | O11: 2H20 | P11: 2H20 | Q11: 1H21 | R11: 1H21 | S11: 2H21 | T11: 2H21 | U11: 1H22 | V11: 1H22 | W11: 2H22 | X11: 2H22 | Y11: 1H23 | Z11: 1H23 | AA11: 2H23 | AB11: 2H23 | AC11: 1H24 | AD11: 1H24 | AE11: 2H24 | AF11: 2H24 | AG11: 1H25 | AH11: 1H25 | AI11: 2H25 | AJ11: 2H25 | AK11: 1H26 | AL11: 1H26 | AM11: 2H26 | AN11: 2H26
C12: Units | D12: 4Q17 | E12: 1Q18 | F12: 2Q18 | G12: 3Q18 | H12: 4Q18 | I12: 1Q19 | J12: 2Q19 | K12: 3Q19 | L12: 4Q19 | M12: 1Q20 | N12: 2Q20 | O12: 3Q20 | P12: 4Q20 | Q12: 1Q21 | R12: 2Q21 | S12: 3Q21 | T12: 4Q21 | U12: 1Q22 | V12: 2Q22 | W12: 3Q22 | X12: 4Q22 | Y12: 1Q23 | Z12: 2Q23 | AA12: 3Q23 | AB12: 4Q23 | AC12: 1Q24 | AD12: 2Q24 | AE12: 3Q24 | AF12: 4Q24 | AG12: 1Q25 | AH12: 2Q25 | AI12: 3Q25 | AJ12: 4Q25 | AK12: 1Q26 | AL12: 2Q26 | AM12: 3Q26 | AN12: 4Q26
D13: 42916 | E13: =EOMONTH( D13, 3) -> 43008 | F13: =EOMONTH( E13, 3) -> 43100 | G13: =EOMONTH( F13, 3) -> 43190 | H13: =EOMONTH( G13, 3) -> 43281 | I13: =EOMONTH( H13, 3) -> 43373 | J13: =EOMONTH( I13, 3) -> 43465 | K13: =EOMONTH( J13, 3) -> 43555 | L13: =EOMONTH( K13, 3) -> 43646 | ... AN13: =EOMONTH( AM13, 3) -> 46203
B15: US | AM15: FY24 (june)
B16: Turnover | C16: US$m | S16: 3379.2051 | T16: 3561.3984 | U16: 4581.0703 | V16: 4562.7286 | W16: 3386.8935 | X16: 3377.2182 | Y16: 3376.7265 | Z16: 3766.7405 | AA16: 3142.8397 | AB16: 2959.4014 | AC16: 2927.6763 | AD16: 3021 | AE16: 2546.2987 | AF16: 2726 | AG16: 2684 | AH16: 2857 | AK16: =AG16*(1+AK17) -> 2549.8 | AM16: =SUM(AC16:AF16) -> 11220.975
B17: Growth | C17: % | AK17: -0.05
B19: Net Revenue | C19: US$m | S19: 384.78953 | T19: 428.97687 | U19: 513.39045 | V19: 454.57203 | W19: 390.05293 | X19: 404.45265 | Y19: 373.8983 | Z19: 389.23181 | AA19: 350.50448 | AB19: 389.47452 | AC19: 331.83749 | AD19: 375 | AE19: 328.83894 | AF19: 349 | AG19: 371 | AH19: 346 | AI19: =AE19*(1+AI21) -> 269.64793 | AM19: =SUM(AC19:AF19) -> 1384.6764
B20: Net Margin | C20: % | S20: 0.11386984 | T20: 0.12045181 | U20: 0.1120678 | V20: 0.099627235 | W20: 0.1151654 | X20: 0.11975911 | Y20: 0.11072804 | Z20: 0.10333385 | AA20: 0.11152477 | AB20: 0.13160585 | AC20: 0.11334501 | AD20: 0.12431417 | AE20: 0.1291439 | AF20: 0.128 | AG20: 0.138 | AH20: 0.121
B21: Growth | C21: % | AI21: -0.18
B24: Adjusted EBITDA | C24: US$m | S24: 148.73192 | T24: 131.08437 | U24: 185.05653 | V24: 140.2235 | W24: 141.00243 | X24: 143.76083 | Y24: 98.6097 | Z24: 101.70612 | AA24: 84.976508 | AB24: 107.59599 | AC24: 63.002567 | AD24: 100 | AE24: 82.602199 | AF24: 74 | AG24: 72 | AH24: 66
B25: Margin | C25: US$m | S25: =S24/S19 -> 0.38652798 | T25: =T24/T19 -> 0.30557446 | U25: =U24/U19 -> 0.36045962 | V25: =V24/V19 -> 0.30847366 | W25: =W24/W19 -> 0.36149562 | X25: =X24/X19 -> 0.35544538 | Y25: =Y24/Y19 -> 0.26373402 | Z25: =Z24/Z19 -> 0.26129961 | ... AH25: =AH24/AH19 -> 0.19075145
W26: =W24/S24-1 -> -0.0519693 | X26: =X24/T24-1 -> 0.096704534 | Y26: =Y24/U24-1 -> -0.46713741 | Z26: =Z24/V24-1 -> -0.27468562 | AA26: =AA24/W24-1 -> -0.3973401 | AB26: =AB24/X24-1 -> -0.25156252 | AC26: =AC24/Y24-1 -> -0.36109158 | AD26: =AD24/Z24-1 -> -0.016775004 | ... AH26: =AH24/AD24-1 -> -0.34
B27: Other
B28: Cost of sales | S28: 177.11938 | T28: 202.11462 | U28: 235.27885 | V28: 240.03077 | W28: 184.24373 | X28: 185.26411 | Y28: 189.06075 | Z28: 195.34253 | AA28: 186.73942 | AB28: 198.03909 | AC28: 181.96593 | AD28: 197 | AE28: 173.72262 | AF28: 192 | AG28: 207 | AH28: 190
B29: Technology, research and development expenses | S29: 7.3864106 | T29: 8.4393985 | U29: 6.5744555 | V29: 8.6009782 | W29: 6.3170277 | X29: 8.2596997 | Y29: 6.7157571 | Z29: 6.9343037 | AA29: 9.7940145 | AB29: 6.2655882 | AC29: 9.9015001 | AD29: 6 | AE29: 8.7680674 | AF29: 9 | AG29: 8 | AH29: 8
B30: Sales & marketing expenses | S30: 41.294453 | T30: 68.559888 | U30: 65.453073 | V30: 56.521443 | W30: 46.312131 | X30: 53.674191 | Y30: 62.552075 | Z30: 66.334489 | AA30: 52.495681 | AB30: 56.614528 | AC30: 58.332554 | AD30: 58 | AE30: 46.908244 | AF30: 56 | AG30: 60 | AH30: 60
B31: General and administrative expenses | S31: 10.257372 | T31: 18.778597 | U31: 21.027545 | V31: 9.1953434 | W31: 12.177611 | X31: 13.493821 | Y31: 16.960017 | Z31: 18.914364 | AA31: 16.498849 | AB31: 20.959324 | AC31: 18.634935 | AD31: 14 | AE31: 16.837813 | AF31: 18 | AG31: 24 | AH31: 21
B33: Check | S33: =S19-SUM(S28:S31)-S24 -> 0 | T33: =T19-SUM(T28:T31)-T24 -> 0 | U33: =U19-SUM(U28:U31)-U24 -> 0 | V33: =V19-SUM(V28:V31)-V24 -> 0 | W33: =W19-SUM(W28:W31)-W24 -> 0 | X33: =X19-SUM(X28:X31)-X24 -> 0 | Y33: =Y19-SUM(Y28:Y31)-Y24 -> 0 | Z33: =Z19-SUM(Z28:Z31)-Z24 -> 0 | ... AH33: =AH19-SUM(AH28:AH31)-AH24 -> 1
B35: Average Monthly Players | S35: 830.616 | T35: 982.084 | U35: 1086 | V35: 1133 | W35: 914.57833 | X35: 1072.2427 | Y35: 1100.187 | Z35: 1274.6497 | AA35: 992.86633 | AB35: 1139.0143 | AC35: 1123.9953 | AD35: 1189.3203 | AE35: 990.56833 | AF35: 1199 | AG35: 1197 | AH35: 1275
S37: =S28/S16 -> 0.05241451 | T37: =T28/T16 -> 0.056751476 | U37: =U28/U16 -> 0.051358927 | V37: =V28/V16 -> 0.052606848 | W37: =W28/W16 -> 0.054399034 | X37: =X28/X16 -> 0.054857016 | Y37: =Y28/Y16 -> 0.055989357 | Z37: =Z28/Z16 -> 0.051859832 | ... AH37: =AH28/AH16 -> 0.066503325
S38: =S28/S19 -> 0.46030196 | T38: =T28/T19 -> 0.47115504 | U38: =U28/U19 -> 0.45828444 | V38: =V28/V19 -> 0.52803682 | W38: =W28/W19 -> 0.47235572 | X38: =X28/X19 -> 0.45806131 | Y38: =Y28/Y19 -> 0.50564752 | Z38: =Z28/Z19 -> 0.50186682 | ... AH38: =AH28/AH19 -> 0.54913295
S40: =S30/S16 -> 0.012220168 | T40: =T30/T16 -> 0.019250834 | U40: =U30/U16 -> 0.014287725 | V40: =V30/V16 -> 0.012387641 | W40: =W30/W16 -> 0.013673926 | X40: =X30/X16 -> 0.015893018 | Y40: =Y30/Y16 -> 0.018524472 | Z40: =Z30/Z16 -> 0.017610581 | ... AH40: =AH30/AH16 -> 0.02100105
S41: =S30/S19 -> 0.10731699 | T41: =T30/T19 -> 0.15982187 | U41: =U30/U19 -> 0.1274918 | V41: =V30/V19 -> 0.1243399 | W41: =W30/W19 -> 0.11873294 | X41: =X30/X19 -> 0.13270822 | Y41: =Y30/Y19 -> 0.16729703 | Z41: =Z30/Z19 -> 0.17042412 | ... AH41: =AH30/AH19 -> 0.1734104
S42: =S30/S24 -> 0.27764351 | T42: =T30/T24 -> 0.52302105 | U42: =U30/U24 -> 0.35369232 | V42: =V30/V24 -> 0.4030811 | W42: =W30/W24 -> 0.32844918 | X42: =X30/X24 -> 0.37335755 | Y42: =Y30/Y24 -> 0.63433998 | Z42: =Z30/Z24 -> 0.65221728 | ... AH42: =AH30/AH24 -> 0.90909091
B45: UK | AG45: =AG37/S37-1 -> 0.47141882 | AH45: =AH37/T37-1 -> 0.17183428
B46: Turnover | C46: £m | O46: 1545 | P46: =3723-O46 -> 2178 | Q46: 3003 | R46: =9713-SUM(O46:Q46) -> 2987 | S46: 2451 | T46: =5000-S46 -> 2549 | U46: 3323 | V46: =11702-SUM(S46:U46) -> 3379 | W46: =W48/W49 -> 2530.4348 | X46: =5209-W46 -> 2678.5652 | Y46: =Y48/Y49 -> 2873.8739 | Z46: =11296-SUM(W46:Y46) -> 3213.1261 | AA46: =AA48/AA49 -> 2580.3571 | AB46: =4953-AA46 -> 2372.6429 | AC46: =AC48/AC49 -> 2318.5841 | AD46: =12051/(1447/1167)-SUM(AA46:AC46) -> 2447.5016
B48: Net Revenue | C48: £m | O48: 161 | P48: =435-O48 -> 274 | Q48: 320 | R48: =1075-SUM(O48:Q48) -> 320 | S48: 279 | T48: =585-S48 -> 306 | U48: 370 | V48: =1294-SUM(S48:U48) -> 339 | W48: 291 | X48: =612-W48 -> 321 | Y48: 319 | Z48: 332 | AA48: 289 | AB48: =601-AA48 -> 312 | AC48: 262 | AD48: 304
B49: Net Margin | C49: % | O49: 0.104 | P49: =P48/P46 -> 0.12580349 | Q49: 0.107 | R49: =R48/R46 -> 0.1071309 | S49: 0.114 | T49: =T48/T46 -> 0.12004708 | U49: 0.111 | V49: =V48/V46 -> 0.10032554 | W49: 0.115 | X49: =X48/X46 -> 0.11984028 | Y49: 0.111 | Z49: =Z48/Z46 -> 0.10332616 | AA49: 0.112 | AB49: =AB48/AB46 -> 0.13149893 | AC49: 0.113 | AD49: =AD48/AD46 -> 0.12420829
B51: FX
B52: AUD/GBP | C52: X
B53: AUD/USD | C53: X | O53: 0.51400769 | P53: 0.52988462 | Q53: 0.55365303 | R53: 0.55347879 | S53: 0.56027656 | T53: 0.55070769 | U53: 0.53319394 | V53: 0.54052879 | W53: 0.5405125 | X53: 0.56850769 | Y53: 0.58086212 | Z53: 0.55979385 | AA53: 0.56243692 | AB53: 0.53351692 | AC53: 0.51697231 | AD53: 0.52443692 | AE53: 0.51863385 | AF53: 0.52217121 | AG53: 0.5151303 | AH53: 0.50898485
G54: 0.78601577 | H54: 0.75657031 | I54: 0.73147023 | J54: 0.71691333 | K54: 0.71251328 | L54: 0.70020331 | M54: 0.68542265 | N54: 0.68374765 | O54: 0.65818446 | P54: 0.65791254 | Q54: 0.71519015 | R54: 0.73181273 | S54: 0.77268578 | T54: 0.76989738 | U54: 0.73472795 | V54: 0.72868886 | W54: 0.72444102 | X54: 0.714331 | Y54: 0.68321447 | Z54: 0.65743908 | AA54: 0.68357662 | AB54: 0.66801823 | AC54: 0.65461731 | AD54: 0.65131792 | AE54: 0.65772877 | AF54: 0.65907154 | AG54: 0.66981197 | AH54: 0.65235833 | AI54: 0.62766781 | AJ54: 0.64098477 | AK54: 0.65418364 | AL54: 0.65667879 | AM54: 0.69517305
B55: AUS
...

Sheet SBET
D3: =IF(MONTH(D11)>6,RIGHT(YEAR(D11),2)+1,RIGHT(YEAR(D11),2)) -> 17 | E3: =IF(MONTH(E11)>6,RIGHT(YEAR(E11),2)+1,RIGHT(YEAR(E11),2)) -> 18 | F3: =IF(MONTH(F11)>6,RIGHT(YEAR(F11),2)+1,RIGHT(YEAR(F11),2)) -> 18 | G3: =IF(MONTH(G11)>6,RIGHT(YEAR(G11),2)+1,RIGHT(YEAR(G11),2)) -> 19 | H3: =IF(MONTH(H11)>6,RIGHT(YEAR(H11),2)+1,RIGHT(YEAR(H11),2)) -> 19 | I3: =IF(MONTH(I11)>6,RIGHT(YEAR(I11),2)+1,RIGHT(YEAR(I11),2)) -> 20 | J3: =IF(MONTH(J11)>6,RIGHT(YEAR(J11),2)+1,RIGHT(YEAR(J11),2)) -> 20 | K3: =IF(MONTH(K11)>6,RIGHT(YEAR(K11),2)+1,RIGHT(YEAR(K11),2)) -> 21 | ... U3: =IF(MONTH(U11)>6,RIGHT(YEAR(U11),2)+1,RIGHT(YEAR(U11),2)) -> 26
D4: =RIGHT(YEAR(D$11),2) -> 17 | E4: =RIGHT(YEAR(E$11),2) -> 17 | F4: =RIGHT(YEAR(F$11),2) -> 18 | G4: =RIGHT(YEAR(G$11),2) -> 18 | H4: =RIGHT(YEAR(H$11),2) -> 19 | I4: =RIGHT(YEAR(I$11),2) -> 19 | J4: =RIGHT(YEAR(J$11),2) -> 20 | K4: =RIGHT(YEAR(K$11),2) -> 20 | ... U4: =RIGHT(YEAR(U$11),2) -> 25
D5: ="FY"&TEXT(D$3,"00") -> FY17 | E5: ="FY"&TEXT(E$3,"00") -> FY18 | F5: ="FY"&TEXT(F$3,"00") -> FY18 | G5: ="FY"&TEXT(G$3,"00") -> FY19 | H5: ="FY"&TEXT(H$3,"00") -> FY19 | I5: ="FY"&TEXT(I$3,"00") -> FY20 | J5: ="FY"&TEXT(J$3,"00") -> FY20 | K5: ="FY"&TEXT(K$3,"00") -> FY21 | ... U5: ="FY"&TEXT(U$3,"00") -> FY26
D6: ="CY"&TEXT(D$4,"00") -> CY17 | E6: ="CY"&TEXT(E$4,"00") -> CY17 | F6: ="CY"&TEXT(F$4,"00") -> CY18 | G6: ="CY"&TEXT(G$4,"00") -> CY18 | H6: ="CY"&TEXT(H$4,"00") -> CY19 | I6: ="CY"&TEXT(I$4,"00") -> CY19 | J6: ="CY"&TEXT(J$4,"00") -> CY20 | K6: ="CY"&TEXT(K$4,"00") -> CY20 | ... U6: ="CY"&TEXT(U$4,"00") -> CY25
D7: =D11-EOMONTH(D11,-6) -> 181 | E7: =E11-EOMONTH(E11,-6) -> 184 | F7: =F11-EOMONTH(F11,-6) -> 181 | G7: =G11-EOMONTH(G11,-6) -> 184 | H7: =H11-EOMONTH(H11,-6) -> 181 | I7: =I11-EOMONTH(I11,-6) -> 184 | J7: =J11-EOMONTH(J11,-6) -> 182 | K7: =K11-EOMONTH(K11,-6) -> 184 | ... U7: =U11-EOMONTH(U11,-6) -> 184
W8: https://www.flutter.com/media/entjjnsy/ppb-r-n-a-2017-180327.pdf | X8: https://www.flutter.com/media/ebldbz5p/annual-report-and-accounts-2018.pdf | Y8: https://www.flutter.com/media/jtzac4uu/2019-annual-report-28-02-20.pdf | Z8: https://www.flutter.com/media/3akfm0gk/annual-report-and-accounts-2020-1.pdf | AA8: https://www.flutter.com/media/dvvn0ith/flutter-entertainment-plc-annual-report-2021.pdf | AB8: https://www.flutter.com/media/pzuc0n0y/flutter-entertainment-plc-annual-report-accounts-2022.pdf | AC8: https://www.flutter.com/media/a0rj0ng5/flutter-entertainment-plc-annual-report-and-accounts-2023-10-k_updated.pdf
Z9: ID | AA9: https://www.flutter.com/media/otjhgrgn/sb-investor-day-presentation.pdf
G10: Pre BetEasy/BetFair | H10: Pro Forma | X10: Pre BetEasy/BetFair | Y10: Pro Forma
B11: Add SB Quarterly | D11: 42916 | E11: =EOMONTH(D11,6) -> 43100 | F11: =EOMONTH(E11,6) -> 43281 | G11: =EOMONTH(F11,6) -> 43465 | H11: =EOMONTH(G11,6) -> 43646 | I11: =EOMONTH(H11,6) -> 43830 | J11: =EOMONTH(I11,6) -> 44012 | K11: =EOMONTH(J11,6) -> 44196 | L11: =EOMONTH(K11,6) -> 44377 | ... U11: =EOMONTH(T11,6) -> 46022 | W11: 43100 | X11: =EOMONTH(W11,12) -> 43465 | Y11: =EOMONTH(X11,12) -> 43830 | Z11: =EOMONTH(Y11,12) -> 44196 | AA11: =EOMONTH(Z11,12) -> 44561 | AB11: =EOMONTH(AA11,12) -> 44926 | AC11: =EOMONTH(AB11,12) -> 45291 | AD11: =EOMONTH(AC11,12) -> 45657 | AE11: =EOMONTH(AD11,12) -> 46022
W12: CY17 | X12: CY18 | Y12: CY19 | Z12: CY20 | AA12: CY21 | AB12: CY22 | AC12: CY23 | AD12: CY24 | AE12: CY25
B14: FLUTTER HALFS | D14: 1H | E14: 2H | F14: 1H | G14: 2H | H14: 1H | I14: 2H | J14: 1H | K14: 2H | L14: 1H | M14: 2H | N14: 1H | O14: 2H | P14: 1H | Q14: 2H | R14: 1H | S14: 2H | T14: 1H | U14: 2H | W14: FY | X14: FY | Y14: FY | Z14: FY | AA14: FY | AB14: FY | AC14: FY | AD14: FY | AE14: FY
D15: 2017 | E15: 2017 | F15: 2018 | G15: 2018 | H15: 2019 | I15: 2019 | J15: 2020 | K15: 2020 | L15: 2021 | M15: 2021 | N15: 2022 | O15: 2022 | P15: 2023 | Q15: 2023 | R15: 2024 | S15: 2024 | T15: 2025 | U15: 2025 | W15: 2017 | X15: 2018 | Y15: 2019 | Z15: 2020 | AA15: 2021 | AB15: 2022 | AC15: 2023 | AD15: 2024 | AE15: 2025
B17: TABCORP HALFS
D18: =E14&RIGHT(E$15,2) -> 2H17 | E18: =F14&RIGHT(F$15,2) -> 1H18 | F18: =G14&RIGHT(G$15,2) -> 2H18 | G18: =H14&RIGHT(H$15,2) -> 1H19 | H18: =I14&RIGHT(I$15,2) -> 2H19 | I18: =J14&RIGHT(J$15,2) -> 1H20 | J18: =K14&RIGHT(K$15,2) -> 2H20 | K18: =L14&RIGHT(L$15,2) -> 1H21 | ... Q18: =R14&RIGHT(R$15,2) -> 1H24
B20: Headcount | AC20: 1129 | AD20: 1323 | AE20: 1164
B22: Market Share - SB Investor Day | K22: 0.426 | W22: 0.224 | X22: 0.278 | Y22: 0.303 | Z22: 0.403
B23: Market Share - Annual Reports | Y23: 0.43 | Z23: 0.46 | AA23: 0.5 | AB23: 0.48 | AC23: 0.45
B24: Market Share - Annual Reports pre Bet Easy | W24: 0.25 | X24: 0.26 | Y24: 0.27
B26: Sportsbook stakes | C26: US$m | AA26: 16084 | AB26: 13908 | AC26: 12050.556 | AD26: 10813 | AG26: -52m rev, -62m EBITDA
B27: Sportsbook net revenue margin | C27: % | AA27: 0.111 | AB27: 0.112 | AC27: 0.12010439 | AD27: 0.129
B28: Total revenue | C28: US$m | AA28: 1782 | AB28: 1558 | AC28: 1447 | AD28: 1397 | AE28: 1315
B29: Adjusted EBITDA | C29: US$m | AA29: 599 | AB29: 477 | AC29: 348 | AD29: 295 | AE29: =AD29-62 -> 233
B30: Adjusted EBITDA margin | C30: % | AA30: 0.33961189 | AB30: 0.31142011 | AC30: 0.247 | AD30: 0.211 | AE30: 0.211
B32: Sportsbook stakes | C32: £m | D32: 1935 | E32: =W32-D32 -> 1773 | F32: 2114 | G32: =X32-F32 -> 2194 | H32: 3312 | I32: =Y32-H32 -> 3439 | J32: 3723 | K32: =Z32-J32 -> 5990 | L32: 5000 | M32: =AA32-L32 -> 6702 | N32: 5209 | O32: =AB32-N32 -> 6087 | P32: 4953 | W32: 3708 | X32: 4308 | Y32: 6751 | Z32: 9713 | AA32: 11702 | AB32: 11296
B33: Sportsbook net revenue margin | C33: % | D33: 0.094 | E33: =E34/E32 -> 0.12521151 | F33: 0.098 | G33: =G34/G32 -> 0.089334549 | H33: 0.095 | I33: =I34/I32 -> 0.10671707 | J33: 0.117 | K33: =K34/K32 -> 0.10684474 | L33: 0.117 | M33: =M34/M32 -> 0.10578932 | N33: 0.118 | O33: =O34/O32 -> 0.10694924 | P33: 0.121 | W33: 0.109 | X33: 0.094 | Y33: 0.101 | Z33: 0.111 | AA33: 0.111 | AB33: 0.112
B34: Total revenue | C34: £m | D34: 182 | E34: =W34-D34 -> 222 | F34: 207 | G34: =X34-F34 -> 196 | H34: 314 | I34: =Y34-H34 -> 367 | J34: 435 | K34: =Z34-J34 -> 640 | L34: 585 | M34: =AA34-L34 -> 709 | N34: 612 | O34: =AB34-N34 -> 651 | P34: 601 | W34: 404 | X34: 403 | Y34: 681 | Z34: 1075 | AA34: 1294 | AB34: 1263
B35: Cost of sales | C35: £m | D35: -51 | E35: =W35-D35 -> -60 | F35: -83 | G35: =X35-F35 -> -38 | H35: -140 | I35: =Y35-H35 -> -159 | J35: -200 | K35: =Z35-J35 -> -320 | L35: -275 | M35: =AA35-L35 -> -361 | N35: -290 | O35: =AB35-N35 -> -345 | P35: -317 | W35: -111 | X35: -121 | Y35: -299 | Z35: -520 | AA35: -636 | AB35: -635
B36: Cost of sales as a % of net revenue | C36: % | D36: =-D35/D34 -> 0.28021978 | E36: =-E35/E34 -> 0.27027027 | F36: =-F35/F34 -> 0.40096618 | G36: =-G35/G34 -> 0.19387755 | H36: 0.445 | I36: =-I35/I34 -> 0.43324251 | J36: 0.459 | K36: =-K35/K34 -> 0.5 | L36: 0.47 | M36: =-M35/M34 -> 0.50916784 | N36: 0.473 | O36: =-O35/O34 -> 0.52995392 | P36: 0.528 | W36: =-W35/W34 -> 0.27475248 | X36: 0.301 | Y36: 0.439 | Z36: 0.484 | AA36: 0.492 | AB36: 0.503
B37: Gross profit | C37: £m | D37: 131 | E37: =W37-D37 -> 161 | F37: 124 | G37: =X37-F37 -> 158 | H37: 174 | I37: =Y37-H37 -> 208 | J37: 235 | K37: =Z37-J37 -> 320 | L37: 310 | M37: =AA37-L37 -> 348 | N37: 322 | O37: =AB37-N37 -> 306 | P37: 284 | W37: 292 | X37: 282 | Y37: 382 | Z37: 555 | AA37: 658 | AB37: 628
B38: Sales and marketing | C38: £m | D38: -40 | E38: =W38-D38 -> -42 | F38: -34 | G38: =X38-F38 -> -48 | H38: -56 | I38: =Y38-H38 -> -68 | J38: -59 | K38: =Z38-J38 -> -70 | L38: -59 | M38: =AA38-L38 -> -60 | N38: -54 | O38: =AB38-N38 -> -80 | P38: -64 | W38: -82 | X38: -82 | Y38: -124 | Z38: -129 | AA38: -119 | AB38: -134
B39: Contribution | C39: £m | D39: =D37+D38 -> 91 | E39: =W39-D39 -> 119 | F39: =F37+F38 -> 90 | G39: =X39-F39 -> 109 | H39: 118 | I39: =Y39-H39 -> 140 | J39: 176 | K39: =Z39-J39 -> 250 | L39: 252 | M39: =AA39-L39 -> 287 | N39: 269 | O39: =AB39-N39 -> 225 | P39: 219 | W39: =W37+W38 -> 210 | X39: 199 | Y39: 258 | Z39: 426 | AA39: 539 | AB39: 494
B40: Other operating costs | C40: £m | D40: =D41-D39 -> -22 | E40: =W40-D40 -> -49 | F40: =F41-F39 -> -21 | G40: =X40-F40 -> -41 | H40: -49 | I40: =Y40-H40 -> -47 | J40: -55 | K40: =Z40-J40 -> -53 | L40: -51 | M40: =AA40-L40 -> -51 | N40: -50 | O40: =AB40-N40 -> -54 | P40: -61 | W40: =W41-W39 -> -71 | X40: -62 | Y40: -96 | Z40: -108 | AA40: -102 | AB40: -104
B41: Adjusted EBITDA | C41: £m | D41: 69 | E41: =W41-D41 -> 70 | F41: 69 | G41: =X41-F41 -> 68 | H41: 69 | I41: =Y41-H41 -> 92 | J41: 121 | K41: =Z41-J41 -> 197 | L41: 201 | M41: =AA41-L41 -> 236 | N41: 219 | O41: =AB41-N41 -> 171 | P41: 158 | W41: 139 | X41: 137 | Y41: 161 | Z41: 318 | AA41: 437 | AB41: 390
B42: Adjusted EBITDA margin | C42: % | D42: =D41/D34 -> 0.37912088 | E42: =E41/E34 -> 0.31531532 | F42: =F41/F34 -> 0.33333333 | G42: =G41/G34 -> 0.34693878 | H42: 0.219 | I42: =I41/I34 -> 0.2506812 | J42: 0.279 | K42: =K41/K34 -> 0.3078125 | L42: 0.343 | M42: =M41/M34 -> 0.33286319 | N42: 0.358 | O42: =O41/O34 -> 0.26267281 | P42: 0.264 | W42: =W41/W34 -> 0.34405941 | X42: 0.34 | Y42: 0.237 | Z42: 0.296 | AA42: 0.337 | AB42: 0.309
B43: Depreciation and amortisation | C43: £m | D43: -8 | E43: =W43-D43 -> -7 | F43: -10 | G43: =X43-F43 -> -8 | H43: -15 | I43: =Y43-H43 -> -15 | J43: -14 | K43: =Z43-J43 -> -16 | L43: -13 | M43: =AA43-L43 -> -13 | N43: -14 | O43: =AB43-N43 -> -15 | P43: -16 | W43: -15 | X43: -18 | Y43: -30 | Z43: -30 | AA43: -26 | AB43: -29
B44: Adjusted operating profit | C44: £m | D44: 51 | E44: =W44-D44 -> 74 | F44: 47 | G44: =X44-F44 -> 72 | H44: 54 | I44: =Y44-H44 -> 77 | J44: 107 | K44: =Z44-J44 -> 181 | L44: 188 | M44: =AA44-L44 -> 223 | N44: 206 | O44: =AB44-N44 -> 155 | P44: 142 | W44: 125 | X44: 119 | Y44: 131 | Z44: 288 | AA44: 411 | AB44: 361
B46: Exchange Rate (Average) | C46: x | F46: 0.77129154 | G46: 0.72413664 | H46: 0.70631085 | I46: 0.68458409 | J46: 0.65804692 | K46: 0.72349848 | L46: 0.7712845 | M46: 0.7317053 | N46: 0.71934729 | O46: 0.67042595 | P46: 0.67579846 | Q46: 0.65296692 | X46: 0.78601577 | Y46: 0.75657031 | Z46: 0.73147023 | AA46: 0.71691333 | AB46: 0.71251328 | AC46: 0.70020331 | AD46: 0.68542265 | AE46: 0.68374765
B47: Exchange Rate (Average) | C47: x | D47: 0.59926385 | E47: 0.59131154 | F47: 0.56072538 | G47: 0.55946107 | H47: 0.54597674 | I47: 0.54362424 | J47: 0.52194615 | K47: 0.55356591 | L47: 0.55545504 | M47: 0.53686136 | N47: 0.5546186 | O47: 0.5704084 | P47: 0.54797692 | Q47: 0.52070462 | W47: 0.59528769 | X47: 0.5600908 | Y47: 0.54478697 | Z47: 0.53787672 | AA47: 0.54605134 | AB47: 0.56257423 | AC47: 0.53434077
B49: US
B50: Average monthly players | C50: (‘000s) | J50: 596 | L50: 906 | N50: 993 | P50: 1066 | Z50: 794 | AA50: 1008 | AB50: 1090 | AC50: 1111 | AD50: 1165
...

Sheet ENT
D3: =IF(MONTH(D11)>6,RIGHT(YEAR(D11),2)+1,RIGHT(YEAR(D11),2)) -> 17 | E3: =IF(MONTH(E11)>6,RIGHT(YEAR(E11),2)+1,RIGHT(YEAR(E11),2)) -> 18 | F3: =IF(MONTH(F11)>6,RIGHT(YEAR(F11),2)+1,RIGHT(YEAR(F11),2)) -> 18 | G3: =IF(MONTH(G11)>6,RIGHT(YEAR(G11),2)+1,RIGHT(YEAR(G11),2)) -> 19 | H3: =IF(MONTH(H11)>6,RIGHT(YEAR(H11),2)+1,RIGHT(YEAR(H11),2)) -> 19 | I3: =IF(MONTH(I11)>6,RIGHT(YEAR(I11),2)+1,RIGHT(YEAR(I11),2)) -> 20 | J3: =IF(MONTH(J11)>6,RIGHT(YEAR(J11),2)+1,RIGHT(YEAR(J11),2)) -> 20 | K3: =IF(MONTH(K11)>6,RIGHT(YEAR(K11),2)+1,RIGHT(YEAR(K11),2)) -> 21 | ... U3: =IF(MONTH(U11)>6,RIGHT(YEAR(U11),2)+1,RIGHT(YEAR(U11),2)) -> 26
D4: =RIGHT(YEAR(D$11),2) -> 17 | E4: =RIGHT(YEAR(E$11),2) -> 17 | F4: =RIGHT(YEAR(F$11),2) -> 18 | G4: =RIGHT(YEAR(G$11),2) -> 18 | H4: =RIGHT(YEAR(H$11),2) -> 19 | I4: =RIGHT(YEAR(I$11),2) -> 19 | J4: =RIGHT(YEAR(J$11),2) -> 20 | K4: =RIGHT(YEAR(K$11),2) -> 20 | ... U4: =RIGHT(YEAR(U$11),2) -> 25
D5: ="FY"&TEXT(D$3,"00") -> FY17 | E5: ="FY"&TEXT(E$3,"00") -> FY18 | F5: ="FY"&TEXT(F$3,"00") -> FY18 | G5: ="FY"&TEXT(G$3,"00") -> FY19 | H5: ="FY"&TEXT(H$3,"00") -> FY19 | I5: ="FY"&TEXT(I$3,"00") -> FY20 | J5: ="FY"&TEXT(J$3,"00") -> FY20 | K5: ="FY"&TEXT(K$3,"00") -> FY21 | ... U5: ="FY"&TEXT(U$3,"00") -> FY26
D6: ="CY"&TEXT(D$4,"00") -> CY17 | E6: ="CY"&TEXT(E$4,"00") -> CY17 | F6: ="CY"&TEXT(F$4,"00") -> CY18 | G6: ="CY"&TEXT(G$4,"00") -> CY18 | H6: ="CY"&TEXT(H$4,"00") -> CY19 | I6: ="CY"&TEXT(I$4,"00") -> CY19 | J6: ="CY"&TEXT(J$4,"00") -> CY20 | K6: ="CY"&TEXT(K$4,"00") -> CY20 | ... U6: ="CY"&TEXT(U$4,"00") -> CY25
D7: =D11-EOMONTH(D11,-6) -> 181 | E7: =E11-EOMONTH(E11,-6) -> 184 | F7: =F11-EOMONTH(F11,-6) -> 181 | G7: =G11-EOMONTH(G11,-6) -> 184 | H7: =H11-EOMONTH(H11,-6) -> 181 | I7: =I11-EOMONTH(I11,-6) -> 184 | J7: =J11-EOMONTH(J11,-6) -> 182 | K7: =K11-EOMONTH(K11,-6) -> 184 | ... U7: =U11-EOMONTH(U11,-6) -> 184
