Workbook

Sheet NAV
B2: betr
B3: Model navigation
B6: COMPANY DETAILS | G6: ANALYST CONTACTS | J6: COMPANY CONTACTS
B7: Name | E7: betr | G7: Sam Bradshaw | J7: Andrew Menz | L7: CEO | P7: andrew.menz@betr.com.au
B8: Ticker | E8: BBT-ASX | G8: 0488063503 | J8: Bill Richmond | L8: COO | P8: bill.richmond@betr.com.au
B9: Exchange | E9: Australia | G9: sam.bradshaw@eandp.com.au | J9: Blake Matthews | L9: CFO | P9: blake.matthews@betr.com.au
B10: Sector | E10: Gaming
B11: Industry | E11: Wagering
B14: VALUATION | G14: Trading Multiples | J14: FY26 | K14: FY27 | L14: FY28 | M14: FY29 | N14: FY30 | P14: No Visible Alpha Data avaliable
B15: Share price (A$) | E15: =HY!D610 -> 0.2 | G15: EV/AEBITDA | J15: =IFERROR(FY!I271,"Needs Link") -> Needs Link | K15: =IFERROR(FY!J271,"Needs Link") -> Needs Link | L15: =IFERROR(FY!K271,"Needs Link") -> Needs Link | M15: =IFERROR(FY!L271,"Needs Link") -> Needs Link | N15: =IFERROR(FY!M271,"Needs Link") -> Needs Link
B16: Valuation (A$) | E16: =HY!D607 -> 0.27 | G16: P/E | J16: =IFERROR(FY!I273,"Needs Link") -> Needs Link | K16: =IFERROR(FY!J273,"Needs Link") -> Needs Link | L16: =IFERROR(FY!K273,"Needs Link") -> Needs Link | M16: =IFERROR(FY!L273,"Needs Link") -> Needs Link | N16: =IFERROR(FY!M273,"Needs Link") -> Needs Link
B17: Upside / (downside) | E17: =E16/E15-1 -> 0.35
B20: Revs
B21: Consensus
B22: check QTR CFO's & expenses
B23: Qtr First Take

Sheet BM
B1: =D8 -> BBT-ASX
A2: Industrial ResearchWise Sheet | R2: BlueMatrix formulas
C3: Company static items | E3: =+E114 -> FY2022A | F3: =+F114 -> FY2023A | G3: =+G114 -> FY2024A | H3: =+H114 -> FY2025F | I3: =+I114 -> FY2026F | J3: =+J114 -> FY2027F | K3: =+K114 -> FY2028F | L3: =+L114 -> FY2029F | ... Q3: =+Q114 -> FY2034F | S3: 2022 | T3: =S3+1 -> 2023 | U3: =T3+1 -> 2024 | V3: =U3+1 -> 2025 | W3: =V3+1 -> 2026 | X3: =W3+1 -> 2027 | Y3: =X3+1 -> 2028 | Z3: =Y3+1 -> 2029 | AA3: =Z3+1 -> 2030 | ... AE3: =AD3+1 -> 2034
A4: @BEGINSTATIC | D4: @ENDSTATIC
A5: @INSTTYPE | C5: Instrument type | D5: EQ
A6: @CTYPE | C6: Instrument code type | D6: @BB
A7: @VERSION | C7: Version information (Do not change) | D7: 1
A8: @CODE | C8: Ticker | D8: BBT-ASX
A9: @MULT | C9: Multiplier | D9: 1000000
A10: @RCURR | C10: Reporting Currency | D10: $
A11: @ANALYST | C11: Lead analyst | D11: Sam Bradshaw
A13: @TARGET | B13: PRICE_TARGET | C13: Valuation | D13: =HY!D607 -> 0.27 | R13: =_xll.BLUEMATRIX2("/servlet/excelData",$D13,$B$1,$B13) -> #
A14: @REC | B14: REC | C14: Recommendation | D14: Positive | R14: =_xll.BLUEMATRIX2("/servlet/excelData",$D14,$B$1,$B14) -> #
A15: @SHARE_OUT | B15: SHARE_OUT | C15: Shares outstanding | D15: =HY!D565 -> 1054.3063 | R15: =_xll.BLUEMATRIX2("/servlet/excelData",$D15,$B$1,$B15) -> #
A16: @FLOATPER | B16: free_float | C16: Free Float % | D16: 42.66 | R16: =_xll.BLUEMATRIX2("/servlet/excelData",$D16,$B$1,$B16) -> #
B17: PRICE | C17: Current Share Price | D17: 0.195 | R17: =_xll.BLUEMATRIX2("/servlet/excelData",$D17,$B$1,$B17) -> #
C18: Historic Share Price (Closing) | H18: =FY!H302 -> 0.27 | I18: =FY!I302 -> 0.19 | J18: =FY!J302 -> 0.20108205 | K18: =FY!K302 -> 0.21281047 | L18: =FY!L302 -> 0.22522297 | M18: =FY!M302 -> 0.23835946 | N18: =FY!N302 -> 0.25226214 | O18: =FY!O302 -> 0.26697573 | ... Q18: =FY!Q302 -> 0.29902753
C20: TSR
B21: upside_valuation | C21: Upside to valuation | D21: =(D13/D17-1)*100 -> 38.461538 | R21: =_xll.BLUEMATRIX2("/servlet/excelData",$D21,$B$1,$B21) -> #
B22: div_yield | C22: Dividend yield | D22: =I303*100 -> 0 | R22: =_xll.BLUEMATRIX2("/servlet/excelData",$D22,$B$1,$B22) -> #
B23: exp_total_return | C23: Expected total SH return | D23: =D21+D22 -> 38.461538 | R23: =_xll.BLUEMATRIX2("/servlet/excelData",$D23,$B$1,$B23) -> #
C25: Trading Data test
B26: 12_month_high | C26: 12 month high
B27: 12_month_low | C27: 12 month low
B28: MARKET_CAP | C28: Market cap | D28: =D17*D15 -> 205.58973 | R28: =_xll.BLUEMATRIX2("/servlet/excelData",$D28,$B$1,$B28) -> #
B29: free_float | C29: Free Float
B30: 12_month_return | C30: 12 month return (historical)
A31: @pricing_date
C34: Blended Valuation
A35: @DCF_VAL | B35: DCF_VAL | C35: Valuation - DCF | R35: =_xll.BLUEMATRIX2("/servlet/excelData",$D35,$B$1,$B35) -> #
A36: @CAPPER_VAL | B36: CAPPER_VAL | C36: Valuation - Capitalisation of Earnings | R36: =_xll.BLUEMATRIX2("/servlet/excelData",$D36,$B$1,$B36) -> #
A37: @PER_VAL | B37: PER_VAL | C37: Valuation - PER | R37: =_xll.BLUEMATRIX2("/servlet/excelData",$D37,$B$1,$B37) -> #
A38: @SOTP_VAL | B38: SOTP_VAL | C38: Valuation - SOTP | R38: =_xll.BLUEMATRIX2("/servlet/excelData",$D38,$B$1,$B38) -> #
A39: @BLEND_VAL | B39: PRICE_TARGET | C39: Valuation - Blended | R39: =_xll.BLUEMATRIX2("/servlet/excelData",$D39,$B$1,$B39) -> #
A40: @DCF_WT | B40: DCF_WT | C40: DCF Weightage | D40: 50 | R40: =_xll.BLUEMATRIX2("/servlet/excelData",$D40,$B$1,$B40) -> #
A41: @CAPPER_WT | B41: CAPPER_WT | C41: Capitalisation of Earnings Weightage | D41: 50 | R41: =_xll.BLUEMATRIX2("/servlet/excelData",$D41,$B$1,$B41) -> #
A42: @PER_WT | B42: PER_WT | C42: PER Weightage | R42: =_xll.BLUEMATRIX2("/servlet/excelData",$D42,$B$1,$B42) -> #
A43: @SOTP_WT | B43: SOTP_WT | C43: SOTP Weightage | R43: =_xll.BLUEMATRIX2("/servlet/excelData",$D43,$B$1,$B43) -> #
C45: Divisional Summary
A46: @SEG1_NAME | C46: Name of Segment 1 | D46: Turnover | R46: =_xll.BLUEMATRIX2("/servlet/excelData",$D46,$B$1,$B46) -> #
...

Sheet I

Sheet QTR
A2: X | B2: Valuation | D2: VAL | E2: =E8&E12 -> 1Q22A | F2: =F8&F12 -> 2Q22A | G2: =G8&G12 -> 3Q22A | H2: =H8&H12 -> 4Q22A | I2: =I8&I12 -> 1Q23A | J2: =J8&J12 -> 2Q23A | K2: =K8&K12 -> 3Q23A | L2: =L8&L12 -> 4Q23A | ... CB2: =CB8&CB12 -> 4Q40E
B3: Period End | E3: 44469 | F3: =EOMONTH(E3,3) -> 44561 | G3: =EOMONTH(F3,3) -> 44651 | H3: =EOMONTH(G3,3) -> 44742 | I3: =EOMONTH(H3,3) -> 44834 | J3: =EOMONTH(I3,3) -> 44926 | K3: =EOMONTH(J3,3) -> 45016 | L3: =EOMONTH(K3,3) -> 45107 | M3: =EOMONTH(L3,3) -> 45199 | ... CB3: =EOMONTH(CA3,3) -> 51317
B5: Quarter | E5: {=_xlfn.IFS(AND(MONTH(E$3)>=1,MONTH(E$3)<=3),"3Q",AND(MONTH(E$3)>=4,MONTH(E$3)<=6),"4Q",AND(MONTH(E$3)>=7,MONTH(E$3)<=9),"1Q",AND(MONTH(E$3)>=10,MONTH(E$3)<=12),"2Q")} -> 1Q | F5: {=_xlfn.IFS(AND(MONTH(F$3)>=1,MONTH(F$3)<=3),"3Q",AND(MONTH(F$3)>=4,MONTH(F$3)<=6),"4Q",AND(MONTH(F$3)>=7,MONTH(F$3)<=9),"1Q",AND(MONTH(F$3)>=10,MONTH(F$3)<=12),"2Q")} -> 2Q | G5: {=_xlfn.IFS(AND(MONTH(G$3)>=1,MONTH(G$3)<=3),"3Q",AND(MONTH(G$3)>=4,MONTH(G$3)<=6),"4Q",AND(MONTH(G$3)>=7,MONTH(G$3)<=9),"1Q",AND(MONTH(G$3)>=10,MONTH(G$3)<=12),"2Q")} -> 3Q | H5: {=_xlfn.IFS(AND(MONTH(H$3)>=1,MONTH(H$3)<=3),"3Q",AND(MONTH(H$3)>=4,MONTH(H$3)<=6),"4Q",AND(MONTH(H$3)>=7,MONTH(H$3)<=9),"1Q",AND(MONTH(H$3)>=10,MONTH(H$3)<=12),"2Q")} -> 4Q | I5: {=_xlfn.IFS(AND(MONTH(I$3)>=1,MONTH(I$3)<=3),"3Q",AND(MONTH(I$3)>=4,MONTH(I$3)<=6),"4Q",AND(MONTH(I$3)>=7,MONTH(I$3)<=9),"1Q",AND(MONTH(I$3)>=10,MONTH(I$3)<=12),"2Q")} -> 1Q | J5: {=_xlfn.IFS(AND(MONTH(J$3)>=1,MONTH(J$3)<=3),"3Q",AND(MONTH(J$3)>=4,MONTH(J$3)<=6),"4Q",AND(MONTH(J$3)>=7,MONTH(J$3)<=9),"1Q",AND(MONTH(J$3)>=10,MONTH(J$3)<=12),"2Q")} -> 2Q | K5: {=_xlfn.IFS(AND(MONTH(K$3)>=1,MONTH(K$3)<=3),"3Q",AND(MONTH(K$3)>=4,MONTH(K$3)<=6),"4Q",AND(MONTH(K$3)>=7,MONTH(K$3)<=9),"1Q",AND(MONTH(K$3)>=10,MONTH(K$3)<=12),"2Q")} -> 3Q | L5: {=_xlfn.IFS(AND(MONTH(L$3)>=1,MONTH(L$3)<=3),"3Q",AND(MONTH(L$3)>=4,MONTH(L$3)<=6),"4Q",AND(MONTH(L$3)>=7,MONTH(L$3)<=9),"1Q",AND(MONTH(L$3)>=10,MONTH(L$3)<=12),"2Q")} -> 4Q | ... CB5: {=_xlfn.IFS(AND(MONTH(CB$3)>=1,MONTH(CB$3)<=3),"3Q",AND(MONTH(CB$3)>=4,MONTH(CB$3)<=6),"4Q",AND(MONTH(CB$3)>=7,MONTH(CB$3)<=9),"1Q",AND(MONTH(CB$3)>=10,MONTH(CB$3)<=12),"2Q")} -> 4Q
B6: Half | E6: {=_xlfn.IFS(AND(MONTH(E$3)>=1,MONTH(E$3)<=6),"2H",AND(MONTH(E$3)>=7,MONTH(E$3)<=12),"1H")} -> 1H | F6: {=_xlfn.IFS(AND(MONTH(F$3)>=1,MONTH(F$3)<=6),"2H",AND(MONTH(F$3)>=7,MONTH(F$3)<=12),"1H")} -> 1H | G6: {=_xlfn.IFS(AND(MONTH(G$3)>=1,MONTH(G$3)<=6),"2H",AND(MONTH(G$3)>=7,MONTH(G$3)<=12),"1H")} -> 2H | H6: {=_xlfn.IFS(AND(MONTH(H$3)>=1,MONTH(H$3)<=6),"2H",AND(MONTH(H$3)>=7,MONTH(H$3)<=12),"1H")} -> 2H | I6: {=_xlfn.IFS(AND(MONTH(I$3)>=1,MONTH(I$3)<=6),"2H",AND(MONTH(I$3)>=7,MONTH(I$3)<=12),"1H")} -> 1H | J6: {=_xlfn.IFS(AND(MONTH(J$3)>=1,MONTH(J$3)<=6),"2H",AND(MONTH(J$3)>=7,MONTH(J$3)<=12),"1H")} -> 1H | K6: {=_xlfn.IFS(AND(MONTH(K$3)>=1,MONTH(K$3)<=6),"2H",AND(MONTH(K$3)>=7,MONTH(K$3)<=12),"1H")} -> 2H | L6: {=_xlfn.IFS(AND(MONTH(L$3)>=1,MONTH(L$3)<=6),"2H",AND(MONTH(L$3)>=7,MONTH(L$3)<=12),"1H")} -> 2H | ... CB6: {=_xlfn.IFS(AND(MONTH(CB$3)>=1,MONTH(CB$3)<=6),"2H",AND(MONTH(CB$3)>=7,MONTH(CB$3)<=12),"1H")} -> 2H
B7: FY | E7: {=_xlfn.IFS(AND(MONTH(E$3)>=1,MONTH(E$3)<=6),RIGHT(YEAR(E3),2),AND(MONTH(E$3)>=7,MONTH(E$3)<=12),RIGHT(YEAR(E3)+1,2))} -> 22 | F7: {=_xlfn.IFS(AND(MONTH(F$3)>=1,MONTH(F$3)<=6),RIGHT(YEAR(F3),2),AND(MONTH(F$3)>=7,MONTH(F$3)<=12),RIGHT(YEAR(F3)+1,2))} -> 22 | G7: {=_xlfn.IFS(AND(MONTH(G$3)>=1,MONTH(G$3)<=6),RIGHT(YEAR(G3),2),AND(MONTH(G$3)>=7,MONTH(G$3)<=12),RIGHT(YEAR(G3)+1,2))} -> 22 | H7: {=_xlfn.IFS(AND(MONTH(H$3)>=1,MONTH(H$3)<=6),RIGHT(YEAR(H3),2),AND(MONTH(H$3)>=7,MONTH(H$3)<=12),RIGHT(YEAR(H3)+1,2))} -> 22 | I7: {=_xlfn.IFS(AND(MONTH(I$3)>=1,MONTH(I$3)<=6),RIGHT(YEAR(I3),2),AND(MONTH(I$3)>=7,MONTH(I$3)<=12),RIGHT(YEAR(I3)+1,2))} -> 23 | J7: {=_xlfn.IFS(AND(MONTH(J$3)>=1,MONTH(J$3)<=6),RIGHT(YEAR(J3),2),AND(MONTH(J$3)>=7,MONTH(J$3)<=12),RIGHT(YEAR(J3)+1,2))} -> 23 | K7: {=_xlfn.IFS(AND(MONTH(K$3)>=1,MONTH(K$3)<=6),RIGHT(YEAR(K3),2),AND(MONTH(K$3)>=7,MONTH(K$3)<=12),RIGHT(YEAR(K3)+1,2))} -> 23 | L7: {=_xlfn.IFS(AND(MONTH(L$3)>=1,MONTH(L$3)<=6),RIGHT(YEAR(L3),2),AND(MONTH(L$3)>=7,MONTH(L$3)<=12),RIGHT(YEAR(L3)+1,2))} -> 23 | ... CB7: {=_xlfn.IFS(AND(MONTH(CB$3)>=1,MONTH(CB$3)<=6),RIGHT(YEAR(CB3),2),AND(MONTH(CB$3)>=7,MONTH(CB$3)<=12),RIGHT(YEAR(CB3)+1,2))} -> 40
B8: QTR FY | E8: =E$5&TEXT(E$7,"00") -> 1Q22 | F8: =F$5&TEXT(F$7,"00") -> 2Q22 | G8: =G$5&TEXT(G$7,"00") -> 3Q22 | H8: =H$5&TEXT(H$7,"00") -> 4Q22 | I8: =I$5&TEXT(I$7,"00") -> 1Q23 | J8: =J$5&TEXT(J$7,"00") -> 2Q23 | K8: =K$5&TEXT(K$7,"00") -> 3Q23 | L8: =L$5&TEXT(L$7,"00") -> 4Q23 | ... CB8: =CB$5&TEXT(CB$7,"00") -> 4Q40
B9: HY FY | E9: =E$6&TEXT(E$7,"00") -> 1H22 | F9: =F$6&TEXT(F$7,"00") -> 1H22 | G9: =G$6&TEXT(G$7,"00") -> 2H22 | H9: =H$6&TEXT(H$7,"00") -> 2H22 | I9: =I$6&TEXT(I$7,"00") -> 1H23 | J9: =J$6&TEXT(J$7,"00") -> 1H23 | K9: =K$6&TEXT(K$7,"00") -> 2H23 | L9: =L$6&TEXT(L$7,"00") -> 2H23 | ... CB9: =CB$6&TEXT(CB$7,"00") -> 2H40
B10: FY | E10: ="FY"&E7 -> FY22 | F10: ="FY"&F7 -> FY22 | G10: ="FY"&G7 -> FY22 | H10: ="FY"&H7 -> FY22 | I10: ="FY"&I7 -> FY23 | J10: ="FY"&J7 -> FY23 | K10: ="FY"&K7 -> FY23 | L10: ="FY"&L7 -> FY23 | ... CB10: ="FY"&CB7 -> FY40
B11: Calendar Year | E11: =YEAR(E3) -> 2021 | F11: =YEAR(F3) -> 2021 | G11: =YEAR(G3) -> 2022 | H11: =YEAR(H3) -> 2022 | I11: =YEAR(I3) -> 2022 | J11: =YEAR(J3) -> 2022 | K11: =YEAR(K3) -> 2023 | L11: =YEAR(L3) -> 2023 | ... CB11: =YEAR(CB3) -> 2040
B12: Actual/Estimate | E12: =E17 -> A | F12: =F17 -> A | G12: =G17 -> A | H12: =H17 -> A | I12: =I17 -> A | J12: =J17 -> A | K12: =K17 -> A | L12: =L17 -> A | ... CB12: =CB17 -> E
B13: Days in period | E13: 92 | F13: =F3-E3 -> 92 | G13: =G3-F3 -> 90 | H13: =H3-G3 -> 91 | I13: =I3-H3 -> 92 | J13: =J3-I3 -> 92 | K13: =K3-J3 -> 90 | L13: =L3-K3 -> 91 | M13: =M3-L3 -> 92 | ... CB13: =CB3-CA3 -> 91
A15: X | B15: GENERAL
B17: Actual/Estimate | C17: A/E | E17: A | F17: A | G17: A | H17: A | I17: A | J17: A | K17: A | L17: A | M17: A | N17: A | O17: A | P17: A | Q17: A | R17: A | S17: A | T17: A | U17: A | V17: A | W17: E | X17: E | Y17: E | Z17: E | AA17: E | AB17: E | AC17: E | AD17: E | AE17: E | AF17: E | AG17: E | AH17: E | AI17: E | AJ17: E | AK17: E | AL17: E | AM17: E | AN17: E | AO17: E | AP17: E | AQ17: E | AR17: E | AS17: E | AT17: E | AU17: E | AV17: E | AW17: E | AX17: E | AY17: E | AZ17: E | BA17: E | BB17: E | BC17: E | BD17: E | BE17: E | BF17: E | BG17: E | BH17: E | BI17: E | BJ17: E | BK17: E | BL17: E | BM17: E | BN17: E | BO17: E | BP17: E | BQ17: E | BR17: E | BS17: E | BT17: E | BU17: E | BV17: E | BW17: E | BX17: E | BY17: E | BZ17: E | CA17: E | CB17: E
A19: X | B19: KPI's
B21: AUSTRALIA
P22: ~
B23: Underlying | C23: A$m | R23: 357 | V23: =R23*(1+V24) -> 403.41
B24: growth | C24: % | V24: 0.13
B26: TopSport | C26: A$m | V26: =V29-V23 -> 40.99
B27: growth | C27: % | V27: =V26/R26-1 -> #DIV/0!
B29: Turnover | C29: A$m | M29: 143.9 | N29: 154.8 | O29: 139.2 | P29: 153.6 | Q29: 286.6 | R29: 357 | S29: 376 | T29: 399.5 | U29: 363 | V29: 444.4 | W29: 383 | X29: 404.3 | Y29: =U29*(1+Y30) -> 413.82 | Z29: =V29*(1+Z30) -> 473.286
B30: growth | C30: % | Q30: =Q29/M29-1 -> 0.99166088 | R30: =R29/N29-1 -> 1.3062016 | S30: =S29/O29-1 -> 1.7011494 | T30: =T29/P29-1 -> 1.6009115 | U30: =U29/Q29-1 -> 0.26657362 | V30: =V29/R29-1 -> 0.24481793 | W30: =W29/S29-1 -> 0.018617021 | X30: =X29/T29-1 -> 0.012015019 | Y30: 0.14 | Z30: 0.065
B32: Active Customers | C32: 000's | Q32: 120.2 | R32: 144.7 | S32: 153 | T32: 155.4 | U32: 154.7 | V32: 163.5 | W32: 157.264 | X32: 156.479
B33: XX | C33: %
B35: Gross Win | C35: A$m | M35: 18.8 | N35: 21.2 | O35: 18.6 | P35: 20.8 | Q35: 38.8 | R35: 52.2 | S35: 51.7 | T35: 53.1 | U35: 51.8 | V35: 55.9 | W35: 50.3 | X35: 57.1 | Y35: =Y29*Y36 -> 59.17626 | Z35: =Z29*Z36 -> 67.679898
B36: margin | C36: % | M36: =M35/M29 -> 0.13064628 | N36: =N35/N29 -> 0.1369509 | O36: =O35/O29 -> 0.13362069 | P36: =P35/P29 -> 0.13541667 | Q36: =Q35/Q29 -> 0.13538032 | R36: =R35/R29 -> 0.14621849 | S36: =S35/S29 -> 0.1375 | T36: =T35/T29 -> 0.13291615 | ... X36: =X35/X29 -> 0.14123176 | Y36: 0.143 | Z36: 0.143
B38: Promos | C38: A$m | M38: =M41-M35 -> -4.3 | N38: =N41-N35 -> -5 | O38: =O41-O35 -> -3.3 | P38: =P41-P35 -> -3.5 | Q38: =Q41-Q35 -> -10.9 | R38: =R41-R35 -> -13 | S38: =S41-S35 -> -13.9 | T38: =T41-T35 -> -12.9 | ... X38: =X41-X35 -> -13.2 | Y38: =Y29*Y39 -> -14.89752 | Z38: =Z29*Z39 -> -17.984868
B39: Promo % | C39: % | M39: =M38/M29 -> -0.029881862 | N39: =N38/N29 -> -0.032299742 | O39: =O38/O29 -> -0.023706897 | P39: =P38/P29 -> -0.022786458 | Q39: =Q38/Q29 -> -0.0380321 | R39: =R38/R29 -> -0.036414566 | S39: =S38/S29 -> -0.036968085 | T39: =T38/T29 -> -0.032290363 | ... X39: =X38/X29 -> -0.032649023 | Y39: -0.036 | Z39: -0.038
B41: Net Win | C41: A$m | M41: 14.5 | N41: 16.2 | O41: 15.3 | P41: 17.3 | Q41: 27.9 | R41: 39.2 | S41: 37.8 | T41: 40.2 | U41: 38 | V41: 37.9 | W41: 38.2 | X41: 43.9 | Y41: =Y35+Y38 -> 44.27874 | Z41: =Z35+Z38 -> 49.69503
B42: margin | C42: % | M42: =M41/M29 -> 0.10076442 | N42: =N41/N29 -> 0.10465116 | O42: =O41/O29 -> 0.10991379 | P42: =P41/P29 -> 0.11263021 | Q42: =Q41/Q29 -> 0.097348221 | R42: =R41/R29 -> 0.10980392 | S42: =S41/S29 -> 0.10053191 | T42: =T41/T29 -> 0.10062578 | ... Z42: =Z41/Z29 -> 0.105
B43: growth | C43: % | M43: =M41/I41-1 -> #DIV/0! | N43: =N41/J41-1 -> #DIV/0! | O43: =O41/K41-1 -> #DIV/0! | P43: =P41/L41-1 -> #DIV/0! | Q43: =Q41/M41-1 -> 0.92413793 | R43: =R41/N41-1 -> 1.4197531 | S43: =S41/O41-1 -> 1.4705882 | T43: =T41/P41-1 -> 1.3236994 | ... Z43: =Z41/V41-1 -> 0.31121451
B45: Q2 Net Win by ~1.75pp | V45: =V42+1.75% -> 0.10278353
B46: Adjusted Net Win | V46: =V29*V45 -> 45.677
B48: Advertising & Marketing | Q48: -2.9 | R48: -7 | S48: -3.6 | T48: -5.5 | U48: -11.5 | V48: -10.3 | W48: -7.7023 | X48: -4.0542
B49: % of Turnover | M49: =M48/M29 -> 0 | N49: =N48/N29 -> 0 | O49: =O48/O29 -> 0 | P49: =P48/P29 -> 0 | Q49: =Q48/Q29 -> -0.010118632 | R49: =R48/R29 -> -0.019607843 | S49: =S48/S29 -> -0.0095744681 | T49: =T48/T29 -> -0.013767209 | ... X49: =X48/X29 -> -0.010027702
B50: % of Net Win | M50: =M48/M41 -> 0 | N50: =N48/N41 -> 0 | O50: =O48/O41 -> 0 | P50: =P48/P41 -> 0 | Q50: =Q48/Q41 -> -0.10394265 | R50: =R48/R41 -> -0.17857143 | S50: =S48/S41 -> -0.095238095 | T50: =T48/T41 -> -0.13681592 | ... X50: =X48/X41 -> -0.092350797
B52: Operating Cash Flows
B53: Receipts from customers (Client deposits) | Q53: 95.2173 | R53: 124.1533 | S53: 123.82 | T53: 127.4679 | U53: 128.332 | V53: 155.3913 | W53: 136.5391 | X53: 150.7245
B54: Payments to customers (Client withdrawals) | Q54: -72.2125 | R54: -86.8197 | S54: -84.8136 | T54: -95.5732 | U54: -91.9765 | V54: -117.291 | W54: -99.5739 | X54: -106.6411
B55: Cost of Sales | Q55: -10.6027 | R55: -19.7536 | S55: -17.3842 | T55: -22.2244 | U55: -18.4506 | V55: -19.9761 | W55: -21.2051 | X55: -23.3236
...

Sheet HY
K1: =K255 -> 4.3410829 | L1: =L255 -> 7.4191626
B3: Management EBITDA Target (normalised) | I3: 2H26 | J3: $5m-$8m | K3: FY27 | L3: $13m-$19m
B4: E&P | J4: =J119 -> 6.1 | L4: =K119+L119 -> 16.471693 | N4: =M119+N119 -> 21.580368 | P4: =O119+P119 -> 25.531054 | R4: =Q119+R119 -> 28.423656
B6: Checks | C6: =SUM(E6:AL6) -> 0 | E6: =E334 -> 0 | F6: =F334 -> 0 | G6: =G334 -> 0 | H6: =H334 -> 0 | I6: =I334 -> 0 | J6: =J334 -> 0 | K6: =K334 -> 0 | L6: =L334 -> 0 | ... AL6: =AL334 -> 0
A7: X | B7: Valuation | C7: =$D$607 -> 0.27 | D7: VAL | E7: =E13&E16 -> 1H24A | F7: =F13&F16 -> 2H24A | G7: =G13&G16 -> 1H25A | H7: =H13&H16 -> 2H25A | I7: =I13&I16 -> 1H26A | J7: =J13&J16 -> 2H26A | K7: =K13&K16 -> 1H27E | L7: =L13&L16 -> 2H27E | ... AL7: =AL13&AL16 -> 2H40E
B8: Period End | E8: 45291 | F8: =EOMONTH(E8,6) -> 45473 | G8: =EOMONTH(F8,6) -> 45657 | H8: =EOMONTH(G8,6) -> 45838 | I8: =EOMONTH(H8,6) -> 46022 | J8: =EOMONTH(I8,6) -> 46203 | K8: =EOMONTH(J8,6) -> 46387 | L8: =EOMONTH(K8,6) -> 46568 | M8: =EOMONTH(L8,6) -> 46752 | ... AL8: =EOMONTH(AK8,6) -> 51317
B10: Quarter | E10: {=_xlfn.IFS(AND(MONTH(E$8)>=1,MONTH(E$8)<=3),"3Q",AND(MONTH(E$8)>=4,MONTH(E$8)<=6),"4Q",AND(MONTH(E$8)>=7,MONTH(E$8)<=9),"1Q",AND(MONTH(E$8)>=10,MONTH(E$8)<=12),"2Q")} -> 2Q | F10: {=_xlfn.IFS(AND(MONTH(F$8)>=1,MONTH(F$8)<=3),"3Q",AND(MONTH(F$8)>=4,MONTH(F$8)<=6),"4Q",AND(MONTH(F$8)>=7,MONTH(F$8)<=9),"1Q",AND(MONTH(F$8)>=10,MONTH(F$8)<=12),"2Q")} -> 4Q | G10: {=_xlfn.IFS(AND(MONTH(G$8)>=1,MONTH(G$8)<=3),"3Q",AND(MONTH(G$8)>=4,MONTH(G$8)<=6),"4Q",AND(MONTH(G$8)>=7,MONTH(G$8)<=9),"1Q",AND(MONTH(G$8)>=10,MONTH(G$8)<=12),"2Q")} -> 2Q | H10: {=_xlfn.IFS(AND(MONTH(H$8)>=1,MONTH(H$8)<=3),"3Q",AND(MONTH(H$8)>=4,MONTH(H$8)<=6),"4Q",AND(MONTH(H$8)>=7,MONTH(H$8)<=9),"1Q",AND(MONTH(H$8)>=10,MONTH(H$8)<=12),"2Q")} -> 4Q | I10: {=_xlfn.IFS(AND(MONTH(I$8)>=1,MONTH(I$8)<=3),"3Q",AND(MONTH(I$8)>=4,MONTH(I$8)<=6),"4Q",AND(MONTH(I$8)>=7,MONTH(I$8)<=9),"1Q",AND(MONTH(I$8)>=10,MONTH(I$8)<=12),"2Q")} -> 2Q | J10: {=_xlfn.IFS(AND(MONTH(J$8)>=1,MONTH(J$8)<=3),"3Q",AND(MONTH(J$8)>=4,MONTH(J$8)<=6),"4Q",AND(MONTH(J$8)>=7,MONTH(J$8)<=9),"1Q",AND(MONTH(J$8)>=10,MONTH(J$8)<=12),"2Q")} -> 4Q | K10: {=_xlfn.IFS(AND(MONTH(K$8)>=1,MONTH(K$8)<=3),"3Q",AND(MONTH(K$8)>=4,MONTH(K$8)<=6),"4Q",AND(MONTH(K$8)>=7,MONTH(K$8)<=9),"1Q",AND(MONTH(K$8)>=10,MONTH(K$8)<=12),"2Q")} -> 2Q | L10: {=_xlfn.IFS(AND(MONTH(L$8)>=1,MONTH(L$8)<=3),"3Q",AND(MONTH(L$8)>=4,MONTH(L$8)<=6),"4Q",AND(MONTH(L$8)>=7,MONTH(L$8)<=9),"1Q",AND(MONTH(L$8)>=10,MONTH(L$8)<=12),"2Q")} -> 4Q | ... AL10: {=_xlfn.IFS(AND(MONTH(AL$8)>=1,MONTH(AL$8)<=3),"3Q",AND(MONTH(AL$8)>=4,MONTH(AL$8)<=6),"4Q",AND(MONTH(AL$8)>=7,MONTH(AL$8)<=9),"1Q",AND(MONTH(AL$8)>=10,MONTH(AL$8)<=12),"2Q")} -> 4Q
B11: Half | E11: {=_xlfn.IFS(AND(MONTH(E$8)>=1,MONTH(E$8)<=6),"2H",AND(MONTH(E$8)>=7,MONTH(E$8)<=12),"1H")} -> 1H | F11: {=_xlfn.IFS(AND(MONTH(F$8)>=1,MONTH(F$8)<=6),"2H",AND(MONTH(F$8)>=7,MONTH(F$8)<=12),"1H")} -> 2H | G11: {=_xlfn.IFS(AND(MONTH(G$8)>=1,MONTH(G$8)<=6),"2H",AND(MONTH(G$8)>=7,MONTH(G$8)<=12),"1H")} -> 1H | H11: {=_xlfn.IFS(AND(MONTH(H$8)>=1,MONTH(H$8)<=6),"2H",AND(MONTH(H$8)>=7,MONTH(H$8)<=12),"1H")} -> 2H | I11: {=_xlfn.IFS(AND(MONTH(I$8)>=1,MONTH(I$8)<=6),"2H",AND(MONTH(I$8)>=7,MONTH(I$8)<=12),"1H")} -> 1H | J11: {=_xlfn.IFS(AND(MONTH(J$8)>=1,MONTH(J$8)<=6),"2H",AND(MONTH(J$8)>=7,MONTH(J$8)<=12),"1H")} -> 2H | K11: {=_xlfn.IFS(AND(MONTH(K$8)>=1,MONTH(K$8)<=6),"2H",AND(MONTH(K$8)>=7,MONTH(K$8)<=12),"1H")} -> 1H | L11: {=_xlfn.IFS(AND(MONTH(L$8)>=1,MONTH(L$8)<=6),"2H",AND(MONTH(L$8)>=7,MONTH(L$8)<=12),"1H")} -> 2H | ... AL11: {=_xlfn.IFS(AND(MONTH(AL$8)>=1,MONTH(AL$8)<=6),"2H",AND(MONTH(AL$8)>=7,MONTH(AL$8)<=12),"1H")} -> 2H
B12: FY | E12: {=_xlfn.IFS(AND(MONTH(E$8)>=1,MONTH(E$8)<=6),RIGHT(YEAR(E8),2),AND(MONTH(E$8)>=7,MONTH(E$8)<=12),RIGHT(YEAR(E8)+1,2))} -> 24 | F12: {=_xlfn.IFS(AND(MONTH(F$8)>=1,MONTH(F$8)<=6),RIGHT(YEAR(F8),2),AND(MONTH(F$8)>=7,MONTH(F$8)<=12),RIGHT(YEAR(F8)+1,2))} -> 24 | G12: {=_xlfn.IFS(AND(MONTH(G$8)>=1,MONTH(G$8)<=6),RIGHT(YEAR(G8),2),AND(MONTH(G$8)>=7,MONTH(G$8)<=12),RIGHT(YEAR(G8)+1,2))} -> 25 | H12: {=_xlfn.IFS(AND(MONTH(H$8)>=1,MONTH(H$8)<=6),RIGHT(YEAR(H8),2),AND(MONTH(H$8)>=7,MONTH(H$8)<=12),RIGHT(YEAR(H8)+1,2))} -> 25 | I12: {=_xlfn.IFS(AND(MONTH(I$8)>=1,MONTH(I$8)<=6),RIGHT(YEAR(I8),2),AND(MONTH(I$8)>=7,MONTH(I$8)<=12),RIGHT(YEAR(I8)+1,2))} -> 26 | J12: {=_xlfn.IFS(AND(MONTH(J$8)>=1,MONTH(J$8)<=6),RIGHT(YEAR(J8),2),AND(MONTH(J$8)>=7,MONTH(J$8)<=12),RIGHT(YEAR(J8)+1,2))} -> 26 | K12: {=_xlfn.IFS(AND(MONTH(K$8)>=1,MONTH(K$8)<=6),RIGHT(YEAR(K8),2),AND(MONTH(K$8)>=7,MONTH(K$8)<=12),RIGHT(YEAR(K8)+1,2))} -> 27 | L12: {=_xlfn.IFS(AND(MONTH(L$8)>=1,MONTH(L$8)<=6),RIGHT(YEAR(L8),2),AND(MONTH(L$8)>=7,MONTH(L$8)<=12),RIGHT(YEAR(L8)+1,2))} -> 27 | ... AL12: {=_xlfn.IFS(AND(MONTH(AL$8)>=1,MONTH(AL$8)<=6),RIGHT(YEAR(AL8),2),AND(MONTH(AL$8)>=7,MONTH(AL$8)<=12),RIGHT(YEAR(AL8)+1,2))} -> 40
B13: HY FY | E13: =E$11&TEXT(E$12,"00") -> 1H24 | F13: =F$11&TEXT(F$12,"00") -> 2H24 | G13: =G$11&TEXT(G$12,"00") -> 1H25 | H13: =H$11&TEXT(H$12,"00") -> 2H25 | I13: =I$11&TEXT(I$12,"00") -> 1H26 | J13: =J$11&TEXT(J$12,"00") -> 2H26 | K13: =K$11&TEXT(K$12,"00") -> 1H27 | L13: =L$11&TEXT(L$12,"00") -> 2H27 | ... AL13: =AL$11&TEXT(AL$12,"00") -> 2H40
B14: HY FY | E14: ="FY"&E12 -> FY24 | F14: ="FY"&F12 -> FY24 | G14: ="FY"&G12 -> FY25 | H14: ="FY"&H12 -> FY25 | I14: ="FY"&I12 -> FY26 | J14: ="FY"&J12 -> FY26 | K14: ="FY"&K12 -> FY27 | L14: ="FY"&L12 -> FY27 | ... AL14: ="FY"&AL12 -> FY40
B15: Calendar Year | E15: =YEAR(E8) -> 2023 | F15: =YEAR(F8) -> 2024 | G15: =YEAR(G8) -> 2024 | H15: =YEAR(H8) -> 2025 | I15: =YEAR(I8) -> 2025 | J15: =YEAR(J8) -> 2026 | K15: =YEAR(K8) -> 2026 | L15: =YEAR(L8) -> 2027 | ... AL15: =YEAR(AL8) -> 2040
B16: Actual/Estimate | E16: =E21 -> A | F16: =F21 -> A | G16: =G21 -> A | H16: =H21 -> A | I16: =I21 -> A | J16: =J21 -> A | K16: =K21 -> E | L16: =L21 -> E | ... AL16: =AL21 -> E
B17: Days in period | E17: 184 | F17: =F8-E8 -> 182 | G17: =G8-F8 -> 184 | H17: =H8-G8 -> 181 | I17: =I8-H8 -> 184 | J17: =J8-I8 -> 181 | K17: =K8-J8 -> 184 | L17: =L8-K8 -> 181 | M17: =M8-L8 -> 184 | ... AL17: =AL8-AK8 -> 182
A19: X | B19: GENERAL
B21: Actual/Estimate | C21: A/E | E21: A | F21: A | G21: A | H21: A | I21: A | J21: A | K21: E | L21: E | M21: E | N21: E | O21: E | P21: E | Q21: E | R21: E | S21: E | T21: E | U21: E | V21: E | W21: E | X21: E | Y21: E | Z21: E | AA21: E | AB21: E | AC21: E | AD21: E | AE21: E | AF21: E | AG21: E | AH21: E | AI21: E | AJ21: E | AK21: E | AL21: E
B23: Commentary
A24: 1Q | B24: Marketing spend is front-weighted. So, the output in half two will be a reduction on that, approximately circa AUD 10 million for the second half of the year
A25: 2Q | B25: On net win margin, we're modeling that at that 10.4% historical rate that we've been able to achieve over a significant period of time
A26: 2Q | B26: We are assuming that the turnover – that the market will continue to grow in that low-single digits number. And we're assuming that we do continue to take share as we have. It does not need to be at 4 times the market for us to get to the guidance number
A27: 2Q | B27: But we do assume that we continue to take share as we get payback from the investment that we've made in those brand and product initiatives in the first half.
A28: 2Q | B28: This model is designed to enhance productivity, while maintaining service quality, and from Q4 onwards is expected to deliver approximately AUD 6 million in annualized run rate savings.
A29: 3Q | B29: We're confident that we grow in FY 2027 at mid- to high-single digits at the top line
A30: 3Q | B30: What we're not seeing is a reduction in customers or in active user days. We have seen in small cohorts of customers either a reduction in frequency or a reduction in bet size. Now, interestingly, when you have a reduction in bet size, it often translates to higher margin activities. So the impact on revenue has been really negligible in that respect with how the customers have continued to engage with us
A34: X | B34: SEGMENTS
B36: TOP SPORT
B37: Turnover
B38: BBT Underlying | C38: A$m | G38: =G64 -> 645.1 | I38: =G38*(1+I39) -> 728.963
B39: growth | C39: % | I39: 0.13
B41: TopSport | C41: A$m | G41: 198.9 | I41: =I64-I38 -> 78.337
B42: growth | C42: % | I42: =I41/G41-1 -> -0.60614882
B44: Combined | C44: A$m | G44: =G38+G41 -> 844 | I44: =I38+I41 -> 807.3
B45: growth | C45: % | I45: =I44/G44-1 -> -0.043483412
B47: Gross Win
B48: BBT Underlying | C48: A$m | G48: =G68 -> 91.3
B49: TopSport | C49: A$m | G49: 14.4
B50: Combined | C50: A$m | G50: =SUM(G48:G49) -> 105.7 | I50: =I68 -> 108.3
B51: growth | C51: % | I51: =I50/G50-1 -> 0.024597919
B53: Net Win
B54: BBT Underlying | C54: A$m | G54: =G75 -> 67.4
...

Sheet FY
E2: 2022 | F2: =E2+1 -> 2023 | G2: =F2+1 -> 2024 | H2: =G2+1 -> 2025 | I2: =H2+1 -> 2026 | J2: =I2+1 -> 2027 | K2: =J2+1 -> 2028 | L2: =K2+1 -> 2029 | M2: =L2+1 -> 2030 | ... Q2: =P2+1 -> 2034
E3: A | F3: A | G3: A | H3: A | I3: A | J3: E | K3: E | L3: E | M3: E | N3: E | O3: E | P3: E | Q3: E
E4: FY22 | F4: FY23 | G4: FY24 | H4: FY25 | I4: FY26 | J4: FY27 | K4: FY28 | L4: FY29 | M4: FY30 | N4: FY31 | O4: FY32 | P4: FY33 | Q4: FY34
C6: Units | E6: =E4&E3 -> FY22A | F6: =F4&F3 -> FY23A | G6: =G4&G3 -> FY24A | H6: =H4&H3 -> FY25A | I6: =I4&I3 -> FY26A | J6: =J4&J3 -> FY27E | K6: =K4&K3 -> FY28E | L6: =L4&L3 -> FY29E | ... Q6: =Q4&Q3 -> FY34E
E7: 44742 | F7: =EOMONTH(E7,12) -> 45107 | G7: =EOMONTH(F7,12) -> 45473 | H7: =EOMONTH(G7,12) -> 45838 | I7: =EOMONTH(H7,12) -> 46203 | J7: =EOMONTH(I7,12) -> 46568 | K7: =EOMONTH(J7,12) -> 46934 | L7: =EOMONTH(K7,12) -> 47299 | M7: =EOMONTH(L7,12) -> 47664 | ... Q7: =EOMONTH(P7,12) -> 49125
A9: X | B9: AUSTRALIAN WAGERING
B11: KPI's
B12: Turnover | G12: =SUMIFS(HY!64:64,HY!$14:$14,FY!G$4) -> 591.9 | H12: =SUMIFS(HY!64:64,HY!$14:$14,FY!H$4) -> 1420.4 | I12: =SUMIFS(HY!64:64,HY!$14:$14,FY!I$4) -> 1594.7 | J12: =SUMIFS(HY!64:64,HY!$14:$14,FY!J$4) -> 1722.674 | K12: =SUMIFS(HY!64:64,HY!$14:$14,FY!K$4) -> 1808.8077 | L12: =SUMIFS(HY!64:64,HY!$14:$14,FY!L$4) -> 1899.2481 | M12: =SUMIFS(HY!64:64,HY!$14:$14,FY!M$4) -> 1994.2105 | N12: =SUMIFS(HY!64:64,HY!$14:$14,FY!N$4) -> 2093.921 | ... Q12: =SUMIFS(HY!64:64,HY!$14:$14,FY!Q$4) -> 2423.9753
B14: Gross Win | G14: =SUMIFS(HY!68:68,HY!$14:$14,FY!G$4) -> 79.5 | H14: =SUMIFS(HY!68:68,HY!$14:$14,FY!H$4) -> 196.2 | I14: =SUMIFS(HY!68:68,HY!$14:$14,FY!I$4) -> 215.7 | J14: =SUMIFS(HY!68:68,HY!$14:$14,FY!J$4) -> 242.95042 | K14: =SUMIFS(HY!68:68,HY!$14:$14,FY!K$4) -> 255.09794 | L14: =SUMIFS(HY!68:68,HY!$14:$14,FY!L$4) -> 267.85284 | M14: =SUMIFS(HY!68:68,HY!$14:$14,FY!M$4) -> 281.24548 | N14: =SUMIFS(HY!68:68,HY!$14:$14,FY!N$4) -> 295.30775 | ... Q14: =SUMIFS(HY!68:68,HY!$14:$14,FY!Q$4) -> 341.85564
B15: Gross Margin | G15: =G14/G12 -> 0.13431323 | H15: =H14/H12 -> 0.1381301 | I15: =I14/I12 -> 0.13526055 | J15: =J14/J12 -> 0.14103099 | K15: =K14/K12 -> 0.14103099 | L15: =L14/L12 -> 0.14103099 | M15: =M14/M12 -> 0.14103099 | N15: =N14/N12 -> 0.14103099 | ... Q15: =Q14/Q12 -> 0.14103099
B17: Promos | G17: =SUMIFS(HY!71:71,HY!$14:$14,FY!G$4) -> -16.5 | H17: =SUMIFS(HY!71:71,HY!$14:$14,FY!H$4) -> -48.4 | I17: =SUMIFS(HY!71:71,HY!$14:$14,FY!I$4) -> -57.6 | J17: =SUMIFS(HY!71:71,HY!$14:$14,FY!J$4) -> -59.619104 | K17: =SUMIFS(HY!71:71,HY!$14:$14,FY!K$4) -> -62.600059 | L17: =SUMIFS(HY!71:71,HY!$14:$14,FY!L$4) -> -65.730062 | M17: =SUMIFS(HY!71:71,HY!$14:$14,FY!M$4) -> -69.016565 | N17: =SUMIFS(HY!71:71,HY!$14:$14,FY!N$4) -> -72.467394 | ... Q17: =SUMIFS(HY!71:71,HY!$14:$14,FY!Q$4) -> -83.890066
B18: Promo % | G18: =G17/G12 -> -0.02787633 | H18: =H17/H12 -> -0.034074908 | I18: =I17/I12 -> -0.036119646 | J18: =J17/J12 -> -0.034608466 | K18: =K17/K12 -> -0.034608466 | L18: =L17/L12 -> -0.034608466 | M18: =M17/M12 -> -0.034608466 | N18: =N17/N12 -> -0.034608466 | ... Q18: =Q17/Q12 -> -0.034608466
B20: New Win | G20: =SUMIFS(HY!75:75,HY!$14:$14,FY!G$4) -> 63 | H20: =SUMIFS(HY!75:75,HY!$14:$14,FY!H$4) -> 147.8 | I20: =SUMIFS(HY!75:75,HY!$14:$14,FY!I$4) -> 158.1 | J20: =SUMIFS(HY!75:75,HY!$14:$14,FY!J$4) -> 183.33132 | K20: =SUMIFS(HY!75:75,HY!$14:$14,FY!K$4) -> 192.49788 | L20: =SUMIFS(HY!75:75,HY!$14:$14,FY!L$4) -> 202.12278 | M20: =SUMIFS(HY!75:75,HY!$14:$14,FY!M$4) -> 212.22891 | N20: =SUMIFS(HY!75:75,HY!$14:$14,FY!N$4) -> 222.84036 | ... Q20: =SUMIFS(HY!75:75,HY!$14:$14,FY!Q$4) -> 257.96557
B21: Net Margin | G21: =G20/G12 -> 0.1064369 | H21: =H20/H12 -> 0.1040552 | I21: =I20/I12 -> 0.099140904 | J21: =J20/J12 -> 0.10642252 | K21: =K20/K12 -> 0.10642252 | L21: =L20/L12 -> 0.10642252 | M21: =M20/M12 -> 0.10642252 | N21: =N20/N12 -> 0.10642252 | ... Q21: =Q20/Q12 -> 0.10642252
B23: Active Customers | H23: =_xlfn.XLOOKUP(FY!H$7,HY!$8:$8,HY!78:78) -> 155.42 | I23: =_xlfn.XLOOKUP(FY!I$7,HY!$8:$8,HY!78:78) -> 156.479
B25: Growth Rates
B26: Turnover | H26: =H12/G12-1 -> 1.3997297 | I26: =I12/H12-1 -> 0.12271191 | J26: =J12/I12-1 -> 0.080249577 | K26: =K12/J12-1 -> 0.05 | L26: =L12/K12-1 -> 0.05 | M26: =M12/L12-1 -> 0.05 | N26: =N12/M12-1 -> 0.05 | O26: =O12/N12-1 -> 0.05 | ... Q26: =Q12/P12-1 -> 0.05
B27: Gross Win | H27: =H14/G14-1 -> 1.4679245 | I27: =I14/H14-1 -> 0.099388379 | J27: =J14/I14-1 -> 0.12633482 | K27: =K14/J14-1 -> 0.05 | L27: =L14/K14-1 -> 0.05 | M27: =M14/L14-1 -> 0.05 | N27: =N14/M14-1 -> 0.05 | O27: =O14/N14-1 -> 0.05 | ... Q27: =Q14/P14-1 -> 0.05
B28: Promos | H28: =H17/G17-1 -> 1.9333333 | I28: =I17/H17-1 -> 0.19008264 | J28: =J17/I17-1 -> 0.035053889 | K28: =K17/J17-1 -> 0.05 | L28: =L17/K17-1 -> 0.05 | M28: =M17/L17-1 -> 0.05 | N28: =N17/M17-1 -> 0.05 | O28: =O17/N17-1 -> 0.05 | ... Q28: =Q17/P17-1 -> 0.05
B29: New Win | H29: =H20/G20-1 -> 1.3460317 | I29: =I20/H20-1 -> 0.069688769 | J29: =J20/I20-1 -> 0.15959087 | K29: =K20/J20-1 -> 0.05 | L29: =L20/K20-1 -> 0.05 | M29: =M20/L20-1 -> 0.05 | N29: =N20/M20-1 -> 0.05 | O29: =O20/N20-1 -> 0.05 | ... Q29: =Q20/P20-1 -> 0.05
B31: COST OF SALES
B32: POCT | G32: =SUMIFS(HY!197:197,HY!$14:$14,FY!G$4) -> -13.86 | H32: =SUMIFS(HY!197:197,HY!$14:$14,FY!H$4) -> -32.516 | I32: =SUMIFS(HY!197:197,HY!$14:$14,FY!I$4) -> -34.782 | J32: =SUMIFS(HY!197:197,HY!$14:$14,FY!J$4) -> -40.33289 | K32: =SUMIFS(HY!197:197,HY!$14:$14,FY!K$4) -> -42.349534 | L32: =SUMIFS(HY!197:197,HY!$14:$14,FY!L$4) -> -44.467011 | M32: =SUMIFS(HY!197:197,HY!$14:$14,FY!M$4) -> -46.690361 | N32: =SUMIFS(HY!197:197,HY!$14:$14,FY!N$4) -> -49.024879 | ... Q32: =SUMIFS(HY!197:197,HY!$14:$14,FY!Q$4) -> -56.752426
B33: Product Fees | G33: =SUMIFS(HY!198:198,HY!$14:$14,FY!G$4) -> -12.4299 | H33: =SUMIFS(HY!198:198,HY!$14:$14,FY!H$4) -> -29.8284 | I33: =SUMIFS(HY!198:198,HY!$14:$14,FY!I$4) -> -33.4887 | J33: =SUMIFS(HY!198:198,HY!$14:$14,FY!J$4) -> -36.176154 | K33: =SUMIFS(HY!198:198,HY!$14:$14,FY!K$4) -> -37.984962 | L33: =SUMIFS(HY!198:198,HY!$14:$14,FY!L$4) -> -39.88421 | M33: =SUMIFS(HY!198:198,HY!$14:$14,FY!M$4) -> -41.87842 | N33: =SUMIFS(HY!198:198,HY!$14:$14,FY!N$4) -> -43.972341 | ... Q33: =SUMIFS(HY!198:198,HY!$14:$14,FY!Q$4) -> -50.903482
B34: NT Licencing Fees | G34: =SUMIFS(HY!199:199,HY!$14:$14,FY!G$4) -> 0 | H34: =SUMIFS(HY!199:199,HY!$14:$14,FY!H$4) -> -1.4 | I34: =SUMIFS(HY!199:199,HY!$14:$14,FY!I$4) -> -2.9 | J34: =SUMIFS(HY!199:199,HY!$14:$14,FY!J$4) -> -1.5 | K34: =SUMIFS(HY!199:199,HY!$14:$14,FY!K$4) -> -0.6 | L34: =SUMIFS(HY!199:199,HY!$14:$14,FY!L$4) -> -0.618 | M34: =SUMIFS(HY!199:199,HY!$14:$14,FY!M$4) -> -0.63654 | N34: =SUMIFS(HY!199:199,HY!$14:$14,FY!N$4) -> -0.6556362 | ... Q34: =SUMIFS(HY!199:199,HY!$14:$14,FY!Q$4) -> -0.71643138
B35: SkyRacing | G35: =SUMIFS(HY!200:200,HY!$14:$14,FY!G$4) -> 0 | H35: =SUMIFS(HY!200:200,HY!$14:$14,FY!H$4) -> 0 | I35: =SUMIFS(HY!200:200,HY!$14:$14,FY!I$4) -> -5.1496 | J35: =SUMIFS(HY!200:200,HY!$14:$14,FY!J$4) -> -6.890696 | K35: =SUMIFS(HY!200:200,HY!$14:$14,FY!K$4) -> -7.2352308 | L35: =SUMIFS(HY!200:200,HY!$14:$14,FY!L$4) -> -7.5969923 | M35: =SUMIFS(HY!200:200,HY!$14:$14,FY!M$4) -> -7.976842 | N35: =SUMIFS(HY!200:200,HY!$14:$14,FY!N$4) -> -8.3756841 | ... Q35: =SUMIFS(HY!200:200,HY!$14:$14,FY!Q$4) -> -9.6959013
B36: Other | G36: =SUMIFS(HY!201:201,HY!$14:$14,FY!G$4) -> -0.5101 | H36: =SUMIFS(HY!201:201,HY!$14:$14,FY!H$4) -> -10.3556 | I36: =SUMIFS(HY!201:201,HY!$14:$14,FY!I$4) -> -8.5797 | J36: =SUMIFS(HY!201:201,HY!$14:$14,FY!J$4) -> -10.946988 | K36: =SUMIFS(HY!201:201,HY!$14:$14,FY!K$4) -> -11.214608 | L36: =SUMIFS(HY!201:201,HY!$14:$14,FY!L$4) -> -11.775338 | M36: =SUMIFS(HY!201:201,HY!$14:$14,FY!M$4) -> -12.364105 | N36: =SUMIFS(HY!201:201,HY!$14:$14,FY!N$4) -> -12.98231 | ... Q36: =SUMIFS(HY!201:201,HY!$14:$14,FY!Q$4) -> -15.028647
B37: ---------- | G37: ---------- | H37: ---------- | I37: ---------- | J37: ---------- | K37: ---------- | L37: ---------- | M37: ---------- | N37: ---------- | O37: ---------- | P37: ---------- | Q37: ----------
B38: Cost of Sales | G38: =SUMIFS(HY!203:203,HY!$14:$14,FY!G$4) -> -26.8 | H38: =SUMIFS(HY!203:203,HY!$14:$14,FY!H$4) -> -73.4 | I38: =SUMIFS(HY!203:203,HY!$14:$14,FY!I$4) -> -84.9 | J38: =SUMIFS(HY!203:203,HY!$14:$14,FY!J$4) -> -95.846727 | K38: =SUMIFS(HY!203:203,HY!$14:$14,FY!K$4) -> -99.384334 | L38: =SUMIFS(HY!203:203,HY!$14:$14,FY!L$4) -> -104.34155 | M38: =SUMIFS(HY!203:203,HY!$14:$14,FY!M$4) -> -109.54627 | N38: =SUMIFS(HY!203:203,HY!$14:$14,FY!N$4) -> -115.01085 | ... Q38: =SUMIFS(HY!203:203,HY!$14:$14,FY!Q$4) -> -133.09689
B40: Cost of Sales % of Net Win | G40: =G38/G20 -> -0.42539683 | H40: =H38/H20 -> -0.49661705 | I40: =I38/I20 -> -0.5370019 | J40: =J38/J20 -> -0.52280608 | K40: =K38/K20 -> -0.51628794 | L40: =L38/L20 -> -0.51622857 | M40: =M38/M20 -> -0.51617033 | N40: =N38/N20 -> -0.5161132 | ... Q40: =Q38/Q20 -> -0.51594826
B41: Cost of Sales % of Turnover | G41: =G38/G12 -> -0.045277919 | H41: =H38/H12 -> -0.051675584 | I41: =I38/I12 -> -0.053238854 | J41: =J38/J12 -> -0.055638343 | K41: =K38/K12 -> -0.054944666 | L41: =L38/L12 -> -0.054938347 | M41: =M38/M12 -> -0.054932149 | N41: =N38/N12 -> -0.054926069 | ... Q41: =Q38/Q12 -> -0.054908516
B43: OPEX
B44: Employee benefits expense | G44: =SUMIFS(HY!221:221,HY!$14:$14,FY!G$4) -> -10 | H44: =SUMIFS(HY!221:221,HY!$14:$14,FY!H$4) -> -21 | I44: =SUMIFS(HY!221:221,HY!$14:$14,FY!I$4) -> -22.4
B45: Licencing, platform and subscriptions | G45: =SUMIFS(HY!222:222,HY!$14:$14,FY!G$4) -> -3.6 | H45: =SUMIFS(HY!222:222,HY!$14:$14,FY!H$4) -> -3.7 | I45: =SUMIFS(HY!222:222,HY!$14:$14,FY!I$4) -> -5.9
B46: Product & Technology expense | G46: =SUMIFS(HY!223:223,HY!$14:$14,FY!G$4) -> -4 | H46: =SUMIFS(HY!223:223,HY!$14:$14,FY!H$4) -> -5.3 | I46: =SUMIFS(HY!223:223,HY!$14:$14,FY!I$4) -> -5.5
B47: Administration and other expenses | G47: =SUMIFS(HY!224:224,HY!$14:$14,FY!G$4) -> -3 | H47: =SUMIFS(HY!224:224,HY!$14:$14,FY!H$4) -> -5.6 | I47: =SUMIFS(HY!224:224,HY!$14:$14,FY!I$4) -> -6.1
B48: ---------- | G48: ---------- | H48: ---------- | I48: ---------- | J48: ---------- | K48: ---------- | L48: ---------- | M48: ---------- | N48: ---------- | O48: ---------- | P48: ---------- | Q48: ----------
B49: Other Opex | G49: =SUMIFS(HY!226:226,HY!$14:$14,FY!G$4) -> -20.6 | H49: =SUMIFS(HY!226:226,HY!$14:$14,FY!H$4) -> -35.6 | I49: =SUMIFS(HY!226:226,HY!$14:$14,FY!I$4) -> -39.9 | J49: =SUMIFS(HY!226:226,HY!$14:$14,FY!J$4) -> -33.5 | K49: =SUMIFS(HY!226:226,HY!$14:$14,FY!K$4) -> -33.219639 | L49: =SUMIFS(HY!226:226,HY!$14:$14,FY!L$4) -> -32.856353 | M49: =SUMIFS(HY!226:226,HY!$14:$14,FY!M$4) -> -32.895482 | N49: =SUMIFS(HY!226:226,HY!$14:$14,FY!N$4) -> -33.426054 | ... Q49: =SUMIFS(HY!226:226,HY!$14:$14,FY!Q$4) -> -38.694836
B50: Advertising & Marketing expense | G50: =SUMIFS(HY!227:227,HY!$14:$14,FY!G$4) -> -10.5 | H50: =SUMIFS(HY!227:227,HY!$14:$14,FY!H$4) -> -19.5 | I50: =SUMIFS(HY!227:227,HY!$14:$14,FY!I$4) -> -28.2 | J50: =SUMIFS(HY!227:227,HY!$14:$14,FY!J$4) -> -21.5 | K50: =SUMIFS(HY!227:227,HY!$14:$14,FY!K$4) -> -21.5 | L50: =SUMIFS(HY!227:227,HY!$14:$14,FY!L$4) -> -21.7396 | M50: =SUMIFS(HY!227:227,HY!$14:$14,FY!M$4) -> -22.82658 | N50: =SUMIFS(HY!227:227,HY!$14:$14,FY!N$4) -> -23.967909 | ... Q50: =SUMIFS(HY!227:227,HY!$14:$14,FY!Q$4) -> -27.745851
B51: ---------- | G51: ---------- | H51: ---------- | I51: ---------- | J51: ---------- | K51: ---------- | L51: ---------- | M51: ---------- | N51: ---------- | O51: ---------- | P51: ---------- | Q51: ----------
B52: Total Operating Expenses | G52: =SUMIFS(HY!229:229,HY!$14:$14,FY!G$4) -> -31.1 | H52: =SUMIFS(HY!229:229,HY!$14:$14,FY!H$4) -> -55.1 | I52: =SUMIFS(HY!229:229,HY!$14:$14,FY!I$4) -> -68.2 | J52: =SUMIFS(HY!229:229,HY!$14:$14,FY!J$4) -> -55 | K52: =SUMIFS(HY!229:229,HY!$14:$14,FY!K$4) -> -54.719639 | L52: =SUMIFS(HY!229:229,HY!$14:$14,FY!L$4) -> -54.595953 | M52: =SUMIFS(HY!229:229,HY!$14:$14,FY!M$4) -> -55.722062 | N52: =SUMIFS(HY!229:229,HY!$14:$14,FY!N$4) -> -57.393963 | ... Q52: =SUMIFS(HY!229:229,HY!$14:$14,FY!Q$4) -> -66.440687
...

Sheet II

Sheet QTR FT
C2: 4Q26 | AD2: 4Q25A | AE2: ="4Q26A" -> 4Q26A | AG2: 4Q26E | AI2: 1H26 | AL2: NOTES
C4: ="BBT " & $C$2 & " - First Take" -> BBT 4Q26 - First Take
E5: =QTR!M2 -> 1Q24A | F5: =QTR!N2 -> 2Q24A | G5: =QTR!O2 -> 3Q24A | H5: =QTR!P2 -> 4Q24A | I5: =QTR!Q2 -> 1Q25A | J5: =QTR!R2 -> 2Q25A | K5: =QTR!S2 -> 3Q25A | L5: =QTR!T2 -> 4Q25A | ... AB5: =QTR!AJ2 -> 4Q29E | AD5: =AD$2 -> 4Q25A | AE5: =AE$2 -> 4Q26A | AF5: YoY % | AG5: ="E&Pe "&AG$2 -> E&Pe 4Q26E | AH5: % diff | AI5: ="VA Cons. "&AG$2 -> VA Cons. 4Q26E | AJ5: % diff | AR5: 1H24 | AS5: 2H24 | AT5: 1H25 | AU5: 2H25 | AV5: 1H26 | AW5: 2H26 | AX5: 1H27 | AY5: 2H27 | AZ5: 1H28 | BA5: 2H28 | BB5: 1H29 | BC5: 2H29 | BD5: 1H30 | BE5: 2H30 | BF5: 1H31 | BG5: 2H31 | BH5: 1H32 | BI5: 2H32 | BJ5: 1H33 | BK5: 2H33 | BL5: 1H34 | BM5: 2H34 | BN5: 1H35 | BO5: 2H35 | BQ5: 1H24 | BR5: 2H24 | BS5: 1H25 | BT5: 2H25 | BU5: 1H26 | BV5: 2H26 | BW5: 1H27 | BX5: 2H27 | BY5: 1H28 | BZ5: 2H28 | CA5: 1H29 | CB5: 2H29 | CC5: 1H30 | CD5: 2H30 | CE5: 1H31 | CF5: 2H31 | CG5: 1H32 | CH5: 2H32 | CI5: 1H33 | CJ5: 2H33 | CK5: 1H34 | CL5: 2H34 | CM5: 1H35 | CN5: 2H35 | CP5: 1H24 | CQ5: 2H24 | CR5: 1H25 | CS5: 2H25 | CT5: 1H26 | CU5: 2H26 | CV5: 1H27 | CW5: 2H27 | CX5: 1H28 | CY5: 2H28 | CZ5: 1H29 | DA5: 2H29 | DB5: 1H30 | DC5: 2H30 | DD5: 1H31 | DE5: 2H31 | DF5: 1H32 | DG5: 2H32 | DH5: 1H33 | DI5: 2H33 | DJ5: 1H34 | DK5: 2H34 | DL5: 1H35 | DM5: 2H35
C6: Wagering KPI's
C7: Turnover | E7: =QTR!M29 -> 143.9 | F7: =QTR!N29 -> 154.8 | G7: =QTR!O29 -> 139.2 | H7: =QTR!P29 -> 153.6 | I7: =QTR!Q29 -> 286.6 | J7: =QTR!R29 -> 357 | K7: =QTR!S29 -> 376 | L7: =QTR!T29 -> 399.5 | ... AB7: =QTR!AJ29 -> 0 | AD7: =_xlfn.SINGLE(_xlfn.XLOOKUP(AD$2,$E$5:$AB$5,$E7:$AB7)) -> 399.5 | AE7: 404.3 | AF7: =AE7/AD7-1 -> 0.012015019 | AG7: =_xlfn.XLOOKUP(AG$2,$E$5:$AB$5,$E7:$AB7) -> 404.3 | AH7: =$AE7/AG7-1 -> 0
C8: Gross Win | E8: =QTR!M35 -> 18.8 | F8: =QTR!N35 -> 21.2 | G8: =QTR!O35 -> 18.6 | H8: =QTR!P35 -> 20.8 | I8: =QTR!Q35 -> 38.8 | J8: =QTR!R35 -> 52.2 | K8: =QTR!S35 -> 51.7 | L8: =QTR!T35 -> 53.1 | ... AB8: =QTR!AJ35 -> 0 | AD8: =_xlfn.SINGLE(_xlfn.XLOOKUP(AD$2,$E$5:$AB$5,$E8:$AB8)) -> 53.1 | AE8: 57.1 | AF8: =AE8/AD8-1 -> 0.075329567 | AG8: =_xlfn.XLOOKUP(AG$2,$E$5:$AB$5,$E8:$AB8) -> 57.1 | AH8: =$AE8/AG8-1 -> 0
C9: Gross Win Margin | E9: =E8/E7 -> 0.13064628 | F9: =F8/F7 -> 0.1369509 | G9: =G8/G7 -> 0.13362069 | H9: =H8/H7 -> 0.13541667 | I9: =I8/I7 -> 0.13538032 | J9: =J8/J7 -> 0.14621849 | K9: =K8/K7 -> 0.1375 | L9: =L8/L7 -> 0.13291615 | ... AB9: =AB8/AB7 -> #DIV/0! | AD9: =_xlfn.XLOOKUP(AD$2,$E$5:$AB$5,$E9:$AB9) -> 0.13291615 | AE9: =AE8/AE7 -> 0.14123176 | AF9: =(AE9-AD9)*100 -> 0.83156134 | AG9: =_xlfn.XLOOKUP(AG$2,$E$5:$AB$5,$E9:$AB9) -> 0.14123176 | AH9: =($AE9-AG9)*100 -> 0 | AI9: =_xlfn.XLOOKUP(AI$2,$BQ$5:$CN$5,$BQ9:$CN9) -> 0.48739496 | AJ9: =($AE9-AI9)*100 -> -34.61632 | AR9: =#REF!/AR3 -> #REF! | AS9: =#REF!/AS3 -> #REF! | AT9: =#REF!/AT3 -> #REF! | AU9: =#REF!/AU3 -> #REF! | AV9: =#REF!/AV3 -> #REF! | AW9: =#REF!/AW3 -> #REF! | AX9: =#REF!/AX3 -> #REF! | AY9: =#REF!/AY3 -> #REF! | ... BO9: =#REF!/BO3 -> #REF! | BQ9: 0.49164678 | BR9: 0.49469214 | BS9: 0.50537634 | BT9: 0.49395161 | BU9: 0.48739496 | BV9: 0.50463822 | BW9: 0.4972067 | BX9: 0.49902913 | BY9: 0.51313131 | BZ9: 0.53030303 | CA9: 0.54659498 | CB9: 0.5242251 | CC9: 0.53169414 | CD9: 0.53410454 | CE9: 0.53407219 | CF9: 0.5316757 | CG9: 0.53400953 | CH9: 0.53835522 | CI9: 0.53872768 | CJ9: 0.53741363 | CK9: 0.53880648 | CL9: 0.542856 | CM9: 0.54355125 | CN9: 0.54088254 | CP9: =E9-BQ9 -> -0.3610005 | CQ9: =F9-BR9 -> -0.35774124 | CR9: =G9-BS9 -> -0.37175565 | CS9: =H9-BT9 -> -0.35853495 | CT9: =I9-BU9 -> -0.35201464 | CU9: =J9-BV9 -> -0.35841973 | CV9: =K9-BW9 -> -0.3597067 | CW9: =L9-BX9 -> -0.36611298 | ... DM9: =AB9-CN9 -> #DIV/0!
C10: Net Win | E10: =QTR!M41 -> 14.5 | F10: =QTR!N41 -> 16.2 | G10: =QTR!O41 -> 15.3 | H10: =QTR!P41 -> 17.3 | I10: =QTR!Q41 -> 27.9 | J10: =QTR!R41 -> 39.2 | K10: =QTR!S41 -> 37.8 | L10: =QTR!T41 -> 40.2 | ... AB10: =QTR!AJ41 -> 0 | AD10: =_xlfn.SINGLE(_xlfn.XLOOKUP(AD$2,$E$5:$AB$5,$E10:$AB10)) -> 40.2 | AE10: 43.9 | AF10: =AE10/AD10-1 -> 0.092039801 | AG10: =_xlfn.XLOOKUP(AG$2,$E$5:$AB$5,$E10:$AB10) -> 43.9 | AH10: =$AE10/AG10-1 -> 0
C11: Net Win Margin | E11: =E10/E7 -> 0.10076442 | F11: =F10/F7 -> 0.10465116 | G11: =G10/G7 -> 0.10991379 | H11: =H10/H7 -> 0.11263021 | I11: =I10/I7 -> 0.097348221 | J11: =J10/J7 -> 0.10980392 | K11: =K10/K7 -> 0.10053191 | L11: =L10/L7 -> 0.10062578 | ... AB11: =AB10/AB7 -> #DIV/0! | AD11: =_xlfn.XLOOKUP(AD$2,$E$5:$AB$5,$E11:$AB11) -> 0.10062578 | AE11: =AE10/AE7 -> 0.10858274 | AF11: =(AE11-AD11)*100 -> 0.79569534 | AG11: =_xlfn.XLOOKUP(AG$2,$E$5:$AB$5,$E11:$AB11) -> 0.10858274 | AH11: =($AE11-AG11)*100 -> 0 | AI11: =_xlfn.XLOOKUP(AI$2,$BQ$5:$CN$5,$BQ11:$CN11) -> 0.48739496 | AJ11: =($AE11-AI11)*100 -> -37.881222 | AR11: =#REF!/AR5 -> #REF! | AS11: =#REF!/AS5 -> #REF! | AT11: =#REF!/AT5 -> #REF! | AU11: =#REF!/AU5 -> #REF! | AV11: =#REF!/AV5 -> #REF! | AW11: =#REF!/AW5 -> #REF! | AX11: =#REF!/AX5 -> #REF! | AY11: =#REF!/AY5 -> #REF! | ... BO11: =#REF!/BO5 -> #REF! | BQ11: 0.49164678 | BR11: 0.49469214 | BS11: 0.50537634 | BT11: 0.49395161 | BU11: 0.48739496 | BV11: 0.50463822 | BW11: 0.4972067 | BX11: 0.49902913 | BY11: 0.51313131 | BZ11: 0.53030303 | CA11: 0.54659498 | CB11: 0.5242251 | CC11: 0.53169414 | CD11: 0.53410454 | CE11: 0.53407219 | CF11: 0.5316757 | CG11: 0.53400953 | CH11: 0.53835522 | CI11: 0.53872768 | CJ11: 0.53741363 | CK11: 0.53880648 | CL11: 0.542856 | CM11: 0.54355125 | CN11: 0.54088254 | CP11: =E11-BQ11 -> -0.39088236 | CQ11: =F11-BR11 -> -0.39004098 | CR11: =G11-BS11 -> -0.39546255 | CS11: =H11-BT11 -> -0.3813214 | CT11: =I11-BU11 -> -0.39004674 | CU11: =J11-BV11 -> -0.3948343 | CV11: =K11-BW11 -> -0.39667479 | CW11: =L11-BX11 -> -0.39840334 | ... DM11: =AB11-CN11 -> #DIV/0!
E13: =E$5 -> 1Q24A | F13: =F$5 -> 2Q24A | G13: =G$5 -> 3Q24A | H13: =H$5 -> 4Q24A | I13: =I$5 -> 1Q25A | J13: =J$5 -> 2Q25A | K13: =K$5 -> 3Q25A | L13: =L$5 -> 4Q25A | ... AB13: =AB$5 -> 4Q29E | AD13: =AD$2 -> 4Q25A | AE13: =AE$2 -> 4Q26A | AF13: YoY % | AG13: ="E&Pe "&AG$2 -> E&Pe 4Q26E | AH13: % diff | AI13: ="VA Cons. "&AG$2 -> VA Cons. 4Q26E | AJ13: % diff | AR13: 1H24 | AS13: 2H24 | AT13: 1H25 | AU13: 2H25 | AV13: 1H26 | AW13: 2H26 | AX13: 1H27 | AY13: 2H27 | AZ13: 1H28 | BA13: 2H28 | BB13: 1H29 | BC13: 2H29 | BD13: 1H30 | BE13: 2H30 | BF13: 1H31 | BG13: 2H31 | BH13: 1H32 | BI13: 2H32 | BJ13: 1H33 | BK13: 2H33 | BL13: 1H34 | BM13: 2H34 | BN13: 1H35 | BO13: 2H35 | BQ13: 1H24 | BR13: 2H24 | BS13: 1H25 | BT13: 2H25 | BU13: 1H26 | BV13: 2H26 | BW13: 1H27 | BX13: 2H27 | BY13: 1H28 | BZ13: 2H28 | CA13: 1H29 | CB13: 2H29 | CC13: 1H30 | CD13: 2H30 | CE13: 1H31 | CF13: 2H31 | CG13: 1H32 | CH13: 2H32 | CI13: 1H33 | CJ13: 2H33 | CK13: 1H34 | CL13: 2H34 | CM13: 1H35 | CN13: 2H35 | CP13: 1H24 | CQ13: 2H24 | CR13: 1H25 | CS13: 2H25 | CT13: 1H26 | CU13: 2H26 | CV13: 1H27 | CW13: 2H27 | CX13: 1H28 | CY13: 2H28 | CZ13: 1H29 | DA13: 2H29 | DB13: 1H30 | DC13: 2H30 | DD13: 1H31 | DE13: 2H31 | DF13: 1H32 | DG13: 2H32 | DH13: 1H33 | DI13: 2H33 | DJ13: 1H34 | DK13: 2H34 | DL13: 1H35 | DM13: 2H35
C14: Costs
C15: Cost of Sales | E15: =QTR!M55 -> 0 | F15: =QTR!N55 -> 0 | G15: =QTR!O55 -> 0 | H15: =QTR!P55 -> 0 | I15: =QTR!Q55 -> -10.6027 | J15: =QTR!R55 -> -19.7536 | K15: =QTR!S55 -> -17.3842 | L15: =QTR!T55 -> -22.2244 | ... AB15: =QTR!AJ55 -> 0 | AD15: =_xlfn.XLOOKUP(AD$2,$E$5:$AB$5,$E15:$AB15) -> -22.2244 | AF15: =AE15/AD15-1 -> -1 | AG15: =_xlfn.XLOOKUP(AG$2,$E$5:$AB$5,$E15:$AB15) -> -23.3236 | AH15: =$AE15/AG15-1 -> -1 | AI15: =_xlfn.XLOOKUP(AI$2,$BQ$5:$CN$5,$BQ15:$CN15) -> 0 | AJ15: =$AE15/AI15-1 -> #DIV/0!
C16: Advertising & Marketing | E16: =QTR!M48 -> 0 | F16: =QTR!N48 -> 0 | G16: =QTR!O48 -> 0 | H16: =QTR!P48 -> 0 | I16: =QTR!Q48 -> -2.9 | J16: =QTR!R48 -> -7 | K16: =QTR!S48 -> -3.6 | L16: =QTR!T48 -> -5.5 | ... AB16: =QTR!AJ48 -> 0 | AD16: =_xlfn.XLOOKUP(AD$2,$E$5:$AB$5,$E16:$AB16) -> -5.5 | AF16: =AE16/AD16-1 -> -1 | AG16: =_xlfn.XLOOKUP(AG$2,$E$5:$AB$5,$E16:$AB16) -> -4.0542 | AH16: =$AE16/AG16-1 -> -1 | AI16: =_xlfn.XLOOKUP(AI$2,$BQ$5:$CN$5,$BQ16:$CN16) -> 0 | AJ16: =$AE16/AI16-1 -> #DIV/0!
C18: % of Net Win
C19: Cost of Sales | E19: =E15/E$10 -> 0 | F19: =F15/F$10 -> 0 | G19: =G15/G$10 -> 0 | H19: =H15/H$10 -> 0 | I19: =I15/I$10 -> -0.38002509 | J19: =J15/J$10 -> -0.50391837 | K19: =K15/K$10 -> -0.45989947 | L19: =L15/L$10 -> -0.55284577 | ... AB19: =AB15/AB$10 -> #DIV/0! | AD19: =_xlfn.XLOOKUP(AD$2,$E$5:$AB$5,$E19:$AB19) -> -0.55284577 | AE19: =AE15/AE10 -> 0 | AF19: =(AE19-AD19)*100 -> 55.284577 | AG19: =_xlfn.XLOOKUP(AG$2,$E$5:$AB$5,$E19:$AB19) -> -0.53128929 | AH19: =($AE19-AG19)*100 -> 53.128929 | AI19: =_xlfn.XLOOKUP(AI$2,$BQ$5:$CN$5,$BQ19:$CN19) -> 0.48739496 | AJ19: =($AE19-AI19)*100 -> -48.739496 | AR19: =AR14/AR11 -> #REF! | AS19: =AS14/AS11 -> #REF! | AT19: =AT14/AT11 -> #REF! | AU19: =AU14/AU11 -> #REF! | AV19: =AV14/AV11 -> #REF! | AW19: =AW14/AW11 -> #REF! | AX19: =AX14/AX11 -> #REF! | AY19: =AY14/AY11 -> #REF! | ... BO19: =BO14/BO11 -> #REF! | BQ19: 0.49164678 | BR19: 0.49469214 | BS19: 0.50537634 | BT19: 0.49395161 | BU19: 0.48739496 | BV19: 0.50463822 | BW19: 0.4972067 | BX19: 0.49902913 | BY19: 0.51313131 | BZ19: 0.53030303 | CA19: 0.54659498 | CB19: 0.5242251 | CC19: 0.53169414 | CD19: 0.53410454 | CE19: 0.53407219 | CF19: 0.5316757 | CG19: 0.53400953 | CH19: 0.53835522 | CI19: 0.53872768 | CJ19: 0.53741363 | CK19: 0.53880648 | CL19: 0.542856 | CM19: 0.54355125 | CN19: 0.54088254 | CP19: =E19-BQ19 -> -0.49164678 | CQ19: =F19-BR19 -> -0.49469214 | CR19: =G19-BS19 -> -0.50537634 | CS19: =H19-BT19 -> -0.49395161 | CT19: =I19-BU19 -> -0.86742005 | CU19: =J19-BV19 -> -1.0085566 | CV19: =K19-BW19 -> -0.95710617 | CW19: =L19-BX19 -> -1.0518749 | ... DM19: =AB19-CN19 -> #DIV/0!
C20: Advertising & Marketing | E20: =E16/E$10 -> 0 | F20: =F16/F$10 -> 0 | G20: =G16/G$10 -> 0 | H20: =H16/H$10 -> 0 | I20: =I16/I$10 -> -0.10394265 | J20: =J16/J$10 -> -0.17857143 | K20: =K16/K$10 -> -0.095238095 | L20: =L16/L$10 -> -0.13681592 | ... AB20: =AB16/AB$10 -> #DIV/0! | AD20: =_xlfn.XLOOKUP(AD$2,$E$5:$AB$5,$E20:$AB20) -> -0.13681592 | AE20: =AE16/AE10 -> 0 | AF20: =(AE20-AD20)*100 -> 13.681592 | AG20: =_xlfn.XLOOKUP(AG$2,$E$5:$AB$5,$E20:$AB20) -> -0.092350797 | AH20: =($AE20-AG20)*100 -> 9.2350797 | AI20: =_xlfn.XLOOKUP(AI$2,$BQ$5:$CN$5,$BQ20:$CN20) -> 0.48739496 | AJ20: =($AE20-AI20)*100 -> -48.739496 | AR20: =AR15/AR12 -> #DIV/0! | AS20: =AS15/AS12 -> #DIV/0! | AT20: =AT15/AT12 -> #DIV/0! | AU20: =AU15/AU12 -> #DIV/0! | AV20: =AV15/AV12 -> #DIV/0! | AW20: =AW15/AW12 -> #DIV/0! | AX20: =AX15/AX12 -> #DIV/0! | AY20: =AY15/AY12 -> #DIV/0! | ... BO20: =BO15/BO12 -> #DIV/0! | BQ20: 0.49164678 | BR20: 0.49469214 | BS20: 0.50537634 | BT20: 0.49395161 | BU20: 0.48739496 | BV20: 0.50463822 | BW20: 0.4972067 | BX20: 0.49902913 | BY20: 0.51313131 | BZ20: 0.53030303 | CA20: 0.54659498 | CB20: 0.5242251 | CC20: 0.53169414 | CD20: 0.53410454 | CE20: 0.53407219 | CF20: 0.5316757 | CG20: 0.53400953 | CH20: 0.53835522 | CI20: 0.53872768 | CJ20: 0.53741363 | CK20: 0.53880648 | CL20: 0.542856 | CM20: 0.54355125 | CN20: 0.54088254 | CP20: =E20-BQ20 -> -0.49164678 | CQ20: =F20-BR20 -> -0.49469214 | CR20: =G20-BS20 -> -0.50537634 | CS20: =H20-BT20 -> -0.49395161 | CT20: =I20-BU20 -> -0.59133761 | CU20: =J20-BV20 -> -0.68320965 | CV20: =K20-BW20 -> -0.5924448 | CW20: =L20-BX20 -> -0.63584505 | ... DM20: =AB20-CN20 -> #DIV/0!

Sheet HY FT
C2: 1H26 | AD2: 1H25A | AE2: ="1H26A" -> 1H26A | AG2: 1H27E | AI2: 1H27E | AL2: NOTES
C4: ="BBT " & $C$2 & " - First Take" -> BBT 1H26 - First Take
E5: =HY!E7 -> 1H24A | F5: =HY!F7 -> 2H24A | G5: =HY!G7 -> 1H25A | H5: =HY!H7 -> 2H25A | I5: =HY!I7 -> 1H26A | J5: =HY!J7 -> 2H26A | K5: =HY!K7 -> 1H27E | L5: =HY!L7 -> 2H27E | ... AB5: =HY!AB7 -> 2H35E | AD5: =AD$2 -> 1H25A | AE5: =AE$2 -> 1H26A | AF5: YoY % | AG5: ="E&Pe "&AG$2 -> E&Pe 1H27E | AH5: % diff | AI5: ="VA Cons. "&AG$2 -> VA Cons. 1H27E | AJ5: % diff | AR5: 1H24 | AS5: 2H24 | AT5: 1H25 | AU5: 2H25 | AV5: 1H26 | AW5: 2H26 | AX5: 1H27 | AY5: 2H27 | AZ5: 1H28 | BA5: 2H28 | BB5: 1H29 | BC5: 2H29 | BD5: 1H30 | BE5: 2H30 | BF5: 1H31 | BG5: 2H31 | BH5: 1H32 | BI5: 2H32 | BJ5: 1H33 | BK5: 2H33 | BL5: 1H34 | BM5: 2H34 | BN5: 1H35 | BO5: 2H35 | BQ5: 1H24 | BR5: 2H24 | BS5: 1H25 | BT5: 2H25 | BU5: 1H26 | BV5: 2H26 | BW5: 1H27 | BX5: 2H27 | BY5: 1H28 | BZ5: 2H28 | CA5: 1H29 | CB5: 2H29 | CC5: 1H30 | CD5: 2H30 | CE5: 1H31 | CF5: 2H31 | CG5: 1H32 | CH5: 2H32 | CI5: 1H33 | CJ5: 2H33 | CK5: 1H34 | CL5: 2H34 | CM5: 1H35 | CN5: 2H35 | CP5: 1H24 | CQ5: 2H24 | CR5: 1H25 | CS5: 2H25 | CT5: 1H26 | CU5: 2H26 | CV5: 1H27 | CW5: 2H27 | CX5: 1H28 | CY5: 2H28 | CZ5: 1H29 | DA5: 2H29 | DB5: 1H30 | DC5: 2H30 | DD5: 1H31 | DE5: 2H31 | DF5: 1H32 | DG5: 2H32 | DH5: 1H33 | DI5: 2H33 | DJ5: 1H34 | DK5: 2H34 | DL5: 1H35 | DM5: 2H35
C6: P&L - Normalised
C7: Revenue | E7: =HY!E112 -> 27.9 | F7: =HY!F112 -> 29.7 | G7: =HY!G112 -> 63.6 | H7: =HY!H112 -> 71 | I7: =HY!I112 -> 68.9 | J7: =HY!J112 -> 76.5 | K7: =HY!K112 -> 83.9592 | L7: =HY!L112 -> 82.705633 | ... AB7: =HY!AB112 -> 122.19389 | AD7: =_xlfn.XLOOKUP(AD$2,$E$5:$AB$5,$E7:$AB7) -> 63.6 | AF7: =AE7/AD7-1 -> -1 | AG7: =_xlfn.XLOOKUP(AG$2,$E$5:$AB$5,$E7:$AB7) -> 83.9592 | AH7: =$AE7/AG7-1 -> -1 | AI7: =_xlfn.XLOOKUP(AI$2,$BQ$5:$CN$5,$BQ7:$CN7) -> #N/A | AJ7: =$AE7/AI7-1 -> #N/A | AN7: BBT_AU | AO7: Total revenue | AP7: consensus.vaactuals | AR7: =_xll.VAData($AN7,AR$5,$AO7,$AP7) -> #NotAvailable | AS7: =_xll.VAData($AN7,AS$5,$AO7,$AP7) -> #NotAvailable | AT7: =_xll.VAData($AN7,AT$5,$AO7,$AP7) -> #NotAvailable | AU7: =_xll.VAData($AN7,AU$5,$AO7,$AP7) -> #NotAvailable | AV7: =_xll.VAData($AN7,AV$5,$AO7,$AP7) -> #NotAvailable | AW7: =_xll.VAData($AN7,AW$5,$AO7,$AP7) -> #NotAvailable | AX7: =_xll.VAData($AN7,AX$5,$AO7,$AP7) -> #NotAvailable | AY7: =_xll.VAData($AN7,AY$5,$AO7,$AP7) -> #NotAvailable | ... BO7: =_xll.VAData($AN7,BO$5,$AO7,$AP7) -> #NotAvailable | BQ7: 670 | BR7: 731 | BS7: 731 | BT7: 770 | BU7: 756 | BV7: 818 | BW7: 817 | BX7: 797 | BY7: 774 | BZ7: 809 | CA7: 841 | CB7: 905.3682 | CC7: 875.46347 | CD7: 898.12114 | CE7: 908.46086 | CF7: 944.75271 | CG7: 931.68799 | CH7: 950.03303 | CI7: 959.12289 | CJ7: 1007.0197 | CK7: 1002.1748 | CL7: 1019.648 | CM7: 1027.268 | CN7: 1068.7797 | CP7: =E7-BQ7 -> -642.1 | CQ7: =F7-BR7 -> -701.3 | CR7: =G7-BS7 -> -667.4 | CS7: =H7-BT7 -> -699 | CT7: =I7-BU7 -> -687.1 | CU7: =J7-BV7 -> -741.5 | CV7: =K7-BW7 -> -733.0408 | CW7: =L7-BX7 -> -714.29437 | ... DM7: =AB7-CN7 -> -946.58581
C8: AEBITDA | E8: =HY!E119 -> -1.7 | F8: =HY!F119 -> 1.9 | G8: =HY!G119 -> 1.7 | H8: =HY!H119 -> 5.5 | I8: =HY!I119 -> -13.2 | J8: =HY!J119 -> 6.1 | K8: =HY!K119 -> 5.4973804 | L8: =HY!L119 -> 10.974313 | ... AB8: =HY!AB119 -> 20.655618 | AD8: =_xlfn.XLOOKUP(AD$2,$E$5:$AB$5,$E8:$AB8) -> 1.7 | AF8: =AE8/AD8-1 -> -1 | AG8: =_xlfn.XLOOKUP(AG$2,$E$5:$AB$5,$E8:$AB8) -> 5.4973804 | AH8: =$AE8/AG8-1 -> -1 | AI8: =_xlfn.XLOOKUP(AI$2,$BQ$5:$CN$5,$BQ8:$CN8) -> #N/A | AJ8: =$AE8/AI8-1 -> #N/A | AN8: LNW_AU | AO8: EBITDA - operating (incl. equity investments) | AP8: consensus.vaactuals | AR8: =_xll.VAData($AN8,AR$5,$AO8,$AP8) -> 611 | AS8: =_xll.VAData($AN8,AS$5,$AO8,$AP8) -> 633 | AT8: =_xll.VAData($AN8,AT$5,$AO8,$AP8) -> 663 | AU8: =_xll.VAData($AN8,AU$5,$AO8,$AP8) -> 780 | AV8: =_xll.VAData($AN8,AV$5,$AO8,$AP8) -> 710 | AW8: =_xll.VAData($AN8,AW$5,$AO8,$AP8) -> 811.54578 | AX8: =_xll.VAData($AN8,AX$5,$AO8,$AP8) -> 787.47314 | AY8: =_xll.VAData($AN8,AY$5,$AO8,$AP8) -> 871.99966 | ... BO8: =_xll.VAData($AN8,BO$5,$AO8,$AP8) -> 1298.5502 | BQ8: 249 | BR8: 281 | BS8: 286 | BT8: 302 | BU8: 281 | BV8: 330 | BW8: 319 | BX8: 315 | BY8: 311 | BZ8: 352 | CA8: 375 | CB8: 398.4559 | CC8: 375.8389 | CD8: 393.4508 | CE8: 398.89711 | CF8: 420.22789 | CG8: 412.25929 | CH8: 427.15191 | CI8: 430.79264 | CJ8: 458.49148 | CK8: 453.39751 | CL8: 466.6607 | CM8: 470.28873 | CN8: 491.94915 | CP8: =E8-BQ8 -> -250.7 | CQ8: =F8-BR8 -> -279.1 | CR8: =G8-BS8 -> -284.3 | CS8: =H8-BT8 -> -296.5 | CT8: =I8-BU8 -> -294.2 | CU8: =J8-BV8 -> -323.9 | CV8: =K8-BW8 -> -313.50262 | CW8: =L8-BX8 -> -304.02569 | ... DM8: =AB8-CN8 -> -471.29353
C9: NPAT | E9: =HY!E123 -> 0 | F9: =HY!F123 -> 0 | G9: =HY!G123 -> -0.4 | H9: =HY!H123 -> 0.6 | I9: =HY!I123 -> -19 | J9: =HY!J123 -> -1.8 | K9: =HY!K123 -> -0.16466657 | L9: =HY!L123 -> 5.3351073 | ... AB9: =HY!AB123 -> 14.217181 | AD9: =_xlfn.XLOOKUP(AD$2,$E$5:$AB$5,$E9:$AB9) -> -0.4 | AF9: =AE9/AD9-1 -> -1 | AG9: =_xlfn.XLOOKUP(AG$2,$E$5:$AB$5,$E9:$AB9) -> -0.16466657 | AH9: =$AE9/AG9-1 -> -1 | AI9: =_xlfn.XLOOKUP(AI$2,$BQ$5:$CN$5,$BQ9:$CN9) -> #N/A | AJ9: =$AE9/AI9-1 -> #N/A | AN9: LNW_AU | AO9: NPATA - Operating | AP9: consensus.vaactuals | AR9: =_xll.VAData($AN9,AR$5,$AO9,$AP9) -> 235 | AS9: =_xll.VAData($AN9,AS$5,$AO9,$AP9) -> 249 | AT9: =_xll.VAData($AN9,AT$5,$AO9,$AP9) -> 252 | AU9: =_xll.VAData($AN9,AU$5,$AO9,$AP9) -> 315 | AV9: =_xll.VAData($AN9,AV$5,$AO9,$AP9) -> 271 | AW9: =_xll.VAData($AN9,AW$5,$AO9,$AP9) -> 328.9725 | AX9: =_xll.VAData($AN9,AX$5,$AO9,$AP9) -> 321.09662 | AY9: =_xll.VAData($AN9,AY$5,$AO9,$AP9) -> 383.19396 | ... BO9: =_xll.VAData($AN9,BO$5,$AO9,$AP9) -> 686.03927 | BQ9: 86 | BR9: 93 | BS9: 99 | BT9: 109 | BU9: 105 | BV9: 130 | BW9: 122 | BX9: 127 | BY9: 117 | BZ9: 135 | CA9: 153 | CB9: 151.96383 | CC9: 154.71254 | CD9: 160.77721 | CE9: 164.37328 | CF9: 176.85627 | CG9: 173.51213 | CH9: 182.93768 | CI9: 185.36362 | CJ9: 209.74325 | CK9: 205.58916 | CL9: 214.24141 | CM9: 218.22522 | CN9: 232.70408 | CP9: =E9-BQ9 -> -86 | CQ9: =F9-BR9 -> -93 | CR9: =G9-BS9 -> -99.4 | CS9: =H9-BT9 -> -108.4 | CT9: =I9-BU9 -> -124 | CU9: =J9-BV9 -> -131.8 | CV9: =K9-BW9 -> -122.16467 | CW9: =L9-BX9 -> -121.66489 | ... DM9: =AB9-CN9 -> -218.4869
C11: Wagering KPI's
C12: Turnover | E12: =HY!E64 -> 298.8 | F12: =HY!F64 -> 293.1 | G12: =HY!G64 -> 645.1 | H12: =HY!H64 -> 775.3 | I12: =HY!I64 -> 807.3 | J12: =HY!J64 -> 787.4 | K12: =HY!K64 -> 888.03 | L12: =HY!L64 -> 834.644 | ... AB12: =HY!AB64 -> 1233.1493 | AD12: =_xlfn.SINGLE(_xlfn.XLOOKUP(AD$2,$E$5:$AB$5,$E12:$AB12)) -> 645.1 | AF12: =AE12/AD12-1 -> -1 | AG12: =_xlfn.XLOOKUP(AG$2,$E$5:$AB$5,$E12:$AB12) -> 888.03 | AH12: =$AE12/AG12-1 -> -1
C13: Gross Win | E13: =HY!E68 -> 40 | F13: =HY!F68 -> 39.5 | G13: =HY!G68 -> 91.3 | H13: =HY!H68 -> 104.9 | I13: =HY!I68 -> 108.3 | J13: =HY!J68 -> 107.4 | K13: =HY!K68 -> 126.10026 | L13: =HY!L68 -> 116.85016 | ... AB13: =HY!AB68 -> 172.6409 | AD13: =_xlfn.SINGLE(_xlfn.XLOOKUP(AD$2,$E$5:$AB$5,$E13:$AB13)) -> 91.3 | AF13: =AE13/AD13-1 -> -1 | AG13: =_xlfn.XLOOKUP(AG$2,$E$5:$AB$5,$E13:$AB13) -> 126.10026 | AH13: =$AE13/AG13-1 -> -1
C14: Gross Win Margin | E14: =E13/E12 -> 0.13386881 | F14: =F13/F12 -> 0.13476629 | G14: =G13/G12 -> 0.14152845 | H14: =H13/H12 -> 0.13530246 | I14: =I13/I12 -> 0.13415087 | J14: =J13/J12 -> 0.13639827 | K14: =K13/K12 -> 0.142 | L14: =L13/L12 -> 0.14 | ... AB14: =AB13/AB12 -> 0.14 | AD14: =_xlfn.XLOOKUP(AD$2,$E$5:$AB$5,$E14:$AB14) -> 0.14152845 | AF14: =(AE14-AD14)*100 -> -14.152845 | AG14: =_xlfn.XLOOKUP(AG$2,$E$5:$AB$5,$E14:$AB14) -> 0.142 | AH14: =($AE14-AG14)*100 -> -14.2 | AI14: =_xlfn.XLOOKUP(AI$2,$BQ$5:$CN$5,$BQ14:$CN14) -> #N/A | AJ14: =($AE14-AI14)*100 -> #N/A | AR14: =AR8/AR3 -> #DIV/0! | AS14: =AS8/AS3 -> #DIV/0! | AT14: =AT8/AT3 -> #DIV/0! | AU14: =AU8/AU3 -> #DIV/0! | AV14: =AV8/AV3 -> #DIV/0! | AW14: =AW8/AW3 -> #DIV/0! | AX14: =AX8/AX3 -> #DIV/0! | AY14: =AY8/AY3 -> #DIV/0! | ... BO14: =BO8/BO3 -> #DIV/0! | BQ14: 0.49164678 | BR14: 0.49469214 | BS14: 0.50537634 | BT14: 0.49395161 | BU14: 0.48739496 | BV14: 0.50463822 | BW14: 0.4972067 | BX14: 0.49902913 | BY14: 0.51313131 | BZ14: 0.53030303 | CA14: 0.54659498 | CB14: 0.5242251 | CC14: 0.53169414 | CD14: 0.53410454 | CE14: 0.53407219 | CF14: 0.5316757 | CG14: 0.53400953 | CH14: 0.53835522 | CI14: 0.53872768 | CJ14: 0.53741363 | CK14: 0.53880648 | CL14: 0.542856 | CM14: 0.54355125 | CN14: 0.54088254 | CP14: =E14-BQ14 -> -0.35777797 | CQ14: =F14-BR14 -> -0.35992585 | CR14: =G14-BS14 -> -0.3638479 | CS14: =H14-BT14 -> -0.35864915 | CT14: =I14-BU14 -> -0.35324408 | CU14: =J14-BV14 -> -0.36823995 | CV14: =K14-BW14 -> -0.3552067 | CW14: =L14-BX14 -> -0.35902913 | ... DM14: =AB14-CN14 -> -0.40088254
C15: Net Win | E15: =HY!E75 -> 30.7 | F15: =HY!F75 -> 32.3 | G15: =HY!G75 -> 67.4 | H15: =HY!H75 -> 80.4 | I15: =HY!I75 -> 75.8 | J15: =HY!J75 -> 82.3 | K15: =HY!K75 -> 92.35512 | L15: =HY!L75 -> 90.976196 | ... AB15: =HY!AB75 -> 134.41328 | AD15: =_xlfn.SINGLE(_xlfn.XLOOKUP(AD$2,$E$5:$AB$5,$E15:$AB15)) -> 67.4 | AF15: =AE15/AD15-1 -> -1 | AG15: =_xlfn.XLOOKUP(AG$2,$E$5:$AB$5,$E15:$AB15) -> 92.35512 | AH15: =$AE15/AG15-1 -> -1
C16: Net Win Margin | E16: =E15/E12 -> 0.10274431 | F16: =F15/F12 -> 0.1102013 | G16: =G15/G12 -> 0.10447993 | H16: =H15/H12 -> 0.10370179 | I16: =I15/I12 -> 0.093893224 | J16: =J15/J12 -> 0.10452121 | K16: =K15/K12 -> 0.104 | L16: =L15/L12 -> 0.109 | ... AB16: =AB15/AB12 -> 0.109 | AD16: =_xlfn.XLOOKUP(AD$2,$E$5:$AB$5,$E16:$AB16) -> 0.10447993 | AF16: =(AE16-AD16)*100 -> -10.447993 | AG16: =_xlfn.XLOOKUP(AG$2,$E$5:$AB$5,$E16:$AB16) -> 0.104 | AH16: =($AE16-AG16)*100 -> -10.4 | AI16: =_xlfn.XLOOKUP(AI$2,$BQ$5:$CN$5,$BQ16:$CN16) -> #N/A | AJ16: =($AE16-AI16)*100 -> #N/A | AR16: =AR10/AR5 -> #VALUE! | AS16: =AS10/AS5 -> #VALUE! | AT16: =AT10/AT5 -> #VALUE! | AU16: =AU10/AU5 -> #VALUE! | AV16: =AV10/AV5 -> #VALUE! | AW16: =AW10/AW5 -> #VALUE! | AX16: =AX10/AX5 -> #VALUE! | AY16: =AY10/AY5 -> #VALUE! | ... BO16: =BO10/BO5 -> #VALUE! | BQ16: 0.49164678 | BR16: 0.49469214 | BS16: 0.50537634 | BT16: 0.49395161 | BU16: 0.48739496 | BV16: 0.50463822 | BW16: 0.4972067 | BX16: 0.49902913 | BY16: 0.51313131 | BZ16: 0.53030303 | CA16: 0.54659498 | CB16: 0.5242251 | CC16: 0.53169414 | CD16: 0.53410454 | CE16: 0.53407219 | CF16: 0.5316757 | CG16: 0.53400953 | CH16: 0.53835522 | CI16: 0.53872768 | CJ16: 0.53741363 | CK16: 0.53880648 | CL16: 0.542856 | CM16: 0.54355125 | CN16: 0.54088254 | CP16: =E16-BQ16 -> -0.38890247 | CQ16: =F16-BR16 -> -0.38449085 | CR16: =G16-BS16 -> -0.40089642 | CS16: =H16-BT16 -> -0.39024982 | CT16: =I16-BU16 -> -0.39350173 | CU16: =J16-BV16 -> -0.40011701 | CV16: =K16-BW16 -> -0.3932067 | CW16: =L16-BX16 -> -0.39002913 | ... DM16: =AB16-CN16 -> -0.43188254
