Workbook

Sheet EMAIL LIST
B1: Name | C1: Fund | D1: Type | E1: Notes | F1: Email | G1: Gaming | I1: ALL | J1: LNW | K1: TLC | L1: JIN | M1: TAH | N1: PBH | O1: SKC | P1: SGR | R1: Paste
B2: Matt Tripp | C2: Melbourne Storm | D2: Industry | F2: matt@trippgroup.com.au | G2: 1 | I2: 1 | J2: 1 | K2: 1 | L2: 1 | M2: 1 | N2: 1 | O2: 1 | P2: 1 | R2: =F2&";" -> matt@trippgroup.com.au;
B3: Tim Hall | C3: Fairview Equity Partners Pty Ltd | D3: Small Cap Fund | F3: tim.hall@fairviewequity.com.au | G3: 1 | I3: 1 | J3: 1 | K3: 1 | L3: 1 | M3: 1 | N3: 1 | O3: 1 | P3: 1 | R3: =F3&";" -> tim.hall@fairviewequity.com.au;
B4: William Earnshaw | C4: Solaris Investment Management Limited | D4: Small Cap Fund | F4: william.earnshaw@solariswealth.com.au | G4: 1 | I4: 1 | J4: 1 | K4: 1 | L4: 1 | M4: 1 | N4: 1 | O4: 1 | P4: 1 | R4: =F4&";" -> william.earnshaw@solariswealth.com.au;
B5: Andrew McLennan | C5: Solaris Investment Management Limited | D5: Small Cap Fund | F5: andrew.mclennan@solariswealth.com.au | G5: 1 | I5: 1 | J5: 1 | K5: 1 | L5: 1 | M5: 1 | N5: 1 | O5: 1 | P5: 1 | R5: =F5&";" -> andrew.mclennan@solariswealth.com.au;
B6: Guy Robinson | C6: Accident Compensation Corporation | F6: guy.robinson@acc.co.nz | G6: 1 | I6: 1 | J6: 1 | K6: 1 | L6: 1 | M6: 1 | N6: 1 | O6: 1 | P6: 1 | R6: =F6&";" -> guy.robinson@acc.co.nz;
B7: Matt Williams | C7: Airlie Funds Management | F7: matt.williams@airliefm.com.au | G7: 1 | I7: 1 | J7: 1 | K7: 1 | L7: 1 | M7: 1 | N7: 1 | O7: 1 | P7: 1 | R7: =F7&";" -> matt.williams@airliefm.com.au;
B8: Jack McNally | C8: Airlie Funds Management | F8: jack.mcnally@airliefm.com.au | G8: 1 | I8: 1 | J8: 1 | K8: 1 | L8: 1 | M8: 1 | N8: 1 | O8: 1 | P8: 1 | R8: =F8&";" -> jack.mcnally@airliefm.com.au;
B9: Will Granger | C9: Airlie Funds Management | F9: will.granger@airliefm.com.au | G9: 1 | I9: 1 | J9: 1 | K9: 1 | L9: 1 | M9: 1 | N9: 1 | O9: 1 | P9: 1 | R9: =F9&";" -> will.granger@airliefm.com.au;
B10: Yipeng Liu | C10: Allan Gray Australia | F10: yipeng.liu@allangray.com.au | G10: 1 | I10: 1 | J10: 1 | K10: 1 | L10: 1 | M10: 1 | N10: 1 | O10: 1 | P10: 1 | R10: =F10&";" -> yipeng.liu@allangray.com.au;
B11: Tim Morrison | C11: Allan Gray Australia | F11: tim.morrison@allangray.com.au | G11: 1 | I11: 1 | J11: 1 | K11: 1 | L11: 1 | M11: 1 | N11: 1 | O11: 1 | P11: 1 | R11: =F11&";" -> tim.morrison@allangray.com.au;
B12: Rajeev Gupta | C12: Alium Capital Management | F12: rg@aliumcap.com | G12: 1 | I12: 1 | J12: 1 | K12: 1 | L12: 1 | M12: 1 | N12: 1 | O12: 1 | P12: 1 | R12: =F12&";" -> rg@aliumcap.com;
B13: James Roberston | C13: Alliance Bernstein Australia | F13: james.robertson@bernstein.com | G13: 1 | I13: 1 | J13: 1 | K13: 1 | L13: 1 | M13: 1 | N13: 1 | O13: 1 | P13: 1 | R13: =F13&";" -> james.robertson@bernstein.com;
B14: Hamish Fitzsimons | C14: Alliance Bernstein Australia | F14: hamish.fitzsimons@bernstein.com | G14: 1 | I14: 1 | J14: 1 | K14: 1 | L14: 1 | M14: 1 | N14: 1 | O14: 1 | P14: 1 | R14: =F14&";" -> hamish.fitzsimons@bernstein.com;
B15: Jacob Barnes | C15: Alphinity Investment Management | F15: jacob.barnes@alphinity.com.au | G15: 1 | I15: 1 | J15: 1 | K15: 1 | L15: 1 | M15: 1 | N15: 1 | O15: 1 | P15: 1 | R15: =F15&";" -> jacob.barnes@alphinity.com.au;
B16: Nick Pashias | C16: Antares Capital Partners | F16: nick.pashias@antaresequities.com.au | G16: 1 | I16: 1 | J16: 1 | K16: 1 | L16: 1 | M16: 1 | N16: 1 | O16: 1 | P16: 1 | R16: =F16&";" -> nick.pashias@antaresequities.com.au;
B17: Jennifer Lam | C17: Antares Capital Partners | F17: jennifer.lam@antaresequities.com.au | G17: 1 | I17: 1 | J17: 1 | K17: 1 | L17: 1 | M17: 1 | N17: 1 | O17: 1 | P17: 1 | R17: =F17&";" -> jennifer.lam@antaresequities.com.au;
... B340: Josh Clark | C340: QVG Capital Pty Ltd | F340: josh@qvgcapital.com.au | G340: 1 | I340: 1 | J340: 1 | K340: 1 | L340: 1 | M340: 1 | N340: 1 | O340: 0 | P340: 0 | R340: =F340&";" -> josh@qvgcapital.com.au;
B341: Josh Phillips | C341: Tyndall Management Australia | E341: Small Caps | F341: josh.phillips@tyndallam.com | G341: 1 | I341: 0 | J341: 1 | K341: 1 | L341: 1 | M341: 1 | N341: 1 | O341: 1 | P341: 1 | R341: =F341&";" -> josh.phillips@tyndallam.com;
B342: Ben Griffiths | C342: Eley Griffiths Group | D342: Small Cap Fund | F342: ben@eg-group.com.au | G342: 1 | I342: 0 | J342: 1 | K342: 1 | L342: 1 | M342: 1 | N342: 1 | O342: 1 | P342: 1 | R342: =F342&";" -> ben@eg-group.com.au;
B343: Tim Serjeant | C343: Eley Griffiths Group | D343: Small Cap Fund | F343: tim@eg-group.com.au | G343: 1 | I343: 0 | J343: 1 | K343: 1 | L343: 1 | M343: 1 | N343: 1 | O343: 1 | P343: 1 | R343: =F343&";" -> tim@eg-group.com.au;
B344: Lachlan Ridhalgh | C344: Eley Griffiths Group | D344: Small Cap Fund | F344: lachlan@eg-group.com.au | G344: 1 | I344: 0 | J344: 1 | K344: 1 | L344: 1 | M344: 1 | N344: 1 | O344: 1 | P344: 1 | R344: =F344&";" -> lachlan@eg-group.com.au;
B345: David Allingham | C345: Eley Griffiths Group | D345: Small Cap Fund | F345: david@eg-group.com.au | G345: 1 | I345: 0 | J345: 1 | K345: 1 | L345: 1 | M345: 1 | N345: 1 | O345: 1 | P345: 1 | R345: =F345&";" -> david@eg-group.com.au;
B346: Nick Guidera | C346: Eley Griffiths Group | D346: Small Cap Fund | F346: nick@eg-group.com.au | G346: 1 | I346: 0 | J346: 1 | K346: 1 | L346: 1 | M346: 1 | N346: 1 | O346: 1 | P346: 1 | R346: =F346&";" -> nick@eg-group.com.au;
B347: Sean Kiriwan | C347: Eley Griffiths Group | D347: Small Cap Fund | F347: sean@eg-group.com.au | G347: 1 | I347: 0 | J347: 1 | K347: 1 | L347: 1 | M347: 1 | N347: 1 | O347: 1 | P347: 1 | R347: =F347&";" -> sean@eg-group.com.au;
B348: Chris Stott | C348: 1851 Capital | D348: Small Cap Fund | F348: cstott@1851capital.com.au | G348: 1 | I348: 0 | J348: 1 | K348: 1 | L348: 1 | M348: 1 | N348: 1 | O348: 1 | P348: 1 | R348: =F348&";" -> cstott@1851capital.com.au;
B349: Matthew Nicholas | C349: 1851 Capital | D349: Small Cap Fund | F349: mnicholas@1851capital.com.au | G349: 1 | I349: 0 | J349: 0 | K349: 1 | L349: 1 | M349: 1 | N349: 1 | O349: 1 | P349: 1 | R349: =F349&";" -> mnicholas@1851capital.com.au;
B350: Martin Hickson | C350: 1851 Capital | D350: Small Cap Fund | F350: mhickson@1851capital.com.au | G350: 1 | I350: 0 | J350: 0 | K350: 1 | L350: 1 | M350: 1 | N350: 1 | O350: 1 | P350: 1 | R350: =F350&";" -> mhickson@1851capital.com.au;
B351: Leo Barry | C351: Fairview Equity Partners Pty Ltd | D351: Small Cap Fund | F351: leo.barry@fairviewequity.com.au | G351: 1 | I351: 0 | J351: 0 | K351: 1 | L351: 1 | M351: 1 | N351: 1 | O351: 1 | P351: 1 | R351: =F351&";" -> leo.barry@fairviewequity.com.au;
B352: Michael Glenane | C352: Fairview Equity Partners Pty Ltd | D352: Small Cap Fund | F352: michael.glenane@fairviewequity.com.au | G352: 1 | I352: 0 | J352: 0 | K352: 1 | L352: 1 | M352: 1 | N352: 1 | O352: 1 | P352: 1 | R352: =F352&";" -> michael.glenane@fairviewequity.com.au;
B353: Michael Ross | C353: Pie Funds Management Limited | D353: Small Cap Fund | F353: mross@piefunds.co.nz | G353: 1 | I353: 0 | J353: 0 | K353: 1 | L353: 1 | M353: 1 | N353: 1 | O353: 1 | P353: 1 | R353: =F353&";" -> mross@piefunds.co.nz;
... B372: Andrew King | C372: Perennial Investment Partners Limited | D372: Small/MicroCap Fund | F372: aking@perennial.net.au | G372: 1 | I372: 0 | J372: 0 | K372: 1 | L372: 1 | M372: 1 | N372: 1 | O372: 1 | P372: 1 | R372: =F372&";" -> aking@perennial.net.au;
B373: Arden Jennings | C373: Ausbil Investment Management Limited | F373: arden.jennings@ausbil.com.au | G373: 1 | I373: 0 | J373: 0 | K373: 1 | L373: 1 | M373: 1 | N373: 1 | O373: 1 | P373: 1 | R373: =F373&";" -> arden.jennings@ausbil.com.au;
B374: Carta Ryan | C374: Firetrail Investments Pty Ltd | F374: carta.ryan@firetrail.com | G374: 1 | I374: 0 | J374: 0 | K374: 1 | L374: 1 | M374: 1 | N374: 1 | O374: 1 | P374: 1 | R374: =F374&";" -> carta.ryan@firetrail.com;

Sheet Inactive
B3: David Slack | C3: Karara Capital Pty Ltd | F3: david.slack@karara.com.au | G3: 1 | I3: 1 | J3: 1 | K3: 1 | L3: 1 | M3: 1 | N3: 1 | O3: 1 | P3: 1 | R3: =F3&";" -> david.slack@karara.com.au;
B4: Aakash Saha | C4: Accident Compensation Corporation | F4: aakash.saha@acc.co.nz | G4: 1 | I4: 1 | J4: 1 | K4: 1 | L4: 1 | M4: 1 | N4: 1 | O4: 1 | P4: 1 | R4: =F4&";" -> aakash.saha@acc.co.nz;
B5: John Sevior | C5: Airlie Funds Management | F5: john.sevior@airliefm.com.au | G5: 1 | I5: 1 | J5: 1 | K5: 1 | L5: 1 | M5: 1 | N5: 1 | O5: 1 | P5: 1 | R5: =F5&";" -> john.sevior@airliefm.com.au;
B6: Roy Maslen | C6: Alliance Bernstein Australia | F6: roy.maslen@bernstein.com | G6: 1 | I6: 1 | J6: 1 | K6: 1 | L6: 1 | M6: 1 | N6: 1 | O6: 1 | P6: 1 | R6: =F6&";" -> roy.maslen@bernstein.com;
B7: Johan Carlberg | C7: Alphinity Investment Management | F7: johan.carlberg@alphinity.com.au | G7: 1 | I7: 1 | J7: 1 | K7: 1 | L7: 1 | M7: 1 | N7: 1 | O7: 1 | P7: 1 | R7: =F7&";" -> johan.carlberg@alphinity.com.au;
B8: Will Kent | C8: AMP Capital Investors | F8: will.kent@ampcapital.com | G8: 1 | I8: 1 | J8: 1 | K8: 1 | L8: 1 | M8: 1 | N8: 1 | O8: 1 | P8: 1 | R8: =F8&";" -> will.kent@ampcapital.com;
B9: Vik Gupta | C9: Antares Capital Partners | F9: vik.gupta@antaresequities.com.au | G9: 1 | I9: 1 | J9: 1 | K9: 1 | L9: 1 | M9: 1 | N9: 1 | O9: 1 | P9: 1 | R9: =F9&";" -> vik.gupta@antaresequities.com.au;
B10: Madeleine Beaumont | C10: Blackrock Investment Management Ltd | F10: madeleine.beaumont@blackrock.com | G10: 1 | I10: 1 | J10: 1 | K10: 1 | L10: 1 | M10: 1 | N10: 1 | O10: 1 | P10: 1 | R10: =F10&";" -> madeleine.beaumont@blackrock.com;
B11: Jamie O'Neill | C11: Brookfield | F11: jamie.o'neill@au.brookfield.com | G11: 1 | I11: 1 | J11: 1 | K11: 1 | L11: 1 | M11: 1 | N11: 1 | O11: 1 | P11: 1 | R11: =F11&";" -> jamie.o'neill@au.brookfield.com;
B12: Isabelle Steadman | C12: DNR Capital Pty Ltd | F12: isabelle.steadman@dnrcapital.com.au | G12: 1 | I12: 1 | J12: 1 | K12: 1 | L12: 1 | M12: 1 | N12: 1 | O12: 1 | P12: 1 | R12: =F12&";" -> isabelle.steadman@dnrcapital.com.au;
B13: Victor Lee | C13: Eight Investment Partners | F13: victor.lee@8ip.com.au | G13: 1 | I13: 1 | J13: 1 | K13: 1 | L13: 1 | M13: 1 | N13: 1 | O13: 1 | P13: 1 | R13: =F13&";" -> victor.lee@8ip.com.au;
B14: Tim Canham | C14: First Sentier Investors (Australia) Limited | F14: tim.canham@firstsentier.com | G14: 1 | I14: 1 | J14: 1 | K14: 1 | L14: 1 | M14: 1 | N14: 1 | O14: 1 | P14: 1 | R14: =F14&";" -> tim.canham@firstsentier.com;
... B24: Marjorie Tang | C24: Myer Family Investments Pty Ltd | F24: marjorie.tang@myerfamilyinvestments.com.au | G24: 1 | I24: 1 | J24: 1 | K24: 1 | L24: 1 | M24: 1 | N24: 1 | O24: 1 | P24: 1 | R24: =F24&";" -> marjorie.tang@myerfamilyinvestments.com.au;
B25: Sinclair Currie | C25: NovaPort Capital Pty Ltd | D25: Small/MicroCap Fund | F25: scurrie@novaportcapital.com | G25: 1 | I25: 0 | J25: 0 | K25: 1 | L25: 1 | M25: 1 | N25: 1 | O25: 1 | P25: 1 | R25: =F25&";" -> scurrie@novaportcapital.com;
B26: Alex Milton | C26: NovaPort Capital Pty Ltd | D26: Small/MicroCap Fund | F26: amilton@novaportcapital.com | G26: 1 | I26: 0 | J26: 0 | K26: 1 | L26: 1 | M26: 1 | N26: 1 | O26: 1 | P26: 1 | R26: =F26&";" -> amilton@novaportcapital.com;
B27: Carly Turner | C27: Perpetual Investment Management Limited | F27: carlyt@endeavoram.com.au | G27: 1 | I27: 1 | J27: 1 | K27: 1 | L27: 1 | M27: 1 | N27: 1 | O27: 1 | P27: 1 | R27: =F27&";" -> carlyt@endeavoram.com.au;
B28: Paul Drzewucki | C28: Polymer Capital Management | F28: pdrzewucki@polymercapital.com | G28: 1 | I28: 1 | J28: 1 | K28: 1 | L28: 1 | M28: 1 | N28: 1 | O28: 1 | P28: 1 | R28: =F28&";" -> pdrzewucki@polymercapital.com;
B29: Michael Skinner | C29: Renaissance Asset Management Pty Ltd | F29: mskinner@renaissanceasset.com.au | G29: 1 | I29: 1 | J29: 1 | K29: 1 | L29: 1 | M29: 1 | N29: 1 | O29: 1 | P29: 1 | R29: =F29&";" -> mskinner@renaissanceasset.com.au;
B30: R Hook | C30: SG Hiscock & Company Limited | F30: rhook@sghiscock.com.au | G30: 1 | I30: 1 | J30: 1 | K30: 1 | L30: 1 | M30: 1 | N30: 1 | O30: 1 | P30: 1 | R30: =F30&";" -> rhook@sghiscock.com.au;
B31: Sean Martin | C31: Solaris Investment Management Limited | D31: Small Cap Fund | F31: sean.martin@solariswealth.com.au | G31: 1 | I31: 1 | J31: 1 | K31: 1 | L31: 1 | M31: 1 | N31: 1 | O31: 1 | P31: 1 | R31: =F31&";" -> sean.martin@solariswealth.com.au;
B32: Martin Pretty | C32: Thorney Opportunities Ltd | F32: martin.pretty@thorney.com.au | G32: 1 | I32: 1 | J32: 1 | K32: 1 | L32: 1 | M32: 1 | N32: 1 | O32: 1 | P32: 1 | R32: =F32&";" -> martin.pretty@thorney.com.au;
B33: Mabel Chen | C33: UniSuper Management Pty Ltd | F33: mabel.chen@unisuper.com.au | G33: 1 | I33: 1 | J33: 1 | K33: 1 | L33: 1 | M33: 1 | N33: 1 | O33: 1 | P33: 1 | R33: =F33&";" -> mabel.chen@unisuper.com.au;
B34: Chris Harris | C34: UniSuper Management Pty Ltd | F34: chris.harris@unisuper.com.au | G34: 1 | I34: 1 | J34: 1 | K34: 1 | L34: 1 | M34: 1 | N34: 1 | O34: 1 | P34: 1 | R34: =F34&";" -> chris.harris@unisuper.com.au;
B35: Jack Lawrence | C35: UniSuper Management Pty Ltd | F35: jack.lawrence@unisuper.com.au | G35: 1 | I35: 1 | J35: 1 | K35: 1 | L35: 1 | M35: 1 | N35: 1 | O35: 1 | P35: 1 | R35: =F35&";" -> jack.lawrence@unisuper.com.au;
B36: Harry Dudley | C36: Watermark Funds Management Pty Ltd | F36: dudley@wfunds.com.au | G36: 1 | I36: 1 | J36: 1 | K36: 1 | L36: 1 | M36: 1 | N36: 1 | O36: 1 | P36: 1 | R36: =F36&";" -> dudley@wfunds.com.au;
B37: Henry Hill | C37: WaveStone Capital Pty Ltd | F37: henry.hill@wavestonecapital.com | G37: 1 | I37: 1 | J37: 1 | K37: 1 | L37: 1 | M37: 1 | N37: 1 | O37: 1 | P37: 1 | R37: =F37&";" -> henry.hill@wavestonecapital.com;
B38: Phillip Hudak | C38: AMP Capital Investors | F38: phillip.hudak@ampcapital.com | G38: 1 | I38: 1 | J38: 1 | K38: 1 | L38: 1 | M38: 1 | N38: 1 | O38: 1 | P38: 1 | R38: =F38&";" -> phillip.hudak@ampcapital.com;
B39: Dan Bosscher | C39: Polymer Capital Management | F39: dbosscher@polymercapital.com | G39: 1 | I39: 1 | J39: 1 | K39: 1 | L39: 1 | M39: 1 | N39: 1 | O39: 1 | P39: 1 | R39: =F39&";" -> dbosscher@polymercapital.com;
B40: Bradley King | C40: Armytage Private Proprietary Limited | F40: bking@armytage.com.au | G40: 1 | I40: 1 | J40: 1 | K40: 1 | L40: 1 | M40: 1 | N40: 1 | O40: 1 | P40: 1 | R40: =F40&";" -> bking@armytage.com.au;
B41: Scott Kelly | C41: DNR Capital Pty Ltd | F41: scott.kelly@dnrcapital.com.au | G41: 1 | I41: 1 | J41: 1 | K41: 1 | L41: 1 | M41: 1 | N41: 1 | O41: 1 | P41: 1 | R41: =F41&";" -> scott.kelly@dnrcapital.com.au;
B42: Ryan Sohn | C42: Perennial Investment Partners Limited | D42: Small/MicroCap Fund | F42: rsohn@perennial.net.au | G42: 1 | I42: 0 | J42: 0 | K42: 1 | L42: 1 | M42: 1 | N42: 1 | O42: 1 | P42: 1 | R42: =F42&";" -> rsohn@perennial.net.au;
B43: Sean Drennan | C43: Firetrail Investments Pty Ltd | F43: sean.drennan@firetrail.com | G43: 1 | I43: 1 | J43: 1 | K43: 1 | L43: 1 | M43: 1 | N43: 1 | O43: 1 | P43: 1 | R43: =F43&";" -> sean.drennan@firetrail.com;
B44: Peter Johnston | C44: Accident Compensation Corporation | F44: peter.johnston@acc.co.nz | G44: 1 | I44: 1 | J44: 1 | K44: 1 | L44: 1 | M44: 1 | N44: 1 | O44: 1 | P44: 1 | R44: =F44&";" -> peter.johnston@acc.co.nz;
B45: Mason Willoughby-Thomas | C45: ICE Investors Pty Ltd | F45: mason.w.thomas@iceinvestors.com.au | G45: 1 | I45: 1 | J45: 1 | K45: 1 | L45: 1 | M45: 1 | N45: 1 | O45: 1 | P45: 1 | R45: =F45&";" -> mason.w.thomas@iceinvestors.com.au;
B46: Simon Conn | C46: Investors Mutual Limited | F46: simon.conn@iml.com.au | G46: 1 | I46: 1 | J46: 1 | K46: 1 | L46: 1 | M46: 1 | N46: 1 | O46: 1 | P46: 1 | R46: =F46&";" -> simon.conn@iml.com.au;
B47: Andrew South | C47: Quay Street Asset Management Limited | F47: andrew.south@quaystreet.com | G47: 1 | I47: 1 | J47: 1 | K47: 1 | L47: 1 | M47: 1 | N47: 1 | O47: 1 | P47: 1 | R47: =F47&";" -> andrew.south@quaystreet.com;
B48: Gordon Lee | C48: Cooper Investors Pty Ltd | F48: glee@cooperinvestors.com | G48: 1 | I48: 1 | J48: 1 | K48: 1 | L48: 1 | M48: 1 | N48: 1 | O48: 1 | P48: 1 | R48: =F48&";" -> glee@cooperinvestors.com;
B49: Jason Darling | C49: Caledonia Investment Pty Ltd | F49: jdarling@caledonia.com.au | G49: 1 | I49: 1 | J49: 1 | K49: 1 | L49: 1 | M49: 1 | N49: 1 | O49: 1 | P49: 1 | R49: =F49&";" -> jdarling@caledonia.com.au;
B50: Geoff Little | C50: Caledonia Investment Pty Ltd | F50: glittle@caledonia.com.au | G50: 1 | I50: 1 | J50: 1 | K50: 1 | L50: 1 | M50: 1 | N50: 1 | O50: 1 | P50: 1 | R50: =F50&";" -> glittle@caledonia.com.au;
B51: Chris Sleep | C51: Caledonia Investment Pty Ltd | F51: csleep@caledonia.com.au | G51: 1 | I51: 1 | J51: 1 | K51: 1 | L51: 1 | M51: 1 | N51: 1 | O51: 1 | P51: 1 | R51: =F51&";" -> csleep@caledonia.com.au;
...

Sheet CALL ROUND
C2: Name | D2: Fund | E2: Email | F2: Buddy | G2: Tier | H2: L/S | I2: Stocks | K2: ALL | L2: LNW | M2: TLC | N2: JIN | O2: TAH | P2: BBT | Q2: SKC | R2: SGR | T2: ALL | U2: LNW | V2: TLC | W2: JIN | X2: TAH | Y2: BBT | Z2: SKC | AA2: SGR | AD2: Email Paste | AE2: Check
C4: Sound out Thesis
C5: James Fuller | D5: QVG Capital | E5: james@qvgcapital.com.au | F5: Bill | G5: D | H5: L/S | I5: Everything | K5: 1 | L5: 1 | M5: 1 | N5: 1 | O5: 1 | P5: 1 | Q5: 1 | R5: 1 | T5: 1 | U5: 1 | V5: 1 | W5: 1 | X5: 1 | Y5: 1 | Z5: 1 | AA5: 1 | AD5: =D5&" - "&C5&" - " -> QVG Capital - James Fuller - | AE5: =MATCH(E5,'EMAIL LIST'!$F:$F,0) -> 339
C7: Tier 1
C8: Jovita Khilnani | D8: Regal | E8: jovita.khilnani@regalfm.com | F8: Rocky | G8: T1 | H8: L/S | I8: All Gaming | K8: 1 | L8: 1 | M8: 1 | N8: 1 | O8: 1 | P8: 0 | Q8: 1 | R8: 0 | T8: 1 | U8: 1 | V8: 1 | W8: 1 | X8: 1 | Y8: 1 | Z8: 1 | AA8: 1 | AD8: =D8&" - "&C8&" - " -> Regal - Jovita Khilnani - | AE8: =MATCH(E8,'EMAIL LIST'!$F:$F,0) -> 257
C9: Mark Nathan | D9: Regal | E9: mark.nathan@regalfm.com | F9: Rocky | G9: T1 | H9: L/S | K9: 0 | L9: 0 | M9: 0 | N9: 0 | O9: 0 | P9: 0 | Q9: 0 | R9: 0 | T9: 1 | U9: 1 | V9: 1 | W9: 1 | X9: 0 | Y9: 0 | Z9: 0 | AA9: 0 | AD9: =D9&" - "&C9&" - " -> Regal - Mark Nathan - | AE9: =MATCH(E9,'EMAIL LIST'!$F:$F,0) -> 259
C10: Nira Sonah | D10: UniSuper | E10: nira.sonah@unisuper.com.au | F10: Steve | G10: T1 | I10: ALL, LNW, TLC, TAH | K10: 1 | L10: 1 | M10: 1 | N10: 1 | O10: 1 | P10: 0 | Q10: 0 | R10: 0 | T10: 1 | U10: 1 | V10: 1 | W10: 1 | X10: 1 | Y10: 1 | Z10: 0 | AA10: 0 | AD10: =D10&" - "&C10&" - " -> UniSuper - Nira Sonah - | AE10: =MATCH(E10,'EMAIL LIST'!$F:$F,0) -> 309
C11: Marc Hester | D11: Greencape | E11: mhester@greencapecapital.com | F11: Steve | G11: T1 | I11: ALL, TLC, JIN | K11: 1 | L11: 1 | M11: 0 | N11: 0 | O11: 1 | P11: 0 | Q11: 1 | R11: 0 | T11: 1 | U11: 1 | V11: 0 | W11: 0 | X11: 1 | Y11: 0 | Z11: 1 | AA11: 0 | AD11: =D11&" - "&C11&" - " -> Greencape - Marc Hester - | AE11: =MATCH(E11,'EMAIL LIST'!$F:$F,0) -> 137
C12: Anthony Moran | D12: Pendal | E12: anthony.moran@pendalgroup.com | F12: Rocky | G12: T1 | I12: Slots, TLC, TAH | K12: 1 | L12: 1 | M12: 1 | N12: 0 | O12: 1 | P12: 0 | Q12: 0 | R12: 0 | T12: 1 | U12: 1 | V12: 1 | W12: 0 | X12: 1 | Y12: 0 | Z12: 0 | AA12: 0 | AD12: =D12&" - "&C12&" - " -> Pendal - Anthony Moran - | AE12: =MATCH(E12,'EMAIL LIST'!$F:$F,0) -> 228
C13: Damian Diamant | D13: Pendal | E13: damien.diamant@pendalgroup.com | F13: Bill | G13: T1 | I13: LNW, SKC | K13: 0 | L13: 1 | M13: 0 | N13: 0 | O13: 0 | P13: 0 | Q13: 1 | R13: 0 | T13: 0 | U13: 1 | V13: 0 | W13: 0 | X13: 0 | Y13: 0 | Z13: 1 | AA13: 0 | AD13: =D13&" - "&C13&" - " -> Pendal - Damian Diamant - | AE13: =MATCH(E13,'EMAIL LIST'!$F:$F,0) -> 234
C14: Sean Roger | D14: Perpetual | E14: sean.roger@perpetual.com.au | F14: Anna | G14: T1 | I14: Slots, Lotteries, Flutter, TAH | K14: 1 | L14: 1 | M14: 1 | N14: 0 | O14: 1 | P14: 0 | Q14: 0 | R14: 0 | T14: 1 | U14: 1 | V14: 1 | W14: 0 | X14: 0 | Y14: 0 | Z14: 0 | AA14: 0 | AD14: =D14&" - "&C14&" - " -> Perpetual - Sean Roger - | AE14: =MATCH(E14,'EMAIL LIST'!$F:$F,0) -> 238
C15: Mitchell Hubble | D15: Perpetual | E15: mitchell.hubble@perpetual.com.au | F15: Anna | G15: T1 | I15: All Gaming | K15: 1 | L15: 1 | M15: 1 | N15: 1 | O15: 0 | P15: 0 | Q15: 0 | R15: 0 | T15: 1 | U15: 1 | V15: 1 | W15: 1 | X15: 0 | Y15: 0 | Z15: 0 | AA15: 0 | AD15: =D15&" - "&C15&" - " -> Perpetual - Mitchell Hubble - | AE15: =MATCH(E15,'EMAIL LIST'!$F:$F,0) -> 243
C16: John Ayoub | D16: Wilson | E16: john@wilsonassetmanagement.com.au | F16: Rocky | G16: T1 | H16: L/S | I16: Not sure | K16: 1 | L16: 1 | M16: 0 | N16: 0 | O16: 0 | P16: 0 | Q16: 0 | R16: 0 | T16: 1 | U16: 1 | V16: 0 | W16: 0 | X16: 0 | Y16: 0 | Z16: 0 | AA16: 0 | AD16: =D16&" - "&C16&" - " -> Wilson - John Ayoub - | AE16: =MATCH(E16,'EMAIL LIST'!$F:$F,0) -> 323
C17: Shaun Weick | D17: Wilson | E17: shaun@wilsonassetmanagement.com.au | F17: Rocky | G17: T1 | H17: L/S | I17: Not sure | K17: 1 | L17: 1 | M17: 0 | N17: 0 | O17: 1 | P17: 0 | Q17: 0 | R17: 0 | T17: 1 | U17: 1 | V17: 0 | W17: 0 | X17: 1 | Y17: 1 | Z17: 0 | AA17: 0 | AD17: =D17&" - "&C17&" - " -> Wilson - Shaun Weick - | AE17: =MATCH(E17,'EMAIL LIST'!$F:$F,0) -> 322
C18: Hailey Kim | D18: Wilson | E18: hailey@wilsonassetmanagement.com.au | F18: Rocky | G18: T1 | H18: L/S | I18: TAH | K18: 0 | L18: 0 | M18: 0 | N18: 0 | O18: 1 | P18: 0 | Q18: 0 | R18: 0 | T18: 0 | U18: 0 | V18: 0 | W18: 0 | X18: 1 | Y18: 1 | Z18: 0 | AA18: 0 | AD18: =D18&" - "&C18&" - " -> Wilson - Hailey Kim - | AE18: =MATCH(E18,'EMAIL LIST'!$F:$F,0) -> 328
C19: Amar Naik | D19: L1 Capital | E19: anaik@l1.com.au | F19: Fletch | G19: T1 | H19: L/S | I19: Slots, TLC, TAH | K19: 1 | L19: 1 | M19: 1 | N19: 0 | O19: 1 | P19: 0 | Q19: 0 | R19: 0 | T19: 1 | U19: 1 | V19: 1 | W19: 1 | X19: 1 | Y19: 1 | Z19: 0 | AA19: 0 | AD19: =D19&" - "&C19&" - " -> L1 Capital - Amar Naik - | AE19: =MATCH(E19,'EMAIL LIST'!$F:$F,0) -> 175
C20: Philip Wensley | D20: Paradice | E20: philip.wensley@paradice.com | F20: Rocky | G20: T1 | I20: ALL, LNW | K20: 1 | L20: 1 | M20: 0 | N20: 0 | O20: 0 | P20: 0 | Q20: 0 | R20: 0 | T20: 1 | U20: 1 | V20: 0 | W20: 0 | X20: 0 | Y20: 0 | Z20: 0 | AA20: 0 | AD20: =D20&" - "&C20&" - " -> Paradice - Philip Wensley - | AE20: =MATCH(E20,'EMAIL LIST'!$F:$F,0) -> 223
C21: Matt Riordan | D21: Paradice | E21: matthew.riordan@paradice.com | F21: Rocky | G21: T1 | I21: ALL, LNW | K21: 1 | L21: 1 | M21: 0 | N21: 0 | O21: 0 | P21: 0 | Q21: 0 | R21: 0 | T21: 1 | U21: 1 | V21: 0 | W21: 0 | X21: 0 | Y21: 0 | Z21: 0 | AA21: 0 | AD21: =D21&" - "&C21&" - " -> Paradice - Matt Riordan - | AE21: =MATCH(E21,'EMAIL LIST'!$F:$F,0) -> 219
C22: David Feng | D22: Paradice | E22: david.feng@paradice.com | F22: Rocky | G22: T1 | I22: JIN | K22: 1 | L22: 1 | M22: 1 | N22: 1 | O22: 0 | P22: 0 | Q22: 0 | R22: 0 | T22: 1 | U22: 1 | V22: 1 | W22: 1 | X22: 1 | Y22: 1 | Z22: 0 | AA22: 0 | AD22: =D22&" - "&C22&" - " -> Paradice - David Feng - | AE22: =MATCH(E22,'EMAIL LIST'!$F:$F,0) -> 220
C23: Jovana Gagic | D23: Paradice | E23: jovana.gagic@paradice.com | F23: Rocky | G23: T1 | K23: 0 | L23: 0 | M23: 0 | N23: 0 | O23: 0 | P23: 0 | Q23: 0 | R23: 0 | T23: 1 | U23: 1 | V23: 0 | W23: 0 | X23: 0 | Y23: 0 | Z23: 0 | AA23: 0 | AD23: =D23&" - "&C23&" - " -> Paradice - Jovana Gagic - | AE23: =MATCH(E23,'EMAIL LIST'!$F:$F,0) -> 226
C24: Michael Ward | D24: BAEP | E24: michael.ward@baep.com.au | F24: Fletch | G24: T1 | K24: 1 | L24: 1 | M24: 1 | N24: 0 | O24: 0 | P24: 0 | Q24: 0 | R24: 0 | T24: 1 | U24: 1 | V24: 1 | W24: 0 | X24: 0 | Y24: 0 | Z24: 0 | AA24: 0 | AD24: =D24&" - "&C24&" - " -> BAEP - Michael Ward - | AE24: =MATCH(E24,'EMAIL LIST'!$F:$F,0) -> 51
C25: Mark East | D25: BAEP | E25: mark.east@baep.com.au | F25: Fletch | G25: T1 | K25: 0 | L25: 0 | M25: 0 | N25: 0 | O25: 0 | P25: 0 | Q25: 0 | R25: 0 | T25: 1 | U25: 1 | V25: 1 | W25: 0 | X25: 0 | Y25: 0 | Z25: 0 | AA25: 0 | AD25: =D25&" - "&C25&" - " -> BAEP - Mark East - | AE25: =MATCH(E25,'EMAIL LIST'!$F:$F,0) -> 47
C26: Stella McMullen | D26: Ausbil | E26: stella.mcmullen@ausbil.com.au | F26: Anna | G26: T1 | K26: 1 | L26: 1 | M26: 1 | N26: 0 | O26: 1 | P26: 0 | Q26: 0 | R26: 0 | T26: 1 | U26: 1 | V26: 1 | W26: 0 | X26: 1 | Y26: 0 | Z26: 0 | AA26: 0 | AD26: =D26&" - "&C26&" - " -> Ausbil - Stella McMullen - | AE26: =MATCH(E26,'EMAIL LIST'!$F:$F,0) -> 30
C27: Andrew Peros | D27: Ausbil | E27: andrew.peros@ausbil.com.au | F27: Anna | G27: T1 | I27: LNW | K27: 0 | L27: 1 | M27: 0 | N27: 0 | O27: 0 | P27: 0 | Q27: 0 | R27: 0 | T27: 0 | U27: 1 | V27: 0 | W27: 0 | X27: 0 | Y27: 0 | Z27: 0 | AA27: 0 | AD27: =D27&" - "&C27&" - " -> Ausbil - Andrew Peros - | AE27: =MATCH(E27,'EMAIL LIST'!$F:$F,0) -> 28
C28: Jacob Barnes | D28: Alphinity | E28: jacob.barnes@alphinity.com.au | F28: Anna | G28: T1 | I28: Not sure | K28: 1 | L28: 1 | M28: 1 | N28: 1 | O28: 0 | P28: 0 | Q28: 0 | R28: 0 | T28: 1 | U28: 1 | V28: 1 | W28: 1 | X28: 1 | Y28: 1 | Z28: 1 | AA28: 1 | AD28: =D28&" - "&C28&" - " -> Alphinity - Jacob Barnes - | AE28: =MATCH(E28,'EMAIL LIST'!$F:$F,0) -> 15
C30: Tier 2
C31: Andrew Mclennan | D31: Solaris | E31: andrew.mclennan@solariswealth.com.au | F31: Anna | G31: T2 | H31: L/S | I31: ALL, LNW, TLC (not atm), FLUT, TAH | K31: 1 | L31: 1 | M31: 1 | N31: 1 | O31: 0 | P31: 0 | Q31: 0 | R31: 0 | T31: 1 | U31: 1 | V31: 1 | W31: 1 | X31: 0 | Y31: 0 | Z31: 0 | AA31: 0 | AD31: =D31&" - "&C31&" - " -> Solaris - Andrew Mclennan - | AE31: =MATCH(E31,'EMAIL LIST'!$F:$F,0) -> 5
C32: Roland Houghton | D32: Milford | E32: rhoughton@milfordasset.com | F32: Anna | G32: T2 | I32: Slots, TLC, Jumbo | K32: 1 | L32: 1 | M32: 1 | N32: 1 | O32: 0 | P32: 0 | Q32: 0 | R32: 0 | T32: 1 | U32: 1 | V32: 1 | W32: 1 | X32: 0 | Y32: 0 | Z32: 0 | AA32: 0 | AD32: =D32&" - "&C32&" - " -> Milford - Roland Houghton - | AE32: =MATCH(E32,'EMAIL LIST'!$F:$F,0) -> 197
C33: Sanjay Magotra | D33: CBUS | E33: sanjay.magotra@cbussuper.com.au | F33: Fletch | G33: T2 | I33: LNW, TLC | K33: 0 | L33: 1 | M33: 1 | N33: 0 | O33: 0 | P33: 0 | Q33: 0 | R33: 0 | T33: 1 | U33: 1 | V33: 1 | W33: 1 | X33: 0 | Y33: 0 | Z33: 0 | AA33: 0 | AD33: =D33&" - "&C33&" - " -> CBUS - Sanjay Magotra - | AE33: =MATCH(E33,'EMAIL LIST'!$F:$F,0) -> 60
C34: Edward Pham | D34: CBUS | E34: edward.pham@cbussuper.com.au | F34: Fletch | G34: T2 | I34: Mainly slots but a bit TLC | K34: 1 | L34: 1 | M34: 1 | N34: 0 | O34: 0 | P34: 0 | Q34: 0 | R34: 0 | T34: 1 | U34: 1 | V34: 1 | W34: 1 | X34: 1 | Y34: 1 | Z34: 0 | AA34: 0 | AD34: =D34&" - "&C34&" - " -> CBUS - Edward Pham - | AE34: =MATCH(E34,'EMAIL LIST'!$F:$F,0) -> 66
C35: Frank Podrug | D35: DKAM | E35: frank.podrug@dkam.com | F35: Steve | G35: T2 | I35: Slots, TLC | K35: 1 | L35: 1 | M35: 1 | N35: 0 | O35: 0 | P35: 0 | Q35: 0 | R35: 0 | T35: 1 | U35: 1 | V35: 1 | W35: 1 | X35: 0 | Y35: 0 | Z35: 0 | AA35: 0 | AD35: =D35&" - "&C35&" - " -> DKAM - Frank Podrug - | AE35: =MATCH(E35,'EMAIL LIST'!$F:$F,0) -> 90
C36: Scott Olsson | D36: Firetrail | E36: scott.olsson@firetrailinvest.com | F36: Rocky | G36: T2 | I36: Slots, TLC | K36: 1 | L36: 1 | M36: 1 | N36: 0 | O36: 0 | P36: 0 | Q36: 0 | R36: 0 | T36: 1 | U36: 1 | V36: 1 | W36: 1 | X36: 1 | Y36: 1 | Z36: 1 | AA36: 1 | AD36: =D36&" - "&C36&" - " -> Firetrail - Scott Olsson - | AE36: =MATCH(E36,'EMAIL LIST'!$F:$F,0) -> 117
C37: Aleks Stankovic | D37: First Sentier | E37: aleksandar.stankovic@firstsentier.com.au | F37: Fletch | G37: T2 | I37: In ALL | K37: 1 | L37: 1 | M37: 1 | N37: 0 | O37: 1 | P37: 0 | Q37: 0 | R37: 0 | T37: 1 | U37: 1 | V37: 1 | W37: 1 | X37: 0 | Y37: 0 | Z37: 0 | AA37: 0 | AD37: =D37&" - "&C37&" - " -> First Sentier - Aleks Stankovic - | AE37: =MATCH(E37,'EMAIL LIST'!$F:$F,0) -> 127
C38: Tahlia Gugusheff | D38: First Sentier | E38: tahlia.gugusheff@firstsentier.com | F38: Anna | G38: T2 | I38: TLC, JIN, TAH | K38: 0 | L38: 0 | M38: 1 | N38: 1 | O38: 1 | P38: 0 | Q38: 0 | R38: 0 | T38: 0 | U38: 0 | V38: 1 | W38: 1 | X38: 0 | Y38: 0 | Z38: 0 | AA38: 0 | AD38: =D38&" - "&C38&" - " -> First Sentier - Tahlia Gugusheff - | AE38: =MATCH(E38,'EMAIL LIST'!$F:$F,0) -> 123
C39: Michael Joukhador | D39: First Sentier | E39: michael.joukhador@firstsentier.com | F39: Bill | G39: T2 | K39: 0 | L39: 1 | M39: 0 | N39: 0 | O39: 0 | P39: 0 | Q39: 0 | R39: 0 | T39: 0 | U39: 1 | V39: 0 | W39: 0 | X39: 0 | Y39: 0 | Z39: 0 | AA39: 0 | AD39: =D39&" - "&C39&" - " -> First Sentier - Michael Joukhador - | AE39: =MATCH(E39,'EMAIL LIST'!$F:$F,0) -> 122
C40: Steven Green | D40: Rest | E40: steven.green@rest.com.au | F40: Steve | G40: T2 | I40: Not sure | K40: 1 | L40: 1 | M40: 1 | N40: 1 | O40: 0 | P40: 0 | Q40: 0 | R40: 0 | T40: 1 | U40: 1 | V40: 1 | W40: 1 | X40: 1 | Y40: 1 | Z40: 0 | AA40: 0 | AD40: =D40&" - "&C40&" - " -> Rest - Steven Green - | AE40: =MATCH(E40,'EMAIL LIST'!$F:$F,0) -> 265
C41: Sean Fenton | D41: Sage | E41: sean.fenton@sagecap.com.au | F41: Rocky | G41: T2 | H41: L/S | K41: 1 | L41: 1 | M41: 1 | N41: 1 | O41: 0 | P41: 0 | Q41: 0 | R41: 0 | T41: 1 | U41: 1 | V41: 1 | W41: 1 | X41: 0 | Y41: 0 | Z41: 0 | AA41: 0 | AD41: =D41&" - "&C41&" - " -> Sage - Sean Fenton - | AE41: =MATCH(E41,'EMAIL LIST'!$F:$F,0) -> 275
C42: Jen Lee | D42: Australian Super | E42: jlee@australiansuper.com | F42: Fletch | G42: T2 | I42: Not sure | K42: 1 | L42: 1 | M42: 0 | N42: 0 | O42: 0 | P42: 0 | Q42: 0 | R42: 0 | T42: 1 | U42: 1 | V42: 1 | W42: 0 | X42: 1 | Y42: 0 | Z42: 1 | AA42: 1 | AD42: =D42&" - "&C42&" - " -> Australian Super - Jen Lee - | AE42: =MATCH(E42,'EMAIL LIST'!$F:$F,0) -> 38
C43: Simon Brown | D43: Tribeca | E43: simon.brown@tribecaip.com.au | F43: Rocky | G43: T2 | K43: 1 | L43: 1 | M43: 1 | N43: 1 | O43: 1 | P43: 1 | Q43: 0 | R43: 0 | T43: 1 | U43: 1 | V43: 1 | W43: 1 | X43: 0 | Y43: 0 | Z43: 0 | AA43: 0 | AD43: =D43&" - "&C43&" - " -> Tribeca - Simon Brown - | AE43: =MATCH(E43,'EMAIL LIST'!$F:$F,0) -> 307
C44: Mark Kellock | D44: Ten Capital | E44: mark@tencap.com.au | F44: Rocky | G44: T2 | H44: L/S | I44: JIN | K44: 0 | L44: 0 | M44: 1 | N44: 1 | O44: 0 | P44: 0 | Q44: 0 | R44: 0 | T44: 0 | U44: 0 | V44: 1 | W44: 1 | X44: 0 | Y44: 0 | Z44: 0 | AA44: 0 | AD44: =D44&" - "&C44&" - " -> Ten Capital - Mark Kellock - | AE44: =MATCH(E44,'EMAIL LIST'!$F:$F,0) -> 295
...

Sheet Corporates
B1: Name | C1: Fund | E1: Email | G1: Gaming | H1: ALL | I1: LNW | J1: TLC | K1: JIN | L1: TAH | M1: PBH | N1: SKC | O1: SGR | Q1: Paste
B2: Trevor Croker | C2: Aristocrat Leisure Limited | D2: Corporate | E2: trevor.croker@aristocrat.com | G2: 1 | H2: 1 | I2: 1 | J2: 0 | K2: 0 | L2: 0 | M2: 0 | N2: 0 | O2: 0 | Q2: =E2&";" -> trevor.croker@aristocrat.com;
B3: James Coghill | C3: Aristocrat Leisure Limited | D3: Corporate | E3: james.coghill@aristocrat.com | G3: 1 | H3: 1 | I3: 1 | J3: 0 | K3: 0 | L3: 0 | M3: 0 | N3: 0 | O3: 0 | Q3: =E3&";" -> james.coghill@aristocrat.com;
B4: Marla Sims | C4: Aristocrat Leisure Limited | D4: Corporate | E4: marla.sims@aristocrat.com | G4: 1 | H4: 1 | I4: 1 | J4: 0 | K4: 0 | L4: 0 | M4: 0 | N4: 0 | O4: 0 | Q4: =E4&";" -> marla.sims@aristocrat.com;
B5: Prashani Veerasamy | C5: Aristocrat Leisure Limited | D5: Corporate | E5: prashani.veerasamy@aristocrat.com | G5: 1 | H5: 1 | I5: 1 | J5: 0 | K5: 0 | L5: 0 | M5: 0 | N5: 0 | O5: 0 | Q5: =E5&";" -> prashani.veerasamy@aristocrat.com;
B6: Reuben Rattos | C6: Light & Wonder Inc. | D6: Corporate | E6: rrattos@lnw.com | G6: 1 | H6: 1 | I6: 1 | J6: 0 | K6: 0 | L6: 0 | M6: 0 | N6: 0 | O6: 0 | Q6: =E6&";" -> rrattos@lnw.com;
B7: Nick Zangari | C7: Light & Wonder Inc. | D7: Corporate | E7: dzangari@lnw.com | G7: 1 | H7: 1 | I7: 1 | J7: 0 | K7: 0 | L7: 0 | M7: 0 | N7: 0 | O7: 0 | Q7: =E7&";" -> dzangari@lnw.com;
B8: Steve Wan | C8: Light & Wonder Inc. | D8: Corporate | E8: swan@lnw.com | G8: 1 | H8: 1 | I8: 1 | J8: 0 | K8: 0 | L8: 0 | M8: 0 | N8: 0 | O8: 0 | Q8: =E8&";" -> swan@lnw.com;
B9: Matt Wilson | C9: Light & Wonder Inc. | D9: Corporate | E9: mwilson@lnw.com | G9: 1 | H9: 1 | I9: 1 | J9: 0 | K9: 0 | L9: 0 | M9: 0 | N9: 0 | O9: 0 | Q9: =E9&";" -> mwilson@lnw.com;
B10: Toni Korsanos | C10: Light & Wonder Inc. | D10: Corporate | E10: toni.korsanos@icloud.com | G10: 1 | H10: 1 | I10: 1 | J10: 0 | K10: 0 | L10: 0 | M10: 0 | N10: 0 | O10: 0 | Q10: =E10&";" -> toni.korsanos@icloud.com;
B11: Oliver Chow | C11: Light & Wonder Inc. | D11: Corporate | E11: ochow@lnw.com | G11: 1 | H11: 1 | I11: 1 | J11: 0 | K11: 0 | L11: 0 | M11: 0 | N11: 0 | O11: 0 | Q11: =E11&";" -> ochow@lnw.com;
B12: Jamie Odell | C12: Light & Wonder Inc. | D12: Corporate | E12: jamie@jamieodell.com.au | G12: 1 | H12: 1 | I12: 1 | J12: 0 | K12: 0 | L12: 0 | M12: 0 | N12: 0 | O12: 0 | Q12: =E12&";" -> jamie@jamieodell.com.au;
B13: Research Team | C13: Light & Wonder Inc. | D13: Corporate | E13: irresearch@lnw.com | G13: 1 | H13: 1 | I13: 1 | J13: 0 | K13: 0 | L13: 0 | M13: 0 | N13: 0 | O13: 0 | Q13: =E13&";" -> irresearch@lnw.com;
B14: Sachchit Sivaram | C14: Light & Wonder Inc. | D14: Corporate | E14: SSivaram@lnw.com | G14: 1 | H14: 1 | I14: 1 | J14: 0 | K14: 0 | L14: 0 | M14: 0 | N14: 0 | O14: 0 | Q14: =E14&";" -> SSivaram@lnw.com;
B15: Jack Martin | C15: Light & Wonder Inc. | D15: Corporate | E15: jtmartin@lnw.com | G15: 1 | H15: 1 | I15: 1 | J15: 0 | K15: 0 | L15: 0 | M15: 0 | N15: 0 | O15: 0 | Q15: jtmartin@lnw.com
B16: Jatin Khosla | C16: Jumbo Interactive Limited | D16: Corporate | E16: jatink@jumbointeractive.com | G16: 1 | H16: 0 | I16: 0 | J16: 1 | K16: 1 | L16: 0 | M16: 0 | N16: 0 | O16: 0 | Q16: =E16&";" -> jatink@jumbointeractive.com;
B17: Jonathan Chuong | C17: Jumbo Interactive Limited | D17: Corporate | E17: jonathanch@jumbointeractive.com | G17: 1 | H17: 0 | I17: 0 | J17: 1 | K17: 1 | L17: 0 | M17: 0 | N17: 0 | O17: 0 | Q17: =E17&";" -> jonathanch@jumbointeractive.com;
B18: Stephen Forman | C18: PointsBet Holdings Limited | D18: Corporate | E18: stephen.forman@pointsbet.com | G18: 1 | H18: 0 | I18: 0 | J18: 0 | K18: 0 | L18: 1 | M18: 1 | N18: 0 | O18: 0 | Q18: =E18&";" -> stephen.forman@pointsbet.com;
B19: Craig Brown | C19: SkyCity Entertainment Group Limited | D19: Corporate | E19: craig.brown@skycity.co.nz | G19: 1 | H19: 0 | I19: 0 | J19: 0 | K19: 0 | L19: 0 | M19: 0 | N19: 1 | O19: 1 | Q19: =E19&";" -> craig.brown@skycity.co.nz;
B20: Chris Martin | C20: Sportsbet | D20: Corporate | E20: christopher.martin@sportsbet.com.au | G20: 1 | H20: 0 | I20: 0 | J20: 0 | K20: 0 | L20: 1 | M20: 1 | N20: 0 | O20: 0 | Q20: =E20&";" -> christopher.martin@sportsbet.com.au;
B21: Danny Huang | C21: Star Entertainment Group Limited | D21: Corporate | E21: dannyzhaoxiang.huang@star.com.au | G21: 1 | H21: 0 | I21: 0 | J21: 0 | K21: 0 | L21: 0 | M21: 0 | N21: 1 | O21: 1 | Q21: =E21&";" -> dannyzhaoxiang.huang@star.com.au;
B22: Terry Couper | C22: Tabcorp Holdings Limited | D22: Corporate | E22: terry.couper@tabcorp.com.au | G22: 1 | H22: 0 | I22: 0 | J22: 0 | K22: 0 | L22: 1 | M22: 1 | N22: 0 | O22: 0 | Q22: =E22&";" -> terry.couper@tabcorp.com.au;
B23: Dan Butcher | C23: Tabcorp Holdings Limited | D23: Corporate | E23: dan.butcher@tabcorp.com.au | G23: 1 | H23: 0 | I23: 0 | J23: 0 | K23: 0 | L23: 1 | M23: 1 | N23: 0 | O23: 0 | Q23: =E23&";" -> dan.butcher@tabcorp.com.au;
B24: Jacky Dong | C24: Tabcorp Holdings Limited | D24: Corporate | E24: jacky.dong@tabcorp.com.au | G24: 1 | H24: 0 | I24: 0 | J24: 0 | K24: 0 | L24: 1 | M24: 1 | N24: 0 | O24: 0 | Q24: =E24&";" -> jacky.dong@tabcorp.com.au;
B25: Chris Richardson | C25: The Lottery Corporation | D25: Corporate | E25: chris.richardson@thelotterycorporation.com | G25: 1 | H25: 0 | I25: 0 | J25: 1 | K25: 1 | L25: 0 | M25: 0 | N25: 0 | O25: 0 | Q25: =E25&";" -> chris.richardson@thelotterycorporation.com;
B26: Richard Nguyen | C26: The Lottery Corporation | D26: Corporate | E26: richard.nguyen@thelotterycorporation.com | G26: 1 | H26: 0 | I26: 0 | J26: 1 | K26: 1 | L26: 0 | M26: 0 | N26: 0 | O26: 0 | Q26: =E26&";" -> richard.nguyen@thelotterycorporation.com;
B27: Ruvani Fernando | C27: The Lottery Corporation | D27: Corporate | E27: ruvani.fernando2@thelotterycorporation.com | G27: 1 | H27: 0 | I27: 0 | J27: 1 | K27: 1 | L27: 0 | M27: 0 | N27: 0 | O27: 0 | Q27: =E27&";" -> ruvani.fernando2@thelotterycorporation.com;
B28: Alex Hiotis | C28: The Lottery Corporation | D28: Corporate | E28: alex.hiotis@thelotterycorporation.com | G28: 1 | H28: 0 | I28: 0 | J28: 1 | K28: 1 | L28: 0 | M28: 0 | N28: 0 | O28: 0 | Q28: =E28&";" -> alex.hiotis@thelotterycorporation.com;

Sheet ACC TIERS

Sheet LNW Oct-24
A1: Codes | B1: Rank | C1: Name | D1: % ISC | E1: % INST. | F1: 31 Oct 2024 | G1: Net Change | H1: Position History | I1: 30 Sep 2024 | J1: 31 Aug 2024 | K1: 31 Jul 2024 | L1: 30 Jun 2024 | M1: 31 May 2024 | N1: 30 Apr 2024 | O1: 28 Mar 2024 | P1: 29 Feb 2024 | Q1: 31 Jan 2024 | R1: 31 Dec 2023 | S1: 30 Nov 2023 | T1: 31 Oct 2023 | U1: Av. % INST. Weighting | V1: FW % INST. Weighting | W1: Upside (000's shares) | X1: Saturation Level | Y1: Sector Activity | Z1: 12 Month Fund Flow ($Bn) | AA1: 4Q Fund Flow History | AB1: Investor Type | AC1: Orientation | AD1: Style | AE1: Turnover | AF1: EAUM ($Bn) | AG1: City | AH1: Country
C2: TOTAL | D2: 0.96978903 | E2: 1 | F2: 24697505 | G2: 566361 | I2: 24131144 | J2: 23051002 | K2: 22462427 | L2: 22279904 | M2: 22204962 | N2: 19447641 | O2: 17580079 | P2: 17569290 | Q2: 15160233 | R2: 15267359 | S2: 15339532 | T2: 15512303
A3: CLDNPR001 | B3: 1 (1) | C3: Caledonia (Private) Investments Pty Limited | D3: 0.22599592 | E3: 0.2530636 | F3: 5755412 | G3: 0 | I3: 5755412 | J3: 5927501 | K3: 7041264 | L3: 7042404 | M3: 7766025 | N3: 7766025 | O3: 7191195 | P3: 6597862 | Q3: 5231359 | R3: 5358593 | S3: 5542979 | T3: 5043429 | U3: 0.000581143 | V3: 0.000761953 | W3: -5738.0829 | X3: 1 | Y3: Top Buyer | AB3: Investment Advisor | AC3: Active | AD3: Growth | AE3: Low | AF3: 8.02572 | AG3: Sydney | AH3: Australia
A4: GRNCPC001 | B4: 2 (2) | C4: Greencape Capital Pty. Ltd. | D4: 0.05552788 | E4: 0.06217849 | F4: 1414122 | G4: 90500 | I4: 1323622 | J4: 1005606 | K4: 818907 | L4: 1206094 | M4: 1129072 | N4: 940513 | O4: 940513 | P4: 1166219 | Q4: 1190238 | R4: 1190238 | S4: 1156753 | T4: 1155804 | U4: 0.032719823 | V4: 0.039868057 | W4: -507.40489 | X4: 1 | Y4: Top Seller | Z4: 52 | AB4: Investment Advisor | AC4: Active | AD4: GARP | AE4: Low | AF4: 0.80504 | AG4: Melbourne | AH4: Australia
A5: G0464312 | B5: 4 (3) | C5: Jonathan Munz | D5: 0.04207142 | E5: 0 | F5: 1071428 | G5: 0 | I5: 1071428 | J5: 1071428 | K5: 1071428 | L5: 1071428 | M5: 1071428 | N5: 1071428 | O5: 1071428 | P5: 1071428 | Q5: 1071428 | R5: 1071428 | S5: 1071428 | T5: 1071428 | AB5: Individual Investor | AD5: N/A | AE5: N/A | AF5: 0 | AG5: Melbourne | AH5: Australia
A6: UNVRST006 | B6: - (-) | C6: University of Pennsylvania Trustees | D6: 0 | E6: 0 | F6: 0 | G6: 0 | I6: 0 | J6: 0 | K6: 0 | L6: 714285 | M6: 714285 | N6: 714285 | O6: 714285 | P6: 714285 | Q6: 714285 | R6: 714285 | S6: 714285 | T6: 714285 | Y6: Neutral | AB6: Endowment Fund | AC6: Active | AD6: Income Value | AE6: Low | AF6: 0.07085 | AG6: Philadelphia | AH6: United States
A7: UBSWRB011 | B7: 156 (155) | C7: UBS Securities Australia Ltd. | D7: 4.3e-07 | E7: 0 | F7: 11 | G7: 0 | I7: 11 | J7: 11 | K7: 11 | L7: 11 | M7: 0 | N7: 0 | O7: 0 | P7: 537456 | Q7: 0 | R7: 0 | S7: 0 | T7: 0 | AB7: Research Firm | AC7: Passive | AD7: N/A | AE7: Low | AF7: 0.00822 | AG7: Sydney | AH7: Australia
A8: PRPTLN007 | B8: 8 (4) | C8: Perpetual Investment Management Limited | D8: 0.0318814 | E8: 0.03569986 | F8: 811920 | G8: -7976 | I8: 819896 | J8: 775720 | K8: 815720 | L8: 782689 | M8: 782689 | N8: 643453 | O8: 581561 | P8: 501750 | Q8: 472403 | R8: 454933 | S8: 426359 | T8: 452183 | U8: 0.017716236 | V8: 0.057206037 | W8: 489.11387 | X8: 0.62 | Y8: Top Buyer | Z8: 81 | AB8: Investment Advisor/Hedge Fund | AC8: Active | AD8: Core Value | AE8: Low | AF8: 5.60268 | AG8: Sydney | AH8: Australia
A9: PRDCNV001 | B9: 12 (11) | C9: Paradice Investment Management Pty. Ltd. | D9: 0.0188453 | E9: 0.02110241 | F9: 479931 | G9: -99534 | I9: 579465 | J9: 528320 | K9: 526220 | L9: 518820 | M9: 517960 | N9: 518073 | O9: 318396 | P9: 432308 | Q9: 422338 | R9: 422452 | S9: 406481 | T9: 365211 | U9: 0.019112117 | V9: 0.044837039 | W9: 539.7954 | X9: 0.47 | Y9: Seller | Z9: -31 | AB9: Investment Advisor | AC9: Active | AD9: Core Value | AE9: Low | AF9: 1.69234 | AG9: Sydney | AH9: Australia
A10: MLFRDS001 | B10: 36 (36) | C10: Milford Asset Management Ltd. | D10: 0.00589786 | E10: 0.00660425 | F10: 150200 | G10: -20240 | I10: 170440 | J10: 177404 | K10: 208934 | L10: 194568 | M10: 399967 | N10: 417864 | O10: 374076 | P10: 394619 | Q10: 100809 | R10: 84724 | S10: 60389 | T10: 21687 | U10: 0.016721898 | V10: 0.048047953 | W10: 942.55205 | X10: 0.14 | Y10: Top Seller | Z10: 81 | AB10: Investment Advisor | AC10: Active | AD10: Growth | AE10: Low | AF10: 0.81115 | AG10: Auckland | AH10: New Zealand
A11: WSHNGT01E | B11: 13 (13) | C11: Washington H. Soul Pattinson and Company Limited | D11: 0.018628 | E11: 0.02085908 | F11: 474397 | G11: 0 | I11: 474397 | J11: 475000 | K11: 468249 | L11: 386952 | M11: 385000 | N11: 378000 | O11: 350000 | P11: 358752 | Q11: 358752 | R11: 350000 | S11: 350000 | T11: 350000 | U11: 0.01406005 | V11: 0.037135075 | W11: 370.16404 | X11: 0.56 | Y11: Seller | AB11: Investment Advisor | AC11: Active | AD11: N/A | AE11: Low | AF11: 5.26599 | AG11: Sydney | AH11: Australia
A12: ASBLDX001 | B12: 43 (33) | C12: Ausbil Investment Management Limited | D12: 0.00473383 | E12: 0.00530081 | F12: 120556 | G12: -61028 | I12: 181584 | J12: 194635 | K12: 202656 | L12: 222484 | M12: 229612 | N12: 316754 | O12: 306070 | P12: 351426 | Q12: 356952 | R12: 292715 | S12: 198178 | T12: 198996 | U12: 0.015368148 | V12: 0.049003856 | W12: 993.9361 | X12: 0.11 | Y12: Top Buyer | Z12: -218 | AB12: Investment Advisor | AC12: Active | AD12: GARP | AE12: Low | AF12: 4.00881 | AG12: Sydney | AH12: Australia
A13: WLSNSS001 | B13: 42 (21) | C13: Wilson Asset Management (International) Pty. Ltd. | D13: 0.00500642 | E13: 0.00560605 | F13: 127498 | G13: -190947 | I13: 318445 | J13: 336069 | K13: 435735 | L13: 347079 | M13: 411191 | N13: 381948 | O13: 247347 | P13: 345276 | Q13: 399900 | R13: 469020 | S13: 356216 | T13: 346387 | U13: 0.008394488 | V13: 0.030774502 | W13: 572.40487 | X13: 0.18 | Y13: Top Seller | AB13: Investment Advisor | AC13: Active | AD13: GARP | AE13: Low | AF13: 1.05026 | AG13: Sydney | AH13: Australia
A14: CNSTRC00Z | B14: 20 (16) | C14: Cbus Super | D14: 0.0145666 | E14: 0.01631125 | F14: 370966 | G14: -45000 | I14: 415966 | J14: 400148 | K14: 380148 | L14: 440794 | M14: 413640 | N14: 367640 | O14: 330640 | P14: 330640 | Q14: 320074 | R14: 307640 | S14: 307640 | T14: 327640 | U14: 0.017064193 | V14: 0.043425298 | W14: 616.65325 | X14: 0.38 | Y14: Buyer | AB14: Pension Fund | AC14: Active | AD14: N/A | AE14: Low | AF14: 0.01528 | AG14: Melbourne | AH14: Australia
A15: BNKRST005 | B15: 21 (22) | C15: Pendal Group Limited | D15: 0.01349333 | E15: 0.01510943 | F15: 343633 | G15: 26967 | I15: 316666 | J15: 409577 | K15: 408428 | L15: 406545 | M15: 406545 | N15: 383479 | O15: 354226 | P15: 310406 | Q15: 131687 | R15: 95112 | S15: 105617 | T15: 105617 | U15: 0.011961758 | V15: 0.034761158 | W15: 446.93817 | X15: 0.43 | Y15: Buyer | Z15: -1216 | AB15: Investment Advisor | AC15: Active | AD15: Core Growth | AE15: Low | AF15: 5.49517 | AG15: Sydney | AH15: Australia
A16: JNKNSN001 | B16: - (35) | C16: Tribeca Investment Partners Pty Ltd. | D16: 0 | E16: 0 | F16: 0 | G16: -176754 | I16: 176754 | J16: 375825 | K16: 352007 | L16: 324780 | M16: 325465 | N16: 296578 | O16: 275817 | P16: 269974 | Q16: 146958 | R16: 275304 | S16: 275215 | T16: 219573 | U16: 0.012202184 | V16: 0.026954175 | W16: 613.01737 | X16: 0 | Y16: Top Seller | Z16: 27 | AB16: Investment Advisor | AC16: Active | AD16: Core Value | AE16: Low | AF16: 0.17986 | AG16: Sydney | AH16: Australia
A17: STTSTR065 | B17: 7 (5) | C17: State Street Global Advisors Australia Ltd. | D17: 0.03266956 | E17: 0.03658242 | F17: 831992 | G17: 14397 | I17: 817595 | J17: 665961 | K17: 501107 | L17: 459758 | M17: 373125 | N17: 280841 | O17: 279831 | P17: 226495 | Q17: 172228 | R17: 155707 | S17: 112292 | T17: 111180 | U17: 0.042074573 | V17: 0.069620494 | W17: 751.38321 | X17: 0.53 | Y17: Top Buyer | Z17: -163 | AB17: Investment Advisor/Hedge Fund | AC17: Passive | AD17: Index | AE17: Low | AF17: 62.72055 | AG17: Sydney | AH17: Australia
A18: CHSTRS005 | B18: 26 (28) | C18: Chester Asset Management Pty Ltd. | D18: 0.01110854 | E18: 0.01243902 | F18: 282900 | G18: 30350 | I18: 252550 | J18: 207000 | K18: 181800 | L18: 166250 | M18: 192000 | N18: 182150 | O18: 202200 | P18: 217500 | Q18: 132700 | R18: 112062 | S18: 212500 | T18: 252200 | U18: 0.010980224 | V18: 0.0119486 | W18: -11.153623 | X18: 1 | Y18: Neutral | Z18: 167 | AB18: Investment Advisor | AC18: Active | AD18: GARP | AE18: Low | AF18: 0.04849 | AG18: Melbourne | AH18: Australia
A19: VNGRDN026 | B19: 22 (20) | C19: Vanguard Investments Australia Ltd. | D19: 0.01329778 | E19: 0.01489046 | F19: 338653 | G19: 3581 | I19: 335072 | J19: 269290 | K19: 267018 | L19: 265466 | M19: 223658 | N19: 222556 | O19: 223483 | P19: 202790 | Q19: 202880 | R19: 201875 | S19: 168702 | T19: 167403 | U19: 0.020312238 | V19: 0.043478874 | W19: 650.18473 | X19: 0.34 | Y19: Buyer | Z19: -582 | AB19: Investment Advisor | AC19: Passive | AD19: Index | AE19: Low | AF19: 82.15743 | AG19: Melbourne | AH19: Australia
A20: ICNVST009 | B20: 34 (31) | C20: ICE Investors Pty., Ltd. | D20: 0.0061419 | E20: 0.00687752 | F20: 156415 | G20: -42469 | I20: 198884 | J20: 198995 | K20: 198586 | L20: 208749 | M20: 208749 | N20: 208442 | O20: 183471 | P20: 200757 | Q20: 236020 | R20: 213888 | S20: 213973 | T20: 206723 | U20: 0.00858372 | V20: 0.010007453 | W20: 71.183973 | X20: 0.69 | Y20: Neutral | Z20: -32 | AB20: Investment Advisor | AC20: Active | AD20: N/A | AE20: Low | AF20: 0.03066 | AG20: Melbourne | AH20: Australia
A21: SLSFND001 | B21: 29 (30) | C21: Celeste Funds Management Limited | D21: 0.00830212 | E21: 0.00929646 | F21: 211429 | G21: -3395 | I21: 214824 | J21: 256043 | K21: 260201 | L21: 262255 | M21: 262377 | N21: 262058 | O21: 254189 | P21: 199521 | Q21: 269184 | R21: 262390 | S21: 252749 | T21: 212346 | U21: 0.005045503 | V21: 0.009027773 | W21: -6.1108371 | X21: 1 | Y21: Neutral | Z21: -3 | AB21: Investment Advisor | AC21: Active | AD21: GARP | AE21: Low | AF21: 0.05018 | AG21: Sydney | AH21: Australia
A22: DVNFND001 | B22: 101 (57) | C22: Devon Funds Management Limited | D22: 0.0001593 | E22: 0.00017838 | F22: 4057 | G22: -41616 | I22: 45673 | J22: 188338 | K22: 163206 | L22: 175042 | M22: 167189 | N22: 172761 | O22: 171660 | P22: 191674 | Q22: 272953 | R22: 142232 | S22: 78209 | T22: 91571 | U22: 0.014352401 | V22: 0.029899618 | W22: 675.94843 | X22: 0.01 | Y22: Seller | AB22: Investment Advisor | AC22: Active | AD22: Growth | AE22: Low | AF22: 0.00629 | AG22: Auckland | AH22: New Zealand
A23: OPSCPT002 | B23: 14 (14) | C23: OC Funds Management Pty Ltd. | D23: 0.01796686 | E23: 0.02011876 | F23: 457560 | G23: 2560 | I23: 455000 | J23: 477600 | K23: 492480 | L23: 473230 | M23: 383748 | N23: 148040 | O23: 147850 | P23: 191625 | Q23: 191625 | R23: 191625 | S23: 99475 | T23: 0 | U23: 0.007844571 | V23: 0.020459339 | W23: 7.7456625 | X23: 0.98 | Y23: Top Buyer | Z23: -49 | AB23: Investment Advisor | AC23: Active | AD23: Core Value | AE23: Low | AF23: 0.12313 | AG23: Melbourne | AH23: Australia
A24: INDSTR09N | B24: 19 (18) | C24: IFM Investors | D24: 0.01581595 | E24: 0.01771024 | F24: 402783 | G24: 21099 | I24: 381684 | J24: 293103 | K24: 292184 | L24: 286835 | M24: 276385 | N24: 272452 | O24: 212847 | P24: 190354 | Q24: 179320 | R24: 209658 | S24: 191677 | T24: 185392 | U24: 0.0154958 | V24: 0.028650318 | W24: 248.80966 | X24: 0.62 | Y24: Top Buyer | AB24: Investment Advisor | AC24: Passive | AD24: Index | AE24: Low | AF24: 12.88981 | AG24: Melbourne | AH24: Australia
A25: RGLFND002 | B25: 35 (42) | C25: Regal Funds Management Pty. Ltd. | D25: 0.00597988 | E25: 0.0066961 | F25: 152289 | G25: 30061 | I25: 122228 | J25: 145564 | K25: 136163 | L25: 140471 | M25: 162122 | N25: 165622 | O25: 164160 | P25: 185172 | Q25: 141910 | R25: 152789 | S25: 144875 | T25: 158953 | U25: 0.009035977 | V25: 0.017264975 | W25: 240.36741 | X25: 0.39 | Y25: Buyer | Z25: -10 | AB25: Hedge Fund | AC25: Active | AD25: Hedge Fund | AE25: High | AF25: 0.53591 | AG25: Sydney | AH25: Australia
A26: CPTLPT00C | B26: 41 (39) | C26: 1851 Capital Pty Ltd | D26: 0.00511095 | E26: 0.00572309 | F26: 130160 | G26: 0 | I26: 130160 | J26: 95673 | K26: 87452 | L26: 66502 | M26: 148846 | N26: 199557 | O26: 161057 | P26: 161057 | Q26: 161057 | R26: 161057 | S26: 142057 | T26: 120057 | U26: 0.007413437 | V26: 0.008968388 | W26: 73.807573 | X26: 0.64 | Y26: Seller | Z26: 8 | AB26: Investment Advisor | AC26: Active | AD26: N/A | AE26: Low | AF26: 0.02408 | AG26: Sydney | AH26: Australia
A27: MPLBRW001 | B27: 31 (34) | C27: Maple-Brown Abbott Ltd. | D27: 0.0071326 | E27: 0.00798687 | F27: 181645 | G27: 2916 | I27: 178729 | J27: 130476 | K27: 128633 | L27: 128073 | M27: 153720 | N27: 123212 | O27: 123212 | P27: 160826 | Q27: 160663 | R27: 85845 | S27: 0 | T27: 0 | U27: 0.010964649 | V27: 0.029576572 | W27: 491.01341 | X27: 0.27 | Y27: Seller | Z27: 42 | AB27: Investment Advisor | AC27: Active | AD27: Core Value | AE27: Low | AF27: 1.86005 | AG27: Sydney | AH27: Australia
A28: VNVNVS001 | B28: 5 (6) | C28: Vinva Investment Management Limited | D28: 0.03323599 | E28: 0.03721668 | F28: 846417 | G28: 40131 | I28: 806286 | J28: 704855 | K28: 683298 | L28: 666636 | M28: 580903 | N28: 448299 | O28: 247950 | P28: 158629 | Q28: 141814 | R28: 141606 | S28: 131106 | T28: 0 | U28: 0.015440715 | V28: 0.037796591 | W28: 13.188866 | X28: 0.98 | Y28: Top Seller | AB28: Investment Advisor/Hedge Fund | AC28: Passive | AD28: N/A | AE28: Low | AF28: 3.04449 | AG28: Sydney | AH28: Australia
A29: PTTRWR001 | B29: 27 (26) | C29: BlackRock Investment Management (Australia) Ltd. | D29: 0.01052449 | E29: 0.01178502 | F29: 268026 | G29: 7509 | I29: 260517 | J29: 225813 | K29: 219565 | L29: 225160 | M29: 211061 | N29: 206283 | O29: 201525 | P29: 152276 | Q29: 147985 | R29: 149286 | S29: 163381 | T29: 134834 | U29: 0.015683254 | V29: 0.026813979 | W29: 341.8029 | X29: 0.44 | Y29: Top Buyer | Z29: 1163 | AB29: Investment Advisor | AC29: Passive | AD29: Index | AE29: Low | AF29: 87.37601 | AG29: Melbourne | AH29: Australia
A30: BNNLNG00E | B30: 44 (41) | C30: Bennelong Long Short Equity Management Pty Ltd | D30: 0.00470093 | E30: 0.00526396 | F30: 119718 | G30: -5400 | I30: 125118 | J30: 130000 | K30: 130000 | L30: 150000 | M30: 150000 | N30: 150000 | O30: 150000 | P30: 150000 | Q30: 150000 | R30: 150000 | S30: 184000 | T30: 192000 | U30: 0.005408883 | V30: 0.009247821 | W30: 90.604703 | X30: 0.57 | Y30: Seller | AB30: Hedge Fund | AC30: Active | AD30: Hedge Fund | AE30: Med | AF30: 0.27599 | AG30: Melbourne | AH30: Australia
A31: QVGCPT001 | B31: 30 (32) | C31: QVG Capital Pty Ltd. | D31: 0.00809196 | E31: 0.00906114 | F31: 206077 | G31: 15000 | I31: 191077 | J31: 181077 | K31: 174577 | L31: 182077 | M31: 182077 | N31: 176077 | O31: 151577 | P31: 142377 | Q31: 120577 | R31: 120577 | S31: 109680 | T31: 71680 | U31: 0.007806757 | V31: 0.029716421 | W31: 469.76199 | X31: 0.3 | Y31: Buyer | Z31: 3 | AB31: Investment Advisor | AC31: Active | AD31: N/A | AE31: High | AF31: 0.39946 | AG31: Sydney | AH31: Australia
A32: BRCLYS005 | B32: 69 (38) | C32: Barclays Capital | D32: 0.00067126 | E32: 0 | F32: 17095 | G32: -117736 | I32: 134831 | J32: 132327 | K32: 162214 | L32: 162708 | M32: 163096 | N32: 135686 | O32: 97489 | P32: 137181 | Q32: 162880 | R32: 142879 | S32: 141282 | T32: 143302 | AB32: Research Firm | AC32: Passive | AD32: Broker-Dealer | AE32: Low | AF32: 50.66338 | AG32: London | AH32: United Kingdom
A33: VCTRNF001 | B33: 28 (29) | C33: Victorian Funds Management Corporation | D33: 0.01000279 | E33: 0.01120084 | F33: 254740 | G33: 38334 | I33: 216406 | J33: 193457 | K33: 163188 | L33: 188677 | M33: 147210 | N33: 103320 | O33: 111059 | P33: 118554 | Q33: 118554 | R33: 136715 | S33: 136715 | T33: 123118 | U33: 0.007986003 | V33: 0.017952552 | W33: 153.55394 | X33: 0.62 | Y33: Seller | AB33: Investment Advisor | AC33: Active | AD33: N/A | AE33: Low | AF33: 0.00752 | AG33: Melbourne | AH33: Australia
A34: RLNDXN002 | B34: 39 (40) | C34: RQI Investors | D34: 0.00520492 | E34: 0.00582831 | F34: 132553 | G34: 3187 | I34: 129366 | J34: 113902 | K34: 125489 | L34: 119148 | M34: 119062 | N34: 107880 | O34: 107843 | P34: 103231 | Q34: 102702 | R34: 73716 | S34: 40375 | T34: 33538 | U34: 0.008600195 | V34: 0.026198004 | W34: 463.26682 | X34: 0.22 | Y34: Seller | Z34: -148 | AB34: Investment Advisor | AC34: Passive | AD34: Index | AE34: Low | AF34: 1.50584 | AG34: Sydney | AH34: Australia
A35: OPHRSS001 | B35: - (-) | C35: Ophir Asset Management Pty Ltd | D35: 0 | E35: 0 | F35: 0 | G35: 0 | I35: 0 | J35: 165240 | K35: 151019 | L35: 170215 | M35: 200820 | N35: 161892 | O35: 161892 | P35: 83442 | Q35: 0 | R35: 0 | S35: 2450 | T35: 0 | U35: 0.010576945 | V35: 0.014804617 | W35: 336.70062 | X35: 0 | Y35: Neutral | AB35: Investment Advisor | AC35: Active | AD35: GARP | AE35: High | AF35: 0.68565 | AG35: Sydney | AH35: Australia
A36: UBSSST006 | B36: 37 (51) | C36: UBS Asset Management (Australia) Ltd. | D36: 0.00577864 | E36: 0.00647075 | F36: 147164 | G36: 84107 | I36: 63057 | J36: 108523 | K36: 105101 | L36: 96167 | M36: 84867 | N36: 81345 | O36: 76132 | P36: 76132 | Q36: 76132 | R36: 76132 | S36: 61880 | T36: 55011 | U36: 0.006412461 | V36: 0.01257083 | W36: 138.73372 | X36: 0.51 | Y36: Seller | Z36: -292 | AB36: Investment Advisor | AC36: Active | AD36: GARP | AE36: Low | AF36: 0.59171 | AG36: Sydney | AH36: Australia
A37: FRVWQT001 | B37: 49 (58) | C37: Fairview Equity Partners Pty Ltd | D37: 0.00263931 | E37: 0.00295542 | F37: 67215 | G37: 23125 | I37: 44090 | J37: 107952 | K37: 109148 | L37: 100760 | M37: 105452 | N37: 83816 | O37: 78766 | P37: 68766 | Q37: 0 | R37: 0 | S37: 0 | T37: 0 | U37: 0.008039459 | V37: 0.014791233 | W37: 269.18123 | X37: 0.2 | Y37: Buyer | Z37: -7 | AB37: Investment Advisor | AC37: Active | AD37: Growth | AE37: Low | AF37: 0 | AG37: Melbourne | AH37: Australia
A38: CLNLFR001 | B38: 33 (37) | C38: First Sentier Investors | D38: 0.00628895 | E38: 0.00704218 | F38: 160160 | G38: 7 | I38: 160153 | J38: 177860 | K38: 176548 | L38: 176888 | M38: 186433 | N38: 162941 | O38: 96560 | P38: 66292 | Q38: 0 | R38: 0 | S38: 6478 | T38: 1474 | U38: 0.01369301 | V38: 0.040020333 | W38: 750.02031 | X38: 0.18 | Y38: Top Buyer | Z38: -1591 | AB38: Investment Advisor | AC38: Active | AD38: N/A | AE38: Low | AF38: 8.784 | AG38: Sydney | AH38: Australia
A39: FRTRLN001 | B39: 6 (9) | C39: Firetrail Investments Pty Limited | D39: 0.03284736 | E39: 0.03678151 | F39: 836520 | G39: 183061 | I39: 653459 | J39: 538101 | K39: 64015 | L39: 59531 | M39: 59531 | N39: 59531 | O39: 77929 | P39: 66200 | Q39: 81118 | R39: 71700 | S39: 103600 | T39: 113400 | U39: 0.015487592 | V39: 0.038261755 | W39: 33.665066 | X39: 0.96 | Y39: Top Buyer | Z39: -106 | AB39: Investment Advisor | AC39: Active | AD39: N/A | AE39: Low | AF39: 1.55319 | AG39: Sydney | AH39: Australia
A40: FDLTYN023 | B40: 47 (48) | C40: FIL Investment Management (Australia) Limited | D40: 0.0027661 | E40: 0.0030974 | F40: 70444 | G40: 0 | I40: 70444 | J40: 119334 | K40: 77388 | L40: 61981 | M40: 61981 | N40: 61981 | O40: 61981 | P40: 61981 | Q40: 61981 | R40: 61981 | S40: 40282 | T40: 0 | U40: 0.026853574 | V40: 0.058267638 | W40: 1254.7338 | X40: 0.05 | Y40: Buyer | Z40: -879 | AB40: Investment Advisor | AC40: Active | AD40: GARP | AE40: Low | AF40: 6.33088 | AG40: Sydney | AH40: Australia
...
