Workbook

Sheet I

Sheet FY25
D2: SOLE TAGS | G2: FUNDS - SOLE TAGS | M2: Filter | P2: SOLE TAGS | T2: CONTRIBUTED TAGS
B3: From | C3: To | D3: Date | E3: Amount | G3: Rank | H3: Fund | I3: Amount | J3: Count | K3: % | M3: Fund | N3: Amount | P3: Date | Q3: Amount | R3: Fund | T3: Date | U3: Amount | V3: Fund | W3: Comment
B4: 45474 | C4: =EOMONTH(B4,0) -> 45504 | D4: =C4 -> 45504 | E4: =SUMIFS($Q:$Q,$P:$P,">="&B4,$P:$P,"<="&C4) -> 0 | G4: 1 | H4: =_xlfn.XLOOKUP(I4,$N:$N,$M:$M) -> BAEP | I4: =LARGE($N:$N,G4) -> 17200 | J4: =COUNTIF($R:$R,$H4) -> 8 | K4: =I4/$I$24 -> 0.2721519 | M4: {=_xlfn.UNIQUE(_xlfn._xlws.FILTER($R$4:$R$25,$R$4:$R$25<>""))} -> BAEP | N4: =SUMIF($R:$R,$M4,$Q:$Q) -> 17200 | P4: 45716 | Q4: 1500 | R4: BAEP | T4: 45623 | U4: 6100 | V4: BAEP | W4: Sam Bradshaw and Paul Mason
B5: =C4+1 -> 45505 | C5: =EOMONTH(B5,0) -> 45535 | D5: =C5 -> 45535 | E5: =SUMIFS($Q:$Q,$P:$P,">="&B5,$P:$P,"<="&C5) -> 0 | G5: 2 | H5: =_xlfn.XLOOKUP(I5,$N:$N,$M:$M) -> CBUS | I5: =LARGE($N:$N,G5) -> 17000 | J5: =COUNTIF($R:$R,$H5) -> 2 | K5: =I5/$I$24 -> 0.26898734 | M5: CBUS | N5: =SUMIF($R:$R,$M5,$Q:$Q) -> 17000 | P5: 45749 | Q5: 2300 | R5: BAEP | T5: 45632 | U5: 32900 | V5: L1 | W5: Paul Mason / Sam Bradshaw
B6: =C5+1 -> 45536 | C6: =EOMONTH(B6,0) -> 45565 | D6: =C6 -> 45565 | E6: =SUMIFS($Q:$Q,$P:$P,">="&B6,$P:$P,"<="&C6) -> 0 | G6: 3 | H6: =_xlfn.XLOOKUP(I6,$N:$N,$M:$M) -> Greencape | I6: =LARGE($N:$N,G6) -> 15000 | J6: =COUNTIF($R:$R,$H6) -> 2 | K6: =I6/$I$24 -> 0.23734177 | M6: Wavestone | N6: =SUMIF($R:$R,$M6,$Q:$Q) -> 1500 | P6: 45750 | Q6: 1100 | R6: BAEP | T6: 45645 | U6: 2800 | V6: BAEP | W6: Paul Mason, Sam Bradshaw
B7: =C6+1 -> 45566 | C7: =EOMONTH(B7,0) -> 45596 | D7: =C7 -> 45596 | E7: =SUMIFS($Q:$Q,$P:$P,">="&B7,$P:$P,"<="&C7) -> 0 | G7: 4 | H7: =_xlfn.XLOOKUP(I7,$N:$N,$M:$M) -> ICE | I7: =LARGE($N:$N,G7) -> 7500 | J7: =COUNTIF($R:$R,$H7) -> 2 | K7: =I7/$I$24 -> 0.11867089 | M7: Greencape | N7: =SUMIF($R:$R,$M7,$Q:$Q) -> 15000 | P7: 45750 | Q7: 10000 | R7: CBUS | T7: 45687 | U7: 3200 | V7: BAEP | W7: Paul Mason, Sam Bradshaw
B8: =C7+1 -> 45597 | C8: =EOMONTH(B8,0) -> 45626 | D8: =C8 -> 45626 | E8: =SUMIFS($Q:$Q,$P:$P,">="&B8,$P:$P,"<="&C8) -> 0 | G8: 5 | H8: =_xlfn.XLOOKUP(I8,$N:$N,$M:$M) -> Solaris | I8: =LARGE($N:$N,G8) -> 5000 | J8: =COUNTIF($R:$R,$H8) -> 1 | K8: =I8/$I$24 -> 0.079113924 | M8: ICE | N8: =SUMIF($R:$R,$M8,$Q:$Q) -> 7500 | P8: 45756 | Q8: 3000 | R8: BAEP | T8: 45688 | U8: 10000 | V8: Coopers | W8: strong support from Sam Bradshaw
B9: =C8+1 -> 45627 | C9: =EOMONTH(B9,0) -> 45657 | D9: =C9 -> 45657 | E9: =SUMIFS($Q:$Q,$P:$P,">="&B9,$P:$P,"<="&C9) -> 0 | G9: 6 | H9: =_xlfn.XLOOKUP(I9,$N:$N,$M:$M) -> Wavestone | I9: =LARGE($N:$N,G9) -> 1500 | J9: =COUNTIF($R:$R,$H9) -> 1 | K9: =I9/$I$24 -> 0.023734177 | M9: Solaris | N9: =SUMIF($R:$R,$M9,$Q:$Q) -> 5000 | P9: 45761 | Q9: 3400 | R9: BAEP | T9: 45691 | U9: 3000 | V9: BAEP | W9: Paul Mason, Sam Bradshaw
B10: =C9+1 -> 45658 | C10: =EOMONTH(B10,0) -> 45688 | D10: =C10 -> 45688 | E10: =SUMIFS($Q:$Q,$P:$P,">="&B10,$P:$P,"<="&C10) -> 0 | G10: 7 | N10: =SUMIF($R:$R,$M10,$Q:$Q) -> 0 | P10: 45776 | Q10: 3000 | R10: BAEP | T10: 45793 | U10: 10000 | V10: Devon | W10: Steve Comment - Maso/Sam
B11: =C10+1 -> 45689 | C11: =EOMONTH(B11,0) -> 45716 | D11: =C11 -> 45716 | E11: =SUMIFS($Q:$Q,$P:$P,">="&B11,$P:$P,"<="&C11) -> 1500 | G11: 8 | N11: =SUMIF($R:$R,$M11,$Q:$Q) -> 0 | P11: 45777 | Q11: 1400 | R11: BAEP | T11: 45838 | U11: 25000 | V11: EQT | W11: Sam/Maso | X11: Paul has said this one is all mine.
B12: =C11+1 -> 45717 | C12: =EOMONTH(B12,0) -> 45747 | D12: =C12 -> 45747 | E12: =SUMIFS($Q:$Q,$P:$P,">="&B12,$P:$P,"<="&C12) -> 0 | G12: 9 | N12: =SUMIF($R:$R,$M12,$Q:$Q) -> 0 | P12: 45777 | Q12: 1500 | R12: BAEP
B13: =C12+1 -> 45748 | C13: =EOMONTH(B13,0) -> 45777 | D13: =C13 -> 45777 | E13: =SUMIFS($Q:$Q,$P:$P,">="&B13,$P:$P,"<="&C13) -> 25700 | G13: 10 | N13: =SUMIF($R:$R,$M13,$Q:$Q) -> 0 | P13: 45782 | Q13: 1500 | R13: Wavestone
B14: =C13+1 -> 45778 | C14: =EOMONTH(B14,0) -> 45808 | D14: =C14 -> 45808 | E14: =SUMIFS($Q:$Q,$P:$P,">="&B14,$P:$P,"<="&C14) -> 14500 | G14: 11 | N14: =SUMIF($R:$R,$M14,$Q:$Q) -> 0 | P14: 45783 | Q14: 7500 | R14: Greencape
B15: =C14+1 -> 45809 | C15: =EOMONTH(B15,0) -> 45838 | D15: =C15 -> 45838 | E15: =SUMIFS($Q:$Q,$P:$P,">="&B15,$P:$P,"<="&C15) -> 21500 | G15: 12 | N15: =SUMIF($R:$R,$M15,$Q:$Q) -> 0 | P15: 45789 | Q15: 5500 | R15: ICE
G16: 13 | N16: =SUMIF($R:$R,$M16,$Q:$Q) -> 0 | P16: 45811 | Q16: 7500 | R16: Greencape
G17: 14 | N17: =SUMIF($R:$R,$M17,$Q:$Q) -> 0 | P17: 45818 | Q17: 2000 | R17: ICE
G18: 15 | N18: =SUMIF($R:$R,$M18,$Q:$Q) -> 0 | P18: 45828 | Q18: 5000 | R18: Solaris
G19: 16 | N19: =SUMIF($R:$R,$M19,$Q:$Q) -> 0 | P19: 45833 | Q19: 7000 | R19: CBUS
G20: 17 | N20: =SUMIF($R:$R,$M20,$Q:$Q) -> 0
G21: 18 | N21: =SUMIF($R:$R,$M21,$Q:$Q) -> 0
G22: 19 | N22: =SUMIF($R:$R,$M22,$Q:$Q) -> 0
G23: 20 | N23: =SUMIF($R:$R,$M23,$Q:$Q) -> 0
G24: Total | I24: =SUM(I4:I23) -> 63200

Sheet FY26
D2: MONTHS | I2: STATS | M2: FUNDS | S2: FILTER | W2: TAG LIST
B3: From | C3: To | D3: Date | E3: Amount | G3: Date | H3: Amount | I3: Category | J3: Amount | K3: Proportion | M3: Rank | N3: Fund | O3: Amount | P3: Count | Q3: % | S3: Fund | T3: Fund | U3: Amount | W3: Date | X3: Amount | Y3: Fund
B4: 45839 | C4: =EOMONTH(B4,0) -> 45869 | D4: =C4 -> 45869 | E4: =SUMIFS($X:$X,$W:$W,">="&B4,$W:$W,"<="&C4) -> 29600 | G4: 1 | H4: 5 | I4: 1-5 | J4: {=IF(G4>COUNT($O$4:$O$33), NA(), SUM(LARGE($O$4:$O$33, _xlfn.SEQUENCE(MIN(H4,COUNT($O$4:$O$33))-G4+1, 1, G4))))} -> 235787 | K4: =_xlfn.IFNA(NA(),J4/$O$34) -> 0.4768624 | M4: 1 | N4: =_xlfn.XLOOKUP(M4,$S:$S,$T:$T) -> Greencape | O4: =_xlfn.XLOOKUP(M4,$S:$S,$U:$U) -> 67500 | P4: =COUNTIF($Y:$Y,$N4) -> 7 | Q4: =O4/$O$34 -> 0.13651394 | S4: =RANK($U4,$U$4:$U$33,0)+COUNTIF($U$4:$U4,$U4)-1 -> 2 | T4: {=_xlfn.UNIQUE(_xlfn._xlws.FILTER($Y$4:$Y$498,$Y$4:$Y$498<>""))} -> BAEP | U4: =SUMIF($Y:$Y,$T4,$X:$X) -> 55100 | W4: 45841 | X4: 6100 | Y4: BAEP
B5: =C4+1 -> 45870 | C5: =EOMONTH(B5,0) -> 45900 | D5: =C5 -> 45900 | E5: =SUMIFS($X:$X,$W:$W,">="&B5,$W:$W,"<="&C5) -> 58800 | G5: 6 | H5: 10 | I5: 6-10 | J5: {=IF(G5>COUNT($O$4:$O$33), NA(), SUM(LARGE($O$4:$O$33, _xlfn.SEQUENCE(MIN(H5,COUNT($O$4:$O$33))-G5+1, 1, G5))))} -> 102700 | K5: =_xlfn.IFNA(NA(),J5/$O$34) -> 0.20770343 | M5: =M4+1 -> 2 | N5: =_xlfn.XLOOKUP(M5,$S:$S,$T:$T) -> BAEP | O5: =_xlfn.XLOOKUP(M5,$S:$S,$U:$U) -> 55100 | P5: =COUNTIF($Y:$Y,$N5) -> 16 | Q5: =O5/$O$34 -> 0.11143582 | S5: =RANK($U5,$U$4:$U$33,0)+COUNTIF($U$4:$U5,$U5)-1 -> 25 | T5: SG Hiscock | U5: =SUMIF($Y:$Y,$T5,$X:$X) -> 5000 | W5: 45841 | X5: 5000 | Y5: SG Hiscock
B6: =C5+1 -> 45901 | C6: =EOMONTH(B6,0) -> 45930 | D6: =C6 -> 45930 | E6: =SUMIFS($X:$X,$W:$W,">="&B6,$W:$W,"<="&C6) -> 32137 | G6: 11 | H6: 15 | I6: 11-15 | J6: {=IF(G6>COUNT($O$4:$O$33), NA(), SUM(LARGE($O$4:$O$33, _xlfn.SEQUENCE(MIN(H6,COUNT($O$4:$O$33))-G6+1, 1, G6))))} -> 65968 | K6: =_xlfn.IFNA(NA(),J6/$O$34) -> 0.13341558 | M6: =M5+1 -> 3 | N6: =_xlfn.XLOOKUP(M6,$S:$S,$T:$T) -> Quest | O6: =_xlfn.XLOOKUP(M6,$S:$S,$U:$U) -> 45687 | P6: =COUNTIF($Y:$Y,$N6) -> 3 | Q6: =O6/$O$34 -> 0.092398702 | S6: =RANK($U6,$U$4:$U$33,0)+COUNTIF($U$4:$U6,$U6)-1 -> 12 | T6: Ellerston | U6: =SUMIF($Y:$Y,$T6,$X:$X) -> 15000 | W6: 45854 | X6: 3500 | Y6: Ellerston
B7: =C6+1 -> 45931 | C7: =EOMONTH(B7,0) -> 45961 | D7: =C7 -> 45961 | E7: =SUMIFS($X:$X,$W:$W,">="&B7,$W:$W,"<="&C7) -> 34700 | G7: 16 | H7: 20 | I7: 16-20 | J7: {=IF(G7>COUNT($O$4:$O$33), NA(), SUM(LARGE($O$4:$O$33, _xlfn.SEQUENCE(MIN(H7,COUNT($O$4:$O$33))-G7+1, 1, G7))))} -> 47500 | K7: =_xlfn.IFNA(NA(),J7/$O$34) -> 0.096065365 | M7: =M6+1 -> 4 | N7: =_xlfn.XLOOKUP(M7,$S:$S,$T:$T) -> WAM | O7: =_xlfn.XLOOKUP(M7,$S:$S,$U:$U) -> 40000 | P7: =COUNTIF($Y:$Y,$N7) -> 3 | Q7: =O7/$O$34 -> 0.080897149 | S7: =RANK($U7,$U$4:$U$33,0)+COUNTIF($U$4:$U7,$U7)-1 -> 4 | T7: WAM | U7: =SUMIF($Y:$Y,$T7,$X:$X) -> 40000 | W7: 45855 | X7: 15000 | Y7: WAM
B8: =C7+1 -> 45962 | C8: =EOMONTH(B8,0) -> 45991 | D8: =C8 -> 45991 | E8: =SUMIFS($X:$X,$W:$W,">="&B8,$W:$W,"<="&C8) -> 32500 | G8: 21 | H8: 25 | I8: 21-25 | J8: {=IF(G8>COUNT($O$4:$O$33), NA(), SUM(LARGE($O$4:$O$33, _xlfn.SEQUENCE(MIN(H8,COUNT($O$4:$O$33))-G8+1, 1, G8))))} -> 30500 | K8: =_xlfn.IFNA(NA(),J8/$O$34) -> 0.061684076 | M8: =M7+1 -> 5 | N8: =_xlfn.XLOOKUP(M8,$S:$S,$T:$T) -> Solaris | O8: =_xlfn.XLOOKUP(M8,$S:$S,$U:$U) -> 27500 | P8: =COUNTIF($Y:$Y,$N8) -> 5 | Q8: =O8/$O$34 -> 0.05561679 | S8: =RANK($U8,$U$4:$U$33,0)+COUNTIF($U$4:$U8,$U8)-1 -> 6 | T8: ICE | U8: =SUMIF($Y:$Y,$T8,$X:$X) -> 23500 | W8: 45873 | X8: 4000 | Y8: ICE
B9: =C8+1 -> 45992 | C9: =EOMONTH(B9,0) -> 46022 | D9: =C9 -> 46022 | E9: =SUMIFS($X:$X,$W:$W,">="&B9,$W:$W,"<="&C9) -> 61000 | G9: 26 | H9: 30 | I9: 26-30 | J9: {=IF(G9>COUNT($O$4:$O$33), NA(), SUM(LARGE($O$4:$O$33, _xlfn.SEQUENCE(MIN(H9,COUNT($O$4:$O$33))-G9+1, 1, G9))))} -> 12000 | K9: =_xlfn.IFNA(NA(),J9/$O$34) -> 0.024269145 | M9: =M8+1 -> 6 | N9: =_xlfn.XLOOKUP(M9,$S:$S,$T:$T) -> ICE | O9: =_xlfn.XLOOKUP(M9,$S:$S,$U:$U) -> 23500 | P9: =COUNTIF($Y:$Y,$N9) -> 7 | Q9: =O9/$O$34 -> 0.047527075 | S9: =RANK($U9,$U$4:$U$33,0)+COUNTIF($U$4:$U9,$U9)-1 -> 1 | T9: Greencape | U9: =SUMIF($Y:$Y,$T9,$X:$X) -> 67500 | W9: 45873 | X9: 10000 | Y9: Greencape
B10: =C9+1 -> 46023 | C10: =EOMONTH(B10,0) -> 46053 | D10: =C10 -> 46053 | E10: =SUMIFS($X:$X,$W:$W,">="&B10,$W:$W,"<="&C10) -> 35000 | G10: 31 | H10: 35 | I10: 31-35 | J10: {=IF(G10>COUNT($O$4:$O$33), NA(), SUM(LARGE($O$4:$O$33, _xlfn.SEQUENCE(MIN(H10,COUNT($O$4:$O$33))-G10+1, 1, G10))))} -> #N/A | K10: =_xlfn.IFNA(NA(),J10/$O$34) -> #N/A | M10: =M9+1 -> 7 | N10: =_xlfn.XLOOKUP(M10,$S:$S,$T:$T) -> CBUS | O10: =_xlfn.XLOOKUP(M10,$S:$S,$U:$U) -> 21000 | P10: =COUNTIF($Y:$Y,$N10) -> 3 | Q10: =O10/$O$34 -> 0.042471003 | S10: =RANK($U10,$U$4:$U$33,0)+COUNTIF($U$4:$U10,$U10)-1 -> 10 | T10: Arrow | U10: =SUMIF($Y:$Y,$T10,$X:$X) -> 18000 | W10: 45874 | X10: 3200 | Y10: BAEP
B11: =C10+1 -> 46054 | C11: =EOMONTH(B11,0) -> 46081 | D11: =C11 -> 46081 | E11: =SUMIFS($X:$X,$W:$W,">="&B11,$W:$W,"<="&C11) -> 28168 | G11: 36 | H11: 40 | I11: 36-40 | J11: {=IF(G11>COUNT($O$4:$O$33), NA(), SUM(LARGE($O$4:$O$33, _xlfn.SEQUENCE(MIN(H11,COUNT($O$4:$O$33))-G11+1, 1, G11))))} -> #N/A | K11: =_xlfn.IFNA(NA(),J11/$O$34) -> #N/A | M11: =M10+1 -> 8 | N11: =_xlfn.XLOOKUP(M11,$S:$S,$T:$T) -> Perps Private | O11: =_xlfn.XLOOKUP(M11,$S:$S,$U:$U) -> 21000 | P11: =COUNTIF($Y:$Y,$N11) -> 3 | Q11: =O11/$O$34 -> 0.042471003 | S11: =RANK($U11,$U$4:$U$33,0)+COUNTIF($U$4:$U11,$U11)-1 -> 5 | T11: Solaris | U11: =SUMIF($Y:$Y,$T11,$X:$X) -> 27500 | W11: 45876 | X11: 8000 | Y11: Arrow
B12: =C11+1 -> 46082 | C12: =EOMONTH(B12,0) -> 46112 | D12: =C12 -> 46112 | E12: =SUMIFS($X:$X,$W:$W,">="&B12,$W:$W,"<="&C12) -> 35500 | M12: =M11+1 -> 9 | N12: =_xlfn.XLOOKUP(M12,$S:$S,$T:$T) -> L1 Capital | O12: =_xlfn.XLOOKUP(M12,$S:$S,$U:$U) -> 19200 | P12: =COUNTIF($Y:$Y,$N12) -> 1 | Q12: =O12/$O$34 -> 0.038830632 | S12: =RANK($U12,$U$4:$U$33,0)+COUNTIF($U$4:$U12,$U12)-1 -> 21 | T12: Pendal | U12: =SUMIF($Y:$Y,$T12,$X:$X) -> 7500 | W12: 45880 | X12: 2500 | Y12: Solaris
B13: =C12+1 -> 46113 | C13: =EOMONTH(B13,0) -> 46142 | D13: =C13 -> 46142 | E13: =SUMIFS($X:$X,$W:$W,">="&B13,$W:$W,"<="&C13) -> 86050 | G13: 1 | H13: 3 | I13: Top 3 | J13: {=IF(G13>COUNT($O$4:$O$33), NA(), SUM(LARGE($O$4:$O$33, _xlfn.SEQUENCE(MIN(H13,COUNT($O$4:$O$33))-G13+1, 1, G13))))} -> 168287 | K13: =_xlfn.IFNA(NA(),J13/$O$34) -> 0.34034846 | M13: =M12+1 -> 10 | N13: =_xlfn.XLOOKUP(M13,$S:$S,$T:$T) -> Arrow | O13: =_xlfn.XLOOKUP(M13,$S:$S,$U:$U) -> 18000 | P13: =COUNTIF($Y:$Y,$N13) -> 2 | Q13: =O13/$O$34 -> 0.036403717 | S13: =RANK($U13,$U$4:$U$33,0)+COUNTIF($U$4:$U13,$U13)-1 -> 26 | T13: Regal | U13: =SUMIF($Y:$Y,$T13,$X:$X) -> 5000 | W13: 45880 | X13: 7500 | Y13: Pendal
B14: =C13+1 -> 46143 | C14: =EOMONTH(B14,0) -> 46173 | D14: =C14 -> 46173 | E14: =SUMIFS($X:$X,$W:$W,">="&B14,$W:$W,"<="&C14) -> 22500 | G14: 1 | H14: 5 | I14: Top 5 | J14: {=IF(G14>COUNT($O$4:$O$33), NA(), SUM(LARGE($O$4:$O$33, _xlfn.SEQUENCE(MIN(H14,COUNT($O$4:$O$33))-G14+1, 1, G14))))} -> 235787 | K14: =_xlfn.IFNA(NA(),J14/$O$34) -> 0.4768624 | M14: =M13+1 -> 11 | N14: =_xlfn.XLOOKUP(M14,$S:$S,$T:$T) -> Antares | O14: =_xlfn.XLOOKUP(M14,$S:$S,$U:$U) -> 17500 | P14: =COUNTIF($Y:$Y,$N14) -> 3 | Q14: =O14/$O$34 -> 0.035392503 | S14: =RANK($U14,$U$4:$U$33,0)+COUNTIF($U$4:$U14,$U14)-1 -> 16 | T14: Coopers | U14: =SUMIF($Y:$Y,$T14,$X:$X) -> 10000 | W14: 45881 | X14: 3100 | Y14: BAEP
B15: =C14+1 -> 46174 | C15: =EOMONTH(B15,0) -> 46203 | D15: =C15 -> 46203 | E15: =SUMIFS($X:$X,$W:$W,">="&B15,$W:$W,"<="&C15) -> 38500 | G15: 1 | H15: 10 | I15: Top 10 | J15: {=IF(G15>COUNT($O$4:$O$33), NA(), SUM(LARGE($O$4:$O$33, _xlfn.SEQUENCE(MIN(H15,COUNT($O$4:$O$33))-G15+1, 1, G15))))} -> 338487 | K15: =_xlfn.IFNA(NA(),J15/$O$34) -> 0.68456584 | M15: =M14+1 -> 12 | N15: =_xlfn.XLOOKUP(M15,$S:$S,$T:$T) -> Ellerston | O15: =_xlfn.XLOOKUP(M15,$S:$S,$U:$U) -> 15000 | P15: =COUNTIF($Y:$Y,$N15) -> 5 | Q15: =O15/$O$34 -> 0.030336431 | S15: =RANK($U15,$U$4:$U$33,0)+COUNTIF($U$4:$U15,$U15)-1 -> 22 | T15: Hesta | U15: =SUMIF($Y:$Y,$T15,$X:$X) -> 6000 | W15: 45881 | X15: 2500 | Y15: Solaris
G16: 1 | H16: 20 | I16: Top 20 | J16: {=IF(G16>COUNT($O$4:$O$33), NA(), SUM(LARGE($O$4:$O$33, _xlfn.SEQUENCE(MIN(H16,COUNT($O$4:$O$33))-G16+1, 1, G16))))} -> 451955 | K16: =_xlfn.IFNA(NA(),J16/$O$34) -> 0.91404678 | M16: =M15+1 -> 13 | N16: =_xlfn.XLOOKUP(M16,$S:$S,$T:$T) -> Centennial | O16: =_xlfn.XLOOKUP(M16,$S:$S,$U:$U) -> 12500 | P16: =COUNTIF($Y:$Y,$N16) -> 1 | Q16: =O16/$O$34 -> 0.025280359 | S16: =RANK($U16,$U$4:$U$33,0)+COUNTIF($U$4:$U16,$U16)-1 -> 3 | T16: Quest | U16: =SUMIF($Y:$Y,$T16,$X:$X) -> 45687 | W16: 45881 | X16: 5000 | Y16: Regal
G17: 1 | H17: 50 | I17: Top 50 | J17: {=IF(G17>COUNT($O$4:$O$33), NA(), SUM(LARGE($O$4:$O$33, _xlfn.SEQUENCE(MIN(H17,COUNT($O$4:$O$33))-G17+1, 1, G17))))} -> 494455 | K17: =_xlfn.IFNA(NA(),J17/$O$34) -> 1 | M17: =M16+1 -> 14 | N17: =_xlfn.XLOOKUP(M17,$S:$S,$T:$T) -> Aus Super | O17: =_xlfn.XLOOKUP(M17,$S:$S,$U:$U) -> 10900 | P17: =COUNTIF($Y:$Y,$N17) -> 1 | Q17: =O17/$O$34 -> 0.022044473 | S17: =RANK($U17,$U$4:$U$33,0)+COUNTIF($U$4:$U17,$U17)-1 -> 7 | T17: CBUS | U17: =SUMIF($Y:$Y,$T17,$X:$X) -> 21000 | W17: 45883 | X17: 10000 | Y17: Coopers
M18: =M17+1 -> 15 | N18: =_xlfn.XLOOKUP(M18,$S:$S,$T:$T) -> SMID | O18: =_xlfn.XLOOKUP(M18,$S:$S,$U:$U) -> 10068 | P18: =COUNTIF($Y:$Y,$N18) -> 1 | Q18: =O18/$O$34 -> 0.020361813 | S18: =RANK($U18,$U$4:$U$33,0)+COUNTIF($U$4:$U18,$U18)-1 -> 17 | T18: Ophir | U18: =SUMIF($Y:$Y,$T18,$X:$X) -> 10000 | W18: 45895 | X18: 3000 | Y18: Hesta
M19: =M18+1 -> 16 | N19: =_xlfn.XLOOKUP(M19,$S:$S,$T:$T) -> Coopers | O19: =_xlfn.XLOOKUP(M19,$S:$S,$U:$U) -> 10000 | P19: =COUNTIF($Y:$Y,$N19) -> 1 | Q19: =O19/$O$34 -> 0.020224287 | S19: =RANK($U19,$U$4:$U$33,0)+COUNTIF($U$4:$U19,$U19)-1 -> 8 | T19: Perps Private | U19: =SUMIF($Y:$Y,$T19,$X:$X) -> 21000 | W19: 45905 | X19: 10937 | Y19: Quest
M20: =M19+1 -> 17 | N20: =_xlfn.XLOOKUP(M20,$S:$S,$T:$T) -> Ophir | O20: =_xlfn.XLOOKUP(M20,$S:$S,$U:$U) -> 10000 | P20: =COUNTIF($Y:$Y,$N20) -> 1 | Q20: =O20/$O$34 -> 0.020224287 | S20: =RANK($U20,$U$4:$U$33,0)+COUNTIF($U$4:$U20,$U20)-1 -> 18 | T20: Platypus | U20: =SUMIF($Y:$Y,$T20,$X:$X) -> 10000 | W20: 45912 | X20: 7000 | Y20: CBUS
M21: =M20+1 -> 18 | N21: =_xlfn.XLOOKUP(M21,$S:$S,$T:$T) -> Platypus | O21: =_xlfn.XLOOKUP(M21,$S:$S,$U:$U) -> 10000 | P21: =COUNTIF($Y:$Y,$N21) -> 2 | Q21: =O21/$O$34 -> 0.020224287 | S21: =RANK($U21,$U$4:$U$33,0)+COUNTIF($U$4:$U21,$U21)-1 -> 23 | T21: Aware | U21: =SUMIF($Y:$Y,$T21,$X:$X) -> 6000 | W21: 45929 | X21: 4200 | Y21: BAEP
M22: =M21+1 -> 19 | N22: =_xlfn.XLOOKUP(M22,$S:$S,$T:$T) -> QVG | O22: =_xlfn.XLOOKUP(M22,$S:$S,$U:$U) -> 9000 | P22: =COUNTIF($Y:$Y,$N22) -> 2 | Q22: =O22/$O$34 -> 0.018201859 | S22: =RANK($U22,$U$4:$U$33,0)+COUNTIF($U$4:$U22,$U22)-1 -> 27 | T22: Eley Griffiths | U22: =SUMIF($Y:$Y,$T22,$X:$X) -> 5000 | W22: 45930 | X22: 10000 | Y22: Ophir
M23: =M22+1 -> 20 | N23: =_xlfn.XLOOKUP(M23,$S:$S,$T:$T) -> OC Funds | O23: =_xlfn.XLOOKUP(M23,$S:$S,$U:$U) -> 8500 | P23: =COUNTIF($Y:$Y,$N23) -> 3 | Q23: =O23/$O$34 -> 0.017190644 | S23: =RANK($U23,$U$4:$U$33,0)+COUNTIF($U$4:$U23,$U23)-1 -> 20 | T23: OC Funds | U23: =SUMIF($Y:$Y,$T23,$X:$X) -> 8500 | W23: 45933 | X23: 3500 | Y23: BAEP
M24: =M23+1 -> 21 | N24: =_xlfn.XLOOKUP(M24,$S:$S,$T:$T) -> Pendal | O24: =_xlfn.XLOOKUP(M24,$S:$S,$U:$U) -> 7500 | P24: =COUNTIF($Y:$Y,$N24) -> 1 | Q24: =O24/$O$34 -> 0.015168216 | S24: =RANK($U24,$U$4:$U$33,0)+COUNTIF($U$4:$U24,$U24)-1 -> 9 | T24: L1 Capital | U24: =SUMIF($Y:$Y,$T24,$X:$X) -> 19200 | W24: 45933 | X24: 2500 | Y24: ICE
M25: =M24+1 -> 22 | N25: =_xlfn.XLOOKUP(M25,$S:$S,$T:$T) -> Hesta | O25: =_xlfn.XLOOKUP(M25,$S:$S,$U:$U) -> 6000 | P25: =COUNTIF($Y:$Y,$N25) -> 2 | Q25: =O25/$O$34 -> 0.012134572 | S25: =RANK($U25,$U$4:$U$33,0)+COUNTIF($U$4:$U25,$U25)-1 -> 11 | T25: Antares | U25: =SUMIF($Y:$Y,$T25,$X:$X) -> 17500 | W25: 45937 | X25: 10000 | Y25: Greencape
M26: =M25+1 -> 23 | N26: =_xlfn.XLOOKUP(M26,$S:$S,$T:$T) -> Aware | O26: =_xlfn.XLOOKUP(M26,$S:$S,$U:$U) -> 6000 | P26: =COUNTIF($Y:$Y,$N26) -> 2 | Q26: =O26/$O$34 -> 0.012134572 | S26: =RANK($U26,$U$4:$U$33,0)+COUNTIF($U$4:$U26,$U26)-1 -> 19 | T26: QVG | U26: =SUMIF($Y:$Y,$T26,$X:$X) -> 9000 | W26: 45939 | X26: 4000 | Y26: Perps Private
M27: =M26+1 -> 24 | N27: =_xlfn.XLOOKUP(M27,$S:$S,$T:$T) -> Firetrail | O27: =_xlfn.XLOOKUP(M27,$S:$S,$U:$U) -> 6000 | P27: =COUNTIF($Y:$Y,$N27) -> 2 | Q27: =O27/$O$34 -> 0.012134572 | S27: =RANK($U27,$U$4:$U$33,0)+COUNTIF($U$4:$U27,$U27)-1 -> 15 | T27: SMID | U27: =SUMIF($Y:$Y,$T27,$X:$X) -> 10068 | W27: 45945 | X27: 3000 | Y27: Hesta
M28: =M27+1 -> 25 | N28: =_xlfn.XLOOKUP(M28,$S:$S,$T:$T) -> SG Hiscock | O28: =_xlfn.XLOOKUP(M28,$S:$S,$U:$U) -> 5000 | P28: =COUNTIF($Y:$Y,$N28) -> 1 | Q28: =O28/$O$34 -> 0.010112144 | S28: =RANK($U28,$U$4:$U$33,0)+COUNTIF($U$4:$U28,$U28)-1 -> 24 | T28: Firetrail | U28: =SUMIF($Y:$Y,$T28,$X:$X) -> 6000 | W28: 45954 | X28: 2500 | Y28: BAEP
M29: =M28+1 -> 26 | N29: =_xlfn.XLOOKUP(M29,$S:$S,$T:$T) -> Regal | O29: =_xlfn.XLOOKUP(M29,$S:$S,$U:$U) -> 5000 | P29: =COUNTIF($Y:$Y,$N29) -> 1 | Q29: =O29/$O$34 -> 0.010112144 | S29: =RANK($U29,$U$4:$U$33,0)+COUNTIF($U$4:$U29,$U29)-1 -> 13 | T29: Centennial | U29: =SUMIF($Y:$Y,$T29,$X:$X) -> 12500 | W29: 45954 | X29: 5000 | Y29: Platypus
... M31: =M30+1 -> 28 | N31: =_xlfn.XLOOKUP(M31,$S:$S,$T:$T) -> Alliance Bernstein | O31: =_xlfn.XLOOKUP(M31,$S:$S,$U:$U) -> 2000 | P31: =COUNTIF($Y:$Y,$N31) -> 1 | Q31: =O31/$O$34 -> 0.0040448575 | S31: =RANK($U31,$U$4:$U$33,0)+COUNTIF($U$4:$U31,$U31)-1 -> 28 | T31: Alliance Bernstein | U31: =SUMIF($Y:$Y,$T31,$X:$X) -> 2000 | W31: 45967 | X31: 10000 | Y31: Greencape
W32: 45968 | X32: 3000 | Y32: Aware
W33: 45968 | X33: 2500 | Y33: Ellerston
M34: Total | O34: =SUM(O4:O33) -> 494455 | W34: 45968 | X34: 5000 | Y34: Eley Griffiths
W35: 45975 | X35: 2000 | Y35: OC Funds
W36: 45986 | X36: 10000 | Y36: Solaris
W37: 45992 | X37: 4000 | Y37: ICE
W38: 45994 | X38: 7500 | Y38: Greencape
W39: 45996 | X39: 6300 | Y39: BAEP
W40: 45998 | X40: 10000 | Y40: Quest
W41: 46000 | X41: 3000 | Y41: Ellerston
W42: 46003 | X42: 7000 | Y42: CBUS
...

Sheet FY27
D2: MONTHS | I2: STATS | M2: FUNDS | S2: FILTER | W2: TAG LIST
B3: From | C3: To | D3: Date | E3: Amount | G3: Date | H3: Amount | I3: Category | J3: Amount | K3: Proportion | M3: Rank | N3: Fund | O3: Amount | P3: Count | Q3: % | S3: Fund | T3: Fund | U3: Amount | W3: Date | X3: Amount | Y3: Fund
B4: 46204 | C4: =EOMONTH(B4,0) -> 46234 | D4: =C4 -> 46234 | E4: =SUMIFS($X:$X,$W:$W,">="&B4,$W:$W,"<="&C4) -> 35000 | G4: 1 | H4: 5 | I4: 1-5 | J4: {=IF(G4>COUNT($O$4:$O$43), NA(), SUM(LARGE($O$4:$O$43, _xlfn.SEQUENCE(MIN(H4,COUNT($O$4:$O$43))-G4+1, 1, G4))))} -> 50000 | K4: =_xlfn.IFNA(NA(),J4/$O$44) -> 0.78064012 | M4: 1 | N4: =_xlfn.XLOOKUP(M4,$S:$S,$T:$T) -> Greencape | O4: =_xlfn.XLOOKUP(M4,$S:$S,$U:$U) -> 20000 | P4: =COUNTIF($Y:$Y,$N4) -> 3 | Q4: =IF(O4>0,O4/$O$44,0) -> 0.31225605 | S4: =RANK($U4,$U$4:$U$33,0)+COUNTIF($U$4:$U4,$U4)-1 -> 1 | T4: {=_xlfn.UNIQUE(_xlfn._xlws.FILTER($Y$4:$Y$498,$Y$4:$Y$498<>""))} -> Greencape | U4: =SUMIF($Y:$Y,$T4,$X:$X) -> 20000 | W4: 46206 | X4: 10000 | Y4: Greencape
B5: =C4+1 -> 46235 | C5: =EOMONTH(B5,0) -> 46265 | D5: =C5 -> 46265 | E5: =SUMIFS($X:$X,$W:$W,">="&B5,$W:$W,"<="&C5) -> 12000 | G5: 6 | H5: 10 | I5: 6-10 | J5: {=IF(G5>COUNT($O$4:$O$43), NA(), SUM(LARGE($O$4:$O$43, _xlfn.SEQUENCE(MIN(H5,COUNT($O$4:$O$43))-G5+1, 1, G5))))} -> 14050 | K5: =_xlfn.IFNA(NA(),J5/$O$44) -> 0.21935988 | M5: =M4+1 -> 2 | N5: =_xlfn.XLOOKUP(M5,$S:$S,$T:$T) -> Perps Private | O5: =_xlfn.XLOOKUP(M5,$S:$S,$U:$U) -> 11000 | P5: =COUNTIF($Y:$Y,$N5) -> 1 | Q5: =IF(O5>0,O5/$O$44,0) -> 0.17174083 | S5: =RANK($U5,$U$4:$U$33,0)+COUNTIF($U$4:$U5,$U5)-1 -> 9 | T5: Hyperion | U5: =SUMIF($Y:$Y,$T5,$X:$X) -> 2000 | W5: 46206 | X5: 2000 | Y5: Hyperion
B6: =C5+1 -> 46266 | C6: =EOMONTH(B6,0) -> 46295 | D6: =C6 -> 46295 | E6: =SUMIFS($X:$X,$W:$W,">="&B6,$W:$W,"<="&C6) -> 17050 | G6: 11 | H6: 15 | I6: 11-15 | J6: {=IF(G6>COUNT($O$4:$O$43), NA(), SUM(LARGE($O$4:$O$43, _xlfn.SEQUENCE(MIN(H6,COUNT($O$4:$O$43))-G6+1, 1, G6))))} -> 0 | K6: =_xlfn.IFNA(NA(),J6/$O$44) -> 0 | M6: =M5+1 -> 3 | N6: =_xlfn.XLOOKUP(M6,$S:$S,$T:$T) -> OC Funds | O6: =_xlfn.XLOOKUP(M6,$S:$S,$U:$U) -> 9000 | P6: =COUNTIF($Y:$Y,$N6) -> 3 | Q6: =IF(O6>0,O6/$O$44,0) -> 0.14051522 | S6: =RANK($U6,$U$4:$U$33,0)+COUNTIF($U$4:$U6,$U6)-1 -> 2 | T6: Perps Private | U6: =SUMIF($Y:$Y,$T6,$X:$X) -> 11000 | W6: 46213 | X6: 11000 | Y6: Perps Private
B7: =C6+1 -> 46296 | C7: =EOMONTH(B7,0) -> 46326 | D7: =C7 -> 46326 | E7: =SUMIFS($X:$X,$W:$W,">="&B7,$W:$W,"<="&C7) -> 0 | G7: 16 | H7: 20 | I7: 16-20 | J7: {=IF(G7>COUNT($O$4:$O$43), NA(), SUM(LARGE($O$4:$O$43, _xlfn.SEQUENCE(MIN(H7,COUNT($O$4:$O$43))-G7+1, 1, G7))))} -> 0 | K7: =_xlfn.IFNA(NA(),J7/$O$44) -> 0 | M7: =M6+1 -> 4 | N7: =_xlfn.XLOOKUP(M7,$S:$S,$T:$T) -> Airlie | O7: =_xlfn.XLOOKUP(M7,$S:$S,$U:$U) -> 5000 | P7: =COUNTIF($Y:$Y,$N7) -> 1 | Q7: =IF(O7>0,O7/$O$44,0) -> 0.078064012 | S7: =RANK($U7,$U$4:$U$33,0)+COUNTIF($U$4:$U7,$U7)-1 -> 3 | T7: OC Funds | U7: =SUMIF($Y:$Y,$T7,$X:$X) -> 9000 | W7: 46216 | X7: 4000 | Y7: OC Funds
B8: =C7+1 -> 46327 | C8: =EOMONTH(B8,0) -> 46356 | D8: =C8 -> 46356 | E8: =SUMIFS($X:$X,$W:$W,">="&B8,$W:$W,"<="&C8) -> 0 | G8: 21 | H8: 25 | I8: 21-25 | J8: {=IF(G8>COUNT($O$4:$O$43), NA(), SUM(LARGE($O$4:$O$43, _xlfn.SEQUENCE(MIN(H8,COUNT($O$4:$O$43))-G8+1, 1, G8))))} -> 0 | K8: =_xlfn.IFNA(NA(),J8/$O$44) -> 0 | M8: =M7+1 -> 5 | N8: =_xlfn.XLOOKUP(M8,$S:$S,$T:$T) -> Solaris | O8: =_xlfn.XLOOKUP(M8,$S:$S,$U:$U) -> 5000 | P8: =COUNTIF($Y:$Y,$N8) -> 1 | Q8: =IF(O8>0,O8/$O$44,0) -> 0.078064012 | S8: =RANK($U8,$U$4:$U$33,0)+COUNTIF($U$4:$U8,$U8)-1 -> 4 | T8: Airlie | U8: =SUMIF($Y:$Y,$T8,$X:$X) -> 5000 | W8: 46217 | X8: 5000 | Y8: Airlie
B9: =C8+1 -> 46357 | C9: =EOMONTH(B9,0) -> 46387 | D9: =C9 -> 46387 | E9: =SUMIFS($X:$X,$W:$W,">="&B9,$W:$W,"<="&C9) -> 0 | G9: 26 | H9: 30 | I9: 26-30 | J9: {=IF(G9>COUNT($O$4:$O$43), NA(), SUM(LARGE($O$4:$O$43, _xlfn.SEQUENCE(MIN(H9,COUNT($O$4:$O$43))-G9+1, 1, G9))))} -> 0 | K9: =_xlfn.IFNA(NA(),J9/$O$44) -> 0 | M9: =M8+1 -> 6 | N9: =_xlfn.XLOOKUP(M9,$S:$S,$T:$T) -> QVG | O9: =_xlfn.XLOOKUP(M9,$S:$S,$U:$U) -> 5000 | P9: =COUNTIF($Y:$Y,$N9) -> 1 | Q9: =IF(O9>0,O9/$O$44,0) -> 0.078064012 | S9: =RANK($U9,$U$4:$U$33,0)+COUNTIF($U$4:$U9,$U9)-1 -> 7 | T9: Aware | U9: =SUMIF($Y:$Y,$T9,$X:$X) -> 3000 | W9: 46225 | X9: 3000 | Y9: Aware
B10: =C9+1 -> 46388 | C10: =EOMONTH(B10,0) -> 46418 | D10: =C10 -> 46418 | E10: =SUMIFS($X:$X,$W:$W,">="&B10,$W:$W,"<="&C10) -> 0 | G10: 31 | H10: 35 | I10: 31-35 | J10: {=IF(G10>COUNT($O$4:$O$43), NA(), SUM(LARGE($O$4:$O$43, _xlfn.SEQUENCE(MIN(H10,COUNT($O$4:$O$43))-G10+1, 1, G10))))} -> #N/A | K10: =_xlfn.IFNA(NA(),J10/$O$44) -> #N/A | M10: =M9+1 -> 7 | N10: =_xlfn.XLOOKUP(M10,$S:$S,$T:$T) -> Aware | O10: =_xlfn.XLOOKUP(M10,$S:$S,$U:$U) -> 3000 | P10: =COUNTIF($Y:$Y,$N10) -> 1 | Q10: =IF(O10>0,O10/$O$44,0) -> 0.046838407 | S10: =RANK($U10,$U$4:$U$33,0)+COUNTIF($U$4:$U10,$U10)-1 -> 5 | T10: Solaris | U10: =SUMIF($Y:$Y,$T10,$X:$X) -> 5000 | W10: 46240 | X10: 5000 | Y10: Greencape
B11: =C10+1 -> 46419 | C11: =EOMONTH(B11,0) -> 46446 | D11: =C11 -> 46446 | E11: =SUMIFS($X:$X,$W:$W,">="&B11,$W:$W,"<="&C11) -> 0 | G11: 36 | H11: 40 | I11: 36-40 | J11: {=IF(G11>COUNT($O$4:$O$43), NA(), SUM(LARGE($O$4:$O$43, _xlfn.SEQUENCE(MIN(H11,COUNT($O$4:$O$43))-G11+1, 1, G11))))} -> #N/A | K11: =_xlfn.IFNA(NA(),J11/$O$44) -> #N/A | M11: =M10+1 -> 8 | N11: =_xlfn.XLOOKUP(M11,$S:$S,$T:$T) -> BAEP | O11: =_xlfn.XLOOKUP(M11,$S:$S,$U:$U) -> 2800 | P11: =COUNTIF($Y:$Y,$N11) -> 1 | Q11: =IF(O11>0,O11/$O$44,0) -> 0.043715847 | S11: =RANK($U11,$U$4:$U$33,0)+COUNTIF($U$4:$U11,$U11)-1 -> 8 | T11: BAEP | U11: =SUMIF($Y:$Y,$T11,$X:$X) -> 2800 | W11: 46246 | X11: 2000 | Y11: OC Funds
B12: =C11+1 -> 46447 | C12: =EOMONTH(B12,0) -> 46477 | D12: =C12 -> 46477 | E12: =SUMIFS($X:$X,$W:$W,">="&B12,$W:$W,"<="&C12) -> 0 | M12: =M11+1 -> 9 | N12: =_xlfn.XLOOKUP(M12,$S:$S,$T:$T) -> Hyperion | O12: =_xlfn.XLOOKUP(M12,$S:$S,$U:$U) -> 2000 | P12: =COUNTIF($Y:$Y,$N12) -> 1 | Q12: =IF(O12>0,O12/$O$44,0) -> 0.031225605 | S12: =RANK($U12,$U$4:$U$33,0)+COUNTIF($U$4:$U12,$U12)-1 -> 6 | T12: QVG | U12: =SUMIF($Y:$Y,$T12,$X:$X) -> 5000 | W12: 46247 | X12: 5000 | Y12: Solaris
B13: =C12+1 -> 46478 | C13: =EOMONTH(B13,0) -> 46507 | D13: =C13 -> 46507 | E13: =SUMIFS($X:$X,$W:$W,">="&B13,$W:$W,"<="&C13) -> 0 | G13: 1 | H13: 3 | I13: Top 3 | J13: {=IF(G13>COUNT($O$4:$O$43), NA(), SUM(LARGE($O$4:$O$43, _xlfn.SEQUENCE(MIN(H13,COUNT($O$4:$O$43))-G13+1, 1, G13))))} -> 40000 | K13: =_xlfn.IFNA(NA(),J13/$O$44) -> 0.6245121 | M13: =M12+1 -> 10 | N13: =_xlfn.XLOOKUP(M13,$S:$S,$T:$T) -> Antares | O13: =_xlfn.XLOOKUP(M13,$S:$S,$U:$U) -> 1250 | P13: =COUNTIF($Y:$Y,$N13) -> 1 | Q13: =IF(O13>0,O13/$O$44,0) -> 0.019516003 | S13: =RANK($U13,$U$4:$U$33,0)+COUNTIF($U$4:$U13,$U13)-1 -> 10 | T13: Antares | U13: =SUMIF($Y:$Y,$T13,$X:$X) -> 1250 | W13: 46266 | X13: 5000 | Y13: Greencape
B14: =C13+1 -> 46508 | C14: =EOMONTH(B14,0) -> 46538 | D14: =C14 -> 46538 | E14: =SUMIFS($X:$X,$W:$W,">="&B14,$W:$W,"<="&C14) -> 0 | G14: 1 | H14: 5 | I14: Top 5 | J14: {=IF(G14>COUNT($O$4:$O$43), NA(), SUM(LARGE($O$4:$O$43, _xlfn.SEQUENCE(MIN(H14,COUNT($O$4:$O$43))-G14+1, 1, G14))))} -> 50000 | K14: =_xlfn.IFNA(NA(),J14/$O$44) -> 0.78064012 | M14: =M13+1 -> 11 | N14: =_xlfn.XLOOKUP(M14,$S:$S,$T:$T) -> 0 | O14: =_xlfn.XLOOKUP(M14,$S:$S,$U:$U) -> 0 | P14: =COUNTIF($Y:$Y,$N14) -> 0 | Q14: =IF(O14>0,O14/$O$44,0) -> 0 | S14: =RANK($U14,$U$4:$U$33,0)+COUNTIF($U$4:$U14,$U14)-1 -> 11 | U14: =SUMIF($Y:$Y,$T14,$X:$X) -> 0 | W14: 46273 | X14: 2800 | Y14: BAEP
B15: =C14+1 -> 46539 | C15: =EOMONTH(B15,0) -> 46568 | D15: =C15 -> 46568 | E15: =SUMIFS($X:$X,$W:$W,">="&B15,$W:$W,"<="&C15) -> 0 | G15: 1 | H15: 10 | I15: Top 10 | J15: {=IF(G15>COUNT($O$4:$O$43), NA(), SUM(LARGE($O$4:$O$43, _xlfn.SEQUENCE(MIN(H15,COUNT($O$4:$O$43))-G15+1, 1, G15))))} -> 64050 | K15: =_xlfn.IFNA(NA(),J15/$O$44) -> 1 | M15: =M14+1 -> 12 | N15: =_xlfn.XLOOKUP(M15,$S:$S,$T:$T) -> 0 | O15: =_xlfn.XLOOKUP(M15,$S:$S,$U:$U) -> 0 | P15: =COUNTIF($Y:$Y,$N15) -> 0 | Q15: =IF(O15>0,O15/$O$44,0) -> 0 | S15: =RANK($U15,$U$4:$U$33,0)+COUNTIF($U$4:$U15,$U15)-1 -> 12 | U15: =SUMIF($Y:$Y,$T15,$X:$X) -> 0 | W15: 46273 | X15: 3000 | Y15: OC Funds
G16: 1 | H16: 20 | I16: Top 20 | J16: {=IF(G16>COUNT($O$4:$O$43), NA(), SUM(LARGE($O$4:$O$43, _xlfn.SEQUENCE(MIN(H16,COUNT($O$4:$O$43))-G16+1, 1, G16))))} -> 64050 | K16: =_xlfn.IFNA(NA(),J16/$O$44) -> 1 | M16: =M15+1 -> 13 | N16: =_xlfn.XLOOKUP(M16,$S:$S,$T:$T) -> 0 | O16: =_xlfn.XLOOKUP(M16,$S:$S,$U:$U) -> 0 | P16: =COUNTIF($Y:$Y,$N16) -> 0 | Q16: =IF(O16>0,O16/$O$44,0) -> 0 | S16: =RANK($U16,$U$4:$U$33,0)+COUNTIF($U$4:$U16,$U16)-1 -> 13 | U16: =SUMIF($Y:$Y,$T16,$X:$X) -> 0 | W16: 46281 | X16: 5000 | Y16: QVG
G17: 1 | H17: 50 | I17: Top 50 | J17: {=IF(G17>COUNT($O$4:$O$43), NA(), SUM(LARGE($O$4:$O$43, _xlfn.SEQUENCE(MIN(H17,COUNT($O$4:$O$43))-G17+1, 1, G17))))} -> 64050 | K17: =_xlfn.IFNA(NA(),J17/$O$44) -> 1 | M17: =M16+1 -> 14 | N17: =_xlfn.XLOOKUP(M17,$S:$S,$T:$T) -> 0 | O17: =_xlfn.XLOOKUP(M17,$S:$S,$U:$U) -> 0 | P17: =COUNTIF($Y:$Y,$N17) -> 0 | Q17: =IF(O17>0,O17/$O$44,0) -> 0 | S17: =RANK($U17,$U$4:$U$33,0)+COUNTIF($U$4:$U17,$U17)-1 -> 14 | U17: =SUMIF($Y:$Y,$T17,$X:$X) -> 0 | W17: 46288 | X17: 1250 | Y17: Antares
M18: =M17+1 -> 15 | N18: =_xlfn.XLOOKUP(M18,$S:$S,$T:$T) -> 0 | O18: =_xlfn.XLOOKUP(M18,$S:$S,$U:$U) -> 0 | P18: =COUNTIF($Y:$Y,$N18) -> 0 | Q18: =IF(O18>0,O18/$O$44,0) -> 0 | S18: =RANK($U18,$U$4:$U$33,0)+COUNTIF($U$4:$U18,$U18)-1 -> 15 | U18: =SUMIF($Y:$Y,$T18,$X:$X) -> 0
M19: =M18+1 -> 16 | N19: =_xlfn.XLOOKUP(M19,$S:$S,$T:$T) -> 0 | O19: =_xlfn.XLOOKUP(M19,$S:$S,$U:$U) -> 0 | P19: =COUNTIF($Y:$Y,$N19) -> 0 | Q19: =IF(O19>0,O19/$O$44,0) -> 0 | S19: =RANK($U19,$U$4:$U$33,0)+COUNTIF($U$4:$U19,$U19)-1 -> 16 | U19: =SUMIF($Y:$Y,$T19,$X:$X) -> 0
M20: =M19+1 -> 17 | N20: =_xlfn.XLOOKUP(M20,$S:$S,$T:$T) -> 0 | O20: =_xlfn.XLOOKUP(M20,$S:$S,$U:$U) -> 0 | P20: =COUNTIF($Y:$Y,$N20) -> 0 | Q20: =IF(O20>0,O20/$O$44,0) -> 0 | S20: =RANK($U20,$U$4:$U$33,0)+COUNTIF($U$4:$U20,$U20)-1 -> 17 | U20: =SUMIF($Y:$Y,$T20,$X:$X) -> 0
M21: =M20+1 -> 18 | N21: =_xlfn.XLOOKUP(M21,$S:$S,$T:$T) -> 0 | O21: =_xlfn.XLOOKUP(M21,$S:$S,$U:$U) -> 0 | P21: =COUNTIF($Y:$Y,$N21) -> 0 | Q21: =IF(O21>0,O21/$O$44,0) -> 0 | S21: =RANK($U21,$U$4:$U$33,0)+COUNTIF($U$4:$U21,$U21)-1 -> 18 | U21: =SUMIF($Y:$Y,$T21,$X:$X) -> 0
D22: Date | E22: =TODAY() -> 46297 | M22: =M21+1 -> 19 | N22: =_xlfn.XLOOKUP(M22,$S:$S,$T:$T) -> 0 | O22: =_xlfn.XLOOKUP(M22,$S:$S,$U:$U) -> 0 | P22: =COUNTIF($Y:$Y,$N22) -> 0 | Q22: =IF(O22>0,O22/$O$44,0) -> 0 | S22: =RANK($U22,$U$4:$U$33,0)+COUNTIF($U$4:$U22,$U22)-1 -> 19 | U22: =SUMIF($Y:$Y,$T22,$X:$X) -> 0
D23: Days | E23: =E22-EOMONTH(D4,-1) -> 94 | M23: =M22+1 -> 20 | N23: =_xlfn.XLOOKUP(M23,$S:$S,$T:$T) -> 0 | O23: =_xlfn.XLOOKUP(M23,$S:$S,$U:$U) -> 0 | P23: =COUNTIF($Y:$Y,$N23) -> 0 | Q23: =IF(O23>0,O23/$O$44,0) -> 0 | S23: =RANK($U23,$U$4:$U$33,0)+COUNTIF($U$4:$U23,$U23)-1 -> 20 | U23: =SUMIF($Y:$Y,$T23,$X:$X) -> 0
D24: Run Rate | E24: =O44/E23*365 -> 248704.79 | M24: =M23+1 -> 21 | N24: =_xlfn.XLOOKUP(M24,$S:$S,$T:$T) -> 0 | O24: =_xlfn.XLOOKUP(M24,$S:$S,$U:$U) -> 0 | P24: =COUNTIF($Y:$Y,$N24) -> 0 | Q24: =IF(O24>0,O24/$O$44,0) -> 0 | S24: =RANK($U24,$U$4:$U$33,0)+COUNTIF($U$4:$U24,$U24)-1 -> 21 | U24: =SUMIF($Y:$Y,$T24,$X:$X) -> 0
M25: =M24+1 -> 22 | N25: =_xlfn.XLOOKUP(M25,$S:$S,$T:$T) -> 0 | O25: =_xlfn.XLOOKUP(M25,$S:$S,$U:$U) -> 0 | P25: =COUNTIF($Y:$Y,$N25) -> 0 | Q25: =IF(O25>0,O25/$O$44,0) -> 0 | S25: =RANK($U25,$U$4:$U$33,0)+COUNTIF($U$4:$U25,$U25)-1 -> 22 | U25: =SUMIF($Y:$Y,$T25,$X:$X) -> 0
M26: =M25+1 -> 23 | N26: =_xlfn.XLOOKUP(M26,$S:$S,$T:$T) -> 0 | O26: =_xlfn.XLOOKUP(M26,$S:$S,$U:$U) -> 0 | P26: =COUNTIF($Y:$Y,$N26) -> 0 | Q26: =IF(O26>0,O26/$O$44,0) -> 0 | S26: =RANK($U26,$U$4:$U$33,0)+COUNTIF($U$4:$U26,$U26)-1 -> 23 | U26: =SUMIF($Y:$Y,$T26,$X:$X) -> 0
M27: =M26+1 -> 24 | N27: =_xlfn.XLOOKUP(M27,$S:$S,$T:$T) -> 0 | O27: =_xlfn.XLOOKUP(M27,$S:$S,$U:$U) -> 0 | P27: =COUNTIF($Y:$Y,$N27) -> 0 | Q27: =IF(O27>0,O27/$O$44,0) -> 0 | S27: =RANK($U27,$U$4:$U$33,0)+COUNTIF($U$4:$U27,$U27)-1 -> 24 | U27: =SUMIF($Y:$Y,$T27,$X:$X) -> 0
M28: =M27+1 -> 25 | N28: =_xlfn.XLOOKUP(M28,$S:$S,$T:$T) -> 0 | O28: =_xlfn.XLOOKUP(M28,$S:$S,$U:$U) -> 0 | P28: =COUNTIF($Y:$Y,$N28) -> 0 | Q28: =IF(O28>0,O28/$O$44,0) -> 0 | S28: =RANK($U28,$U$4:$U$33,0)+COUNTIF($U$4:$U28,$U28)-1 -> 25 | U28: =SUMIF($Y:$Y,$T28,$X:$X) -> 0
M29: =M28+1 -> 26 | N29: =_xlfn.XLOOKUP(M29,$S:$S,$T:$T) -> 0 | O29: =_xlfn.XLOOKUP(M29,$S:$S,$U:$U) -> 0 | P29: =COUNTIF($Y:$Y,$N29) -> 0 | Q29: =IF(O29>0,O29/$O$44,0) -> 0 | S29: =RANK($U29,$U$4:$U$33,0)+COUNTIF($U$4:$U29,$U29)-1 -> 26 | U29: =SUMIF($Y:$Y,$T29,$X:$X) -> 0
M30: =M29+1 -> 27 | N30: =_xlfn.XLOOKUP(M30,$S:$S,$T:$T) -> 0 | O30: =_xlfn.XLOOKUP(M30,$S:$S,$U:$U) -> 0 | P30: =COUNTIF($Y:$Y,$N30) -> 0 | Q30: =IF(O30>0,O30/$O$44,0) -> 0 | S30: =RANK($U30,$U$4:$U$33,0)+COUNTIF($U$4:$U30,$U30)-1 -> 27 | U30: =SUMIF($Y:$Y,$T30,$X:$X) -> 0
M31: =M30+1 -> 28 | N31: =_xlfn.XLOOKUP(M31,$S:$S,$T:$T) -> 0 | O31: =_xlfn.XLOOKUP(M31,$S:$S,$U:$U) -> 0 | P31: =COUNTIF($Y:$Y,$N31) -> 0 | Q31: =IF(O31>0,O31/$O$44,0) -> 0 | S31: =RANK($U31,$U$4:$U$33,0)+COUNTIF($U$4:$U31,$U31)-1 -> 28 | U31: =SUMIF($Y:$Y,$T31,$X:$X) -> 0
S32: =RANK($U32,$U$4:$U$33,0)+COUNTIF($U$4:$U32,$U32)-1 -> 29 | U32: =SUMIF($Y:$Y,$T32,$X:$X) -> 0
S33: =RANK($U33,$U$4:$U$33,0)+COUNTIF($U$4:$U33,$U33)-1 -> 30 | U33: =SUMIF($Y:$Y,$T33,$X:$X) -> 0
S34: =RANK($U34,$U$4:$U$33,0)+COUNTIF($U$4:$U34,$U34)-1 -> 31 | U34: =SUMIF($Y:$Y,$T34,$X:$X) -> 0
S35: =RANK($U35,$U$4:$U$33,0)+COUNTIF($U$4:$U35,$U35)-1 -> 32 | U35: =SUMIF($Y:$Y,$T35,$X:$X) -> 0
S36: =RANK($U36,$U$4:$U$33,0)+COUNTIF($U$4:$U36,$U36)-1 -> 33 | U36: =SUMIF($Y:$Y,$T36,$X:$X) -> 0
S37: =RANK($U37,$U$4:$U$33,0)+COUNTIF($U$4:$U37,$U37)-1 -> 34 | U37: =SUMIF($Y:$Y,$T37,$X:$X) -> 0
S38: =RANK($U38,$U$4:$U$33,0)+COUNTIF($U$4:$U38,$U38)-1 -> 35 | U38: =SUMIF($Y:$Y,$T38,$X:$X) -> 0
S39: =RANK($U39,$U$4:$U$33,0)+COUNTIF($U$4:$U39,$U39)-1 -> 36 | U39: =SUMIF($Y:$Y,$T39,$X:$X) -> 0
S40: =RANK($U40,$U$4:$U$33,0)+COUNTIF($U$4:$U40,$U40)-1 -> 37 | U40: =SUMIF($Y:$Y,$T40,$X:$X) -> 0
S41: =RANK($U41,$U$4:$U$33,0)+COUNTIF($U$4:$U41,$U41)-1 -> 38 | U41: =SUMIF($Y:$Y,$T41,$X:$X) -> 0
...

Sheet Peter Lee
B4: Rank | C4: Analyst | D4: Firm | E4: Top20 | F4: Top20 Lead | G4: All | J4: Sectors
B6: Peter Lee 2024
B7: 1 | C7: Matt Ryan | D7: BarrenJoey | E7: 78 | J7: Transport, Infrastructure
B8: 2 | C8: Don Carducci | D8: JPM | E8: 56 | J8: Internet/Media
B9: 3 | C9: Rohan Gallagher | D9: Jarden | E9: 28 | J9: Building, Packaging
B10: 4 | C10: David Fabris | D10: Macquarie | E10: 39 | J10: Media
B11: 5 | C11: Rohan Sundram | D11: MST | E11: 33 | J11: Contractors
B12: 6 | C12: Paul Mason | D12: E&P | E12: 28 | J12: Tech
B13: 7 | C13: Justin Barrett | D13: CLSA | E13: 28 | J13: Transport, Packaging
B14: 8 | C14: Andrew Orbach | D14: Taylor Collison | E14: 17 | J14: Pure Gaming
B15: 9 | C15: Andre Fromyhr | D15: UBS | E15: 22 | J15: Travel & Packaging
B16: 10 | C16: Adrian Lemme | D16: Citi | E16: 11 | J16: Consumer
B17: NA | C17: Kai Erman | D17: Jeffries | J17: Secondary Building Materials & Steel
B18: NA | C18: Leo Partridge | D18: Morgans | J18: Property
B19: NA | C19: Annabel Li | D19: Goldman | J19: TMT
B20: NA | C20: Melinda Baxter | D20: Morgan Stanley | J20: Consumer
B21: NA | C21: Baxter Kirk | D21: Bell Potter | J21: Defence
B22: NA | C22: Sriharsh Singh | D22: Bank of America | J22: TMT
B24: Peter Lee 2025 | E24: 18 voters | F24: 18 voters | G24: 55 voters | H24: 55 voters
B25: 1 | C25: Matt Ryan | D25: BarrenJoey | E25: 94 | F25: 61 | G25: 73 | H25: 40
B26: 2 | C26: David Fabris | D26: Macquarie | E26: 44 | F26: 0 | G26: 53 | H26: 11
B27: 3 | C27: Andrew Orbach | D27: Taylor Collison | E27: 39 | F27: 11 | G27: 24 | H27: 11
B28: 4 | C28: Sam Bradshaw | D28: E&P | E28: 33 | F28: 6 | G28: 25 | H28: 4 | I28: 6 ouf of 18 votes
B29: 5 | C29: Rohan Sundram | D29: MST | E29: 33 | F29: 0 | G29: 22 | H29: 2
B30: 6 | C30: Don Carducci | D30: JPM | E30: 28 | F30: 6 | G30: 35 | H30: 15
B31: 7 | C31: Kai Erman | D31: Jeffries | E31: 28 | F31: 0 | G31: 13 | H31: 0
B32: 8 | C32: Andre Fromyhr | D32: UBS | E32: 22 | F32: 0 | G32: 36 | H32: 4
B33: 9 | C33: Rohan Gallagher | D33: Jarden | E33: 17 | F33: 6 | G33: 25 | H33: 9
B34: 10 | C34: Adrian Lemme | D34: Citi | E34: 11 | F34: 0 | G34: 13 | H34: 0
B35: NA | C35: Justin Barrett | D35: CLSA | E35: 11 | F35: 0 | G35: 16 | H35: 0
B36: NA | C36: Melinda Baxter | D36: Morgan Stanley | E36: 6 | F36: 0 | G36: 2 | H36: 0
B37: NA | C37: Leo Partridge | D37: Morgans | E37: 6 | F37: 0 | G37: 9 | H37: 0
B38: NA
B39: NA
B40: NA
C43: Yes | D43: Maybe | E43: Unlikely | F43: No
C45: Coopers #1 | D45: BAEP | E45: WAM | F45: First Sentier
C46: Pendal | D46: Greencape | E46: Milford | F46: Alphinity
C47: UniSuper | D47: Regal | E47: Perpetual | F47: Aus Super
C48: Firetrail | D48: Paradice | E48: Tribecca
...

Sheet Total
D2: MONTHS | I2: HY's | N2: FY's | S2: STATS | W2: FUNDS - SOLE TAGS | AB2: Filter | AF2: SOLE TAGS
B3: From | C3: To | D3: Date | E3: Amount | G3: From | H3: To | I3: Date | J3: Amount | L3: From | M3: To | N3: Date | O3: Amount | Q3: Date | R3: Amount | S3: Category | T3: Amount | U3: Proportion | W3: Rank | X3: Fund | Y3: Amount | Z3: Count | AB3: Fund | AC3: Fund | AD3: Amount | AF3: Date | AG3: Amount | AH3: Fund
B4: 45474 | C4: =EOMONTH(B4,0) -> 45504 | D4: =C4 -> 45504 | E4: =SUMIFS($AG:$AG,$AF:$AF,">="&B4,$AF:$AF,"<="&C4) -> 0 | G4: 45474 | H4: =EOMONTH(G4,5) -> 45657 | I4: 1H25 | J4: =SUMIFS($AG:$AG,$AF:$AF,">="&G4,$AF:$AF,"<="&H4) -> 0 | L4: 45474 | M4: =EOMONTH(L4,11) -> 45838 | N4: FY25 | O4: =SUMIFS($AG:$AG,$AF:$AF,">="&L4,$AF:$AF,"<="&M4) -> 63200 | Q4: 1 | R4: 5 | S4: 1-5 | T4: {=IF(Q4>COUNT($Y$4:$Y$43), NA(), SUM(LARGE($Y$4:$Y$43, _xlfn.SEQUENCE(MIN(R4,COUNT($Y$4:$Y$43))-Q4+1, 1,Q4))))} -> 301287 | U4: =_xlfn.IFNA(NA(),T4/$Y$44) -> 0.48854314 | W4: 1 | X4: =_xlfn.XLOOKUP(W4,$AB:$AB,$AC:$AC) -> Greencape | Y4: =_xlfn.XLOOKUP(W4,$AB:$AB,$AD:$AD) -> 102500 | Z4: =COUNTIF($AH:$AH,$X4) -> 12 | AB4: =RANK($AD4,$AD$4:$AD$33,0)+COUNTIF($AD$4:$AD4,$AD4)-1 -> 2 | AC4: {=_xlfn.UNIQUE(_xlfn._xlws.FILTER($AH$4:$AH$497,$AH$4:$AH$497<>""))} -> BAEP | AD4: =SUMIF($AH:$AH,$AC4,$AG:$AG) -> 75100 | AF4: 45716 | AG4: 1500 | AH4: BAEP
B5: =C4+1 -> 45505 | C5: =EOMONTH(B5,0) -> 45535 | D5: =C5 -> 45535 | E5: =SUMIFS($AG:$AG,$AF:$AF,">="&B5,$AF:$AF,"<="&C5) -> 0 | G5: =H4+1 -> 45658 | H5: =EOMONTH(G5,5) -> 45838 | I5: 2H25 | J5: =SUMIFS($AG:$AG,$AF:$AF,">="&G5,$AF:$AF,"<="&H5) -> 63200 | L5: =M4+1 -> 45839 | M5: =EOMONTH(L5,11) -> 46203 | N5: FY26 | O5: =SUMIFS($AG:$AG,$AF:$AF,">="&L5,$AF:$AF,"<="&M5) -> 494455 | Q5: 6 | R5: 10 | S5: 6-10 | T5: {=IF(Q5>COUNT($Y$4:$Y$43), NA(), SUM(LARGE($Y$4:$Y$43, _xlfn.SEQUENCE(MIN(R5,COUNT($Y$4:$Y$43))-Q5+1, 1,Q5))))} -> 138450 | U5: =_xlfn.IFNA(NA(),T5/$Y$44) -> 0.22449956 | W5: =IF(COUNT($W$4:$W4)+1>MAX($AB$4:$AB$43),"",W4+1) -> 2 | X5: =_xlfn.XLOOKUP(W5,$AB:$AB,$AC:$AC) -> BAEP | Y5: =_xlfn.XLOOKUP(W5,$AB:$AB,$AD:$AD) -> 75100 | Z5: =COUNTIF($AH:$AH,$X5) -> 25 | AB5: =RANK($AD5,$AD$4:$AD$33,0)+COUNTIF($AD$4:$AD5,$AD5)-1 -> 5 | AC5: CBUS | AD5: =SUMIF($AH:$AH,$AC5,$AG:$AG) -> 38000 | AF5: 45749 | AG5: 2300 | AH5: BAEP
B6: =C5+1 -> 45536 | C6: =EOMONTH(B6,0) -> 45565 | D6: =C6 -> 45565 | E6: =SUMIFS($AG:$AG,$AF:$AF,">="&B6,$AF:$AF,"<="&C6) -> 0 | G6: =H5+1 -> 45839 | H6: =EOMONTH(G6,5) -> 46022 | I6: 1H26 | J6: =SUMIFS($AG:$AG,$AF:$AF,">="&G6,$AF:$AF,"<="&H6) -> 248737 | L6: =M5+1 -> 46204 | M6: =EOMONTH(L6,11) -> 46568 | N6: FY27 | O6: =SUMIFS($AG:$AG,$AF:$AF,">="&L6,$AF:$AF,"<="&M6) -> 64050 | Q6: 11 | R6: 15 | S6: 11-15 | T6: {=IF(Q6>COUNT($Y$4:$Y$43), NA(), SUM(LARGE($Y$4:$Y$43, _xlfn.SEQUENCE(MIN(R6,COUNT($Y$4:$Y$43))-Q6+1, 1,Q6))))} -> 77000 | U6: =_xlfn.IFNA(NA(),T6/$Y$44) -> 0.1248571 | W6: =IF(COUNT($W$4:$W5)+1>MAX($AB$4:$AB$43),"",W5+1) -> 3 | X6: =_xlfn.XLOOKUP(W6,$AB:$AB,$AC:$AC) -> Quest | Y6: =_xlfn.XLOOKUP(W6,$AB:$AB,$AD:$AD) -> 45687 | Z6: =COUNTIF($AH:$AH,$X6) -> 3 | AB6: =RANK($AD6,$AD$4:$AD$33,0)+COUNTIF($AD$4:$AD6,$AD6)-1 -> 30 | AC6: Wavestone | AD6: =SUMIF($AH:$AH,$AC6,$AG:$AG) -> 1500 | AF6: 45750 | AG6: 1100 | AH6: BAEP
B7: =C6+1 -> 45566 | C7: =EOMONTH(B7,0) -> 45596 | D7: =C7 -> 45596 | E7: =SUMIFS($AG:$AG,$AF:$AF,">="&B7,$AF:$AF,"<="&C7) -> 0 | G7: =H6+1 -> 46023 | H7: =EOMONTH(G7,5) -> 46203 | I7: 2H26 | J7: =SUMIFS($AG:$AG,$AF:$AF,">="&G7,$AF:$AF,"<="&H7) -> 245718 | L7: =M6+1 -> 46569 | M7: =EOMONTH(L7,11) -> 46934 | N7: FY28 | O7: =SUMIFS($AG:$AG,$AF:$AF,">="&L7,$AF:$AF,"<="&M7) -> 0 | Q7: 16 | R7: 20 | S7: 16-20 | T7: {=IF(Q7>COUNT($Y$4:$Y$43), NA(), SUM(LARGE($Y$4:$Y$43, _xlfn.SEQUENCE(MIN(R7,COUNT($Y$4:$Y$43))-Q7+1, 1,Q7))))} -> 50968 | U7: =_xlfn.IFNA(NA(),T7/$Y$44) -> 0.082645673 | W7: =IF(COUNT($W$4:$W6)+1>MAX($AB$4:$AB$43),"",W6+1) -> 4 | X7: =_xlfn.XLOOKUP(W7,$AB:$AB,$AC:$AC) -> WAM | Y7: =_xlfn.XLOOKUP(W7,$AB:$AB,$AD:$AD) -> 40000 | Z7: =COUNTIF($AH:$AH,$X7) -> 3 | AB7: =RANK($AD7,$AD$4:$AD$33,0)+COUNTIF($AD$4:$AD7,$AD7)-1 -> 1 | AC7: Greencape | AD7: =SUMIF($AH:$AH,$AC7,$AG:$AG) -> 102500 | AF7: 45750 | AG7: 10000 | AH7: CBUS
B8: =C7+1 -> 45597 | C8: =EOMONTH(B8,0) -> 45626 | D8: =C8 -> 45626 | E8: =SUMIFS($AG:$AG,$AF:$AF,">="&B8,$AF:$AF,"<="&C8) -> 0 | G8: =H7+1 -> 46204 | H8: =EOMONTH(G8,5) -> 46387 | I8: 1H27 | J8: =SUMIFS($AG:$AG,$AF:$AF,">="&G8,$AF:$AF,"<="&H8) -> 64050 | L8: =M7+1 -> 46935 | M8: =EOMONTH(L8,11) -> 47299 | N8: FY29 | O8: =SUMIFS($AG:$AG,$AF:$AF,">="&L8,$AF:$AF,"<="&M8) -> 0 | Q8: 21 | R8: 25 | S8: 21-25 | T8: {=IF(Q8>COUNT($Y$4:$Y$43), NA(), SUM(LARGE($Y$4:$Y$43, _xlfn.SEQUENCE(MIN(R8,COUNT($Y$4:$Y$43))-Q8+1, 1,Q8))))} -> 33500 | U8: =_xlfn.IFNA(NA(),T8/$Y$44) -> 0.054320948 | W8: =IF(COUNT($W$4:$W7)+1>MAX($AB$4:$AB$43),"",W7+1) -> 5 | X8: =_xlfn.XLOOKUP(W8,$AB:$AB,$AC:$AC) -> CBUS | Y8: =_xlfn.XLOOKUP(W8,$AB:$AB,$AD:$AD) -> 38000 | Z8: =COUNTIF($AH:$AH,$X8) -> 5 | AB8: =RANK($AD8,$AD$4:$AD$33,0)+COUNTIF($AD$4:$AD8,$AD8)-1 -> 8 | AC8: ICE | AD8: =SUMIF($AH:$AH,$AC8,$AG:$AG) -> 31000 | AF8: 45756 | AG8: 3000 | AH8: BAEP
B9: =C8+1 -> 45627 | C9: =EOMONTH(B9,0) -> 45657 | D9: =C9 -> 45657 | E9: =SUMIFS($AG:$AG,$AF:$AF,">="&B9,$AF:$AF,"<="&C9) -> 0 | G9: =H8+1 -> 46388 | H9: =EOMONTH(G9,5) -> 46568 | I9: 2H27 | J9: =SUMIFS($AG:$AG,$AF:$AF,">="&G9,$AF:$AF,"<="&H9) -> 0 | L9: =M8+1 -> 47300 | M9: =EOMONTH(L9,11) -> 47664 | N9: FY30 | O9: =SUMIFS($AG:$AG,$AF:$AF,">="&L9,$AF:$AF,"<="&M9) -> 0 | Q9: 26 | R9: 30 | S9: 26-30 | T9: {=IF(Q9>COUNT($Y$4:$Y$43), NA(), SUM(LARGE($Y$4:$Y$43, _xlfn.SEQUENCE(MIN(R9,COUNT($Y$4:$Y$43))-Q9+1, 1,Q9))))} -> 15500 | U9: =_xlfn.IFNA(NA(),T9/$Y$44) -> 0.025133573 | W9: =IF(COUNT($W$4:$W8)+1>MAX($AB$4:$AB$43),"",W8+1) -> 6 | X9: =_xlfn.XLOOKUP(W9,$AB:$AB,$AC:$AC) -> Solaris | Y9: =_xlfn.XLOOKUP(W9,$AB:$AB,$AD:$AD) -> 37500 | Z9: =COUNTIF($AH:$AH,$X9) -> 7 | AB9: =RANK($AD9,$AD$4:$AD$33,0)+COUNTIF($AD$4:$AD9,$AD9)-1 -> 6 | AC9: Solaris | AD9: =SUMIF($AH:$AH,$AC9,$AG:$AG) -> 37500 | AF9: 45761 | AG9: 3400 | AH9: BAEP
B10: =C9+1 -> 45658 | C10: =EOMONTH(B10,0) -> 45688 | D10: =C10 -> 45688 | E10: =SUMIFS($AG:$AG,$AF:$AF,">="&B10,$AF:$AF,"<="&C10) -> 0 | G10: =H9+1 -> 46569 | H10: =EOMONTH(G10,5) -> 46752 | I10: 1H28 | J10: =SUMIFS($AG:$AG,$AF:$AF,">="&G10,$AF:$AF,"<="&H10) -> 0 | L10: =M9+1 -> 47665 | M10: =EOMONTH(L10,11) -> 48029 | N10: FY31 | O10: =SUMIFS($AG:$AG,$AF:$AF,">="&L10,$AF:$AF,"<="&M10) -> 0 | Q10: 31 | R10: 35 | S10: 31-35 | T10: {=IF(Q10>COUNT($Y$4:$Y$43), NA(), SUM(LARGE($Y$4:$Y$43, _xlfn.SEQUENCE(MIN(R10,COUNT($Y$4:$Y$43))-Q10+1, 1,Q10))))} -> 0 | U10: =_xlfn.IFNA(NA(),T10/$Y$44) -> 0 | W10: =IF(COUNT($W$4:$W9)+1>MAX($AB$4:$AB$43),"",W9+1) -> 7 | X10: =_xlfn.XLOOKUP(W10,$AB:$AB,$AC:$AC) -> Perps Private | Y10: =_xlfn.XLOOKUP(W10,$AB:$AB,$AD:$AD) -> 32000 | Z10: =COUNTIF($AH:$AH,$X10) -> 4 | AB10: =RANK($AD10,$AD$4:$AD$33,0)+COUNTIF($AD$4:$AD10,$AD10)-1 -> 25 | AC10: SG Hiscock | AD10: =SUMIF($AH:$AH,$AC10,$AG:$AG) -> 5000 | AF10: 45776 | AG10: 3000 | AH10: BAEP
B11: =C10+1 -> 45689 | C11: =EOMONTH(B11,0) -> 45716 | D11: =C11 -> 45716 | E11: =SUMIFS($AG:$AG,$AF:$AF,">="&B11,$AF:$AF,"<="&C11) -> 1500 | G11: =H10+1 -> 46753 | H11: =EOMONTH(G11,5) -> 46934 | I11: 2H28 | J11: =SUMIFS($AG:$AG,$AF:$AF,">="&G11,$AF:$AF,"<="&H11) -> 0 | L11: =M10+1 -> 48030 | M11: =EOMONTH(L11,11) -> 48395 | N11: FY32 | O11: =SUMIFS($AG:$AG,$AF:$AF,">="&L11,$AF:$AF,"<="&M11) -> 0 | Q11: 36 | R11: 40 | S11: 36-40 | T11: {=IF(Q11>COUNT($Y$4:$Y$43), NA(), SUM(LARGE($Y$4:$Y$43, _xlfn.SEQUENCE(MIN(R11,COUNT($Y$4:$Y$43))-Q11+1, 1,Q11))))} -> 0 | U11: =_xlfn.IFNA(NA(),T11/$Y$44) -> 0 | W11: =IF(COUNT($W$4:$W10)+1>MAX($AB$4:$AB$43),"",W10+1) -> 8 | X11: =_xlfn.XLOOKUP(W11,$AB:$AB,$AC:$AC) -> ICE | Y11: =_xlfn.XLOOKUP(W11,$AB:$AB,$AD:$AD) -> 31000 | Z11: =COUNTIF($AH:$AH,$X11) -> 9 | AB11: =RANK($AD11,$AD$4:$AD$33,0)+COUNTIF($AD$4:$AD11,$AD11)-1 -> 13 | AC11: Ellerston | AD11: =SUMIF($AH:$AH,$AC11,$AG:$AG) -> 15000 | AF11: 45777 | AG11: 1400 | AH11: BAEP
B12: =C11+1 -> 45717 | C12: =EOMONTH(B12,0) -> 45747 | D12: =C12 -> 45747 | E12: =SUMIFS($AG:$AG,$AF:$AF,">="&B12,$AF:$AF,"<="&C12) -> 0 | G12: =H11+1 -> 46935 | H12: =EOMONTH(G12,5) -> 47118 | I12: 1H29 | J12: =SUMIFS($AG:$AG,$AF:$AF,">="&G12,$AF:$AF,"<="&H12) -> 0 | L12: =M11+1 -> 48396 | M12: =EOMONTH(L12,11) -> 48760 | N12: FY33 | O12: =SUMIFS($AG:$AG,$AF:$AF,">="&L12,$AF:$AF,"<="&M12) -> 0 | W12: =IF(COUNT($W$4:$W11)+1>MAX($AB$4:$AB$43),"",W11+1) -> 9 | X12: =_xlfn.XLOOKUP(W12,$AB:$AB,$AC:$AC) -> L1 Capital | Y12: =_xlfn.XLOOKUP(W12,$AB:$AB,$AD:$AD) -> 19200 | Z12: =COUNTIF($AH:$AH,$X12) -> 1 | AB12: =RANK($AD12,$AD$4:$AD$33,0)+COUNTIF($AD$4:$AD12,$AD12)-1 -> 4 | AC12: WAM | AD12: =SUMIF($AH:$AH,$AC12,$AG:$AG) -> 40000 | AF12: 45777 | AG12: 1500 | AH12: BAEP
B13: =C12+1 -> 45748 | C13: =EOMONTH(B13,0) -> 45777 | D13: =C13 -> 45777 | E13: =SUMIFS($AG:$AG,$AF:$AF,">="&B13,$AF:$AF,"<="&C13) -> 25700 | G13: =H12+1 -> 47119 | H13: =EOMONTH(G13,5) -> 47299 | I13: 2H29 | J13: =SUMIFS($AG:$AG,$AF:$AF,">="&G13,$AF:$AF,"<="&H13) -> 0 | L13: =M12+1 -> 48761 | M13: =EOMONTH(L13,11) -> 49125 | N13: FY34 | O13: =SUMIFS($AG:$AG,$AF:$AF,">="&L13,$AF:$AF,"<="&M13) -> 0 | Q13: 1 | R13: 3 | S13: Top 3 | T13: {=IF(Q13>COUNT($Y$4:$Y$43), NA(), SUM(LARGE($Y$4:$Y$43, _xlfn.SEQUENCE(MIN(R13,COUNT($Y$4:$Y$43))-Q13+1, 1,Q13))))} -> 223287 | U13: =_xlfn.IFNA(NA(),T13/$Y$44) -> 0.36206452 | W13: =IF(COUNT($W$4:$W12)+1>MAX($AB$4:$AB$43),"",W12+1) -> 10 | X13: =_xlfn.XLOOKUP(W13,$AB:$AB,$AC:$AC) -> Antares | Y13: =_xlfn.XLOOKUP(W13,$AB:$AB,$AD:$AD) -> 18750 | Z13: =COUNTIF($AH:$AH,$X13) -> 4 | AB13: =RANK($AD13,$AD$4:$AD$33,0)+COUNTIF($AD$4:$AD13,$AD13)-1 -> 11 | AC13: Arrow | AD13: =SUMIF($AH:$AH,$AC13,$AG:$AG) -> 18000 | AF13: 45782 | AG13: 1500 | AH13: Wavestone
B14: =C13+1 -> 45778 | C14: =EOMONTH(B14,0) -> 45808 | D14: =C14 -> 45808 | E14: =SUMIFS($AG:$AG,$AF:$AF,">="&B14,$AF:$AF,"<="&C14) -> 14500 | G14: =H13+1 -> 47300 | H14: =EOMONTH(G14,5) -> 47483 | I14: 1H30 | J14: =SUMIFS($AG:$AG,$AF:$AF,">="&G14,$AF:$AF,"<="&H14) -> 0 | L14: =M13+1 -> 49126 | M14: =EOMONTH(L14,11) -> 49490 | N14: FY35 | O14: =SUMIFS($AG:$AG,$AF:$AF,">="&L14,$AF:$AF,"<="&M14) -> 0 | Q14: 1 | R14: 5 | S14: Top 5 | T14: {=IF(Q14>COUNT($Y$4:$Y$43), NA(), SUM(LARGE($Y$4:$Y$43, _xlfn.SEQUENCE(MIN(R14,COUNT($Y$4:$Y$43))-Q14+1, 1,Q14))))} -> 301287 | U14: =_xlfn.IFNA(NA(),T14/$Y$44) -> 0.48854314 | W14: =IF(COUNT($W$4:$W13)+1>MAX($AB$4:$AB$43),"",W13+1) -> 11 | X14: =_xlfn.XLOOKUP(W14,$AB:$AB,$AC:$AC) -> Arrow | Y14: =_xlfn.XLOOKUP(W14,$AB:$AB,$AD:$AD) -> 18000 | Z14: =COUNTIF($AH:$AH,$X14) -> 2 | AB14: =RANK($AD14,$AD$4:$AD$33,0)+COUNTIF($AD$4:$AD14,$AD14)-1 -> 22 | AC14: Pendal | AD14: =SUMIF($AH:$AH,$AC14,$AG:$AG) -> 7500 | AF14: 45783 | AG14: 7500 | AH14: Greencape
B15: =C14+1 -> 45809 | C15: =EOMONTH(B15,0) -> 45838 | D15: =C15 -> 45838 | E15: =SUMIFS($AG:$AG,$AF:$AF,">="&B15,$AF:$AF,"<="&C15) -> 21500 | G15: =H14+1 -> 47484 | H15: =EOMONTH(G15,5) -> 47664 | I15: 2H30 | J15: =SUMIFS($AG:$AG,$AF:$AF,">="&G15,$AF:$AF,"<="&H15) -> 0 | Q15: 1 | R15: 10 | S15: Top 10 | T15: {=IF(Q15>COUNT($Y$4:$Y$43), NA(), SUM(LARGE($Y$4:$Y$43, _xlfn.SEQUENCE(MIN(R15,COUNT($Y$4:$Y$43))-Q15+1, 1,Q15))))} -> 439737 | U15: =_xlfn.IFNA(NA(),T15/$Y$44) -> 0.7130427 | W15: =IF(COUNT($W$4:$W14)+1>MAX($AB$4:$AB$43),"",W14+1) -> 12 | X15: =_xlfn.XLOOKUP(W15,$AB:$AB,$AC:$AC) -> OC Funds | Y15: =_xlfn.XLOOKUP(W15,$AB:$AB,$AD:$AD) -> 17500 | Z15: =COUNTIF($AH:$AH,$X15) -> 6 | AB15: =RANK($AD15,$AD$4:$AD$33,0)+COUNTIF($AD$4:$AD15,$AD15)-1 -> 26 | AC15: Regal | AD15: =SUMIF($AH:$AH,$AC15,$AG:$AG) -> 5000 | AF15: 45789 | AG15: 5500 | AH15: ICE
B16: =C15+1 -> 45839 | C16: =EOMONTH(B16,0) -> 45869 | D16: =C16 -> 45869 | E16: =SUMIFS($AG:$AG,$AF:$AF,">="&B16,$AF:$AF,"<="&C16) -> 29600 | G16: =H15+1 -> 47665 | H16: =EOMONTH(G16,5) -> 47848 | I16: 1H31 | J16: =SUMIFS($AG:$AG,$AF:$AF,">="&G16,$AF:$AF,"<="&H16) -> 0 | Q16: 1 | R16: 20 | S16: Top 20 | T16: {=IF(Q16>COUNT($Y$4:$Y$43), NA(), SUM(LARGE($Y$4:$Y$43, _xlfn.SEQUENCE(MIN(R16,COUNT($Y$4:$Y$43))-Q16+1, 1,Q16))))} -> 567705 | U16: =_xlfn.IFNA(NA(),T16/$Y$44) -> 0.92054548 | W16: =IF(COUNT($W$4:$W15)+1>MAX($AB$4:$AB$43),"",W15+1) -> 13 | X16: =_xlfn.XLOOKUP(W16,$AB:$AB,$AC:$AC) -> Ellerston | Y16: =_xlfn.XLOOKUP(W16,$AB:$AB,$AD:$AD) -> 15000 | Z16: =COUNTIF($AH:$AH,$X16) -> 5 | AB16: =RANK($AD16,$AD$4:$AD$33,0)+COUNTIF($AD$4:$AD16,$AD16)-1 -> 18 | AC16: Coopers | AD16: =SUMIF($AH:$AH,$AC16,$AG:$AG) -> 10000 | AF16: 45811 | AG16: 7500 | AH16: Greencape
B17: =C16+1 -> 45870 | C17: =EOMONTH(B17,0) -> 45900 | D17: =C17 -> 45900 | E17: =SUMIFS($AG:$AG,$AF:$AF,">="&B17,$AF:$AF,"<="&C17) -> 58800 | G17: =H16+1 -> 47849 | H17: =EOMONTH(G17,5) -> 48029 | I17: 2H31 | J17: =SUMIFS($AG:$AG,$AF:$AF,">="&G17,$AF:$AF,"<="&H17) -> 0 | Q17: 1 | R17: 50 | S17: Top 50 | T17: {=IF(Q17>COUNT($Y$4:$Y$43), NA(), SUM(LARGE($Y$4:$Y$43, _xlfn.SEQUENCE(MIN(R17,COUNT($Y$4:$Y$43))-Q17+1, 1,Q17))))} -> 616705 | U17: =_xlfn.IFNA(NA(),T17/$Y$44) -> 1 | W17: =IF(COUNT($W$4:$W16)+1>MAX($AB$4:$AB$43),"",W16+1) -> 14 | X17: =_xlfn.XLOOKUP(W17,$AB:$AB,$AC:$AC) -> QVG | Y17: =_xlfn.XLOOKUP(W17,$AB:$AB,$AD:$AD) -> 14000 | Z17: =COUNTIF($AH:$AH,$X17) -> 3 | AB17: =RANK($AD17,$AD$4:$AD$33,0)+COUNTIF($AD$4:$AD17,$AD17)-1 -> 23 | AC17: Hesta | AD17: =SUMIF($AH:$AH,$AC17,$AG:$AG) -> 6000 | AF17: 45818 | AG17: 2000 | AH17: ICE
B18: =C17+1 -> 45901 | C18: =EOMONTH(B18,0) -> 45930 | D18: =C18 -> 45930 | E18: =SUMIFS($AG:$AG,$AF:$AF,">="&B18,$AF:$AF,"<="&C18) -> 32137 | G18: =H17+1 -> 48030 | H18: =EOMONTH(G18,5) -> 48213 | I18: 1H32 | J18: =SUMIFS($AG:$AG,$AF:$AF,">="&G18,$AF:$AF,"<="&H18) -> 0 | W18: =IF(COUNT($W$4:$W17)+1>MAX($AB$4:$AB$43),"",W17+1) -> 15 | X18: =_xlfn.XLOOKUP(W18,$AB:$AB,$AC:$AC) -> Centennial | Y18: =_xlfn.XLOOKUP(W18,$AB:$AB,$AD:$AD) -> 12500 | Z18: =COUNTIF($AH:$AH,$X18) -> 1 | AB18: =RANK($AD18,$AD$4:$AD$33,0)+COUNTIF($AD$4:$AD18,$AD18)-1 -> 3 | AC18: Quest | AD18: =SUMIF($AH:$AH,$AC18,$AG:$AG) -> 45687 | AF18: 45828 | AG18: 5000 | AH18: Solaris
B19: =C18+1 -> 45931 | C19: =EOMONTH(B19,0) -> 45961 | D19: =C19 -> 45961 | E19: =SUMIFS($AG:$AG,$AF:$AF,">="&B19,$AF:$AF,"<="&C19) -> 34700 | G19: =H18+1 -> 48214 | H19: =EOMONTH(G19,5) -> 48395 | I19: 2H32 | J19: =SUMIFS($AG:$AG,$AF:$AF,">="&G19,$AF:$AF,"<="&H19) -> 0 | W19: =IF(COUNT($W$4:$W18)+1>MAX($AB$4:$AB$43),"",W18+1) -> 16 | X19: =_xlfn.XLOOKUP(W19,$AB:$AB,$AC:$AC) -> Aus Super | Y19: =_xlfn.XLOOKUP(W19,$AB:$AB,$AD:$AD) -> 10900 | Z19: =COUNTIF($AH:$AH,$X19) -> 1 | AB19: =RANK($AD19,$AD$4:$AD$33,0)+COUNTIF($AD$4:$AD19,$AD19)-1 -> 19 | AC19: Ophir | AD19: =SUMIF($AH:$AH,$AC19,$AG:$AG) -> 10000 | AF19: 45833 | AG19: 7000 | AH19: CBUS
B20: =C19+1 -> 45962 | C20: =EOMONTH(B20,0) -> 45991 | D20: =C20 -> 45991 | E20: =SUMIFS($AG:$AG,$AF:$AF,">="&B20,$AF:$AF,"<="&C20) -> 32500 | G20: =H19+1 -> 48396 | H20: =EOMONTH(G20,5) -> 48579 | I20: 1H33 | J20: =SUMIFS($AG:$AG,$AF:$AF,">="&G20,$AF:$AF,"<="&H20) -> 0 | W20: =IF(COUNT($W$4:$W19)+1>MAX($AB$4:$AB$43),"",W19+1) -> 17 | X20: =_xlfn.XLOOKUP(W20,$AB:$AB,$AC:$AC) -> SMID | Y20: =_xlfn.XLOOKUP(W20,$AB:$AB,$AD:$AD) -> 10068 | Z20: =COUNTIF($AH:$AH,$X20) -> 1 | AB20: =RANK($AD20,$AD$4:$AD$33,0)+COUNTIF($AD$4:$AD20,$AD20)-1 -> 7 | AC20: Perps Private | AD20: =SUMIF($AH:$AH,$AC20,$AG:$AG) -> 32000 | AF20: =IF(ISBLANK('FY26'!W4),NA(),'FY26'!W4) -> 45841 | AG20: =IF(ISBLANK('FY26'!X4),NA(),'FY26'!X4) -> 6100 | AH20: =IF(ISBLANK('FY26'!Y4),NA(),'FY26'!Y4) -> BAEP
B21: =C20+1 -> 45992 | C21: =EOMONTH(B21,0) -> 46022 | D21: =C21 -> 46022 | E21: =SUMIFS($AG:$AG,$AF:$AF,">="&B21,$AF:$AF,"<="&C21) -> 61000 | G21: =H20+1 -> 48580 | H21: =EOMONTH(G21,5) -> 48760 | I21: 2H33 | J21: =SUMIFS($AG:$AG,$AF:$AF,">="&G21,$AF:$AF,"<="&H21) -> 0 | W21: =IF(COUNT($W$4:$W20)+1>MAX($AB$4:$AB$43),"",W20+1) -> 18 | X21: =_xlfn.XLOOKUP(W21,$AB:$AB,$AC:$AC) -> Coopers | Y21: =_xlfn.XLOOKUP(W21,$AB:$AB,$AD:$AD) -> 10000 | Z21: =COUNTIF($AH:$AH,$X21) -> 1 | AB21: =RANK($AD21,$AD$4:$AD$33,0)+COUNTIF($AD$4:$AD21,$AD21)-1 -> 20 | AC21: Platypus | AD21: =SUMIF($AH:$AH,$AC21,$AG:$AG) -> 10000 | AF21: =IF(ISBLANK('FY26'!W5),NA(),'FY26'!W5) -> 45841 | AG21: =IF(ISBLANK('FY26'!X5),NA(),'FY26'!X5) -> 5000 | AH21: =IF(ISBLANK('FY26'!Y5),NA(),'FY26'!Y5) -> SG Hiscock
B22: =C21+1 -> 46023 | C22: =EOMONTH(B22,0) -> 46053 | D22: =C22 -> 46053 | E22: =SUMIFS($AG:$AG,$AF:$AF,">="&B22,$AF:$AF,"<="&C22) -> 35000 | G22: =H21+1 -> 48761 | H22: =EOMONTH(G22,5) -> 48944 | I22: 1H34 | J22: =SUMIFS($AG:$AG,$AF:$AF,">="&G22,$AF:$AF,"<="&H22) -> 0 | W22: =IF(COUNT($W$4:$W21)+1>MAX($AB$4:$AB$43),"",W21+1) -> 19 | X22: =_xlfn.XLOOKUP(W22,$AB:$AB,$AC:$AC) -> Ophir | Y22: =_xlfn.XLOOKUP(W22,$AB:$AB,$AD:$AD) -> 10000 | Z22: =COUNTIF($AH:$AH,$X22) -> 1 | AB22: =RANK($AD22,$AD$4:$AD$33,0)+COUNTIF($AD$4:$AD22,$AD22)-1 -> 21 | AC22: Aware | AD22: =SUMIF($AH:$AH,$AC22,$AG:$AG) -> 9000 | AF22: =IF(ISBLANK('FY26'!W6),NA(),'FY26'!W6) -> 45854 | AG22: =IF(ISBLANK('FY26'!X6),NA(),'FY26'!X6) -> 3500 | AH22: =IF(ISBLANK('FY26'!Y6),NA(),'FY26'!Y6) -> Ellerston
B23: =C22+1 -> 46054 | C23: =EOMONTH(B23,0) -> 46081 | D23: =C23 -> 46081 | E23: =SUMIFS($AG:$AG,$AF:$AF,">="&B23,$AF:$AF,"<="&C23) -> 28168 | G23: =H22+1 -> 48945 | H23: =EOMONTH(G23,5) -> 49125 | I23: 2H34 | J23: =SUMIFS($AG:$AG,$AF:$AF,">="&G23,$AF:$AF,"<="&H23) -> 0 | W23: =IF(COUNT($W$4:$W22)+1>MAX($AB$4:$AB$43),"",W22+1) -> 20 | X23: =_xlfn.XLOOKUP(W23,$AB:$AB,$AC:$AC) -> Platypus | Y23: =_xlfn.XLOOKUP(W23,$AB:$AB,$AD:$AD) -> 10000 | Z23: =COUNTIF($AH:$AH,$X23) -> 2 | AB23: =RANK($AD23,$AD$4:$AD$33,0)+COUNTIF($AD$4:$AD23,$AD23)-1 -> 27 | AC23: Eley Griffiths | AD23: =SUMIF($AH:$AH,$AC23,$AG:$AG) -> 5000 | AF23: =IF(ISBLANK('FY26'!W7),NA(),'FY26'!W7) -> 45855 | AG23: =IF(ISBLANK('FY26'!X7),NA(),'FY26'!X7) -> 15000 | AH23: =IF(ISBLANK('FY26'!Y7),NA(),'FY26'!Y7) -> WAM
B24: =C23+1 -> 46082 | C24: =EOMONTH(B24,0) -> 46112 | D24: =C24 -> 46112 | E24: =SUMIFS($AG:$AG,$AF:$AF,">="&B24,$AF:$AF,"<="&C24) -> 35500 | G24: =H23+1 -> 49126 | H24: =EOMONTH(G24,5) -> 49309 | I24: 1H35 | J24: =SUMIFS($AG:$AG,$AF:$AF,">="&G24,$AF:$AF,"<="&H24) -> 0 | W24: =IF(COUNT($W$4:$W23)+1>MAX($AB$4:$AB$43),"",W23+1) -> 21 | X24: =_xlfn.XLOOKUP(W24,$AB:$AB,$AC:$AC) -> Aware | Y24: =_xlfn.XLOOKUP(W24,$AB:$AB,$AD:$AD) -> 9000 | Z24: =COUNTIF($AH:$AH,$X24) -> 3 | AB24: =RANK($AD24,$AD$4:$AD$33,0)+COUNTIF($AD$4:$AD24,$AD24)-1 -> 12 | AC24: OC Funds | AD24: =SUMIF($AH:$AH,$AC24,$AG:$AG) -> 17500 | AF24: =IF(ISBLANK('FY26'!W8),NA(),'FY26'!W8) -> 45873 | AG24: =IF(ISBLANK('FY26'!X8),NA(),'FY26'!X8) -> 4000 | AH24: =IF(ISBLANK('FY26'!Y8),NA(),'FY26'!Y8) -> ICE
B25: =C24+1 -> 46113 | C25: =EOMONTH(B25,0) -> 46142 | D25: =C25 -> 46142 | E25: =SUMIFS($AG:$AG,$AF:$AF,">="&B25,$AF:$AF,"<="&C25) -> 86050 | G25: =H24+1 -> 49310 | H25: =EOMONTH(G25,5) -> 49490 | I25: 2H35 | J25: =SUMIFS($AG:$AG,$AF:$AF,">="&G25,$AF:$AF,"<="&H25) -> 0 | W25: =IF(COUNT($W$4:$W24)+1>MAX($AB$4:$AB$43),"",W24+1) -> 22 | X25: =_xlfn.XLOOKUP(W25,$AB:$AB,$AC:$AC) -> Pendal | Y25: =_xlfn.XLOOKUP(W25,$AB:$AB,$AD:$AD) -> 7500 | Z25: =COUNTIF($AH:$AH,$X25) -> 1 | AB25: =RANK($AD25,$AD$4:$AD$33,0)+COUNTIF($AD$4:$AD25,$AD25)-1 -> 9 | AC25: L1 Capital | AD25: =SUMIF($AH:$AH,$AC25,$AG:$AG) -> 19200 | AF25: =IF(ISBLANK('FY26'!W9),NA(),'FY26'!W9) -> 45873 | AG25: =IF(ISBLANK('FY26'!X9),NA(),'FY26'!X9) -> 10000 | AH25: =IF(ISBLANK('FY26'!Y9),NA(),'FY26'!Y9) -> Greencape
B26: =C25+1 -> 46143 | C26: =EOMONTH(B26,0) -> 46173 | D26: =C26 -> 46173 | E26: =SUMIFS($AG:$AG,$AF:$AF,">="&B26,$AF:$AF,"<="&C26) -> 22500 | W26: =IF(COUNT($W$4:$W25)+1>MAX($AB$4:$AB$43),"",W25+1) -> 23 | X26: =_xlfn.XLOOKUP(W26,$AB:$AB,$AC:$AC) -> Hesta | Y26: =_xlfn.XLOOKUP(W26,$AB:$AB,$AD:$AD) -> 6000 | Z26: =COUNTIF($AH:$AH,$X26) -> 2 | AB26: =RANK($AD26,$AD$4:$AD$33,0)+COUNTIF($AD$4:$AD26,$AD26)-1 -> 10 | AC26: Antares | AD26: =SUMIF($AH:$AH,$AC26,$AG:$AG) -> 18750 | AF26: =IF(ISBLANK('FY26'!W10),NA(),'FY26'!W10) -> 45874 | AG26: =IF(ISBLANK('FY26'!X10),NA(),'FY26'!X10) -> 3200 | AH26: =IF(ISBLANK('FY26'!Y10),NA(),'FY26'!Y10) -> BAEP
B27: =C26+1 -> 46174 | C27: =EOMONTH(B27,0) -> 46203 | D27: =C27 -> 46203 | E27: =SUMIFS($AG:$AG,$AF:$AF,">="&B27,$AF:$AF,"<="&C27) -> 38500 | W27: =IF(COUNT($W$4:$W26)+1>MAX($AB$4:$AB$43),"",W26+1) -> 24 | X27: =_xlfn.XLOOKUP(W27,$AB:$AB,$AC:$AC) -> Firetrail | Y27: =_xlfn.XLOOKUP(W27,$AB:$AB,$AD:$AD) -> 6000 | Z27: =COUNTIF($AH:$AH,$X27) -> 2 | AB27: =RANK($AD27,$AD$4:$AD$33,0)+COUNTIF($AD$4:$AD27,$AD27)-1 -> 14 | AC27: QVG | AD27: =SUMIF($AH:$AH,$AC27,$AG:$AG) -> 14000 | AF27: =IF(ISBLANK('FY26'!W11),NA(),'FY26'!W11) -> 45876 | AG27: =IF(ISBLANK('FY26'!X11),NA(),'FY26'!X11) -> 8000 | AH27: =IF(ISBLANK('FY26'!Y11),NA(),'FY26'!Y11) -> Arrow
B28: =C27+1 -> 46204 | C28: =EOMONTH(B28,0) -> 46234 | D28: =C28 -> 46234 | E28: =SUMIFS($AG:$AG,$AF:$AF,">="&B28,$AF:$AF,"<="&C28) -> 35000 | W28: =IF(COUNT($W$4:$W27)+1>MAX($AB$4:$AB$43),"",W27+1) -> 25 | X28: =_xlfn.XLOOKUP(W28,$AB:$AB,$AC:$AC) -> SG Hiscock | Y28: =_xlfn.XLOOKUP(W28,$AB:$AB,$AD:$AD) -> 5000 | Z28: =COUNTIF($AH:$AH,$X28) -> 1 | AB28: =RANK($AD28,$AD$4:$AD$33,0)+COUNTIF($AD$4:$AD28,$AD28)-1 -> 17 | AC28: SMID | AD28: =SUMIF($AH:$AH,$AC28,$AG:$AG) -> 10068 | AF28: =IF(ISBLANK('FY26'!W12),NA(),'FY26'!W12) -> 45880 | AG28: =IF(ISBLANK('FY26'!X12),NA(),'FY26'!X12) -> 2500 | AH28: =IF(ISBLANK('FY26'!Y12),NA(),'FY26'!Y12) -> Solaris
B29: =C28+1 -> 46235 | C29: =EOMONTH(B29,0) -> 46265 | D29: =C29 -> 46265 | E29: =SUMIFS($AG:$AG,$AF:$AF,">="&B29,$AF:$AF,"<="&C29) -> 12000 | W29: =IF(COUNT($W$4:$W28)+1>MAX($AB$4:$AB$43),"",W28+1) -> 26 | X29: =_xlfn.XLOOKUP(W29,$AB:$AB,$AC:$AC) -> Regal | Y29: =_xlfn.XLOOKUP(W29,$AB:$AB,$AD:$AD) -> 5000 | Z29: =COUNTIF($AH:$AH,$X29) -> 1 | AB29: =RANK($AD29,$AD$4:$AD$33,0)+COUNTIF($AD$4:$AD29,$AD29)-1 -> 24 | AC29: Firetrail | AD29: =SUMIF($AH:$AH,$AC29,$AG:$AG) -> 6000 | AF29: =IF(ISBLANK('FY26'!W13),NA(),'FY26'!W13) -> 45880 | AG29: =IF(ISBLANK('FY26'!X13),NA(),'FY26'!X13) -> 7500 | AH29: =IF(ISBLANK('FY26'!Y13),NA(),'FY26'!Y13) -> Pendal
B30: =C29+1 -> 46266 | C30: =EOMONTH(B30,0) -> 46295 | D30: =C30 -> 46295 | E30: =SUMIFS($AG:$AG,$AF:$AF,">="&B30,$AF:$AF,"<="&C30) -> 17050 | W30: =IF(COUNT($W$4:$W29)+1>MAX($AB$4:$AB$43),"",W29+1) -> 27 | X30: =_xlfn.XLOOKUP(W30,$AB:$AB,$AC:$AC) -> Eley Griffiths | Y30: =_xlfn.XLOOKUP(W30,$AB:$AB,$AD:$AD) -> 5000 | Z30: =COUNTIF($AH:$AH,$X30) -> 1 | AB30: =RANK($AD30,$AD$4:$AD$33,0)+COUNTIF($AD$4:$AD30,$AD30)-1 -> 15 | AC30: Centennial | AD30: =SUMIF($AH:$AH,$AC30,$AG:$AG) -> 12500 | AF30: =IF(ISBLANK('FY26'!W14),NA(),'FY26'!W14) -> 45881 | AG30: =IF(ISBLANK('FY26'!X14),NA(),'FY26'!X14) -> 3100 | AH30: =IF(ISBLANK('FY26'!Y14),NA(),'FY26'!Y14) -> BAEP
B31: =C30+1 -> 46296 | C31: =EOMONTH(B31,0) -> 46326 | D31: =C31 -> 46326 | E31: =SUMIFS($AG:$AG,$AF:$AF,">="&B31,$AF:$AF,"<="&C31) -> 0 | W31: =IF(COUNT($W$4:$W30)+1>MAX($AB$4:$AB$43),"",W30+1) -> 28 | X31: =_xlfn.XLOOKUP(W31,$AB:$AB,$AC:$AC) -> Alliance Bernstein | Y31: =_xlfn.XLOOKUP(W31,$AB:$AB,$AD:$AD) -> 2000 | Z31: =COUNTIF($AH:$AH,$X31) -> 1 | AB31: =RANK($AD31,$AD$4:$AD$33,0)+COUNTIF($AD$4:$AD31,$AD31)-1 -> 16 | AC31: Aus Super | AD31: =SUMIF($AH:$AH,$AC31,$AG:$AG) -> 10900 | AF31: =IF(ISBLANK('FY26'!W15),NA(),'FY26'!W15) -> 45881 | AG31: =IF(ISBLANK('FY26'!X15),NA(),'FY26'!X15) -> 2500 | AH31: =IF(ISBLANK('FY26'!Y15),NA(),'FY26'!Y15) -> Solaris
B32: =C31+1 -> 46327 | C32: =EOMONTH(B32,0) -> 46356 | D32: =C32 -> 46356 | E32: =SUMIFS($AG:$AG,$AF:$AF,">="&B32,$AF:$AF,"<="&C32) -> 0 | W32: =IF(COUNT($W$4:$W31)+1>MAX($AB$4:$AB$43),"",W31+1) -> 29 | X32: =_xlfn.XLOOKUP(W32,$AB:$AB,$AC:$AC) -> Hyperion | Y32: =_xlfn.XLOOKUP(W32,$AB:$AB,$AD:$AD) -> 2000 | Z32: =COUNTIF($AH:$AH,$X32) -> 1 | AB32: =RANK($AD32,$AD$4:$AD$33,0)+COUNTIF($AD$4:$AD32,$AD32)-1 -> 28 | AC32: Alliance Bernstein | AD32: =SUMIF($AH:$AH,$AC32,$AG:$AG) -> 2000 | AF32: =IF(ISBLANK('FY26'!W16),NA(),'FY26'!W16) -> 45881 | AG32: =IF(ISBLANK('FY26'!X16),NA(),'FY26'!X16) -> 5000 | AH32: =IF(ISBLANK('FY26'!Y16),NA(),'FY26'!Y16) -> Regal
