Workbook

Sheet BM
B1: =D8 -> SKC-ASX
A2: Industrial ResearchWise Sheet
C3: Company static items | E3: =+E114 -> FY2018A | F3: =+F114 -> FY2019A | G3: =+G114 -> FY2020A | H3: =+H114 -> FY2021A | I3: =+I114 -> FY2022A | J3: =+J114 -> FY2023A | K3: =+K114 -> FY2024A | L3: =+L114 -> FY2025A | ... Q3: =+Q114 -> FY2030F | AJ3: BlueMatrix formulas
A4: @BEGINSTATIC | D4: @ENDSTATIC
A5: @INSTTYPE | C5: Instrument type | D5: EQ
A6: @CTYPE | C6: Instrument code type | D6: @BB
A7: @VERSION | C7: Version information (Do not change) | D7: 1
A8: @CODE | C8: Ticker | D8: SKC-ASX
A9: @MULT | C9: Multiplier | D9: 1000000 | E9: Please choose from the options available in the dropdown
A10: @RCURR | C10: Reporting Currency | D10: NZD | E10: Please choose from the options available in the dropdown
A11: @ANALYST | C11: Lead analyst | D11: Sam Bradshaw
A13: @TARGET | B13: PRICE_TARGET | C13: Valuation | D13: =HY!$D$654 -> 0.65016617 | AJ13: =_xll.BLUEMATRIX2("/servlet/excelData",$D13,$B$1,$B13) -> #
A14: @REC | B14: REC | C14: Recommendation | D14: Neutral | E14: Please choose from the options available in the dropdown | AJ14: =_xll.BLUEMATRIX2("/servlet/excelData",$D14,$B$1,$B14) -> #
A15: @SHARE_OUT | B15: SHARE_OUT | C15: Shares outstanding | D15: =HY!D628 -> 1103.055 | AJ15: =_xll.BLUEMATRIX2("/servlet/excelData",$D15,$B$1,$B15) -> #
A16: @FLOATPER | B16: free_float | C16: Free Float % | D16: 100 | AJ16: =_xll.BLUEMATRIX2("/servlet/excelData",#REF!,$B$1,$B16) -> #VALUE!
B17: PRICE | C17: Current Share Price | D17: =HY!D656 -> 0.5 | AJ17: =_xll.BLUEMATRIX2("/servlet/excelData",$D17,$B$1,$B17) -> #
C18: Historic Share Price (Closing) | E18: 4.04 | F18: 3.79 | G18: 2.39 | H18: 3.51 | I18: 2.91 | J18: 2.28 | K18: =$D$17 -> 0.5 | L18: =$D$17 -> 0.5 | M18: =$D$17 -> 0.5 | N18: =$D$17 -> 0.5 | O18: =$D$17 -> 0.5 | P18: =$D$17 -> 0.5 | Q18: =$D$17 -> 0.5
C20: TSR
B21: upside_valuation | C21: Upside to valuation | D21: =(D13/D17-1)*100 -> 30.033234 | AJ21: =_xll.BLUEMATRIX2("/servlet/excelData",$D21,$B$1,$B21) -> #
B22: div_yield | C22: Dividend yield | D22: =L304*100 -> 0 | AJ22: =_xll.BLUEMATRIX2("/servlet/excelData",$D22,$B$1,$B22) -> #
B23: exp_total_return | C23: Expected total SH return | D23: =D21+D22 -> 30.033234 | AJ23: =_xll.BLUEMATRIX2("/servlet/excelData",$D23,$B$1,$B23) -> #
C25: Trading Data test
B26: 12_month_high | C26: 12 month high | AJ26: =_xll.BLUEMATRIX2("/servlet/excelData",$D26,$B$1,$B26) -> #
B27: 12_month_low | C27: 12 month low | AJ27: =_xll.BLUEMATRIX2("/servlet/excelData",$D27,$B$1,$B27) -> #
B28: MARKET_CAP | C28: Market cap | D28: =D15*D17 -> 551.52752 | AJ28: =_xll.BLUEMATRIX2("/servlet/excelData",$D28,$B$1,$B28) -> #
B29: free_float | C29: Free Float | AJ29: =_xll.BLUEMATRIX2("/servlet/excelData",$D29,$B$1,$B29) -> #
B30: 12_month_return | C30: 12 month return (historical) | AJ30: =_xll.BLUEMATRIX2("/servlet/excelData",$D30,$B$1,$B30) -> #
A31: @pricing_date
C34: Blended Valuation
A35: @DCF_VAL | B35: DCF_VAL | C35: Valuation - DCF | D35: =HY!$D$654 -> 0.65016617 | AJ35: =_xll.BLUEMATRIX2("/servlet/excelData",$D35,$B$1,$B35) -> #
A36: @CAPPER_VAL | B36: CAPPER_VAL | C36: Valuation - Capitalisation of Earnings | AJ36: =_xll.BLUEMATRIX2("/servlet/excelData",$D36,$B$1,$B36) -> #
A37: @PER_VAL | B37: PER_VAL | C37: Valuation - PER | AJ37: =_xll.BLUEMATRIX2("/servlet/excelData",$D37,$B$1,$B37) -> #
A38: @SOTP_VAL | B38: SOTP_VAL | C38: Valuation - SOTP | AJ38: =_xll.BLUEMATRIX2("/servlet/excelData",$D38,$B$1,$B38) -> #
A39: @BLEND_VAL | B39: PRICE_TARGET | C39: Valuation - Blended | AJ39: =_xll.BLUEMATRIX2("/servlet/excelData",$D39,$B$1,$B39) -> #
A40: @DCF_WT | B40: DCF_WT | C40: DCF Weightage | AJ40: =_xll.BLUEMATRIX2("/servlet/excelData",$D16,$B$1,$B40) -> #
A41: @CAPPER_WT | B41: CAPPER_WT | C41: Capitalisation of Earnings Weightage | AJ41: =_xll.BLUEMATRIX2("/servlet/excelData",$D41,$B$1,$B41) -> #
A42: @PER_WT | B42: PER_WT | C42: PER Weightage | AJ42: =_xll.BLUEMATRIX2("/servlet/excelData",$D42,$B$1,$B42) -> #
A43: @SOTP_WT | B43: SOTP_WT | C43: SOTP Weightage | AJ43: =_xll.BLUEMATRIX2("/servlet/excelData",$D43,$B$1,$B43) -> #
C45: Divisional Summary
A46: @SEG1_NAME | C46: Name of Segment 1 | D46: Auckland
...

Sheet I

Sheet HY
E1: IB Reported Seperately & Ex GST Calcs | O1: Restated | S1: FY25 EBITDA | T1: =S325+T325 -> 233.7 | U1: FY26 EBITDA | V1: =U325+V325 -> 181.6 | W1: FY27 EBITDA | X1: =W325+X325 -> 183.18614 | Y1: FY28 EBITDA | Z1: =Y325+Z325 -> 204.83215
B2: Checks | C2: =SUM(E2:AL2) -> 0 | E2: =E623 -> 0 | F2: =F623 -> 0 | G2: =G623 -> 0 | H2: =H623 -> 0 | I2: =I623 -> 0 | J2: =J623 -> 0 | K2: =K623 -> 0 | L2: =L623 -> 0 | ... AN2: =AN623 -> 0
A3: X | B3: Valuation | C3: =D654 -> 0.65016617 | D3: VAL | E3: =E8&E10 -> 1H18A | F3: =F8&F10 -> 2H18A | G3: =G8&G10 -> 1H19A | H3: =H8&H10 -> 2H19A | I3: =I8&I10 -> 1H20A | J3: =J8&J10 -> 2H20A | K3: =K8&K10 -> 1H21A | L3: =L8&L10 -> 2H21A | ... AN3: =AN8&AN10 -> 2H35E
B4: Period End | E4: 43100 | F4: =EOMONTH(E4,6) -> 43281 | G4: =EOMONTH(F4,6) -> 43465 | H4: =EOMONTH(G4,6) -> 43646 | I4: =EOMONTH(H4,6) -> 43830 | J4: =EOMONTH(I4,6) -> 44012 | K4: =EOMONTH(J4,6) -> 44196 | L4: =EOMONTH(K4,6) -> 44377 | M4: =EOMONTH(L4,6) -> 44561 | ... AN4: =EOMONTH(AM4,6) -> 49490
B6: Half | E6: {=_xlfn.IFS(AND(MONTH(E$4)>=7,MONTH(E$4)<=12),"1H",AND(MONTH(E$4)>=1,MONTH(E$4)<=6),"2H")} -> 1H | F6: {=_xlfn.IFS(AND(MONTH(F$4)>=7,MONTH(F$4)<=12),"1H",AND(MONTH(F$4)>=1,MONTH(F$4)<=6),"2H")} -> 2H | G6: {=_xlfn.IFS(AND(MONTH(G$4)>=7,MONTH(G$4)<=12),"1H",AND(MONTH(G$4)>=1,MONTH(G$4)<=6),"2H")} -> 1H | H6: {=_xlfn.IFS(AND(MONTH(H$4)>=7,MONTH(H$4)<=12),"1H",AND(MONTH(H$4)>=1,MONTH(H$4)<=6),"2H")} -> 2H | I6: {=_xlfn.IFS(AND(MONTH(I$4)>=7,MONTH(I$4)<=12),"1H",AND(MONTH(I$4)>=1,MONTH(I$4)<=6),"2H")} -> 1H | J6: {=_xlfn.IFS(AND(MONTH(J$4)>=7,MONTH(J$4)<=12),"1H",AND(MONTH(J$4)>=1,MONTH(J$4)<=6),"2H")} -> 2H | K6: {=_xlfn.IFS(AND(MONTH(K$4)>=7,MONTH(K$4)<=12),"1H",AND(MONTH(K$4)>=1,MONTH(K$4)<=6),"2H")} -> 1H | L6: {=_xlfn.IFS(AND(MONTH(L$4)>=7,MONTH(L$4)<=12),"1H",AND(MONTH(L$4)>=1,MONTH(L$4)<=6),"2H")} -> 2H | ... AN6: {=_xlfn.IFS(AND(MONTH(AN$4)>=7,MONTH(AN$4)<=12),"1H",AND(MONTH(AN$4)>=1,MONTH(AN$4)<=6),"2H")} -> 2H
B7: FY | E7: =IF(MONTH(E4)>6,RIGHT(YEAR(E4),2)+1,RIGHT(YEAR(E4),2)) -> 18 | F7: =IF(MONTH(F4)>6,RIGHT(YEAR(F4),2)+1,RIGHT(YEAR(F4),2)) -> 18 | G7: =IF(MONTH(G4)>6,RIGHT(YEAR(G4),2)+1,RIGHT(YEAR(G4),2)) -> 19 | H7: =IF(MONTH(H4)>6,RIGHT(YEAR(H4),2)+1,RIGHT(YEAR(H4),2)) -> 19 | I7: =IF(MONTH(I4)>6,RIGHT(YEAR(I4),2)+1,RIGHT(YEAR(I4),2)) -> 20 | J7: =IF(MONTH(J4)>6,RIGHT(YEAR(J4),2)+1,RIGHT(YEAR(J4),2)) -> 20 | K7: =IF(MONTH(K4)>6,RIGHT(YEAR(K4),2)+1,RIGHT(YEAR(K4),2)) -> 21 | L7: =IF(MONTH(L4)>6,RIGHT(YEAR(L4),2)+1,RIGHT(YEAR(L4),2)) -> 21 | ... AN7: =IF(MONTH(AN4)>6,RIGHT(YEAR(AN4),2)+1,RIGHT(YEAR(AN4),2)) -> 35
B8: FY Year | E8: =E$6&TEXT(E$7,"00") -> 1H18 | F8: =F$6&TEXT(F$7,"00") -> 2H18 | G8: =G$6&TEXT(G$7,"00") -> 1H19 | H8: =H$6&TEXT(H$7,"00") -> 2H19 | I8: =I$6&TEXT(I$7,"00") -> 1H20 | J8: =J$6&TEXT(J$7,"00") -> 2H20 | K8: =K$6&TEXT(K$7,"00") -> 1H21 | L8: =L$6&TEXT(L$7,"00") -> 2H21 | ... AN8: =AN$6&TEXT(AN$7,"00") -> 2H35
B9: Financial Year | E9: {=_xlfn.IFS(MONTH(E$4)=12,YEAR(E$4)+1,MONTH(E$4)=6,YEAR(E$4))} -> 2018 | F9: {=_xlfn.IFS(MONTH(F$4)=12,YEAR(F$4)+1,MONTH(F$4)=6,YEAR(F$4))} -> 2018 | G9: {=_xlfn.IFS(MONTH(G$4)=12,YEAR(G$4)+1,MONTH(G$4)=6,YEAR(G$4))} -> 2019 | H9: {=_xlfn.IFS(MONTH(H$4)=12,YEAR(H$4)+1,MONTH(H$4)=6,YEAR(H$4))} -> 2019 | I9: {=_xlfn.IFS(MONTH(I$4)=12,YEAR(I$4)+1,MONTH(I$4)=6,YEAR(I$4))} -> 2020 | J9: {=_xlfn.IFS(MONTH(J$4)=12,YEAR(J$4)+1,MONTH(J$4)=6,YEAR(J$4))} -> 2020 | K9: {=_xlfn.IFS(MONTH(K$4)=12,YEAR(K$4)+1,MONTH(K$4)=6,YEAR(K$4))} -> 2021 | L9: {=_xlfn.IFS(MONTH(L$4)=12,YEAR(L$4)+1,MONTH(L$4)=6,YEAR(L$4))} -> 2021 | ... AN9: {=_xlfn.IFS(MONTH(AN$4)=12,YEAR(AN$4)+1,MONTH(AN$4)=6,YEAR(AN$4))} -> 2035
B10: Actual/Estimate | E10: A | F10: A | G10: A | H10: A | I10: A | J10: A | K10: A | L10: A | M10: A | N10: A | O10: A | P10: A | Q10: A | R10: A | S10: A | T10: A | U10: A | V10: =IF(ISNUMBER(#REF!),"A","E") -> E | W10: =IF(ISNUMBER(#REF!),"A","E") -> E | X10: =IF(ISNUMBER(#REF!),"A","E") -> E | Y10: =IF(ISNUMBER(#REF!),"A","E") -> E | Z10: =IF(ISNUMBER(#REF!),"A","E") -> E | AA10: =IF(ISNUMBER(#REF!),"A","E") -> E | AB10: =IF(ISNUMBER(#REF!),"A","E") -> E | AC10: =IF(ISNUMBER(#REF!),"A","E") -> E | ... AN10: =IF(ISNUMBER(#REF!),"A","E") -> E
A12: X | B12: FOREIGN EXCHANGE
B13: Days in period | E13: =E4-EOMONTH(E4,-6) -> 184 | F13: =F4-E4 -> 181 | G13: =G4-F4 -> 184 | H13: =H4-G4 -> 181 | I13: =I4-H4 -> 184 | J13: =J4-I4 -> 182 | K13: =K4-J4 -> 184 | L13: =L4-K4 -> 181 | M13: =M4-L4 -> 184 | ... AN13: =AN4-AM4 -> 181
A14: CUT
B15: Foreign exchange (NZDAUD) - Average
B16: Reported Average | C16: NZD/AUD | E16: 0.9141 | F16: =AVERAGE(0.9199,E16) -> 0.917 | G16: 0.9291 | H16: =AVERAGE(0.9398,G16) -> 0.93445 | I16: 0.9449 | J16: =AVERAGE(0.9483,I16) -> 0.9466 | K16: 0.9334 | L16: =AVERAGE(0.9323,K16) -> 0.93285 | M16: 0.9525 | N16: =AVERAGE(0.9362,M16) -> 0.94435 | O16: 0.9061 | P16: 0.92347713 | Q16: 0.9246 | R16: =0.9232*2-Q16 -> 0.9218 | S16: 0.9062 | T16: 0.9032 | U16: =T16 -> 0.9032 | V16: =U16 -> 0.9032 | W16: =V16 -> 0.9032 | X16: =W16 -> 0.9032 | Y16: =X16 -> 0.9032 | Z16: =Y16 -> 0.9032 | AA16: =Z16 -> 0.9032 | AB16: =AA16 -> 0.9032 | ... AN16: =AM16 -> 0.9032
B17: Consensus | C17: NZD/AUD | E17: =1/E18 -> 0.93118434 | F17: =1/F18 -> 0.92372396 | G17: =1/G18 -> 0.93465748 | H17: =1/H18 -> 0.95144423 | I17: =1/I18 -> 0.9449 | J17: =1/J18 -> 0.94778741 | K17: =1/K18 -> 0.92712119 | L17: =1/L18 -> 0.93052097 | ... Z17: =1/Z18 -> 0.92929461
B18: Consensus | C18: AUD/NZD | E18: 1.0739012 | F18: 1.0825745 | G18: 1.0699107 | H18: 1.0510338 | I18: 1.058313 | J18: 1.0550889 | K18: 1.0786076 | L18: 1.0746668 | M18: 1.0648957 | N18: 1.0778125 | O18: 1.1036309 | P18: 1.0896318 | Q18: 1.0901836 | R18: 1.0914007 | S18: 1.0847758 | T18: 1.0825061 | U18: 1.0817353 | V18: 1.080588 | W18: 1.0794494 | X18: 1.0783195 | Y18: 1.077198 | Z18: 1.076085
A20: X | B20: GUIDANCE/COMMENTARY
B22: FY26 Result
B24: EBITDA
B25: FY27 EBITDA triangulates to ~$185–190m ex-online: 4Q26 run-rate of just under $40m/qtr continuing into 1Q27 → ~$156–160m annualised, plus $30m net cost-out — management didn't dispute this bridge [Directional]. Then subtract the online launch drag and part-year Grand removal to land the number. Skew 1H-soft (weak run-rate persists early).
B27: COST OUT
B28: $30m net realised FY27 → $70m annualised FY28. Both net [Guidance].
B29: FY27 is organisational/headcount-led; FY28 uplift skews to external spend, process improvement and revenue [Directional].
B30: Adelaide allocation included, but the majority is NZ [Directional].
B31: One-off restructuring costs hit reported (not underlying) FY27 — unquantified; you need a below-EBITDA charge (200–250 NZ roles)
B33: AUCKLAND
B34: Auckland gaming: rebased, not recovering — a full year of MCP is lapped; model growth off the new base, not a snap-back [Directional].
B35: Non-gaming grows faster than gaming, at lower margin → mix is a structural margin drag even as revenue grows [Directional].
B36: Auckland margin "improves demonstrably" FY27 on the NZICC full-year/conference ramp — but stated before any Grand sale [Directional].
... B73: Adelaide ETR: ~A$180m unrecognised tax losses shelter Adelaide tax
A80: X | B80: LAND BASED DOMESTIC SEGMENTS REVENUE
A82: add in other lines | B82: Auckland
B83: Slots | C83: NZ$m | E83: 109.359 | F83: =(252.2-E83)*0.87 -> 124.27167 | G83: 117.189 | H83: =(271-G83)*0.87 -> 133.81557 | I83: 121.278 | J83: =(230.8-I83)*0.87 -> 95.28414 | K83: 105.096 | L83: =(264.3-K83)*0.87 -> 138.50748 | M83: 52.2 | N83: 109.185 | O83: 135.6 | P83: =265.3-O83 -> 129.7 | Q83: 127.9 | R83: =247.7-Q83 -> 119.8 | S83: 118.3 | T83: =233.9-S83 -> 115.6 | U83: 110.9 | V83: =214-U83 -> 103.1 | W83: =W125 -> 99 | X83: =X125 -> 103 | Y83: =Y125 -> 110 | Z83: =Z125 -> 108.665 | AA83: =AA125 -> 113.3 | AB83: =AB125 -> 111.92495 | AC83: =AC125 -> 116.699 | AD83: =AD125 -> 115.2827 | ... AN83: =AN125 -> 133.64424
B84: Tables | C84: NZ$m | E84: 70.557 | F84: =(161.9-E84)*0.87 -> 79.46841 | G84: 73.95 | H84: =(163.3-G84)*0.87 -> 77.7345 | I84: 74.385 | J84: =(128-I84)*0.87 -> 46.64505 | K84: 54.897 | L84: =(133.1-K84)*0.87 -> 68.03661 | M84: 20.445 | N84: 44.805 | O84: 57.7 | P84: =121.6-O84 -> 63.9 | Q84: 66.4 | R84: =127.6-Q84 -> 61.2 | S84: 57.1 | T84: =114.7-S84 -> 57.6 | U84: 54.5 | V84: =104.4-U84 -> 49.9 | W84: =W154 -> 47 | X84: =X154 -> 48 | Y84: =Y154 -> 49 | Z84: =Z154 -> 49.92 | AA84: =AA154 -> 49.49 | AB84: =AB154 -> 50.4192 | AC84: =AC154 -> 49.9849 | AD84: =AD154 -> 50.923392 | ... AN84: =AN154 -> 53.520997
B85: Premium Tables | C85: NZ$m | O85: 6.4 | P85: =7.2-O85 -> 0.8 | Q85: 12.6 | R85: =19.6-Q85 -> 7 | S85: 5.9 | T85: =9.2-S85 -> 3.3 | U85: -0.8 | V85: =-1.1-U85 -> -0.3 | W85: =W165 -> 3 | X85: =X165 -> 3 | Y85: =Y165 -> 3 | Z85: =Z165 -> 3.12 | AA85: =AA165 -> 3.12 | AB85: =AB165 -> 3.2448 | AC85: =AC165 -> 3.2448 | AD85: =AD165 -> 3.374592 | ... AN85: =AN165 -> 4.1057072
B86: Non Gaming | C86: NZ$m | E86: 83.2 | F86: =170.5-E86 -> 87.3 | G86: 88.1 | H86: =172.3-G86 -> 84.2 | I86: 80.7 | J86: =138.5-I86 -> 57.8 | K86: 46.9 | L86: =90.9-K86 -> 44 | M86: 35 | N86: 35.1 | O86: 58.6 | P86: =123.9-O86 -> 65.3 | Q86: 73.7 | R86: =151.8-Q86 -> 78.1 | S86: 77 | T86: =156.4-S86 -> 79.4 | U86: 83.5 | V86: =181.4-U86 -> 97.9 | W86: =W212 -> 107 | X86: =X212 -> 104 | Y86: =Y212 -> 110 | Z86: =Z212 -> 109.72 | AA86: =AA212 -> 114.4 | AB86: =AB212 -> 114.1088 | AC86: =AC212 -> 118.976 | AD86: =AD212 -> 118.67315 | ... AN86: =AN212 -> 144.38403
B87: Total Domestic | C87: NZ$m | E87: =SUM(E83:E86) -> 263.116 | F87: =SUM(F83:F86) -> 291.04008 | G87: =SUM(G83:G86) -> 279.239 | H87: =SUM(H83:H86) -> 295.75007 | I87: =SUM(I83:I86) -> 276.363 | J87: =SUM(J83:J86) -> 199.72919 | K87: =SUM(K83:K86) -> 206.893 | L87: =SUM(L83:L86) -> 250.54409 | ... R87: =SUM(R83:R86) -> 266.1 | S87: 258.3 | T87: =514.3-S87 -> 256 | U87: 248.1 | V87: =498.6-U87 -> 250.5 | W87: =SUM(W83:W86) -> 256 | X87: =SUM(X83:X86) -> 258 | Y87: =SUM(Y83:Y86) -> 272 | Z87: =SUM(Z83:Z86) -> 271.425 | AA87: =SUM(AA83:AA86) -> 280.31 | AB87: =SUM(AB83:AB86) -> 279.69775 | AC87: =SUM(AC83:AC86) -> 288.9047 | AD87: =SUM(AD83:AD86) -> 288.25383 | ... AN87: =SUM(AN83:AN86) -> 335.65498
S88: =S87-SUM(S83:S86) -> 0 | T88: =T87-SUM(T83:T86) -> 0.1 | U88: =U87-SUM(U83:U86) -> 0 | V88: =V87-SUM(V83:V86) -> -0.1
B89: Hamilton & Queenstown
B90: Slots | C90: NZ$m | E90: 18.531 | F90: =(42.9-E90)*0.87 -> 21.20103 | G90: 19.836 | H90: =(44.5-G90)*0.87 -> 21.45768 | I90: 21.054 | J90: =(41.4-I90)*0.87 -> 17.70102 | K90: 23.055 | L90: =(53-K90)*0.87 -> 26.05215 | M90: 17.661 | N90: 24.099 | O90: 28.2 | P90: =54-O90 -> 25.8 | Q90: 26.4 | R90: =52.3-Q90 -> 25.9 | S90: 26 | T90: =50.7-S90 -> 24.7 | U90: 24.8 | V90: =49.8-U90 -> 25 | W90: =W126 -> 25.296 | X90: =X126 -> 25.5 | Y90: =Y126 -> 26.30784 | Z90: =Z126 -> 26.52 | AA90: =AA126 -> 27.360154 | AB90: =AB126 -> 27.3156 | AC90: =AC126 -> 28.180958 | AD90: =AD126 -> 28.135068 | ... AN90: =AN126 -> 32.616255
...

Sheet FY
B2: SKC | C2: 2018 | D2: =C2+1 -> 2019 | E2: =D2+1 -> 2020 | F2: =E2+1 -> 2021 | G2: =F2+1 -> 2022 | H2: =G2+1 -> 2023 | I2: =H2+1 -> 2024 | J2: =I2+1 -> 2025 | K2: =J2+1 -> 2026 | ... S2: =R2+1 -> 2034
C3: 43281 | D3: =EOMONTH(C3,12) -> 43646 | E3: =EOMONTH(D3,12) -> 44012 | F3: =EOMONTH(E3,12) -> 44377 | G3: =EOMONTH(F3,12) -> 44742 | H3: =EOMONTH(G3,12) -> 45107 | I3: =EOMONTH(H3,12) -> 45473 | J3: =EOMONTH(I3,12) -> 45838 | K3: =EOMONTH(J3,12) -> 46203 | ... S3: =EOMONTH(R3,12) -> 49125 | U3: COMMENTS
A5: X | B5: SEGMENTS - NORMALISED | C5: 2018A | D5: 2019A | E5: 2020A | F5: 2021 | G5: 2022 | H5: 2023 | I5: 2024 | J5: 2025 | K5: 2026 | L5: 2027 | M5: 2028 | N5: 2029 | O5: 2030 | P5: 2031 | Q5: 2032 | R5: 2033 | S5: 2034 | U5: <<< POST RESTATEMENT
B6: Auckland | D6: =SUMIFS(HY!$G306:$AN306,HY!$G$9:$AN$9,FY!D$2) -> 550.4 | E6: =SUMIFS(HY!$G306:$AN306,HY!$G$9:$AN$9,FY!E$2) -> 450.9 | F6: =SUMIFS(HY!$G306:$AN306,HY!$G$9:$AN$9,FY!F$2) -> 436.7 | G6: =SUMIFS(HY!$G306:$AN306,HY!$G$9:$AN$9,FY!G$2) -> 296.8 | H6: =SUMIFS(HY!$G306:$AN306,HY!$G$9:$AN$9,FY!H$2) -> 518 | I6: =SUMIFS(HY!$G306:$AN306,HY!$G$9:$AN$9,FY!I$2) -> 546.7 | J6: =SUMIFS(HY!$G306:$AN306,HY!$G$9:$AN$9,FY!J$2) -> 514.3 | K6: =SUMIFS(HY!$G306:$AN306,HY!$G$9:$AN$9,FY!K$2) -> 498.6 | ... S6: =SUMIFS(HY!$G306:$AN306,HY!$G$9:$AN$9,FY!S$2) -> 651.86267
B7: Hamilton & Queenstown | D7: =SUMIFS(HY!$G307:$AN307,HY!$G$9:$AN$9,FY!D$2) -> 59.42301 | E7: =SUMIFS(HY!$G307:$AN307,HY!$G$9:$AN$9,FY!E$2) -> 57.23983 | F7: =SUMIFS(HY!$G307:$AN307,HY!$G$9:$AN$9,FY!F$2) -> 70.20027 | G7: =SUMIFS(HY!$G307:$AN307,HY!$G$9:$AN$9,FY!G$2) -> 58.96 | H7: =SUMIFS(HY!$G307:$AN307,HY!$G$9:$AN$9,FY!H$2) -> 77.9 | I7: =SUMIFS(HY!$G307:$AN307,HY!$G$9:$AN$9,FY!I$2) -> 77.1 | J7: =SUMIFS(HY!$G307:$AN307,HY!$G$9:$AN$9,FY!J$2) -> 74.2 | K7: =SUMIFS(HY!$G307:$AN307,HY!$G$9:$AN$9,FY!K$2) -> 73.9 | ... S7: =SUMIFS(HY!$G307:$AN307,HY!$G$9:$AN$9,FY!S$2) -> 91.230798
B8: Adelaide | D8: =SUMIFS(HY!$G308:$AN308,HY!$G$9:$AN$9,FY!D$2) -> 139.37478 | E8: =SUMIFS(HY!$G308:$AN308,HY!$G$9:$AN$9,FY!E$2) -> 112.76712 | F8: =SUMIFS(HY!$G308:$AN308,HY!$G$9:$AN$9,FY!F$2) -> 187.25327 | G8: =SUMIFS(HY!$G308:$AN308,HY!$G$9:$AN$9,FY!G$2) -> 179.79169 | H8: =SUMIFS(HY!$G308:$AN308,HY!$G$9:$AN$9,FY!H$2) -> 249.8 | I8: =SUMIFS(HY!$G308:$AN308,HY!$G$9:$AN$9,FY!I$2) -> 236.7 | J8: =SUMIFS(HY!$G308:$AN308,HY!$G$9:$AN$9,FY!J$2) -> 232 | K8: =SUMIFS(HY!$G308:$AN308,HY!$G$9:$AN$9,FY!K$2) -> 246.6 | ... S8: =SUMIFS(HY!$G308:$AN308,HY!$G$9:$AN$9,FY!S$2) -> 297.78064
B9: Online (from segments) | D9: =SUMIFS(HY!$G309:$AN309,HY!$G$9:$AN$9,FY!D$2) -> 0 | E9: =SUMIFS(HY!$G309:$AN309,HY!$G$9:$AN$9,FY!E$2) -> 4.5 | F9: =SUMIFS(HY!$G309:$AN309,HY!$G$9:$AN$9,FY!F$2) -> 13.1 | G9: =SUMIFS(HY!$G309:$AN309,HY!$G$9:$AN$9,FY!G$2) -> 16.9 | H9: =SUMIFS(HY!$G309:$AN309,HY!$G$9:$AN$9,FY!H$2) -> 15.4 | I9: =SUMIFS(HY!$G309:$AN309,HY!$G$9:$AN$9,FY!I$2) -> 9.3 | J9: =SUMIFS(HY!$G309:$AN309,HY!$G$9:$AN$9,FY!J$2) -> 4.1 | K9: =SUMIFS(HY!$G309:$AN309,HY!$G$9:$AN$9,FY!K$2) -> 2.8 | ... S9: =SUMIFS(HY!$G309:$AN309,HY!$G$9:$AN$9,FY!S$2) -> 51.46641
B10: Other (balancing) | D10: =SUMIFS(HY!$G310:$AN310,HY!$G$9:$AN$9,FY!D$2) -> 188.58893 | E10: =SUMIFS(HY!$G310:$AN310,HY!$G$9:$AN$9,FY!E$2) -> 79.826988 | F10: =SUMIFS(HY!$G310:$AN310,HY!$G$9:$AN$9,FY!F$2) -> 24.382942 | G10: =SUMIFS(HY!$G310:$AN310,HY!$G$9:$AN$9,FY!G$2) -> 22.96835 | H10: =SUMIFS(HY!$G310:$AN310,HY!$G$9:$AN$9,FY!H$2) -> 1.5 | I10: =SUMIFS(HY!$G310:$AN310,HY!$G$9:$AN$9,FY!I$2) -> 0.7 | J10: =SUMIFS(HY!$G310:$AN310,HY!$G$9:$AN$9,FY!J$2) -> 0.6 | K10: =SUMIFS(HY!$G310:$AN310,HY!$G$9:$AN$9,FY!K$2) -> 0.8 | ... S10: =SUMIFS(HY!$G310:$AN310,HY!$G$9:$AN$9,FY!S$2) -> 0
B11: Normalised Revenue | D11: =SUMIFS(HY!$G311:$AN311,HY!$G$9:$AN$9,FY!D$2) -> 937.78672 | E11: =SUMIFS(HY!$G311:$AN311,HY!$G$9:$AN$9,FY!E$2) -> 705.23394 | F11: =SUMIFS(HY!$G311:$AN311,HY!$G$9:$AN$9,FY!F$2) -> 731.63648 | G11: =SUMIFS(HY!$G311:$AN311,HY!$G$9:$AN$9,FY!G$2) -> 575.42004 | H11: =SUMIFS(HY!$G311:$AN311,HY!$G$9:$AN$9,FY!H$2) -> 862.6 | I11: =SUMIFS(HY!$G311:$AN311,HY!$G$9:$AN$9,FY!I$2) -> 870.5 | J11: =SUMIFS(HY!$G311:$AN311,HY!$G$9:$AN$9,FY!J$2) -> 825.2 | K11: =SUMIFS(HY!$G311:$AN311,HY!$G$9:$AN$9,FY!K$2) -> 822.7 | ... S11: =SUMIFS(HY!$G311:$AN311,HY!$G$9:$AN$9,FY!S$2) -> 1092.3405
B13: Auckland | D13: =SUMIFS(HY!$G319:$AN319,HY!$G$9:$AN$9,FY!D$2) -> 267.4 | E13: =SUMIFS(HY!$G319:$AN319,HY!$G$9:$AN$9,FY!E$2) -> 193.9 | F13: =SUMIFS(HY!$G319:$AN319,HY!$G$9:$AN$9,FY!F$2) -> 203.4 | G13: =SUMIFS(HY!$G319:$AN319,HY!$G$9:$AN$9,FY!G$2) -> 100.9 | H13: =SUMIFS(HY!$G319:$AN319,HY!$G$9:$AN$9,FY!H$2) -> 251.5 | I13: =SUMIFS(HY!$G319:$AN319,HY!$G$9:$AN$9,FY!I$2) -> 237 | J13: =SUMIFS(HY!$G319:$AN319,HY!$G$9:$AN$9,FY!J$2) -> 209.6 | K13: =SUMIFS(HY!$G319:$AN319,HY!$G$9:$AN$9,FY!K$2) -> 179.8 | ... S13: =SUMIFS(HY!$G319:$AN319,HY!$G$9:$AN$9,FY!S$2) -> 243.3139
B14: Hamilton & Queenstown | D14: =SUMIFS(HY!$G320:$AN320,HY!$G$9:$AN$9,FY!D$2) -> 29.2 | E14: =SUMIFS(HY!$G320:$AN320,HY!$G$9:$AN$9,FY!E$2) -> 26.6 | F14: =SUMIFS(HY!$G320:$AN320,HY!$G$9:$AN$9,FY!F$2) -> 38.4 | G14: =SUMIFS(HY!$G320:$AN320,HY!$G$9:$AN$9,FY!G$2) -> 27.5 | H14: =SUMIFS(HY!$G320:$AN320,HY!$G$9:$AN$9,FY!H$2) -> 39.3 | I14: =SUMIFS(HY!$G320:$AN320,HY!$G$9:$AN$9,FY!I$2) -> 35 | J14: =SUMIFS(HY!$G320:$AN320,HY!$G$9:$AN$9,FY!J$2) -> 33.7 | K14: =SUMIFS(HY!$G320:$AN320,HY!$G$9:$AN$9,FY!K$2) -> 31.4 | ... S14: =SUMIFS(HY!$G320:$AN320,HY!$G$9:$AN$9,FY!S$2) -> 40.780371
B15: Adelaide | D15: =SUMIFS(HY!$G321:$AN321,HY!$G$9:$AN$9,FY!D$2) -> 22.549524 | E15: =SUMIFS(HY!$G321:$AN321,HY!$G$9:$AN$9,FY!E$2) -> 11.856147 | F15: =SUMIFS(HY!$G321:$AN321,HY!$G$9:$AN$9,FY!F$2) -> 44.365029 | G15: =SUMIFS(HY!$G321:$AN321,HY!$G$9:$AN$9,FY!G$2) -> 21.610198 | H15: =SUMIFS(HY!$G321:$AN321,HY!$G$9:$AN$9,FY!H$2) -> 36.1 | I15: =SUMIFS(HY!$G321:$AN321,HY!$G$9:$AN$9,FY!I$2) -> 39.6 | J15: =SUMIFS(HY!$G321:$AN321,HY!$G$9:$AN$9,FY!J$2) -> 31.1 | K15: =SUMIFS(HY!$G321:$AN321,HY!$G$9:$AN$9,FY!K$2) -> 22.8 | ... S15: =SUMIFS(HY!$G321:$AN321,HY!$G$9:$AN$9,FY!S$2) -> 43.967352
B16: Online (from segments) | D16: =SUMIFS(HY!$G322:$AN322,HY!$G$9:$AN$9,FY!D$2) -> 0 | E16: =SUMIFS(HY!$G322:$AN322,HY!$G$9:$AN$9,FY!E$2) -> 2.2 | F16: =SUMIFS(HY!$G322:$AN322,HY!$G$9:$AN$9,FY!F$2) -> 9.1 | G16: =SUMIFS(HY!$G322:$AN322,HY!$G$9:$AN$9,FY!G$2) -> 12.9 | H16: =SUMIFS(HY!$G322:$AN322,HY!$G$9:$AN$9,FY!H$2) -> 10.7 | I16: =SUMIFS(HY!$G322:$AN322,HY!$G$9:$AN$9,FY!I$2) -> 3.6 | J16: =SUMIFS(HY!$G322:$AN322,HY!$G$9:$AN$9,FY!J$2) -> -1.8 | K16: =SUMIFS(HY!$G322:$AN322,HY!$G$9:$AN$9,FY!K$2) -> -6.4 | ... S16: =SUMIFS(HY!$G322:$AN322,HY!$G$9:$AN$9,FY!S$2) -> 20.586564
B17: Corporate Costs | D17: =SUMIFS(HY!$G323:$AN323,HY!$G$9:$AN$9,FY!D$2) -> -33.8 | E17: =SUMIFS(HY!$G323:$AN323,HY!$G$9:$AN$9,FY!E$2) -> -31.5 | F17: =SUMIFS(HY!$G323:$AN323,HY!$G$9:$AN$9,FY!F$2) -> -37.9 | G17: =SUMIFS(HY!$G323:$AN323,HY!$G$9:$AN$9,FY!G$2) -> -24.7 | H17: =SUMIFS(HY!$G323:$AN323,HY!$G$9:$AN$9,FY!H$2) -> -37.2 | I17: =SUMIFS(HY!$G323:$AN323,HY!$G$9:$AN$9,FY!I$2) -> -37.9 | J17: =SUMIFS(HY!$G323:$AN323,HY!$G$9:$AN$9,FY!J$2) -> -39.5 | K17: =SUMIFS(HY!$G323:$AN323,HY!$G$9:$AN$9,FY!K$2) -> -46.8 | ... S17: =SUMIFS(HY!$G323:$AN323,HY!$G$9:$AN$9,FY!S$2) -> -72.550098
B18: Other (balancing) | D18: =SUMIFS(HY!$G324:$AN324,HY!$G$9:$AN$9,FY!D$2) -> 36.850476 | E18: =SUMIFS(HY!$G324:$AN324,HY!$G$9:$AN$9,FY!E$2) -> -2.3561471 | F18: =SUMIFS(HY!$G324:$AN324,HY!$G$9:$AN$9,FY!F$2) -> -8.7650288 | G18: =SUMIFS(HY!$G324:$AN324,HY!$G$9:$AN$9,FY!G$2) -> -0.31019807 | H18: =SUMIFS(HY!$G324:$AN324,HY!$G$9:$AN$9,FY!H$2) -> 1.4 | I18: =SUMIFS(HY!$G324:$AN324,HY!$G$9:$AN$9,FY!I$2) -> 0.5 | J18: =SUMIFS(HY!$G324:$AN324,HY!$G$9:$AN$9,FY!J$2) -> 0.6 | K18: =SUMIFS(HY!$G324:$AN324,HY!$G$9:$AN$9,FY!K$2) -> 0.8 | ... S18: =SUMIFS(HY!$G324:$AN324,HY!$G$9:$AN$9,FY!S$2) -> 0
B19: Normalised EBITDA | D19: =SUMIFS(HY!$G325:$AN325,HY!$G$9:$AN$9,FY!D$2) -> 322.2 | E19: =SUMIFS(HY!$G325:$AN325,HY!$G$9:$AN$9,FY!E$2) -> 200.7 | F19: =SUMIFS(HY!$G325:$AN325,HY!$G$9:$AN$9,FY!F$2) -> 248.6 | G19: =SUMIFS(HY!$G325:$AN325,HY!$G$9:$AN$9,FY!G$2) -> 137.9 | H19: =SUMIFS(HY!$G325:$AN325,HY!$G$9:$AN$9,FY!H$2) -> 301.8 | I19: =SUMIFS(HY!$G325:$AN325,HY!$G$9:$AN$9,FY!I$2) -> 277.8 | J19: =SUMIFS(HY!$G325:$AN325,HY!$G$9:$AN$9,FY!J$2) -> 233.7 | K19: =SUMIFS(HY!$G325:$AN325,HY!$G$9:$AN$9,FY!K$2) -> 181.6 | ... S19: =SUMIFS(HY!$G325:$AN325,HY!$G$9:$AN$9,FY!S$2) -> 276.09809
A21: X | B21: P&L - NORMALISED | C21: 2018A | D21: 2019A | E21: 2020A | F21: 2021 | G21: 2022 | H21: 2023 | I21: 2024 | J21: 2025 | K21: 2026 | L21: 2027 | M21: 2028 | N21: 2029 | O21: 2030 | P21: 2030 | Q21: 2030 | R21: 2030 | S21: 2030
B22: Sales Revenue | D22: =SUMIFS(HY!$G311:$AN311,HY!$G$9:$AN$9,FY!D$2) -> 937.78672 | E22: =SUMIFS(HY!$G311:$AN311,HY!$G$9:$AN$9,FY!E$2) -> 705.23394 | F22: =SUMIFS(HY!$G311:$AN311,HY!$G$9:$AN$9,FY!F$2) -> 731.63648 | G22: =SUMIFS(HY!$G311:$AN311,HY!$G$9:$AN$9,FY!G$2) -> 575.42004 | H22: =SUMIFS(HY!$G311:$AN311,HY!$G$9:$AN$9,FY!H$2) -> 862.6 | I22: =SUMIFS(HY!$G311:$AN311,HY!$G$9:$AN$9,FY!I$2) -> 870.5 | J22: =SUMIFS(HY!$G311:$AN311,HY!$G$9:$AN$9,FY!J$2) -> 825.2 | K22: =SUMIFS(HY!$G311:$AN311,HY!$G$9:$AN$9,FY!K$2) -> 822.7 | ... S22: =SUMIFS(HY!$G311:$AN311,HY!$G$9:$AN$9,FY!S$2) -> 1092.3405
B23: Other Income | D23: =SUMIFS(HY!$G$517:$AN$517,HY!$G$9:$AN$9,FY!D$2) -> 0 | E23: =SUMIFS(HY!$G$517:$AN$517,HY!$G$9:$AN$9,FY!E$2) -> 0 | F23: =SUMIFS(HY!$G$517:$AN$517,HY!$G$9:$AN$9,FY!F$2) -> 0 | G23: =SUMIFS(HY!$G$517:$AN$517,HY!$G$9:$AN$9,FY!G$2) -> 0 | H23: =SUMIFS(HY!$G$517:$AN$517,HY!$G$9:$AN$9,FY!H$2) -> 0 | I23: =SUMIFS(HY!$G$517:$AN$517,HY!$G$9:$AN$9,FY!I$2) -> 0 | J23: =SUMIFS(HY!$G$517:$AN$517,HY!$G$9:$AN$9,FY!J$2) -> 0 | K23: =SUMIFS(HY!$G$517:$AN$517,HY!$G$9:$AN$9,FY!K$2) -> 0 | ... S23: =SUMIFS(HY!$G$517:$AN$517,HY!$G$9:$AN$9,FY!S$2) -> 0
B24: ----- | D24: ----- | E24: ----- | F24: ----- | G24: ----- | H24: ----- | I24: ----- | J24: ----- | K24: ----- | L24: ----- | M24: ----- | N24: ----- | O24: ----- | P24: ----- | Q24: ----- | R24: ----- | S24: -----
B25: Total revenue | D25: =D23+D22 -> 937.78672 | E25: =E23+E22 -> 705.23394 | F25: =F23+F22 -> 731.63648 | G25: =G23+G22 -> 575.42004 | H25: =H23+H22 -> 862.6 | I25: =I23+I22 -> 870.5 | J25: =J23+J22 -> 825.2 | K25: =K23+K22 -> 822.7 | ... S25: =S23+S22 -> 1092.3405
B26: COGS | D26: =SUMIFS(HY!$G$518:$AN$518,HY!$G$9:$AN$9,FY!D$2) -> 0 | E26: =SUMIFS(HY!$G$518:$AN$518,HY!$G$9:$AN$9,FY!E$2) -> 0 | F26: =SUMIFS(HY!$G$518:$AN$518,HY!$G$9:$AN$9,FY!F$2) -> 0 | G26: =SUMIFS(HY!$G$518:$AN$518,HY!$G$9:$AN$9,FY!G$2) -> 0 | H26: =SUMIFS(HY!$G$518:$AN$518,HY!$G$9:$AN$9,FY!H$2) -> 0 | I26: =SUMIFS(HY!$G$518:$AN$518,HY!$G$9:$AN$9,FY!I$2) -> 0 | J26: =SUMIFS(HY!$G$518:$AN$518,HY!$G$9:$AN$9,FY!J$2) -> 0 | K26: =SUMIFS(HY!$G$518:$AN$518,HY!$G$9:$AN$9,FY!K$2) -> 0 | ... S26: =SUMIFS(HY!$G$518:$AN$518,HY!$G$9:$AN$9,FY!S$2) -> 0
B27: OPEX | D27: =SUMIFS(HY!$G$313:$AN$313,HY!$G$9:$AN$9,FY!D$2) -> -615.58672 | E27: =SUMIFS(HY!$G$313:$AN$313,HY!$G$9:$AN$9,FY!E$2) -> -504.53394 | F27: =SUMIFS(HY!$G$313:$AN$313,HY!$G$9:$AN$9,FY!F$2) -> -483.03648 | G27: =SUMIFS(HY!$G$313:$AN$313,HY!$G$9:$AN$9,FY!G$2) -> -437.52004 | H27: =SUMIFS(HY!$G$313:$AN$313,HY!$G$9:$AN$9,FY!H$2) -> -560.8 | I27: =SUMIFS(HY!$G$313:$AN$313,HY!$G$9:$AN$9,FY!I$2) -> -592.7 | J27: =SUMIFS(HY!$G$313:$AN$313,HY!$G$9:$AN$9,FY!J$2) -> -591.5 | K27: =SUMIFS(HY!$G$313:$AN$313,HY!$G$9:$AN$9,FY!K$2) -> -641.1 | ... S27: =SUMIFS(HY!$G$313:$AN$313,HY!$G$9:$AN$9,FY!S$2) -> -816.24242
B28: ----- | D28: ----- | E28: ----- | F28: ----- | G28: ----- | H28: ----- | I28: ----- | J28: ----- | K28: ----- | L28: ----- | M28: ----- | N28: ----- | O28: ----- | P28: ----- | Q28: ----- | R28: ----- | S28: -----
B29: EBITDA | D29: =SUMIFS(HY!$G$325:$AN$325,HY!$G$9:$AN$9,FY!D$2) -> 322.2 | E29: =SUMIFS(HY!$G$325:$AN$325,HY!$G$9:$AN$9,FY!E$2) -> 200.7 | F29: =SUMIFS(HY!$G$325:$AN$325,HY!$G$9:$AN$9,FY!F$2) -> 248.6 | G29: =SUMIFS(HY!$G$325:$AN$325,HY!$G$9:$AN$9,FY!G$2) -> 137.9 | H29: =SUMIFS(HY!$G$325:$AN$325,HY!$G$9:$AN$9,FY!H$2) -> 301.8 | I29: =SUMIFS(HY!$G$325:$AN$325,HY!$G$9:$AN$9,FY!I$2) -> 277.8 | J29: =SUMIFS(HY!$G$325:$AN$325,HY!$G$9:$AN$9,FY!J$2) -> 233.7 | K29: =SUMIFS(HY!$G$325:$AN$325,HY!$G$9:$AN$9,FY!K$2) -> 181.6 | ... S29: =SUMIFS(HY!$G$325:$AN$325,HY!$G$9:$AN$9,FY!S$2) -> 276.09809
B30: Depreciation | D30: =SUMIFS(HY!$G$524:$AN$524,HY!$G$9:$AN$9,FY!D$2) -> -67.187398 | E30: =SUMIFS(HY!$G$524:$AN$524,HY!$G$9:$AN$9,FY!E$2) -> -68.613 | F30: =SUMIFS(HY!$G$524:$AN$524,HY!$G$9:$AN$9,FY!F$2) -> -74.995 | G30: =SUMIFS(HY!$G$524:$AN$524,HY!$G$9:$AN$9,FY!G$2) -> -81.499 | H30: =SUMIFS(HY!$G$524:$AN$524,HY!$G$9:$AN$9,FY!H$2) -> -77.343 | I30: =SUMIFS(HY!$G$524:$AN$524,HY!$G$9:$AN$9,FY!I$2) -> -80.266 | J30: =SUMIFS(HY!$G$524:$AN$524,HY!$G$9:$AN$9,FY!J$2) -> -82.918 | K30: =SUMIFS(HY!$G$524:$AN$524,HY!$G$9:$AN$9,FY!K$2) -> -90.655 | ... S30: =SUMIFS(HY!$G$524:$AN$524,HY!$G$9:$AN$9,FY!S$2) -> -86.364261
B31: Amortisation | D31: =SUMIFS(HY!$G$525:$AN$525,HY!$G$9:$AN$9,FY!D$2) -> -12.812602 | E31: =SUMIFS(HY!$G$525:$AN$525,HY!$G$9:$AN$9,FY!E$2) -> -17.987 | F31: =SUMIFS(HY!$G$525:$AN$525,HY!$G$9:$AN$9,FY!F$2) -> -13.405 | G31: =SUMIFS(HY!$G$525:$AN$525,HY!$G$9:$AN$9,FY!G$2) -> -13.201 | H31: =SUMIFS(HY!$G$525:$AN$525,HY!$G$9:$AN$9,FY!H$2) -> -13.329 | I31: =SUMIFS(HY!$G$525:$AN$525,HY!$G$9:$AN$9,FY!I$2) -> -11.755 | J31: =SUMIFS(HY!$G$525:$AN$525,HY!$G$9:$AN$9,FY!J$2) -> -11.295 | K31: =SUMIFS(HY!$G$525:$AN$525,HY!$G$9:$AN$9,FY!K$2) -> -12.802 | ... S31: =SUMIFS(HY!$G$525:$AN$525,HY!$G$9:$AN$9,FY!S$2) -> -13.431597
B32: ----- | D32: ----- | E32: ----- | F32: ----- | G32: ----- | H32: ----- | I32: ----- | J32: ----- | K32: ----- | L32: ----- | M32: ----- | N32: ----- | O32: ----- | P32: ----- | Q32: ----- | R32: ----- | S32: -----
B33: EBIT | D33: =SUMIFS(HY!$G$338:$AN$338,HY!$G$9:$AN$9,FY!D$2) -> 242.2 | E33: =SUMIFS(HY!$G$338:$AN$338,HY!$G$9:$AN$9,FY!E$2) -> 114.1 | F33: =SUMIFS(HY!$G$338:$AN$338,HY!$G$9:$AN$9,FY!F$2) -> 160.2 | G33: =SUMIFS(HY!$G$338:$AN$338,HY!$G$9:$AN$9,FY!G$2) -> 43.2 | H33: =SUMIFS(HY!$G$338:$AN$338,HY!$G$9:$AN$9,FY!H$2) -> 211.128 | I33: =SUMIFS(HY!$G$338:$AN$338,HY!$G$9:$AN$9,FY!I$2) -> 185.779 | J33: =SUMIFS(HY!$G$338:$AN$338,HY!$G$9:$AN$9,FY!J$2) -> 139.487 | K33: =SUMIFS(HY!$G$338:$AN$338,HY!$G$9:$AN$9,FY!K$2) -> 78.143 | ... S33: =SUMIFS(HY!$G$338:$AN$338,HY!$G$9:$AN$9,FY!S$2) -> 176.30223
B34: Net interest expense | D34: =SUMIFS(HY!$G$528:$AN$528,HY!$G$9:$AN$9,FY!D$2)+SUMIFS(HY!$G$529:$AN$529,HY!$G$9:$AN$9,FY!D$2) -> -37.064 | E34: =SUMIFS(HY!$G$528:$AN$528,HY!$G$9:$AN$9,FY!E$2)+SUMIFS(HY!$G$529:$AN$529,HY!$G$9:$AN$9,FY!E$2) -> -40.384 | F34: =SUMIFS(HY!$G$528:$AN$528,HY!$G$9:$AN$9,FY!F$2)+SUMIFS(HY!$G$529:$AN$529,HY!$G$9:$AN$9,FY!F$2) -> -37.65 | G34: =SUMIFS(HY!$G$528:$AN$528,HY!$G$9:$AN$9,FY!G$2)+SUMIFS(HY!$G$529:$AN$529,HY!$G$9:$AN$9,FY!G$2) -> -30.003 | H34: =SUMIFS(HY!$G$528:$AN$528,HY!$G$9:$AN$9,FY!H$2)+SUMIFS(HY!$G$529:$AN$529,HY!$G$9:$AN$9,FY!H$2) -> -37.094 | I34: =SUMIFS(HY!$G$528:$AN$528,HY!$G$9:$AN$9,FY!I$2)+SUMIFS(HY!$G$529:$AN$529,HY!$G$9:$AN$9,FY!I$2) -> -48.011 | J34: =SUMIFS(HY!$G$528:$AN$528,HY!$G$9:$AN$9,FY!J$2)+SUMIFS(HY!$G$529:$AN$529,HY!$G$9:$AN$9,FY!J$2) -> -59.514 | K34: =SUMIFS(HY!$G$528:$AN$528,HY!$G$9:$AN$9,FY!K$2)+SUMIFS(HY!$G$529:$AN$529,HY!$G$9:$AN$9,FY!K$2) -> -53.2875 | ... S34: =SUMIFS(HY!$G$528:$AN$528,HY!$G$9:$AN$9,FY!S$2)+SUMIFS(HY!$G$529:$AN$529,HY!$G$9:$AN$9,FY!S$2) -> -10.619647
B35: Other Financing | D35: =SUMIFS(HY!$G$530:$AD$530,HY!$G$9:$AD$9,FY!D$2) -> 26.864 | E35: =SUMIFS(HY!$G$530:$AD$530,HY!$G$9:$AD$9,FY!E$2) -> 11.784 | F35: =SUMIFS(HY!$G$530:$AD$530,HY!$G$9:$AD$9,FY!F$2) -> 5.15 | G35: =SUMIFS(HY!$G$530:$AD$530,HY!$G$9:$AD$9,FY!G$2) -> -4.997 | H35: =SUMIFS(HY!$G$530:$AD$530,HY!$G$9:$AD$9,FY!H$2) -> 8.968 | I35: =SUMIFS(HY!$G$530:$AD$530,HY!$G$9:$AD$9,FY!I$2) -> 32.011 | J35: =SUMIFS(HY!$G$530:$AD$530,HY!$G$9:$AD$9,FY!J$2) -> 33.114 | K35: =SUMIFS(HY!$G$530:$AD$530,HY!$G$9:$AD$9,FY!K$2) -> 26.6875 | ... S35: =SUMIFS(HY!$G$530:$AD$530,HY!$G$9:$AD$9,FY!S$2) -> 0
B36: Other | D36: =SUMIFS(HY!$G$531:$AN$531,HY!$G$9:$AN$9,FY!D$2) -> 0 | E36: =SUMIFS(HY!$G$531:$AN$531,HY!$G$9:$AN$9,FY!E$2) -> 0 | F36: =SUMIFS(HY!$G$531:$AN$531,HY!$G$9:$AN$9,FY!F$2) -> 0 | G36: =SUMIFS(HY!$G$531:$AN$531,HY!$G$9:$AN$9,FY!G$2) -> 0 | H36: =SUMIFS(HY!$G$531:$AN$531,HY!$G$9:$AN$9,FY!H$2) -> 0 | I36: =SUMIFS(HY!$G$531:$AN$531,HY!$G$9:$AN$9,FY!I$2) -> 0 | J36: =SUMIFS(HY!$G$531:$AN$531,HY!$G$9:$AN$9,FY!J$2) -> 0 | K36: =SUMIFS(HY!$G$531:$AN$531,HY!$G$9:$AN$9,FY!K$2) -> 0 | ... S36: =SUMIFS(HY!$G$531:$AN$531,HY!$G$9:$AN$9,FY!S$2) -> 0
B37: ----- | D37: ----- | E37: ----- | F37: ----- | G37: ----- | H37: ----- | I37: ----- | J37: ----- | K37: ----- | L37: ----- | M37: ----- | N37: ----- | O37: ----- | P37: ----- | Q37: ----- | R37: ----- | S37: -----
B38: NPBT | D38: =SUMIFS(HY!$G$343:$AN$343,HY!$G$9:$AN$9,FY!D$2) -> 232 | E38: =SUMIFS(HY!$G$343:$AN$343,HY!$G$9:$AN$9,FY!E$2) -> 85.5 | F38: =SUMIFS(HY!$G$343:$AN$343,HY!$G$9:$AN$9,FY!F$2) -> 127.7 | G38: =SUMIFS(HY!$G$343:$AN$343,HY!$G$9:$AN$9,FY!G$2) -> 8.2 | H38: =SUMIFS(HY!$G$343:$AN$343,HY!$G$9:$AN$9,FY!H$2) -> 183.002 | I38: =SUMIFS(HY!$G$343:$AN$343,HY!$G$9:$AN$9,FY!I$2) -> 169.779 | J38: =SUMIFS(HY!$G$343:$AN$343,HY!$G$9:$AN$9,FY!J$2) -> 113.087 | K38: =SUMIFS(HY!$G$343:$AN$343,HY!$G$9:$AN$9,FY!K$2) -> 51.543 | ... S38: =SUMIFS(HY!$G$343:$AN$343,HY!$G$9:$AN$9,FY!S$2) -> 165.68259
B39: Tax | D39: =SUMIFS(HY!$G$344:$AN$344,HY!$G$9:$AN$9,FY!D$2) -> -67.4 | E39: =SUMIFS(HY!$G$344:$AN$344,HY!$G$9:$AN$9,FY!E$2) -> -19.2 | F39: =SUMIFS(HY!$G$344:$AN$344,HY!$G$9:$AN$9,FY!F$2) -> -37.7 | G39: =SUMIFS(HY!$G$344:$AN$344,HY!$G$9:$AN$9,FY!G$2) -> 1.5 | H39: =SUMIFS(HY!$G$344:$AN$344,HY!$G$9:$AN$9,FY!H$2) -> -50.302 | I39: =SUMIFS(HY!$G$344:$AN$344,HY!$G$9:$AN$9,FY!I$2) -> -46.579 | J39: =SUMIFS(HY!$G$344:$AN$344,HY!$G$9:$AN$9,FY!J$2) -> -41.587 | K39: =SUMIFS(HY!$G$344:$AN$344,HY!$G$9:$AN$9,FY!K$2) -> -13.543 | ... S39: =SUMIFS(HY!$G$344:$AN$344,HY!$G$9:$AN$9,FY!S$2) -> -49.704776
B40: Effective Tax Rate (%) | D40: =D39/-D38 -> 0.29051724 | E40: =E39/-E38 -> 0.2245614 | F40: =F39/-F38 -> 0.29522318 | G40: =G39/-G38 -> -0.18292683 | H40: =H39/-H38 -> 0.27487131 | I40: =I39/-I38 -> 0.27435077 | J40: =J39/-J38 -> 0.36774342 | K40: =K39/-K38 -> 0.26275149 | ... S40: =S39/-S38 -> 0.3
B41: NPAT | D41: =SUMIFS(HY!$G$348:$AN$348,HY!$G$9:$AN$9,FY!D$2) -> 164.6 | E41: =SUMIFS(HY!$G$348:$AN$348,HY!$G$9:$AN$9,FY!E$2) -> 66.3 | F41: =SUMIFS(HY!$G$348:$AN$348,HY!$G$9:$AN$9,FY!F$2) -> 90 | G41: =SUMIFS(HY!$G$348:$AN$348,HY!$G$9:$AN$9,FY!G$2) -> 9.7 | H41: =SUMIFS(HY!$G$348:$AN$348,HY!$G$9:$AN$9,FY!H$2) -> 132.7 | I41: =SUMIFS(HY!$G$348:$AN$348,HY!$G$9:$AN$9,FY!I$2) -> 123.2 | J41: =SUMIFS(HY!$G$348:$AN$348,HY!$G$9:$AN$9,FY!J$2) -> 71.5 | K41: =SUMIFS(HY!$G$348:$AN$348,HY!$G$9:$AN$9,FY!K$2) -> 38 | ... S41: =SUMIFS(HY!$G$348:$AN$348,HY!$G$9:$AN$9,FY!S$2) -> 115.97781
B42: NPAT Growth | E42: =E41/D41-1 -> -0.59720535 | F42: =F41/E41-1 -> 0.35746606 | G42: =G41/F41-1 -> -0.89222222 | H42: =H41/G41-1 -> 12.680412 | I42: =I41/H41-1 -> -0.071590053 | J42: =J41/I41-1 -> -0.41964286 | K42: =K41/J41-1 -> -0.46853147 | L42: =L41/K41-1 -> -0.19867571 | ... S42: =S41/R41-1 -> 0.047101486
A44: X | B44: P&L - Underlying | D44: 2019A | E44: 2020A | F44: 2021 | G44: 2022 | H44: 2023 | I44: 2024 | J44: 2025 | K44: 2026 | L44: 2027 | M44: 2028 | N44: 2029 | O44: 2030 | P44: 2030 | Q44: 2030 | R44: 2030 | S44: 2030
B45: Sales Revenue | D45: =SUMIFS(HY!$G$516:$AN$516,HY!$G$9:$AN$9,FY!D$2) -> 937.78672 | E45: =SUMIFS(HY!$G$516:$AN$516,HY!$G$9:$AN$9,FY!E$2) -> 705.23394 | F45: =SUMIFS(HY!$G$516:$AN$516,HY!$G$9:$AN$9,FY!F$2) -> 731.63648 | G45: =SUMIFS(HY!$G$516:$AN$516,HY!$G$9:$AN$9,FY!G$2) -> 575.42004 | H45: =SUMIFS(HY!$G$516:$AN$516,HY!$G$9:$AN$9,FY!H$2) -> 862.6 | I45: =SUMIFS(HY!$G$516:$AN$516,HY!$G$9:$AN$9,FY!I$2) -> 870.5 | J45: =SUMIFS(HY!$G$516:$AN$516,HY!$G$9:$AN$9,FY!J$2) -> 825.2 | K45: =SUMIFS(HY!$G$516:$AN$516,HY!$G$9:$AN$9,FY!K$2) -> 822.7 | ... S45: =SUMIFS(HY!$G$516:$AN$516,HY!$G$9:$AN$9,FY!S$2) -> 1092.3405
...

Sheet II

Sheet FT Tables
Q1: EBITDA
C3: SkyCity 1H26 Result - Headline (NZ$m) | BV3: SkyCity FY26 Result - Headline (NZ$m)
D4: 1H22A | E4: 2H22A | F4: 1H23A | G4: 2H23A | H4: 1H24A | I4: 2H24E | J4: 1H25E | K4: 2H25E | L4: 1H26E | M4: 2H26E | N4: 1H27E | O4: 2H27E | Q4: 1H25A | R4: ="1H26A" -> 1H26A | S4: % change | T4: E&Pe 1H26E | U4: % diff | V4: VA Cons. 1H26E | W4: % diff | AB4: 1H25 | AG4: 1H22 | AH4: 2H22 | AI4: 1H23 | AJ4: 2H23 | AK4: 1H24 | AL4: 2H24 | AM4: 1H25 | AN4: 2H25 | AO4: 1H26 | AP4: 2H26 | AQ4: 1H27 | AR4: 2H27 | AT4: 1H22 | AU4: 2H22 | AV4: 1H23 | AW4: 2H23 | AX4: 1H24 | AY4: 2H24 | AZ4: 1H25 | BA4: 2H25 | BB4: 1H26 | BC4: 2H26 | BD4: 1H27 | BE4: 2H27 | BG4: 1H22 | BH4: 2H22 | BI4: 1H23 | BJ4: 2H23 | BK4: 1H24 | BL4: 2H24 | BM4: 1H25 | BN4: 2H25 | BO4: 1H26 | BP4: 2H26 | BQ4: 1H27 | BR4: 2H27 | BW4: FY22A | BX4: FY23A | BY4: FY24E | BZ4: FY25E | CA4: FY26E | CB4: FY27E | CD4: FY25A | CE4: ="FY26A" -> FY26A | CF4: % change | CG4: E&Pe FY26E | CH4: % diff | CI4: VA Cons. FY26E | CJ4: % diff | CM4: FY24 | CR4: FY22 | CS4: FY23 | CT4: FY24 | CU4: FY25 | CV4: FY26 | CW4: FY27 | CY4: FY22 | CZ4: FY23 | DA4: FY24 | DB4: FY25 | DC4: FY26 | DD4: FY27 | DF4: FY22 | DG4: FY23 | DH4: FY24 | DI4: FY25 | DJ4: FY26 | DK4: FY27
C5: P&L - Normalised | BV5: P&L - Normalised
C6: Revenue | F6: =HY!O311 -> 438.9 | G6: =HY!P311 -> 423.7 | H6: =HY!Q311 -> 442.8 | I6: =HY!R311 -> 427.7 | J6: =HY!S311 -> 422 | K6: =HY!T311 -> 403.2 | L6: =HY!U311 -> 411.7 | M6: =HY!V311 -> 411 | ... O6: =HY!X311 -> 421.369 | Q6: =J6 -> 422 | R6: 411.7 | S6: =R6/Q6-1 -> -0.024407583 | T6: =L6 -> 411.7 | U6: =$R6/T6-1 -> 0 | V6: =AB6 -> 385.86341 | W6: =$R6/V6-1 -> 0.066957865 | AB6: =BB6 -> 385.86341 | AD6: SKC_NZ | AE6: Total revenue - Operating | AF6: consensus.vaactuals | AG6: =_xll.VAData($AD6,AG$4,$AE6,$AF6) -> 260.8 | AH6: =_xll.VAData($AD6,AH$4,$AE6,$AF6) -> 370.7 | AI6: =_xll.VAData($AD6,AI$4,$AE6,$AF6) -> 438.9 | AJ6: =_xll.VAData($AD6,AJ$4,$AE6,$AF6) -> 423.7 | AK6: =_xll.VAData($AD6,AK$4,$AE6,$AF6) -> 442.8 | AL6: =_xll.VAData($AD6,AL$4,$AE6,$AF6) -> 427.702 | AM6: =_xll.VAData($AD6,AM$4,$AE6,$AF6) -> 422 | AN6: =_xll.VAData($AD6,AN$4,$AE6,$AF6) -> 403.2 | ... AR6: =_xll.VAData($AD6,AR$4,$AE6,$AF6) -> 403.74455 | AT6: 260.8 | AU6: 370.7 | AV6: 438.9 | AW6: 423.7 | AX6: 442.8 | AY6: 427.7 | AZ6: 422 | BA6: 403.2 | BB6: 385.86341 | BC6: 402.90399 | BD6: 430.51721 | BE6: 434.22619 | BI6: =F6-AV6 -> 0 | BJ6: =G6-AW6 -> 0 | BK6: =H6-AX6 -> 0 | BL6: =I6-AY6 -> 0 | BM6: =J6-AZ6 -> 0 | BN6: =K6-BA6 -> 0 | BO6: =L6-BB6 -> 25.83659 | BP6: =M6-BC6 -> 8.0960121 | ... BR6: =O6-BE6 -> -12.857194 | BV6: Revenue | BW6: =FY!G25 -> 575.42004 | BX6: =FY!H25 -> 862.6 | BY6: =FY!I25 -> 870.5 | BZ6: =FY!J25 -> 825.2 | CA6: =FY!K25 -> 822.7 | CB6: =FY!L25 -> 840.934 | CD6: =BZ6 -> 825.2 | CE6: 822.7 | CF6: =CE6/CD6-1 -> -0.0030295686 | CG6: =CA6 -> 822.7 | CH6: =$CE6/CG6-1 -> 0 | CI6: =CM6 -> 815.21503 | CJ6: =$CE6/CI6-1 -> 0.00918159 | CM6: =DC6 -> 815.21503 | CO6: SKC_NZ | CP6: Total revenue - Operating | CQ6: consensus.vaactuals | CR6: =_xll.VAData($AD6,CR$4,$AE6,$AF6) -> 631.5 | CS6: =_xll.VAData($AD6,CS$4,$AE6,$AF6) -> 862.6 | CT6: =_xll.VAData($AD6,CT$4,$AE6,$AF6) -> 870.5 | CU6: =_xll.VAData($AD6,CU$4,$AE6,$AF6) -> 825.2 | CV6: =_xll.VAData($AD6,CV$4,$AE6,$AF6) -> 822.7 | CW6: =_xll.VAData($AD6,CW$4,$AE6,$AF6) -> 824.73077 | CY6: 631.5 | CZ6: 862.6 | DA6: 870.5 | DB6: 825.2 | DC6: 815.21503 | DD6: 851.50262 | DF6: =BW6-CY6 -> -56.079956 | DG6: =BX6-CZ6 -> 0 | DH6: =BY6-DA6 -> 0 | DI6: =BZ6-DB6 -> 0 | DJ6: =CA6-DC6 -> 7.4849702 | DK6: =CB6-DD6 -> -10.568621
C7: EBITDA | F7: =HY!O325 -> 161.8 | G7: =HY!P325 -> 140 | H7: =HY!Q325 -> 144.3 | I7: =HY!R325 -> 133.5 | J7: =HY!S325 -> 119.5 | K7: =HY!T325 -> 114.2 | L7: =HY!U325 -> 85.5 | M7: =HY!V325 -> 96.1 | ... O7: =HY!X325 -> 94.050503 | Q7: 119.5 | R7: 85.5 | S7: =R7/Q7-1 -> -0.28451883 | T7: =L7 -> 85.5 | U7: =$R7/T7-1 -> 0 | V7: =AB7 -> 88.187782 | W7: =$R7/V7-1 -> -0.030477938 | AB7: =BB7 -> 88.187782 | AD7: SKC_NZ | AE7: EBITDA - Operating | AF7: consensus.vaactuals | AG7: =_xll.VAData($AD7,AG$4,$AE7,$AF7) -> 36.2 | AH7: =_xll.VAData($AD7,AH$4,$AE7,$AF7) -> 101.7 | AI7: =_xll.VAData($AD7,AI$4,$AE7,$AF7) -> 161.8 | AJ7: =_xll.VAData($AD7,AJ$4,$AE7,$AF7) -> 140 | AK7: =_xll.VAData($AD7,AK$4,$AE7,$AF7) -> 144.25346 | AL7: =_xll.VAData($AD7,AL$4,$AE7,$AF7) -> 133.5 | AM7: =_xll.VAData($AD7,AM$4,$AE7,$AF7) -> 119.529 | AN7: =_xll.VAData($AD7,AN$4,$AE7,$AF7) -> 114.2 | ... AR7: =_xll.VAData($AD7,AR$4,$AE7,$AF7) -> 93.164145 | AT7: 36.2 | AU7: 101.7 | AV7: 161.7 | AW7: 140.1 | AX7: 144.3 | AY7: 133.5 | AZ7: 113.1 | BA7: 120.6 | BB7: 88.187782 | BC7: 106.32547 | BD7: 108.19785 | BE7: 118.38289 | BI7: =F7-AV7 -> 0.1 | BJ7: =G7-AW7 -> -0.1 | BK7: =H7-AX7 -> 0 | BL7: =I7-AY7 -> 0 | BM7: =J7-AZ7 -> 6.4 | BN7: =K7-BA7 -> -6.4 | BO7: =L7-BB7 -> -2.6877817 | BP7: =M7-BC7 -> -10.22547 | ... BR7: =O7-BE7 -> -24.332389 | BV7: EBITDA | BW7: =FY!G29 -> 137.9 | BX7: =FY!H29 -> 301.8 | BY7: =FY!I29 -> 277.8 | BZ7: =FY!J29 -> 233.7 | CA7: =FY!K29 -> 181.6 | CB7: =FY!L29 -> 183.18614 | CD7: =BZ7 -> 233.7 | CE7: 181.6 | CF7: =CE7/CD7-1 -> -0.22293539 | CG7: =CA7 -> 181.6 | CH7: =$CE7/CG7-1 -> 0 | CI7: =CM7 -> 182.49152 | CJ7: =$CE7/CI7-1 -> -0.0048852946 | CM7: =DC7 -> 182.49152 | CO7: SKC_NZ | CP7: EBITDA - Operating | CQ7: consensus.vaactuals | CR7: =_xll.VAData($AD7,CR$4,$AE7,$AF7) -> 137.9 | CS7: =_xll.VAData($AD7,CS$4,$AE7,$AF7) -> 301.8 | CT7: =_xll.VAData($AD7,CT$4,$AE7,$AF7) -> 277.8 | CU7: =_xll.VAData($AD7,CU$4,$AE7,$AF7) -> 233.7 | CV7: =_xll.VAData($AD7,CV$4,$AE7,$AF7) -> 181.6 | CW7: =_xll.VAData($AD7,CW$4,$AE7,$AF7) -> 181.26337 | CY7: 137.9 | CZ7: 301.8 | DA7: 277.8 | DB7: 233.7 | DC7: 182.49152 | DD7: 197.49483 | DF7: =BW7-CY7 -> 0 | DG7: =BX7-CZ7 -> 0 | DH7: =BY7-DA7 -> 0 | DI7: =BZ7-DB7 -> 0 | DJ7: =CA7-DC7 -> -0.89152487 | DK7: =CB7-DD7 -> -14.308693
C8: EBIT | F8: =HY!O338 -> 116.336 | G8: =HY!P338 -> 94.792 | H8: =HY!Q338 -> 100.053 | I8: =HY!R338 -> 85.726 | J8: =HY!S338 -> 74.171 | K8: =HY!T338 -> 65.316 | L8: =HY!U338 -> 35.621 | M8: =HY!V338 -> 42.522 | ... O8: =HY!X338 -> 41.32371 | Q8: =J8 -> 74.171 | S8: =R8/Q8-1 -> -1 | T8: =L8 -> 35.621 | U8: =$R8/T8-1 -> -1 | V8: =AB8 -> 35.083138 | W8: =$R8/V8-1 -> -1 | AB8: =BB8 -> 35.083138 | AD8: SKC_NZ | AE8: Operating income/(loss) - Operating | AF8: consensus.vaactuals | AG8: =_xll.VAData($AD8,AG$4,$AE8,$AF8) -> -11.6 | AH8: =_xll.VAData($AD8,AH$4,$AE8,$AF8) -> 54.8 | AI8: =_xll.VAData($AD8,AI$4,$AE8,$AF8) -> 116.3 | AJ8: =_xll.VAData($AD8,AJ$4,$AE8,$AF8) -> 94.8 | AK8: =_xll.VAData($AD8,AK$4,$AE8,$AF8) -> 100 | AL8: =_xll.VAData($AD8,AL$4,$AE8,$AF8) -> 85.8 | AM8: =_xll.VAData($AD8,AM$4,$AE8,$AF8) -> 74.201015 | AN8: =_xll.VAData($AD8,AN$4,$AE8,$AF8) -> 65.3 | ... AR8: =_xll.VAData($AD8,AR$4,$AE8,$AF8) -> 36.268601 | AT8: -17.6 | AU8: 54.8 | AV8: 116.3 | AW8: 94.8 | AX8: 100 | AY8: 85.8 | AZ8: 67.8 | BA8: 71.7 | BB8: 35.083138 | BC8: 52.515608 | BD8: 53.556982 | BE8: 59.38207 | BI8: =F8-AV8 -> 0.036 | BJ8: =G8-AW8 -> -0.008 | BK8: =H8-AX8 -> 0.053 | BL8: =I8-AY8 -> -0.074 | BM8: =J8-AZ8 -> 6.371 | BN8: =K8-BA8 -> -6.384 | BO8: =L8-BB8 -> 0.53786181 | BP8: =M8-BC8 -> -9.9936078 | ... BR8: =O8-BE8 -> -18.058359 | BV8: EBIT | CD8: =BZ8 -> 0 | CF8: =CE8/CD8-1 -> #DIV/0! | CG8: =CA8 -> 0 | CH8: =$CE8/CG8-1 -> #DIV/0! | CI8: =CM8 -> 76.887933 | CJ8: =$CE8/CI8-1 -> -1 | CM8: =DC8 -> 76.887933 | CO8: SKC_NZ | CP8: Operating income/(loss) - Operating | CQ8: consensus.vaactuals | CR8: =_xll.VAData($AD8,CR$4,$AE8,$AF8) -> 43.3 | CS8: =_xll.VAData($AD8,CS$4,$AE8,$AF8) -> 211.1 | CT8: =_xll.VAData($AD8,CT$4,$AE8,$AF8) -> 185.8 | CU8: =_xll.VAData($AD8,CU$4,$AE8,$AF8) -> 139.5 | CV8: =_xll.VAData($AD8,CV$4,$AE8,$AF8) -> 76.5 | CW8: =_xll.VAData($AD8,CW$4,$AE8,$AF8) -> 66.937245 | CY8: 43.3 | CZ8: 211.1 | DA8: 185.8 | DB8: 139.5 | DC8: 76.887933 | DD8: 88.292753 | DF8: =BW8-CY8 -> -43.3 | DG8: =BX8-CZ8 -> -211.1 | DH8: =BY8-DA8 -> -185.8 | DI8: =BZ8-DB8 -> -139.5 | DJ8: =CA8-DC8 -> -76.887933 | DK8: =CB8-DD8 -> -88.292753
C9: NPAT | F9: =HY!O348 -> 72.8 | G9: =HY!P348 -> 59.9 | H9: =HY!Q348 -> 64.5 | I9: =HY!R348 -> 58.7 | J9: =HY!S348 -> 44.2 | K9: =HY!T348 -> 27.3 | L9: =HY!U348 -> 14.4 | M9: =HY!V348 -> 23.6 | ... O9: =HY!X348 -> 21.030314 | Q9: =J9 -> 44.2 | R9: 14.4 | S9: =R9/Q9-1 -> -0.67420814 | T9: =L9 -> 14.4 | U9: =$R9/T9-1 -> 0 | V9: =AB9 -> 10.080031 | W9: =$R9/V9-1 -> 0.42856702 | AB9: =BB9 -> 10.080031 | AD9: SKC_NZ | AE9: Net income/(loss) - Operating | AF9: consensus.vaactuals | AG9: =_xll.VAData($AD9,AG$4,$AE9,$AF9) -> -19.5 | AH9: =_xll.VAData($AD9,AH$4,$AE9,$AF9) -> 29.2 | AI9: =_xll.VAData($AD9,AI$4,$AE9,$AF9) -> 72.8 | AJ9: =_xll.VAData($AD9,AJ$4,$AE9,$AF9) -> 60 | AK9: =_xll.VAData($AD9,AK$4,$AE9,$AF9) -> 64.503335 | AL9: =_xll.VAData($AD9,AL$4,$AE9,$AF9) -> 58.7 | AM9: =_xll.VAData($AD9,AM$4,$AE9,$AF9) -> 44.2 | AN9: =_xll.VAData($AD9,AN$4,$AE9,$AF9) -> 27.3 | ... AR9: =_xll.VAData($AD9,AR$4,$AE9,$AF9) -> 15.845529 | AT9: -19.5 | AU9: 29.3 | AV9: 72.8 | AW9: 60 | AX9: 64.5 | AY9: 58.7 | AZ9: 37.8 | BA9: 33.7 | BB9: 10.080031 | BC9: 21.188801 | BD9: 24.288062 | BE9: 28.693163 | BI9: =F9-AV9 -> 0 | BJ9: =G9-AW9 -> -0.1 | BK9: =H9-AX9 -> 0 | BL9: =I9-AY9 -> 0 | BM9: =J9-AZ9 -> 6.4 | BN9: =K9-BA9 -> -6.4 | BO9: =L9-BB9 -> 4.3199689 | BP9: =M9-BC9 -> 2.4111986 | ... BR9: =O9-BE9 -> -7.6628485 | BV9: NPAT | BW9: =FY!G41 -> 9.7 | BX9: =FY!H41 -> 132.7 | BY9: =FY!I41 -> 123.2 | BZ9: =FY!J41 -> 71.5 | CA9: =FY!K41 -> 38 | CB9: =FY!L41 -> 30.450323 | CD9: =BZ9 -> 71.5 | CE9: 38 | CF9: =CE9/CD9-1 -> -0.46853147 | CG9: =CA9 -> 38 | CH9: =$CE9/CG9-1 -> 0 | CI9: =CM9 -> 28.643992 | CJ9: =$CE9/CI9-1 -> 0.32663075 | CM9: =DC9 -> 28.643992 | CO9: SKC_NZ | CP9: Net income/(loss) - Operating | CQ9: consensus.vaactuals | CR9: =_xll.VAData($AD9,CR$4,$AE9,$AF9) -> 9.7 | CS9: =_xll.VAData($AD9,CS$4,$AE9,$AF9) -> 132.8 | CT9: =_xll.VAData($AD9,CT$4,$AE9,$AF9) -> 123.2 | CU9: =_xll.VAData($AD9,CU$4,$AE9,$AF9) -> 71.5 | CV9: =_xll.VAData($AD9,CV$4,$AE9,$AF9) -> 38 | CW9: =_xll.VAData($AD9,CW$4,$AE9,$AF9) -> 23.612459 | CY9: 9.7 | CZ9: 132.8 | DA9: 123.2 | DB9: 71.5 | DC9: 28.643992 | DD9: 35.23831 | DF9: =BW9-CY9 -> 0 | DG9: =BX9-CZ9 -> -0.1 | DH9: =BY9-DA9 -> 0 | DI9: =BZ9-DB9 -> 0 | DJ9: =CA9-DC9 -> 9.3560084 | DK9: =CB9-DD9 -> -4.7879876
C10: EPS (cps) | F10: =HY!O349 -> 9.6 | G10: =HY!P349 -> 8.7 | H10: =HY!Q349 -> 8.8 | I10: =HY!R349 -> 7.4 | J10: =HY!S349 -> 5 | K10: =HY!T349 -> 4.4 | L10: =HY!U349 -> 1.5 | M10: =HY!V349 -> 2.2 | ... O10: =HY!X349 -> 1.9065517 | Q10: =J10 -> 5 | R10: 1.5 | S10: =R10/Q10-1 -> -0.7 | T10: =L10 -> 1.5 | U10: =$R10/T10-1 -> 0 | V10: =AB10 -> 1.1334306 | W10: =$R10/V10-1 -> 0.32341584 | AB10: =BB10 -> 1.1334306 | AD10: SKC_NZ | AE10: EPS - Basic - Operating | AF10: consensus.vaactuals | AG10: =_xll.VAData($AD10,AG$4,$AE10,$AF10) -> -2.5651057 | AH10: =_xll.VAData($AD10,AH$4,$AE10,$AF10) -> 3.9 | AI10: =_xll.VAData($AD10,AI$4,$AE10,$AF10) -> 9.6 | AJ10: =_xll.VAData($AD10,AJ$4,$AE10,$AF10) -> 7.9143433 | AK10: =_xll.VAData($AD10,AK$4,$AE10,$AF10) -> 8.8 | AL10: =_xll.VAData($AD10,AL$4,$AE10,$AF10) -> 7.4 | AM10: =_xll.VAData($AD10,AM$4,$AE10,$AF10) -> 5 | AN10: =_xll.VAData($AD10,AN$4,$AE10,$AF10) -> 3.5963322 | ... AR10: =_xll.VAData($AD10,AR$4,$AE10,$AF10) -> 1.436513 | AT10: -2.6 | AU10: 3.9 | AV10: 9.6 | AW10: 7.9143433 | AX10: 8.8 | AY10: 7.4 | AZ10: 5 | BA10: 4.4175734 | BB10: 1.1334306 | BC10: 1.5638408 | BD10: 2.2099132 | BE10: 2.6095536 | BI10: =F10-AV10 -> 0 | BJ10: =G10-AW10 -> 0.78565674 | BK10: =H10-AX10 -> 0 | BL10: =I10-AY10 -> 0 | BM10: =J10-AZ10 -> 0 | BN10: =K10-BA10 -> -0.017573412 | BO10: =L10-BB10 -> 0.36656941 | BP10: =M10-BC10 -> 0.63615918 | ... BR10: =O10-BE10 -> -0.70300198 | BV10: EPS (cps) | BW10: =FY!G161 -> 1.3 | BX10: =FY!H161 -> 18.3 | BY10: =FY!I161 -> 16.2 | BZ10: =FY!J161 -> 9.4 | CA10: =FY!K161 -> 3.7 | CB10: =FY!L161 -> 2.7605443 | CD10: =BZ10 -> 9.4 | CF10: =CE10/CD10-1 -> -1 | CG10: =CA10 -> 3.7 | CH10: =$CE10/CG10-1 -> -1 | CI10: =CM10 -> 2.7808761 | CJ10: =$CE10/CI10-1 -> -1 | CM10: =DC10 -> 2.7808761 | CO10: SKC_NZ | CP10: EPS - Basic - Operating | CQ10: consensus.vaactuals | CR10: =_xll.VAData($AD10,CR$4,$AE10,$AF10) -> 1.2805147 | CS10: =_xll.VAData($AD10,CS$4,$AE10,$AF10) -> 17.466665 | CT10: =_xll.VAData($AD10,CT$4,$AE10,$AF10) -> 16.2 | CU10: =_xll.VAData($AD10,CU$4,$AE10,$AF10) -> 9.4175734 | CV10: =_xll.VAData($AD10,CV$4,$AE10,$AF10) -> 3.6639162 | CW10: =_xll.VAData($AD10,CW$4,$AE10,$AF10) -> 2.1618546 | CY10: 1.2775501 | CZ10: 17.51708 | DA10: 16.2 | DB10: 9.4175734 | DC10: 2.7808761 | DD10: 3.1950591 | DF10: =BW10-CY10 -> 0.02244987 | DG10: =BX10-CZ10 -> 0.78292024 | DH10: =BY10-DA10 -> 0 | DI10: =BZ10-DB10 -> -0.017573412 | DJ10: =CA10-DC10 -> 0.91912395 | DK10: =CB10-DD10 -> -0.43451484
C11: DPS (cps) | F11: =HY!O493 -> 6 | G11: =HY!P493 -> 6 | H11: =HY!Q493 -> 5.25 | I11: =HY!R493 -> 0 | J11: =HY!S493 -> 0 | K11: =HY!T493 -> 0 | L11: =HY!U493 -> 0 | M11: =HY!V493 -> 0 | ... O11: =HY!X493 -> 0 | Q11: =J11 -> 0 | R11: 0 | S11: na | T11: =L11 -> 0 | U11: na | V11: =AB11 -> 0 | W11: na | Z11: na'd | AB11: =BB11 -> 0 | AD11: SKC_NZ | AE11: Dividend per share | AF11: consensus.vaactuals | AG11: =_xll.VAData($AD11,AG$4,$AE11,$AF11) -> 0 | AH11: =_xll.VAData($AD11,AH$4,$AE11,$AF11) -> 0 | AI11: =_xll.VAData($AD11,AI$4,$AE11,$AF11) -> 6 | AJ11: =_xll.VAData($AD11,AJ$4,$AE11,$AF11) -> 6 | AK11: =_xll.VAData($AD11,AK$4,$AE11,$AF11) -> 5.25 | AL11: =_xll.VAData($AD11,AL$4,$AE11,$AF11) -> 0 | AM11: =_xll.VAData($AD11,AM$4,$AE11,$AF11) -> 0 | AN11: =_xll.VAData($AD11,AN$4,$AE11,$AF11) -> 0 | ... AR11: =_xll.VAData($AD11,AR$4,$AE11,$AF11) -> 0 | AT11: 0 | AU11: 0 | AV11: 6 | AW11: 6 | AX11: 5.25 | AY11: 0 | AZ11: 0 | BA11: 0 | BB11: 0 | BC11: 0 | BD11: 0.096985175 | BE11: 0.76641862 | BI11: =F11-AV11 -> 0 | BJ11: =G11-AW11 -> 0 | BK11: =H11-AX11 -> 0 | BL11: =I11-AY11 -> 0 | BM11: =J11-AZ11 -> 0 | BN11: =K11-BA11 -> 0 | BO11: =L11-BB11 -> 0 | BP11: =M11-BC11 -> 0 | ... BR11: =O11-BE11 -> -0.76641862 | BV11: DPS (cps) | BW11: =FY!G163 -> 0 | BX11: =FY!H163 -> 12 | BY11: =FY!I163 -> 5.25 | BZ11: =FY!J163 -> 0 | CA11: =FY!K163 -> 0 | CB11: =FY!L163 -> 0 | CD11: =BZ11 -> 0 | CE11: 0 | CF11: na | CG11: =CA11 -> 0 | CH11: na | CI11: =CM11 -> 0 | CJ11: na | CM11: =DC11 -> 0 | CO11: SKC_NZ | CP11: Dividend per share | CQ11: consensus.vaactuals | CR11: =_xll.VAData($AD11,CR$4,$AE11,$AF11) -> 0 | CS11: =_xll.VAData($AD11,CS$4,$AE11,$AF11) -> 12 | CT11: =_xll.VAData($AD11,CT$4,$AE11,$AF11) -> 5.25 | CU11: =_xll.VAData($AD11,CU$4,$AE11,$AF11) -> 0 | CV11: =_xll.VAData($AD11,CV$4,$AE11,$AF11) -> 0 | CW11: =_xll.VAData($AD11,CW$4,$AE11,$AF11) -> 0 | CY11: 0 | CZ11: 12 | DA11: 5.25 | DB11: 0 | DC11: 0 | DD11: 1.2740925 | DF11: =BW11-CY11 -> 0 | DG11: =BX11-CZ11 -> 0 | DH11: =BY11-DA11 -> 0 | DI11: =BZ11-DB11 -> 0 | DJ11: =CA11-DC11 -> 0 | DK11: =CB11-DD11 -> -1.2740925
C13: P&L - Reported | BV13: P&L - Reported
C14: Revenue | F14: =HY!O356 -> 462.6 | G14: =HY!P356 -> 463.6 | H14: =HY!Q356 -> 445.2 | I14: =HY!R356 -> 483.3 | J14: =HY!S356 -> 422 | K14: =HY!T356 -> 403.2 | L14: =HY!U356 -> 411.7 | M14: =HY!V356 -> 467.2 | ... O14: =HY!X356 -> 421.369 | Q14: =J14 -> 422 | S14: =R14/Q14-1 -> -1 | T14: =L14 -> 411.7 | U14: =$R14/T14-1 -> -1 | V14: =AB14 -> 391.40876 | W14: =$R14/V14-1 -> -1 | AB14: =BB14 -> 391.40876 | AD14: SKC_NZ | AE14: Total revenue | AF14: consensus.vaactuals | AG14: =_xll.VAData($AD14,AG$4,$AE14,$AF14) -> 289.8 | AH14: =_xll.VAData($AD14,AH$4,$AE14,$AF14) -> 349.2 | AI14: =_xll.VAData($AD14,AI$4,$AE14,$AF14) -> 462.6 | AJ14: =_xll.VAData($AD14,AJ$4,$AE14,$AF14) -> 463.6 | AK14: =_xll.VAData($AD14,AK$4,$AE14,$AF14) -> 445.2 | AL14: =_xll.VAData($AD14,AL$4,$AE14,$AF14) -> 483.3 | AM14: =_xll.VAData($AD14,AM$4,$AE14,$AF14) -> 422 | AN14: =_xll.VAData($AD14,AN$4,$AE14,$AF14) -> 403.2 | ... AR14: =_xll.VAData($AD14,AR$4,$AE14,$AF14) -> 421.369 | AT14: 289.8 | AU14: 349.2 | AV14: 462.6 | AW14: 463.6 | AX14: 445.2 | AY14: 483.3 | AZ14: 422 | BA14: 403.2 | BB14: 391.40876 | BC14: 404.70455 | BD14: 426.30925 | BE14: 441.15811 | BI14: =F14-AV14 -> 0 | BJ14: =G14-AW14 -> 0 | BK14: =H14-AX14 -> 0 | BL14: =I14-AY14 -> 0 | BM14: =J14-AZ14 -> 0 | BN14: =K14-BA14 -> 0 | BO14: =L14-BB14 -> 20.29124 | BP14: =M14-BC14 -> 62.49545 | ... BR14: =O14-BE14 -> -19.789107 | BV14: Revenue | CD14: =BZ14 -> 0 | CF14: =CE14/CD14-1 -> #DIV/0! | CG14: =CA14 -> 0 | CH14: =$CE14/CG14-1 -> #DIV/0! | CI14: =CM14 -> 831.03512 | CJ14: =$CE14/CI14-1 -> -1 | CM14: =DC14 -> 831.03512 | CO14: SKC_NZ | CP14: Total revenue | CQ14: consensus.vaactuals | CR14: =_xll.VAData($AD14,CR$4,$AE14,$AF14) -> 639 | CS14: =_xll.VAData($AD14,CS$4,$AE14,$AF14) -> 926.2 | CT14: =_xll.VAData($AD14,CT$4,$AE14,$AF14) -> 928.5 | CU14: =_xll.VAData($AD14,CU$4,$AE14,$AF14) -> 825.2 | CV14: =_xll.VAData($AD14,CV$4,$AE14,$AF14) -> 878.9 | CW14: =_xll.VAData($AD14,CW$4,$AE14,$AF14) -> 824.16048 | CY14: 639 | CZ14: 926.2 | DA14: 928.5 | DB14: 825.2 | DC14: 831.03512 | DD14: 865.96229 | DG14: =BX14-CZ14 -> -926.2 | DH14: =BY14-DA14 -> -928.5 | DI14: =BZ14-DB14 -> -825.2 | DJ14: =CA14-DC14 -> -831.03512 | DK14: =CB14-DD14 -> -865.96229
C15: EBITDA | F15: =HY!#REF! -> #REF! | G15: =HY!#REF! -> #REF! | H15: =HY!#REF! -> #REF! | I15: =HY!#REF! -> #REF! | J15: =HY!#REF! -> #REF! | K15: =HY!#REF! -> #REF! | L15: =HY!#REF! -> #REF! | M15: =HY!#REF! -> #REF! | ... O15: =HY!#REF! -> #REF! | Q15: =J15 -> #REF! | S15: =R15/Q15-1 -> #REF! | T15: =L15 -> #REF! | U15: =$R15/T15-1 -> #REF! | V15: =AB15 -> 48.042084 | W15: =$R15/V15-1 -> -1 | AB15: =BB15 -> 48.042084 | AD15: SKC_NZ | AE15: EBITDA | AF15: consensus.vaactuals | AG15: =_xll.VAData($AD15,AG$4,$AE15,$AF15) -> 20.4 | AH15: =_xll.VAData($AD15,AH$4,$AE15,$AF15) -> 76.5 | AI15: =_xll.VAData($AD15,AI$4,$AE15,$AF15) -> 106.34 | AJ15: =_xll.VAData($AD15,AJ$4,$AE15,$AF15) -> 59.559 | AK15: =_xll.VAData($AD15,AK$4,$AE15,$AF15) -> 100.99 | AL15: =_xll.VAData($AD15,AL$4,$AE15,$AF15) -> 37.167 | AM15: =_xll.VAData($AD15,AM$4,$AE15,$AF15) -> 113.084 | AN15: =_xll.VAData($AD15,AN$4,$AE15,$AF15) -> 103.011 | ... AR15: =_xll.VAData($AD15,AR$4,$AE15,$AF15) -> 84.050503 | AT15: 20.4 | AU15: 76.5 | AV15: 106.34 | AW15: 59.559 | AX15: 100.99 | AY15: 37.167 | AZ15: 113.084 | BA15: 103.011 | BB15: 48.042084 | BC15: 99.040578 | BD15: 103.68748 | BE15: 118.45959 | BI15: =F15-AV15 -> #REF! | BJ15: =G15-AW15 -> #REF! | BK15: =H15-AX15 -> #REF! | BL15: =I15-AY15 -> #REF! | BM15: =J15-AZ15 -> #REF! | BN15: =K15-BA15 -> #REF! | BO15: =L15-BB15 -> #REF! | BP15: =M15-BC15 -> #REF! | ... BR15: =O15-BE15 -> #REF! | BV15: EBITDA | CD15: =BZ15 -> 0 | CF15: =CE15/CD15-1 -> #DIV/0! | CG15: =CA15 -> 0 | CH15: =$CE15/CG15-1 -> #DIV/0! | CI15: =CM15 -> 149.96293 | CJ15: =$CE15/CI15-1 -> -1 | CM15: =DC15 -> 149.96293 | CO15: SKC_NZ | CP15: EBITDA | CQ15: consensus.vaactuals | CR15: =_xll.VAData($AD15,CR$4,$AE15,$AF15) -> 96.9 | CS15: =_xll.VAData($AD15,CS$4,$AE15,$AF15) -> 165.899 | CT15: =_xll.VAData($AD15,CT$4,$AE15,$AF15) -> 138.157 | CU15: =_xll.VAData($AD15,CU$4,$AE15,$AF15) -> 216.095 | CV15: =_xll.VAData($AD15,CV$4,$AE15,$AF15) -> 120.474 | CW15: =_xll.VAData($AD15,CW$4,$AE15,$AF15) -> 158.87317 | CY15: 96.9 | CZ15: 165.899 | DA15: 138.157 | DB15: 216.095 | DC15: 149.96293 | DD15: 174.81695 | DG15: =BX15-CZ15 -> -165.899 | DH15: =BY15-DA15 -> -138.157 | DI15: =BZ15-DB15 -> -216.095 | DJ15: =CA15-DC15 -> -149.96293 | DK15: =CB15-DD15 -> -174.81695
C16: EBIT | F16: =HY!#REF! -> #REF! | G16: =HY!#REF! -> #REF! | H16: =HY!#REF! -> #REF! | I16: =HY!#REF! -> #REF! | J16: =HY!#REF! -> #REF! | K16: =HY!#REF! -> #REF! | L16: =HY!#REF! -> #REF! | M16: =HY!#REF! -> #REF! | ... O16: =HY!#REF! -> #REF! | Q16: =J16 -> #REF! | S16: =R16/Q16-1 -> #REF! | T16: =L16 -> #REF! | U16: =$R16/T16-1 -> #REF! | V16: =AB16 -> -4.7813367 | W16: =$R16/V16-1 -> -1 | AB16: =BB16 -> -4.7813367 | AD16: SKC_NZ | AE16: Operating income/(loss) | AF16: consensus.vaactuals | AG16: =_xll.VAData($AD16,AG$4,$AE16,$AF16) -> -27.4 | AH16: =_xll.VAData($AD16,AH$4,$AE16,$AF16) -> 29.68 | AI16: =_xll.VAData($AD16,AI$4,$AE16,$AF16) -> 60.9 | AJ16: =_xll.VAData($AD16,AJ$4,$AE16,$AF16) -> 14.351 | AK16: =_xll.VAData($AD16,AK$4,$AE16,$AF16) -> 56.7 | AL16: =_xll.VAData($AD16,AL$4,$AE16,$AF16) -> -10.5 | AM16: =_xll.VAData($AD16,AM$4,$AE16,$AF16) -> 67.8 | AN16: =_xll.VAData($AD16,AN$4,$AE16,$AF16) -> 54.1 | ... AR16: =_xll.VAData($AD16,AR$4,$AE16,$AF16) -> 31.32371 | AT16: -27.4 | AU16: 29.68 | AV16: 60.9 | AW16: 14.351 | AX16: 56.7 | AY16: -10.5 | AZ16: 67.8 | BA16: 54.1 | BB16: -4.7813367 | BC16: 46.128097 | BD16: 50.846733 | BE16: 65.959904 | BI16: =F16-AV16 -> #REF! | BJ16: =G16-AW16 -> #REF! | BK16: =H16-AX16 -> #REF! | BL16: =I16-AY16 -> #REF! | BM16: =J16-AZ16 -> #REF! | BN16: =K16-BA16 -> #REF! | BO16: =L16-BB16 -> #REF! | BP16: =M16-BC16 -> #REF! | ... BR16: =O16-BE16 -> #REF! | BV16: EBIT | CD16: =BZ16 -> 0 | CF16: =CE16/CD16-1 -> #DIV/0! | CG16: =CA16 -> 0 | CH16: =$CE16/CG16-1 -> #DIV/0! | CI16: =CM16 -> 43.313477 | CJ16: =$CE16/CI16-1 -> -1 | CM16: =DC16 -> 43.313477 | CO16: SKC_NZ | CP16: Operating income/(loss) | CQ16: consensus.vaactuals | CR16: =_xll.VAData($AD16,CR$4,$AE16,$AF16) -> 2.3 | CS16: =_xll.VAData($AD16,CS$4,$AE16,$AF16) -> 75.2 | CT16: =_xll.VAData($AD16,CT$4,$AE16,$AF16) -> 46.2 | CU16: =_xll.VAData($AD16,CU$4,$AE16,$AF16) -> 121.9 | CV16: =_xll.VAData($AD16,CV$4,$AE16,$AF16) -> 15.4 | CW16: =_xll.VAData($AD16,CW$4,$AE16,$AF16) -> 41.524461 | CY16: 2.3 | CZ16: 75.2 | DA16: 46.2 | DB16: 121.9 | DC16: 43.313477 | DD16: 58.423408 | DG16: =BX16-CZ16 -> -75.2 | DH16: =BY16-DA16 -> -46.2 | DI16: =BZ16-DB16 -> -121.9 | DJ16: =CA16-DC16 -> -43.313477 | DK16: =CB16-DD16 -> -58.423408
C17: NPAT | F17: =HY!O368 -> 22.8 | G17: =HY!P368 -> -14.825 | H17: =HY!Q368 -> 22.5 | I17: =HY!R368 -> -165.8 | J17: =HY!S368 -> 6.1 | K17: =HY!T368 -> 23.1 | L17: =HY!U368 -> 12.1 | M17: =HY!V368 -> 6.1 | ... O17: =HY!X368 -> 11.030314 | Q17: =J17 -> 6.1 | S17: =R17/Q17-1 -> -1 | T17: =L17 -> 12.1 | U17: =$R17/T17-1 -> -1 | V17: =AB17 -> -8.8603279 | W17: =$R17/V17-1 -> -1 | AB17: =BB17 -> -8.8603279 | AD17: SKC_NZ | AE17: Net income/(loss) | AF17: consensus.vaactuals | AG17: =_xll.VAData($AD17,AG$4,$AE17,$AF17) -> -33.7 | AH17: =_xll.VAData($AD17,AH$4,$AE17,$AF17) -> 0.1 | AI17: =_xll.VAData($AD17,AI$4,$AE17,$AF17) -> 22.8 | AJ17: =_xll.VAData($AD17,AJ$4,$AE17,$AF17) -> -14.8 | AK17: =_xll.VAData($AD17,AK$4,$AE17,$AF17) -> 22.5 | AL17: =_xll.VAData($AD17,AL$4,$AE17,$AF17) -> -165.8 | AM17: =_xll.VAData($AD17,AM$4,$AE17,$AF17) -> 6.1110154 | AN17: =_xll.VAData($AD17,AN$4,$AE17,$AF17) -> 23.1 | ... AR17: =_xll.VAData($AD17,AR$4,$AE17,$AF17) -> 4.2131086 | AT17: -33.7 | AU17: 0.1 | AV17: 22.8 | AW17: -14.8 | AX17: 22.5 | AY17: -165.8 | AZ17: 6.1 | BA17: 23.1 | BB17: -8.8603279 | BC17: 3.8827136 | BD17: 17.022978 | BE17: 23.209881 | BI17: =F17-AV17 -> 0 | BJ17: =G17-AW17 -> -0.025 | BK17: =H17-AX17 -> 0 | BL17: =I17-AY17 -> 0 | BM17: =J17-AZ17 -> 0 | BN17: =K17-BA17 -> 0 | BO17: =L17-BB17 -> 20.960328 | BP17: =M17-BC17 -> 2.2172864 | ... BR17: =O17-BE17 -> -12.179566 | BV17: NPAT | CD17: =BZ17 -> 0 | CF17: =CE17/CD17-1 -> #DIV/0! | CG17: =CA17 -> 0 | CH17: =$CE17/CG17-1 -> #DIV/0! | CI17: =CM17 -> 7.5803362 | CJ17: =$CE17/CI17-1 -> -1 | CM17: =DC17 -> 7.5803362 | CO17: SKC_NZ | CP17: Net income/(loss) | CQ17: consensus.vaactuals | CR17: =_xll.VAData($AD17,CR$4,$AE17,$AF17) -> -33.595 | CS17: =_xll.VAData($AD17,CS$4,$AE17,$AF17) -> 8 | CT17: =_xll.VAData($AD17,CT$4,$AE17,$AF17) -> -143.3 | CU17: =_xll.VAData($AD17,CU$4,$AE17,$AF17) -> 29.2 | CV17: =_xll.VAData($AD17,CV$4,$AE17,$AF17) -> 18.2 | CW17: =_xll.VAData($AD17,CW$4,$AE17,$AF17) -> 38.052519 | CY17: -33.595 | CZ17: 8 | DA17: -143.3 | DB17: 29.2 | DC17: 7.5803362 | DD17: 25.979537 | DG17: =BX17-CZ17 -> -8 | DH17: =BY17-DA17 -> 143.3 | DI17: =BZ17-DB17 -> -29.2 | DJ17: =CA17-DC17 -> -7.5803362 | DK17: =CB17-DD17 -> -25.979537
