Workbook

Sheet NAV
B2: ARISTOCRAT LEISURE LTD (ALL.ASX)
B3: MODEL NAVIGATION SHEET
B6: ANALYST CONTACTS | L6: COMPANY CONTACTS
B7: James Fuller, CFA | G7: Sam Bradshaw | L7: Trevor Croker (CEO)
B8: Associate | G8: Analyst
B9: Gaming & Leisure | G9: Research
B10: +61 3 9235 9748 | G10: +61 3 9235 9706 | L10: Linda Assatoury (IR)
B11: james.fuller@eap.com.au | G11: sbradshaw@eap.com.au
B14: RECOMMENDATION & VALUATION | G14: KEY MULTIPLES & RATIOS | L14: KEY
B15: Recommendation: | E15: Positive | G15: FY23e PE | J15: 17.949533 | L15: Calculations | O15: Black
B16: Target Price: | E16: 42.8 | G16: FY23e EV/EBITDA | J16: 11.072123 | L16: Actuals | O16: Red
B17: Current price: | E17: 33.73 | G17: FY23e Dividend yield | J17: 0.016777608 | L17: Estimates | O17: Blue
B18: TSR: | E18: 0.28431663 | G18: FY23e Net debt / EBITDA | J18: 0.64794574 | L18: Check | O18: Green
B21: ERROR CHECKS | G21: EARNINGS CHANGES | L21: GENERAL
B22: Model | E22: 0 | G22: Group | J22: 0 | L22: Reporting currency | O22: A$
B23: Segments | E23: 0 | G23: Americas | J23: 0 | L23: Valuation currency | O23: A$
B24: Master | E24: =IF( SUM( E22:E23) < 2, 0, 1) -> 0 | G24: ANZ | J24: 0 | L24: Standard monetary unit | O24: A$m
G25: Digital | J25: 0 | L25: Financial year end | O25: September
G26: Intl Class III | J26: 0 | L26: Reporting frequency | O26: Semi-annual
G27: iGaming | J27: 0 | L27: Rounding tollerance (A$m) | O27: 1

Sheet NAV 2
B2: =$E$7 -> Logitech Intl S.A.
B3: Model navigation
B6: COMPANY DETAILS | G6: ANALYST CONTACTS | L6: COMPANY CONTACTS
B7: Name | E7: Logitech Intl S.A. | G7: James Fuller, CFA | L7: Bracken Darrell, President and CEO
B8: Ticker | E8: LOGI | G8: +44 78 6933 6734 | L8: Nate Olmstead, CFO
B9: Exchange | E9: NASDAQ-GS | G9: james_ fuller@outlook.com | L9: Nate Melihercik, IR
B10: Sector | E10: Technology
B11: Industry | E11: Hardware, Storage and Peripherals
B14: RECOMMENDATION & VALUATION | G14: KEY MULTIPLES & RATIOS (FY24E) | L14: LEGEND
B15: Recommendation | E15: Buy | G15: P/E | J15: 14.544206 | L15: Calculations | O15: Black
B16: IRR | E16: 0.13966356 | G16: EV/EBIT (non-GAAP) | J16: 12.271032 | L16: Actuals | O16: Red
B17: TSR | E17: 0.22992113 | G17: Dividend yield | J17: 0.017188975 | L17: Estimates | O17: Blue
B18: Share price | E18: 66 | G18: Levered FCF/sh yield (excl. SBC) | J18: 0.063611937 | L18: Check | O18: Pink
B19: Valuation | E19: 80.040322 | L19: Offsheet reference | O19: Green
L20: Carry forward | O20: Grey
B23: ERROR CHECKS | G23: GENERAL | L23: PAGES
B24: Valn | E24: 0 | G24: Reporting currency | J24: US$ | L24: Summary
B25: Model | E25: 0 | G25: Standard monetary unit | J25: US$m | L25: Valn
B26: FY23 | E26: 0 | G26: Financial year end | J26: March | L26: Model
B27: Scenario | E27: 0 | G27: Reporting frequency | J27: Quarterly | L27: FY23
B28: Master | E28: =IF( SUM( E24:E27) = 0, 0, 1) -> 0 | G28: ="Rounding tolerance " & "(" & $J$25 & ")" -> Rounding tolerance (US$m) | J28: 1 | L28: Scenario
L29: Comps

Sheet BM
B1: =D8 -> TAH-ASX
A2: Industrial ResearchWise Sheet | R2: BlueMatrix formulas
C3: Company static items | E3: =+E114 -> FY2022A | F3: =+F114 -> FY2023A | G3: =+G114 -> FY2024F | H3: =+H114 -> FY2025F | I3: =+I114 -> FY2026F | J3: =+J114 -> FY2027F | K3: =+K114 -> FY2028F | L3: =+L114 -> FY2029F | ... Q3: =+Q114 -> FY2034F | S3: 2022 | T3: =S3+1 -> 2023 | U3: =T3+1 -> 2024 | V3: =U3+1 -> 2025 | W3: =V3+1 -> 2026 | X3: =W3+1 -> 2027 | Y3: =X3+1 -> 2028 | Z3: =Y3+1 -> 2029 | AA3: =Z3+1 -> 2030 | ... AE3: =AD3+1 -> 2034
A4: @BEGINSTATIC | D4: @ENDSTATIC
A5: @INSTTYPE | C5: Instrument type | D5: EQ
A6: @CTYPE | C6: Instrument code type | D6: @BB
A7: @VERSION | C7: Version information (Do not change) | D7: 1
A8: @CODE | C8: Ticker | D8: TAH-ASX
A9: @MULT | C9: Multiplier | D9: 1000000
A10: @RCURR | C10: Reporting Currency | D10: $
A11: @ANALYST | C11: Lead analyst | D11: Sam Bradshaw
A13: @TARGET | B13: PRICE_TARGET | C13: Valuation | D13: =HY!$D$740 -> 0.89457633 | R13: =_xll.BLUEMATRIX2("/servlet/excelData",$D13,$B$1,$B13) -> #
A14: @REC | B14: REC | C14: Recommendation | D14: Neutral | R14: =_xll.BLUEMATRIX2("/servlet/excelData",$D14,$B$1,$B14) -> #
A15: @SHARE_OUT | B15: SHARE_OUT | C15: Shares outstanding | D15: =HY!D744 -> 2292.6 | R15: =_xll.BLUEMATRIX2("/servlet/excelData",$D15,$B$1,$B15) -> #
A16: @FLOATPER | B16: free_float | C16: Free Float % | D16: 100 | R16: =_xll.BLUEMATRIX2("/servlet/excelData",$D16,$B$1,$B16) -> #
B17: PRICE | C17: Current Share Price | D17: =HY!D749 -> 0.91 | R17: =_xll.BLUEMATRIX2("/servlet/excelData",$D17,$B$1,$B17) -> #
C18: Historic Share Price (Closing) | E18: 1.065 | F18: 1.11 | G18: 0.7 | H18: 0.715 | I18: =$D$17 -> 0.91 | J18: =$D$17 -> 0.91 | K18: =$D$17 -> 0.91 | L18: =$D$17 -> 0.91 | M18: =$D$17 -> 0.91 | N18: =$D$17 -> 0.91 | O18: =$D$17 -> 0.91 | P18: =$D$17 -> 0.91 | Q18: =$D$17 -> 0.91
C20: TSR
B21: upside_valuation | C21: Upside to valuation | D21: =(D13/D17-1)*100 -> -1.6949089 | R21: =_xll.BLUEMATRIX2("/servlet/excelData",$D21,$B$1,$B21) -> #
B22: div_yield | C22: Dividend yield | D22: =H303*100 -> 2.7972028 | R22: =_xll.BLUEMATRIX2("/servlet/excelData",$D22,$B$1,$B22) -> #
B23: exp_total_return | C23: Expected total SH return | D23: =D21+D22 -> 1.1022939 | R23: =_xll.BLUEMATRIX2("/servlet/excelData",$D23,$B$1,$B23) -> #
C25: Trading Data test
B26: 12_month_high | C26: 12 month high
B27: 12_month_low | C27: 12 month low
B28: MARKET_CAP | C28: Market cap | D28: =D17*D15 -> 2086.266 | R28: =_xll.BLUEMATRIX2("/servlet/excelData",$D28,$B$1,$B28) -> #
B29: free_float | C29: Free Float
B30: 12_month_return | C30: 12 month return (historical)
A31: @pricing_date
C34: Blended Valuation
A35: @DCF_VAL | B35: DCF_VAL | C35: Valuation - DCF | D35: =HY!$D$740 -> 0.89457633 | R35: =_xll.BLUEMATRIX2("/servlet/excelData",$D35,$B$1,$B35) -> #
A36: @CAPPER_VAL | B36: CAPPER_VAL | C36: Valuation - Capitalisation of Earnings | R36: =_xll.BLUEMATRIX2("/servlet/excelData",$D36,$B$1,$B36) -> #
A37: @PER_VAL | B37: PER_VAL | C37: Valuation - PER | R37: =_xll.BLUEMATRIX2("/servlet/excelData",$D37,$B$1,$B37) -> #
A38: @SOTP_VAL | B38: SOTP_VAL | C38: Valuation - SOTP | R38: =_xll.BLUEMATRIX2("/servlet/excelData",$D38,$B$1,$B38) -> #
A39: @BLEND_VAL | B39: PRICE_TARGET | C39: Valuation - Blended | R39: =_xll.BLUEMATRIX2("/servlet/excelData",$D39,$B$1,$B39) -> #
A40: @DCF_WT | B40: DCF_WT | C40: DCF Weightage | D40: 100 | R40: =_xll.BLUEMATRIX2("/servlet/excelData",$D40,$B$1,$B40) -> #
A41: @CAPPER_WT | B41: CAPPER_WT | C41: Capitalisation of Earnings Weightage | R41: =_xll.BLUEMATRIX2("/servlet/excelData",$D41,$B$1,$B41) -> #
A42: @PER_WT | B42: PER_WT | C42: PER Weightage | R42: =_xll.BLUEMATRIX2("/servlet/excelData",$D42,$B$1,$B42) -> #
A43: @SOTP_WT | B43: SOTP_WT | C43: SOTP Weightage | R43: =_xll.BLUEMATRIX2("/servlet/excelData",$D43,$B$1,$B43) -> #
C45: Divisional Summary
A46: @SEG1_NAME | C46: Name of Segment 1 | D46: Wagering & Media | R46: =_xll.BLUEMATRIX2("/servlet/excelData",$D46,$B$1,$B46) -> #
...

Sheet I

Sheet HY
C1: Retail Rev (no impact from margins) | R1: =R117+Q117 -> 821.8 | T1: =T117+S117 -> 965.7 | U1: 1H margin | V1: =V117+U117 -> 981.2 | X1: =X117+W117 -> 1015.2483 | Z1: =Z117+Y117 -> 1001.4025 | AB1: =AB117+AA117 -> 988.67399 | AD1: =AD117+AC117 -> 998.56073 | AF1: =AF117+AE117 -> 988.57513
T2: =T1-R1 -> 143.9 | U2: 22m rev | V2: =V1-T1 -> 15.5 | X2: =X1-V1 -> 34.048269 | Z2: =Z1-X1 -> -13.845724 | AB2: =AB1-Z1 -> -12.728552 | AD2: =AD1-AB1 -> 9.8867399 | AF2: =AF1-AD1 -> -9.9856073
C3: W&M VC | R3: =R279+Q279 -> 758.2 | T3: =T279+S279 -> 915.9 | V3: =V279+U279 -> 953.2 | X3: =X279+W279 -> 1001.5534 | Z3: =Z279+Y279 -> 1008.6638 | AB3: =AB279+AA279 -> 1017.4923 | AD3: =AD279+AC279 -> 1040.0833 | AF3: =AF279+AE279 -> 1055.3853
T4: =T3-R3 -> 157.7 | U4: 9m VC | V4: =V3-T3 -> 37.3 | X4: =X3-V3 -> 48.353435 | Z4: =Z3-X3 -> 7.110363 | AB4: =AB3-Z3 -> 8.8284798 | AD4: =AD3-AB3 -> 22.591004 | AF4: =AF3-AD3 -> 15.301999
C5: W&M EBITDA | R5: =R292+Q292 -> 251.2 | T5: =T292+S292 -> 329.1 | V5: =V292+U292 -> 361.8 | X5: =X292+W292 -> 390.48893 | Z5: =Z292+Y292 -> 379.26736 | AB5: =AB292+AA292 -> 369.21395 | AD5: =AD292+AC292 -> 372.3566 | AF5: =AF292+AE292 -> 374.30407
T6: =T5-R5 -> 77.9 | U6: 9m VC | V6: =V5-T5 -> 32.7 | X6: =X5-V5 -> 28.688935 | Z6: =Z5-X5 -> -11.221572 | AB6: =AB5-Z5 -> -10.053413 | AD6: =AD5-AB5 -> 3.1426539 | AF6: =AF5-AD5 -> 1.9474653
B8: Checks | C8: =SUM(M8:AL8) -> 0 | E8: =E710 -> 0 | F8: =F710 -> 0 | G8: =G710 -> 0 | H8: =H710 -> 0 | I8: =I710 -> 0 | J8: =J710 -> 0 | K8: =K710 -> 0 | L8: =L710 -> 73.7 | ... AN8: =AN710 -> 0
A9: X | B9: Valuation | C9: =D740 -> 0.89457633 | D9: VAL | E9: =E14&E16 -> 1H18A | F9: =F14&F16 -> 2H18A | G9: =G14&G16 -> 1H19A | H9: =H14&H16 -> 2H19A | I9: =I14&I16 -> 1H20A | J9: =J14&J16 -> 2H20A | K9: =K14&K16 -> 1H21A | L9: =L14&L16 -> 2H21A | ... AN9: =AN14&AN16 -> 2H35E
B10: Period End | E10: 43100 | F10: =EOMONTH(E10,6) -> 43281 | G10: =EOMONTH(F10,6) -> 43465 | H10: =EOMONTH(G10,6) -> 43646 | I10: =EOMONTH(H10,6) -> 43830 | J10: =EOMONTH(I10,6) -> 44012 | K10: =EOMONTH(J10,6) -> 44196 | L10: =EOMONTH(K10,6) -> 44377 | M10: =EOMONTH(L10,6) -> 44561 | ... AN10: =EOMONTH(AM10,6) -> 49490
B12: Half | E12: {=_xlfn.IFS(AND(MONTH(E$10)>=7,MONTH(E$10)<=12),"1H",AND(MONTH(E$10)>=1,MONTH(E$10)<=6),"2H")} -> 1H | F12: {=_xlfn.IFS(AND(MONTH(F$10)>=7,MONTH(F$10)<=12),"1H",AND(MONTH(F$10)>=1,MONTH(F$10)<=6),"2H")} -> 2H | G12: {=_xlfn.IFS(AND(MONTH(G$10)>=7,MONTH(G$10)<=12),"1H",AND(MONTH(G$10)>=1,MONTH(G$10)<=6),"2H")} -> 1H | H12: {=_xlfn.IFS(AND(MONTH(H$10)>=7,MONTH(H$10)<=12),"1H",AND(MONTH(H$10)>=1,MONTH(H$10)<=6),"2H")} -> 2H | I12: {=_xlfn.IFS(AND(MONTH(I$10)>=7,MONTH(I$10)<=12),"1H",AND(MONTH(I$10)>=1,MONTH(I$10)<=6),"2H")} -> 1H | J12: {=_xlfn.IFS(AND(MONTH(J$10)>=7,MONTH(J$10)<=12),"1H",AND(MONTH(J$10)>=1,MONTH(J$10)<=6),"2H")} -> 2H | K12: {=_xlfn.IFS(AND(MONTH(K$10)>=7,MONTH(K$10)<=12),"1H",AND(MONTH(K$10)>=1,MONTH(K$10)<=6),"2H")} -> 1H | L12: {=_xlfn.IFS(AND(MONTH(L$10)>=7,MONTH(L$10)<=12),"1H",AND(MONTH(L$10)>=1,MONTH(L$10)<=6),"2H")} -> 2H | ... AN12: {=_xlfn.IFS(AND(MONTH(AN$10)>=7,MONTH(AN$10)<=12),"1H",AND(MONTH(AN$10)>=1,MONTH(AN$10)<=6),"2H")} -> 2H
B13: FY | E13: =IF(MONTH(E10)>6,RIGHT(YEAR(E10),2)+1,RIGHT(YEAR(E10),2)) -> 18 | F13: =IF(MONTH(F10)>6,RIGHT(YEAR(F10),2)+1,RIGHT(YEAR(F10),2)) -> 18 | G13: =IF(MONTH(G10)>6,RIGHT(YEAR(G10),2)+1,RIGHT(YEAR(G10),2)) -> 19 | H13: =IF(MONTH(H10)>6,RIGHT(YEAR(H10),2)+1,RIGHT(YEAR(H10),2)) -> 19 | I13: =IF(MONTH(I10)>6,RIGHT(YEAR(I10),2)+1,RIGHT(YEAR(I10),2)) -> 20 | J13: =IF(MONTH(J10)>6,RIGHT(YEAR(J10),2)+1,RIGHT(YEAR(J10),2)) -> 20 | K13: =IF(MONTH(K10)>6,RIGHT(YEAR(K10),2)+1,RIGHT(YEAR(K10),2)) -> 21 | L13: =IF(MONTH(L10)>6,RIGHT(YEAR(L10),2)+1,RIGHT(YEAR(L10),2)) -> 21 | ... AN13: =IF(MONTH(AN10)>6,RIGHT(YEAR(AN10),2)+1,RIGHT(YEAR(AN10),2)) -> 35
B14: FY Year | E14: =E$12&TEXT(E$13,"00") -> 1H18 | F14: =F$12&TEXT(F$13,"00") -> 2H18 | G14: =G$12&TEXT(G$13,"00") -> 1H19 | H14: =H$12&TEXT(H$13,"00") -> 2H19 | I14: =I$12&TEXT(I$13,"00") -> 1H20 | J14: =J$12&TEXT(J$13,"00") -> 2H20 | K14: =K$12&TEXT(K$13,"00") -> 1H21 | L14: =L$12&TEXT(L$13,"00") -> 2H21 | ... AN14: =AN$12&TEXT(AN$13,"00") -> 2H35
B15: Financial Year | E15: {=_xlfn.IFS(MONTH(E$10)=12,YEAR(E$10)+1,MONTH(E$10)=6,YEAR(E$10))} -> 2018 | F15: {=_xlfn.IFS(MONTH(F$10)=12,YEAR(F$10)+1,MONTH(F$10)=6,YEAR(F$10))} -> 2018 | G15: {=_xlfn.IFS(MONTH(G$10)=12,YEAR(G$10)+1,MONTH(G$10)=6,YEAR(G$10))} -> 2019 | H15: {=_xlfn.IFS(MONTH(H$10)=12,YEAR(H$10)+1,MONTH(H$10)=6,YEAR(H$10))} -> 2019 | I15: {=_xlfn.IFS(MONTH(I$10)=12,YEAR(I$10)+1,MONTH(I$10)=6,YEAR(I$10))} -> 2020 | J15: {=_xlfn.IFS(MONTH(J$10)=12,YEAR(J$10)+1,MONTH(J$10)=6,YEAR(J$10))} -> 2020 | K15: {=_xlfn.IFS(MONTH(K$10)=12,YEAR(K$10)+1,MONTH(K$10)=6,YEAR(K$10))} -> 2021 | L15: {=_xlfn.IFS(MONTH(L$10)=12,YEAR(L$10)+1,MONTH(L$10)=6,YEAR(L$10))} -> 2021 | ... AN15: {=_xlfn.IFS(MONTH(AN$10)=12,YEAR(AN$10)+1,MONTH(AN$10)=6,YEAR(AN$10))} -> 2035
B16: Actual/Estimate | E16: =IF(ISNUMBER(E$260),"A","E") -> A | F16: =IF(ISNUMBER(F$260),"A","E") -> A | G16: =IF(ISNUMBER(G$260),"A","E") -> A | H16: =IF(ISNUMBER(H$260),"A","E") -> A | I16: =IF(ISNUMBER(I$260),"A","E") -> A | J16: =IF(ISNUMBER(J$260),"A","E") -> A | K16: =IF(ISNUMBER(K$260),"A","E") -> A | L16: =IF(ISNUMBER(L$260),"A","E") -> A | M16: =IF(ISNUMBER(M$217),"A","E") -> A | N16: =IF(ISNUMBER(N$217),"A","E") -> A | O16: =IF(ISNUMBER(O$217),"A","E") -> A | P16: =IF(ISNUMBER(P$217),"A","E") -> A | Q16: =IF(ISNUMBER(Q$217),"A","E") -> A | R16: =IF(ISNUMBER(R$217),"A","E") -> A | S16: =IF(ISNUMBER(S$217),"A","E") -> A | T16: =IF(ISNUMBER(T$217),"A","E") -> A | ... AN16: =IF(ISNUMBER(AN$217),"A","E") -> E
B17: Days in period | E17: =E10-EOMONTH(E10,-6) -> 184 | F17: =F10-E10 -> 181 | G17: =G10-F10 -> 184 | H17: =H10-G10 -> 181 | I17: =I10-H10 -> 184 | J17: =J10-I10 -> 182 | K17: =K10-J10 -> 184 | L17: =L10-K10 -> 181 | M17: =M10-L10 -> 184 | ... AN17: =AN10-AM10 -> 181
A19: X | B19: GUIDANCE
B21: FY27 Guidance/Commentary
B22: Capex up to $160m
B23: D&A $225–235m
B24: Opex growth +3.0–3.5% on the FY26 $700.7m base
B25: Tax expense will continue to be impacted by non-deductible items of approximately $67m in FY27 in relation to Victorian Licence amortisation and discount unwind on annual licence payments
B26: Betmakers completion targeted during the 3Q of FY27
B27: Domestic wagering turnover growth broadly consistent with FY26, ex-FWC — i.e. ~FY26's underlying, which after stripping the FWC benefit is roughly +0.4–0.6% (FY26 reported +0.9%).
B28: ~$26m incremental EBITDA in FY27
B29: Mechanics: $140m terminal capex × 25% = $35m EBIT; +~$13m D&A = ~$48m run-rate; −$22m already in FY26. Hits both VC and opex lines
B30: It's a net number — already after the removed EBT rental income (~$20.7m in FY26) and loyalty/generosity reinvestment
B31: Victorian Licence +$12m EBITDA in FY26. no further step-up in FY27
B32: ~$5m of FWC A&P in the FY26 opex base. About half the tournament fell in FY27
... B54: PGI
A57: X | B57: WAGERING & MEDIA
B59: WAGERING
B61: Per Customer
B62: Active Users | C62: 000's | I62: 688 | J62: 715 | K62: 777 | L62: 784 | M62: 780 | N62: 783 | O62: 797 | P62: 805 | Q62: 786 | R62: 798 | S62: 801 | T62: 792 | U62: 766 | V62: 786
B63: Turnover | C63: A$ | I63: =I84/AVERAGE(I$62,G$62)*1000 -> 5255.814 | J63: =J84/AVERAGE(J$62,H$62)*1000 -> 5373.4266 | K63: =K84/AVERAGE(K$62,I$62)*1000 -> 7053.9249 | L63: =L84/AVERAGE(L$62,J$62)*1000 -> 5755.8372 | M63: =M84/AVERAGE(M$62,K$62)*1000 -> 6755.2987 | N63: =N84/AVERAGE(N$62,L$62)*1000 -> 5664.3267 | O63: =O84/AVERAGE(O$62,M$62)*1000 -> 6240.3297 | P63: =P84/AVERAGE(P$62,N$62)*1000 -> 5473.8035 | ... V63: =V84/AVERAGE(V$62,T$62)*1000 -> 5200.1267
B64: GGR | C64: A$ | M64: =M93/AVERAGE(M$62,K$62)*1000 -> 1148.4008 | N64: =N93/AVERAGE(N$62,L$62)*1000 -> 950.55903 | O64: =O93/AVERAGE(O$62,M$62)*1000 -> 1023.4141 | P64: =P93/AVERAGE(P$62,N$62)*1000 -> 897.70378 | Q64: =Q93/AVERAGE(Q$62,O$62)*1000 -> 986.28932 | R64: =R93/AVERAGE(R$62,P$62)*1000 -> 875.10767 | S64: =S93/AVERAGE(S$62,Q$62)*1000 -> 932.78261 | T64: =T93/AVERAGE(T$62,R$62)*1000 -> 856.26667 | ... V64: =V93/AVERAGE(V$62,T$62)*1000 -> 873.62129
B65: Promos | C65: A$ | M65: =M94/AVERAGE(M$62,K$62)*1000 -> -246.28131 | N65: =N94/AVERAGE(N$62,L$62)*1000 -> -185.01978 | O65: =O94/AVERAGE(O$62,M$62)*1000 -> -263.49017 | P65: =P94/AVERAGE(P$62,N$62)*1000 -> -213.95063 | Q65: =Q94/AVERAGE(Q$62,O$62)*1000 -> -262.47378 | R65: =R94/AVERAGE(R$62,P$62)*1000 -> -197.00412 | S65: =S94/AVERAGE(S$62,Q$62)*1000 -> -229.69502 | T65: =T94/AVERAGE(T$62,R$62)*1000 -> -198.02767 | ... V65: =V94/AVERAGE(V$62,T$62)*1000 -> -200.99772
B66: NGR | C66: A$ | M66: =M95/AVERAGE(M$62,K$62)*1000 -> 902.11946 | N66: =N95/AVERAGE(N$62,L$62)*1000 -> 765.53925 | O66: =O95/AVERAGE(O$62,M$62)*1000 -> 759.92391 | P66: =P95/AVERAGE(P$62,N$62)*1000 -> 683.75315 | Q66: =Q95/AVERAGE(Q$62,O$62)*1000 -> 723.81554 | R66: =R95/AVERAGE(R$62,P$62)*1000 -> 678.10356 | S66: =S95/AVERAGE(S$62,Q$62)*1000 -> 703.08759 | T66: =T95/AVERAGE(T$62,R$62)*1000 -> 658.23899 | ... V66: =V95/AVERAGE(V$62,T$62)*1000 -> 672.62357
B68: TURNOVER
B69: Racing | C69: A$m | M69: 6032.2 | N69: =11769.7-M69 -> 5737.5 | O69: 6500.8 | P69: =11946.5-O69 -> 5445.7 | Q69: 6120.1 | R69: =11361.2-Q69 -> 5241.1 | S69: 5798.3 | T69: =10903-S69 -> 5104.7 | U69: 5728.3 | V69: =10785-U69 -> 5056.7
B70: Sport | C70: A$m | M70: 947.3 | N70: =2124-M70 -> 1176.7 | O70: 1258.7 | P70: =2604.3-O70 -> 1345.6 | Q70: 1343.5 | R70: =2696.5-Q70 -> 1353 | S70: 1347.4 | T70: =2840-S70 -> 1492.6 | U70: 1440.2 | V70: =3076-U70 -> 1635.8
...

Sheet FY
B2: TAH | C2: 2022 | D2: =C2+1 -> 2023 | E2: =D2+1 -> 2024 | F2: =E2+1 -> 2025 | G2: =F2+1 -> 2026 | H2: =G2+1 -> 2027 | I2: =H2+1 -> 2028 | J2: =I2+1 -> 2029 | K2: =J2+1 -> 2030 | ... O2: =N2+1 -> 2034
C3: A | D3: A | E3: E | F3: E | G3: E | H3: E | I3: E | J3: E | K3: E | L3: E | M3: E | N3: E | O3: E
C4: =C2&C3 -> 2022A | D4: =D2&D3 -> 2023A | E4: =E2&E3 -> 2024E | F4: =F2&F3 -> 2025E | G4: =G2&G3 -> 2026E | H4: =H2&H3 -> 2027E | I4: =I2&I3 -> 2028E | J4: =J2&J3 -> 2029E | ... O4: =O2&O3 -> 2034E
C5: 44742 | D5: =EOMONTH(C5,12) -> 45107 | E5: =EOMONTH(D5,12) -> 45473 | F5: =EOMONTH(E5,12) -> 45838 | G5: =EOMONTH(F5,12) -> 46203 | H5: =EOMONTH(G5,12) -> 46568 | I5: =EOMONTH(H5,12) -> 46934 | J5: =EOMONTH(I5,12) -> 47299 | K5: =EOMONTH(J5,12) -> 47664 | ... O5: =EOMONTH(N5,12) -> 49125
A7: X | B7: SEGMENTS - NORMALISED | C7: =C$4 -> 2022A | D7: =D$4 -> 2023A | E7: =E$4 -> 2024E | F7: =F$4 -> 2025E | G7: =G$4 -> 2026E | H7: =H$4 -> 2027E | I7: =I$4 -> 2028E | J7: =J$4 -> 2029E | ... O7: =O$4 -> 2034E | P7: CAGR 24-27
B8: Wagering & Media | C8: =SUMIFS(HY!$E268:$AL268,HY!$E$15:$AL$15,FY!C$2) -> 2181.9 | D8: =SUMIFS(HY!$E268:$AL268,HY!$E$15:$AL$15,FY!D$2) -> 2230.8 | E8: =SUMIFS(HY!$E268:$AL268,HY!$E$15:$AL$15,FY!E$2) -> 2162.8 | F8: =SUMIFS(HY!$E268:$AL268,HY!$E$15:$AL$15,FY!F$2) -> 2438.8 | G8: =SUMIFS(HY!$E268:$AL268,HY!$E$15:$AL$15,FY!G$2) -> 2454.7 | H8: =SUMIFS(HY!$E268:$AL268,HY!$E$15:$AL$15,FY!H$2) -> 2535.5783 | I8: =SUMIFS(HY!$E268:$AL268,HY!$E$15:$AL$15,FY!I$2) -> 2553.5792 | J8: =SUMIFS(HY!$E268:$AL268,HY!$E$15:$AL$15,FY!J$2) -> 2575.9298 | ... O8: =SUMIFS(HY!$E268:$AL268,HY!$E$15:$AL$15,FY!O$2) -> 2797.6215 | P8: =H8/E8-1 -> 0.17235913
B9: Gaming Services | C9: =SUMIFS(HY!$E269:$AL269,HY!$E$15:$AL$15,FY!C$2) -> 196.9 | D9: =SUMIFS(HY!$E269:$AL269,HY!$E$15:$AL$15,FY!D$2) -> 203.6 | E9: =SUMIFS(HY!$E269:$AL269,HY!$E$15:$AL$15,FY!E$2) -> 163.4 | F9: =SUMIFS(HY!$E269:$AL269,HY!$E$15:$AL$15,FY!F$2) -> 175.8 | G9: =SUMIFS(HY!$E269:$AL269,HY!$E$15:$AL$15,FY!G$2) -> 181.6 | H9: =SUMIFS(HY!$E269:$AL269,HY!$E$15:$AL$15,FY!H$2) -> 186.14 | I9: =SUMIFS(HY!$E269:$AL269,HY!$E$15:$AL$15,FY!I$2) -> 190.7935 | J9: =SUMIFS(HY!$E269:$AL269,HY!$E$15:$AL$15,FY!J$2) -> 196.5173 | ... O9: =SUMIFS(HY!$E269:$AL269,HY!$E$15:$AL$15,FY!O$2) -> 227.81742
B10: BetMakers | C10: =SUMIFS(HY!$E270:$AL270,HY!$E$15:$AL$15,FY!C$2) -> 0 | D10: =SUMIFS(HY!$E270:$AL270,HY!$E$15:$AL$15,FY!D$2) -> 0 | E10: =SUMIFS(HY!$E270:$AL270,HY!$E$15:$AL$15,FY!E$2) -> 0 | F10: =SUMIFS(HY!$E270:$AL270,HY!$E$15:$AL$15,FY!F$2) -> 0 | G10: =SUMIFS(HY!$E270:$AL270,HY!$E$15:$AL$15,FY!G$2) -> 0 | H10: =SUMIFS(HY!$E270:$AL270,HY!$E$15:$AL$15,FY!H$2) -> 25.25 | I10: =SUMIFS(HY!$E270:$AL270,HY!$E$15:$AL$15,FY!I$2) -> 102.485 | J10: =SUMIFS(HY!$E270:$AL270,HY!$E$15:$AL$15,FY!J$2) -> 105.55955 | ... O10: =SUMIFS(HY!$E270:$AL270,HY!$E$15:$AL$15,FY!O$2) -> 122.37245
B11: Normalised Revenue | C11: =SUMIFS(HY!$E271:$AL271,HY!$E$15:$AL$15,FY!C$2) -> 2377.3 | D11: =SUMIFS(HY!$E271:$AL271,HY!$E$15:$AL$15,FY!D$2) -> 2434.4 | E11: =SUMIFS(HY!$E271:$AL271,HY!$E$15:$AL$15,FY!E$2) -> 2338.9 | F11: =SUMIFS(HY!$E271:$AL271,HY!$E$15:$AL$15,FY!F$2) -> 2614.6 | G11: =SUMIFS(HY!$E271:$AL271,HY!$E$15:$AL$15,FY!G$2) -> 2636.3 | H11: =SUMIFS(HY!$E271:$AL271,HY!$E$15:$AL$15,FY!H$2) -> 2746.9683 | I11: =SUMIFS(HY!$E271:$AL271,HY!$E$15:$AL$15,FY!I$2) -> 2846.8577 | J11: =SUMIFS(HY!$E271:$AL271,HY!$E$15:$AL$15,FY!J$2) -> 2878.0067 | ... O11: =SUMIFS(HY!$E271:$AL271,HY!$E$15:$AL$15,FY!O$2) -> 3147.8114
B13: Wagering & Media | C13: =SUMIFS(HY!$E274:$AL274,HY!$E$15:$AL$15,FY!C$2) -> -1380.6 | D13: =SUMIFS(HY!$E274:$AL274,HY!$E$15:$AL$15,FY!D$2) -> -1455.8 | E13: =SUMIFS(HY!$E274:$AL274,HY!$E$15:$AL$15,FY!E$2) -> -1404.6 | F13: =SUMIFS(HY!$E274:$AL274,HY!$E$15:$AL$15,FY!F$2) -> -1522.9 | G13: =SUMIFS(HY!$E274:$AL274,HY!$E$15:$AL$15,FY!G$2) -> -1501.5 | H13: =SUMIFS(HY!$E274:$AL274,HY!$E$15:$AL$15,FY!H$2) -> -1534.0249 | I13: =SUMIFS(HY!$E274:$AL274,HY!$E$15:$AL$15,FY!I$2) -> -1544.9154 | J13: =SUMIFS(HY!$E274:$AL274,HY!$E$15:$AL$15,FY!J$2) -> -1558.4375 | ... O13: =SUMIFS(HY!$E274:$AL274,HY!$E$15:$AL$15,FY!O$2) -> -1692.561
B14: Gaming Services | C14: =SUMIFS(HY!$E275:$AL275,HY!$E$15:$AL$15,FY!C$2) -> -10.6 | D14: =SUMIFS(HY!$E275:$AL275,HY!$E$15:$AL$15,FY!D$2) -> -10.4 | E14: =SUMIFS(HY!$E275:$AL275,HY!$E$15:$AL$15,FY!E$2) -> -1.7 | F14: =SUMIFS(HY!$E275:$AL275,HY!$E$15:$AL$15,FY!F$2) -> -3 | G14: =SUMIFS(HY!$E275:$AL275,HY!$E$15:$AL$15,FY!G$2) -> -2.4 | H14: =SUMIFS(HY!$E275:$AL275,HY!$E$15:$AL$15,FY!H$2) -> -1.8634705 | I14: =SUMIFS(HY!$E275:$AL275,HY!$E$15:$AL$15,FY!I$2) -> -1.9100573 | J14: =SUMIFS(HY!$E275:$AL275,HY!$E$15:$AL$15,FY!J$2) -> -1.967359 | ... O14: =SUMIFS(HY!$E275:$AL275,HY!$E$15:$AL$15,FY!O$2) -> -2.2807083
B15: BetMakers | C15: =SUMIFS(HY!$E276:$AL276,HY!$E$15:$AL$15,FY!C$2) -> 0 | D15: =SUMIFS(HY!$E276:$AL276,HY!$E$15:$AL$15,FY!D$2) -> 0 | E15: =SUMIFS(HY!$E276:$AL276,HY!$E$15:$AL$15,FY!E$2) -> 0 | F15: =SUMIFS(HY!$E276:$AL276,HY!$E$15:$AL$15,FY!F$2) -> 0 | G15: =SUMIFS(HY!$E276:$AL276,HY!$E$15:$AL$15,FY!G$2) -> 0 | H15: =SUMIFS(HY!$E276:$AL276,HY!$E$15:$AL$15,FY!H$2) -> -8.35 | I15: =SUMIFS(HY!$E276:$AL276,HY!$E$15:$AL$15,FY!I$2) -> -27.402 | J15: =SUMIFS(HY!$E276:$AL276,HY!$E$15:$AL$15,FY!J$2) -> -20.43406 | ... O15: =SUMIFS(HY!$E276:$AL276,HY!$E$15:$AL$15,FY!O$2) -> -23.688676
B16: Taxes & Commissions | C16: =SUMIFS(HY!$E277:$AL277,HY!$E$15:$AL$15,FY!C$2) -> -1391.2 | D16: =SUMIFS(HY!$E277:$AL277,HY!$E$15:$AL$15,FY!D$2) -> -1466.2 | E16: =SUMIFS(HY!$E277:$AL277,HY!$E$15:$AL$15,FY!E$2) -> -1406.3 | F16: =SUMIFS(HY!$E277:$AL277,HY!$E$15:$AL$15,FY!F$2) -> -1525.9 | G16: =SUMIFS(HY!$E277:$AL277,HY!$E$15:$AL$15,FY!G$2) -> -1503.9 | H16: =SUMIFS(HY!$E277:$AL277,HY!$E$15:$AL$15,FY!H$2) -> -1544.2384 | I16: =SUMIFS(HY!$E277:$AL277,HY!$E$15:$AL$15,FY!I$2) -> -1574.2275 | J16: =SUMIFS(HY!$E277:$AL277,HY!$E$15:$AL$15,FY!J$2) -> -1580.839 | ... O16: =SUMIFS(HY!$E277:$AL277,HY!$E$15:$AL$15,FY!O$2) -> -1718.5304
B18: Wagering & Media | C18: =SUMIFS(HY!$E279:$AL279,HY!$E$15:$AL$15,FY!C$2) -> 801.3 | D18: =SUMIFS(HY!$E279:$AL279,HY!$E$15:$AL$15,FY!D$2) -> 775 | E18: =SUMIFS(HY!$E279:$AL279,HY!$E$15:$AL$15,FY!E$2) -> 758.2 | F18: =SUMIFS(HY!$E279:$AL279,HY!$E$15:$AL$15,FY!F$2) -> 915.9 | G18: =SUMIFS(HY!$E279:$AL279,HY!$E$15:$AL$15,FY!G$2) -> 953.2 | H18: =SUMIFS(HY!$E279:$AL279,HY!$E$15:$AL$15,FY!H$2) -> 1001.5534 | I18: =SUMIFS(HY!$E279:$AL279,HY!$E$15:$AL$15,FY!I$2) -> 1008.6638 | J18: =SUMIFS(HY!$E279:$AL279,HY!$E$15:$AL$15,FY!J$2) -> 1017.4923 | ... O18: =SUMIFS(HY!$E279:$AL279,HY!$E$15:$AL$15,FY!O$2) -> 1105.0605
B19: Gaming Services | C19: =SUMIFS(HY!$E280:$AL280,HY!$E$15:$AL$15,FY!C$2) -> 186.3 | D19: =SUMIFS(HY!$E280:$AL280,HY!$E$15:$AL$15,FY!D$2) -> 193.2 | E19: =SUMIFS(HY!$E280:$AL280,HY!$E$15:$AL$15,FY!E$2) -> 161.7 | F19: =SUMIFS(HY!$E280:$AL280,HY!$E$15:$AL$15,FY!F$2) -> 172.8 | G19: =SUMIFS(HY!$E280:$AL280,HY!$E$15:$AL$15,FY!G$2) -> 179.2 | H19: =SUMIFS(HY!$E280:$AL280,HY!$E$15:$AL$15,FY!H$2) -> 184.27653 | I19: =SUMIFS(HY!$E280:$AL280,HY!$E$15:$AL$15,FY!I$2) -> 188.88344 | J19: =SUMIFS(HY!$E280:$AL280,HY!$E$15:$AL$15,FY!J$2) -> 194.54995 | ... O19: =SUMIFS(HY!$E280:$AL280,HY!$E$15:$AL$15,FY!O$2) -> 225.53671
B20: BetMakers | C20: =SUMIFS(HY!$E281:$AL281,HY!$E$15:$AL$15,FY!C$2) -> 0 | D20: =SUMIFS(HY!$E281:$AL281,HY!$E$15:$AL$15,FY!D$2) -> 0 | E20: =SUMIFS(HY!$E281:$AL281,HY!$E$15:$AL$15,FY!E$2) -> 0 | F20: =SUMIFS(HY!$E281:$AL281,HY!$E$15:$AL$15,FY!F$2) -> 0 | G20: =SUMIFS(HY!$E281:$AL281,HY!$E$15:$AL$15,FY!G$2) -> 0 | H20: =SUMIFS(HY!$E281:$AL281,HY!$E$15:$AL$15,FY!H$2) -> 16.9 | I20: =SUMIFS(HY!$E281:$AL281,HY!$E$15:$AL$15,FY!I$2) -> 75.083 | J20: =SUMIFS(HY!$E281:$AL281,HY!$E$15:$AL$15,FY!J$2) -> 85.12549 | ... O20: =SUMIFS(HY!$E281:$AL281,HY!$E$15:$AL$15,FY!O$2) -> 98.683774
B21: Variable Contribution | C21: =SUMIFS(HY!$E282:$AL282,HY!$E$15:$AL$15,FY!C$2) -> 987.2 | D21: =SUMIFS(HY!$E282:$AL282,HY!$E$15:$AL$15,FY!D$2) -> 968.4 | E21: =SUMIFS(HY!$E282:$AL282,HY!$E$15:$AL$15,FY!E$2) -> 931.7 | F21: =SUMIFS(HY!$E282:$AL282,HY!$E$15:$AL$15,FY!F$2) -> 1088.7 | G21: =SUMIFS(HY!$E282:$AL282,HY!$E$15:$AL$15,FY!G$2) -> 1132.4 | H21: =SUMIFS(HY!$E282:$AL282,HY!$E$15:$AL$15,FY!H$2) -> 1202.73 | I21: =SUMIFS(HY!$E282:$AL282,HY!$E$15:$AL$15,FY!I$2) -> 1272.6302 | J21: =SUMIFS(HY!$E282:$AL282,HY!$E$15:$AL$15,FY!J$2) -> 1297.1677 | ... O21: =SUMIFS(HY!$E282:$AL282,HY!$E$15:$AL$15,FY!O$2) -> 1429.281
B23: Wagering & Media | C23: =SUMIFS(HY!$E285:$AL285,HY!$E$15:$AL$15,FY!C$2) -> -514.3 | D23: =SUMIFS(HY!$E285:$AL285,HY!$E$15:$AL$15,FY!D$2) -> -467 | E23: =SUMIFS(HY!$E285:$AL285,HY!$E$15:$AL$15,FY!E$2) -> -507 | F23: =SUMIFS(HY!$E285:$AL285,HY!$E$15:$AL$15,FY!F$2) -> -586.8 | G23: =SUMIFS(HY!$E285:$AL285,HY!$E$15:$AL$15,FY!G$2) -> -591.4 | H23: =SUMIFS(HY!$E285:$AL285,HY!$E$15:$AL$15,FY!H$2) -> -611.0645 | I23: =SUMIFS(HY!$E285:$AL285,HY!$E$15:$AL$15,FY!I$2) -> -629.39643 | J23: =SUMIFS(HY!$E285:$AL285,HY!$E$15:$AL$15,FY!J$2) -> -648.27833 | ... O23: =SUMIFS(HY!$E285:$AL285,HY!$E$15:$AL$15,FY!O$2) -> -722.76883
B24: Gaming Services | C24: =SUMIFS(HY!$E286:$AL286,HY!$E$15:$AL$15,FY!C$2) -> -113.1 | D24: =SUMIFS(HY!$E286:$AL286,HY!$E$15:$AL$15,FY!D$2) -> -110.1 | E24: =SUMIFS(HY!$E286:$AL286,HY!$E$15:$AL$15,FY!E$2) -> -102.7 | F24: =SUMIFS(HY!$E286:$AL286,HY!$E$15:$AL$15,FY!F$2) -> -110.4 | G24: =SUMIFS(HY!$E286:$AL286,HY!$E$15:$AL$15,FY!G$2) -> -109.3 | H24: =SUMIFS(HY!$E286:$AL286,HY!$E$15:$AL$15,FY!H$2) -> -113.5454 | I24: =SUMIFS(HY!$E286:$AL286,HY!$E$15:$AL$15,FY!I$2) -> -116.38403 | J24: =SUMIFS(HY!$E286:$AL286,HY!$E$15:$AL$15,FY!J$2) -> -119.87556 | ... O24: =SUMIFS(HY!$E286:$AL286,HY!$E$15:$AL$15,FY!O$2) -> -138.96862
B25: BetMakers | C25: =SUMIFS(HY!$E287:$AL287,HY!$E$15:$AL$15,FY!C$2) -> 0 | D25: =SUMIFS(HY!$E287:$AL287,HY!$E$15:$AL$15,FY!D$2) -> 0 | E25: =SUMIFS(HY!$E287:$AL287,HY!$E$15:$AL$15,FY!E$2) -> 0 | F25: =SUMIFS(HY!$E287:$AL287,HY!$E$15:$AL$15,FY!F$2) -> 0 | G25: =SUMIFS(HY!$E287:$AL287,HY!$E$15:$AL$15,FY!G$2) -> 0 | H25: =SUMIFS(HY!$E287:$AL287,HY!$E$15:$AL$15,FY!H$2) -> -11.7 | I25: =SUMIFS(HY!$E287:$AL287,HY!$E$15:$AL$15,FY!I$2) -> -41.204 | J25: =SUMIFS(HY!$E287:$AL287,HY!$E$15:$AL$15,FY!J$2) -> -34.65012 | ... O25: =SUMIFS(HY!$E287:$AL287,HY!$E$15:$AL$15,FY!O$2) -> -40.168986
B26: Opex | C26: =SUMIFS(HY!$E288:$AL288,HY!$E$15:$AL$15,FY!C$2) -> -626.6 | D26: =SUMIFS(HY!$E288:$AL288,HY!$E$15:$AL$15,FY!D$2) -> -577.4 | E26: =SUMIFS(HY!$E288:$AL288,HY!$E$15:$AL$15,FY!E$2) -> -614 | F26: =SUMIFS(HY!$E288:$AL288,HY!$E$15:$AL$15,FY!F$2) -> -697.2 | G26: =SUMIFS(HY!$E288:$AL288,HY!$E$15:$AL$15,FY!G$2) -> -700.7 | H26: =SUMIFS(HY!$E288:$AL288,HY!$E$15:$AL$15,FY!H$2) -> -736.3099 | I26: =SUMIFS(HY!$E288:$AL288,HY!$E$15:$AL$15,FY!I$2) -> -786.98447 | J26: =SUMIFS(HY!$E288:$AL288,HY!$E$15:$AL$15,FY!J$2) -> -802.804 | ... O26: =SUMIFS(HY!$E288:$AL288,HY!$E$15:$AL$15,FY!O$2) -> -901.90644
H27: =H26/G26-1 -> 0.050820465
H28: =(H23+H24)/(G23+G24)-1 -> 0.034122877 | I28: =(I23+I24)/(H23+H24)-1 -> 0.029216507
B30: Wagering & Media | C30: =SUMIFS(HY!$E292:$AL292,HY!$E$15:$AL$15,FY!C$2) -> 287 | D30: =SUMIFS(HY!$E292:$AL292,HY!$E$15:$AL$15,FY!D$2) -> 308 | E30: =SUMIFS(HY!$E292:$AL292,HY!$E$15:$AL$15,FY!E$2) -> 251.2 | F30: =SUMIFS(HY!$E292:$AL292,HY!$E$15:$AL$15,FY!F$2) -> 329.1 | G30: =SUMIFS(HY!$E292:$AL292,HY!$E$15:$AL$15,FY!G$2) -> 361.8 | H30: =SUMIFS(HY!$E292:$AL292,HY!$E$15:$AL$15,FY!H$2) -> 390.48893 | I30: =SUMIFS(HY!$E292:$AL292,HY!$E$15:$AL$15,FY!I$2) -> 379.26736 | J30: =SUMIFS(HY!$E292:$AL292,HY!$E$15:$AL$15,FY!J$2) -> 369.21395 | ... O30: =SUMIFS(HY!$E292:$AL292,HY!$E$15:$AL$15,FY!O$2) -> 382.29167
B31: Gaming Services | C31: =SUMIFS(HY!$E293:$AL293,HY!$E$15:$AL$15,FY!C$2) -> 73.2 | D31: =SUMIFS(HY!$E293:$AL293,HY!$E$15:$AL$15,FY!D$2) -> 83.1 | E31: =SUMIFS(HY!$E293:$AL293,HY!$E$15:$AL$15,FY!E$2) -> 59 | F31: =SUMIFS(HY!$E293:$AL293,HY!$E$15:$AL$15,FY!F$2) -> 62.4 | G31: =SUMIFS(HY!$E293:$AL293,HY!$E$15:$AL$15,FY!G$2) -> 69.9 | H31: =SUMIFS(HY!$E293:$AL293,HY!$E$15:$AL$15,FY!H$2) -> 70.731129 | I31: =SUMIFS(HY!$E293:$AL293,HY!$E$15:$AL$15,FY!I$2) -> 72.499408 | J31: =SUMIFS(HY!$E293:$AL293,HY!$E$15:$AL$15,FY!J$2) -> 74.67439 | ... O31: =SUMIFS(HY!$E293:$AL293,HY!$E$15:$AL$15,FY!O$2) -> 86.568084
B32: BetMakers | C32: =SUMIFS(HY!$E294:$AL294,HY!$E$15:$AL$15,FY!C$2) -> 0 | D32: =SUMIFS(HY!$E294:$AL294,HY!$E$15:$AL$15,FY!D$2) -> 0 | E32: =SUMIFS(HY!$E294:$AL294,HY!$E$15:$AL$15,FY!E$2) -> 0 | F32: =SUMIFS(HY!$E294:$AL294,HY!$E$15:$AL$15,FY!F$2) -> 0 | G32: =SUMIFS(HY!$E294:$AL294,HY!$E$15:$AL$15,FY!G$2) -> 0 | H32: =SUMIFS(HY!$E294:$AL294,HY!$E$15:$AL$15,FY!H$2) -> 5.2 | I32: =SUMIFS(HY!$E294:$AL294,HY!$E$15:$AL$15,FY!I$2) -> 33.879 | J32: =SUMIFS(HY!$E294:$AL294,HY!$E$15:$AL$15,FY!J$2) -> 50.47537 | ... O32: =SUMIFS(HY!$E294:$AL294,HY!$E$15:$AL$15,FY!O$2) -> 58.514788
B33: Normalised EBITDA | C33: =SUMIFS(HY!$E295:$AL295,HY!$E$15:$AL$15,FY!C$2) -> 360.6 | D33: =SUMIFS(HY!$E295:$AL295,HY!$E$15:$AL$15,FY!D$2) -> 391 | E33: =SUMIFS(HY!$E295:$AL295,HY!$E$15:$AL$15,FY!E$2) -> 317.7 | F33: =SUMIFS(HY!$E295:$AL295,HY!$E$15:$AL$15,FY!F$2) -> 391.5 | G33: =SUMIFS(HY!$E295:$AL295,HY!$E$15:$AL$15,FY!G$2) -> 431.7 | H33: =SUMIFS(HY!$E295:$AL295,HY!$E$15:$AL$15,FY!H$2) -> 466.42006 | I33: =SUMIFS(HY!$E295:$AL295,HY!$E$15:$AL$15,FY!I$2) -> 485.64577 | J33: =SUMIFS(HY!$E295:$AL295,HY!$E$15:$AL$15,FY!J$2) -> 494.36371 | ... O33: =SUMIFS(HY!$E295:$AL295,HY!$E$15:$AL$15,FY!O$2) -> 527.37455
B35: Check | C35: =C33-SUM(C11,C16,C26) -> 1.1 | D35: =D33-SUM(D11,D16,D26) -> 0.2 | E35: =E33-SUM(E11,E16,E26) -> -0.9 | F35: =F33-SUM(F11,F16,F26) -> 0 | G35: =G33-SUM(G11,G16,G26) -> -5.1159077e-13 | H35: =H33-SUM(H11,H16,H26) -> 0 | I35: =I33-SUM(I11,I16,I26) -> 0 | J35: =J33-SUM(J11,J16,J26) -> 0 | ... O35: =O33-SUM(O11,O16,O26) -> 0
A38: X | B38: P&L - NORMALISED | C38: =C$4 -> 2022A | D38: =D$4 -> 2023A | E38: =E$4 -> 2024E | F38: =F$4 -> 2025E | G38: =G$4 -> 2026E | H38: =H$4 -> 2027E | I38: =I$4 -> 2028E | J38: =J$4 -> 2029E | ... O38: =O$4 -> 2034E
B39: Sales Revenue | C39: =C11 -> 2377.3 | D39: =D11 -> 2434.4 | E39: =E11 -> 2338.9 | F39: =F11 -> 2614.6 | G39: =G11 -> 2636.3 | H39: =H11 -> 2746.9683 | I39: =I11 -> 2846.8577 | J39: =J11 -> 2878.0067 | ... O39: =O11 -> 3147.8114
B40: Other Income | C40: 0 | D40: 0 | E40: 0 | F40: 0 | G40: 0 | H40: 0 | I40: 0 | J40: 0 | K40: 0 | L40: 0 | M40: 0 | N40: 0 | O40: 0
B41: ---------- | C41: ---------- | D41: ---------- | E41: ---------- | F41: ---------- | G41: ---------- | H41: ---------- | I41: ---------- | J41: ---------- | K41: ---------- | L41: ---------- | M41: ---------- | N41: ---------- | O41: ----------
B42: Total revenue | C42: =C40+C39 -> 2377.3 | D42: =D40+D39 -> 2434.4 | E42: =E40+E39 -> 2338.9 | F42: =F40+F39 -> 2614.6 | G42: =G40+G39 -> 2636.3 | H42: =H40+H39 -> 2746.9683 | I42: =I40+I39 -> 2846.8577 | J42: =J40+J39 -> 2878.0067 | ... O42: =O40+O39 -> 3147.8114
B43: COGS | C43: =C46-C44-C42 -> -1390.1 | D43: =D46-D44-D42 -> -1466 | E43: =E46-E44-E42 -> -1407.2 | F43: =F46-F44-F42 -> -1525.9 | G43: =G46-G44-G42 -> -1503.9 | H43: =H46-H44-H42 -> -1544.2384 | I43: =I46-I44-I42 -> -1574.2275 | J43: =J46-J44-J42 -> -1580.839 | ... O43: =O46-O44-O42 -> -1718.5304
B44: OPEX | C44: =SUMIFS(HY!$E288:$AL288,HY!$E$15:$AL$15,FY!C$2) -> -626.6 | D44: =SUMIFS(HY!$E288:$AL288,HY!$E$15:$AL$15,FY!D$2) -> -577.4 | E44: =SUMIFS(HY!$E288:$AL288,HY!$E$15:$AL$15,FY!E$2) -> -614 | F44: =SUMIFS(HY!$E288:$AL288,HY!$E$15:$AL$15,FY!F$2) -> -697.2 | G44: =SUMIFS(HY!$E288:$AL288,HY!$E$15:$AL$15,FY!G$2) -> -700.7 | H44: =SUMIFS(HY!$E288:$AL288,HY!$E$15:$AL$15,FY!H$2) -> -736.3099 | I44: =SUMIFS(HY!$E288:$AL288,HY!$E$15:$AL$15,FY!I$2) -> -786.98447 | J44: =SUMIFS(HY!$E288:$AL288,HY!$E$15:$AL$15,FY!J$2) -> -802.804 | ... O44: =SUMIFS(HY!$E288:$AL288,HY!$E$15:$AL$15,FY!O$2) -> -901.90644
B45: ---------- | C45: ---------- | D45: ---------- | E45: ---------- | F45: ---------- | G45: ---------- | H45: ---------- | I45: ---------- | J45: ---------- | K45: ---------- | L45: ---------- | M45: ---------- | N45: ---------- | O45: ----------
B46: EBITDA | C46: =C33 -> 360.6 | D46: =D33 -> 391 | E46: =E33 -> 317.7 | F46: =F33 -> 391.5 | G46: =G33 -> 431.7 | H46: =H33 -> 466.42006 | I46: =I33 -> 485.64577 | J46: =J33 -> 494.36371 | ... O46: =O33 -> 527.37455
B47: D&A | C47: =SUMIFS(HY!$E301:$AL301,HY!$E$15:$AL$15,FY!C$2) -> -286.4 | D47: =SUMIFS(HY!$E301:$AL301,HY!$E$15:$AL$15,FY!D$2) -> -240.5 | E47: =SUMIFS(HY!$E301:$AL301,HY!$E$15:$AL$15,FY!E$2) -> -220.3 | F47: =SUMIFS(HY!$E301:$AL301,HY!$E$15:$AL$15,FY!F$2) -> -202.8 | G47: =SUMIFS(HY!$E301:$AL301,HY!$E$15:$AL$15,FY!G$2) -> -213 | H47: =SUMIFS(HY!$E301:$AL301,HY!$E$15:$AL$15,FY!H$2) -> -228.4 | I47: =SUMIFS(HY!$E301:$AL301,HY!$E$15:$AL$15,FY!I$2) -> -223.4 | J47: =SUMIFS(HY!$E301:$AL301,HY!$E$15:$AL$15,FY!J$2) -> -225.19597 | ... O47: =SUMIFS(HY!$E301:$AL301,HY!$E$15:$AL$15,FY!O$2) -> -199.66011
B48: ---------- | C48: ---------- | D48: ---------- | E48: ---------- | F48: ---------- | G48: ---------- | H48: ---------- | I48: ---------- | J48: ---------- | K48: ---------- | L48: ---------- | M48: ---------- | N48: ---------- | O48: ----------
B49: EBIT | C49: =SUMIFS(HY!$E311:$AL311,HY!$E$15:$AL$15,FY!C$2) -> 74.2 | D49: =SUMIFS(HY!$E311:$AL311,HY!$E$15:$AL$15,FY!D$2) -> 150.5 | E49: =SUMIFS(HY!$E311:$AL311,HY!$E$15:$AL$15,FY!E$2) -> 97.4 | F49: =SUMIFS(HY!$E311:$AL311,HY!$E$15:$AL$15,FY!F$2) -> 188.7 | G49: =SUMIFS(HY!$E311:$AL311,HY!$E$15:$AL$15,FY!G$2) -> 218.7 | H49: =SUMIFS(HY!$E311:$AL311,HY!$E$15:$AL$15,FY!H$2) -> 238.02006 | I49: =SUMIFS(HY!$E311:$AL311,HY!$E$15:$AL$15,FY!I$2) -> 262.24577 | J49: =SUMIFS(HY!$E311:$AL311,HY!$E$15:$AL$15,FY!J$2) -> 269.16774 | ... O49: =SUMIFS(HY!$E311:$AL311,HY!$E$15:$AL$15,FY!O$2) -> 327.71444
...

Sheet II

Sheet FT Tables
C2: Tabcorp 1H26 Result - Headline | BT2: Tabcorp FY26 Result - Headline
D3: 1H22A | E3: 2H22A | F3: 1H23A | G3: 2H23A | H3: 1H24A | I3: 2H24E | J3: 1H25E | K3: 2H25E | L3: 1H26E | M3: 2H26E | N3: 1H27E | O3: 2H27E | Q3: ="1H25A" -> 1H25A | R3: ="1H26A" -> 1H26A | S3: % change | T3: E&Pe 1H26E | U3: % diff | V3: VA Cons. 1H26E | W3: % diff | Z3: 1H25 | AE3: 1H22 | AF3: 2H22 | AG3: 1H23 | AH3: 2H23 | AI3: 1H24 | AJ3: 2H24 | AK3: 1H25 | AL3: 2H25 | AM3: 1H26 | AN3: 2H26 | AO3: 1H27 | AP3: 2H27 | AR3: 1H22 | AS3: 2H22 | AT3: 1H23 | AU3: 2H23 | AV3: 1H24 | AW3: 2H24 | AX3: 1H25 | AY3: 2H25 | AZ3: 1H26 | BA3: 2H26 | BB3: 1H27 | BC3: 2H27 | BE3: 1H22 | BF3: 2H22 | BG3: 1H23 | BH3: 2H23 | BI3: 1H24 | BJ3: 2H24 | BK3: 1H25 | BL3: 2H25 | BM3: 1H26 | BN3: 2H26 | BO3: 1H27 | BP3: 2H27 | BU3: FY22A | BV3: FY23A | BW3: FY24A | BX3: FY25E | BY3: FY26E | BZ3: FY27E | CA3: FY28E | CB3: FY29E | CC3: FY30E | CE3: FY25A | CF3: ="FY26A" -> FY26A | CG3: % change | CH3: E&Pe FY26E | CI3: % diff | CJ3: VA Cons. FY26E | CK3: % diff | CN3: =DG3 -> FY26 | CS3: FY22 | CT3: FY23 | CU3: FY24 | CV3: FY25 | CW3: FY26 | CX3: FY27 | CY3: FY28 | CZ3: FY29 | DA3: FY30 | DC3: FY22 | DD3: FY23 | DE3: FY24 | DF3: FY25 | DG3: FY26 | DH3: FY27 | DI3: FY28 | DJ3: FY29 | DK3: FY30 | DM3: FY22 | DN3: FY23 | DO3: FY24 | DP3: FY25 | DQ3: FY26 | DR3: FY27 | DS3: FY28 | DT3: FY29 | DU3: FY30
C4: P&L | BT4: P&L | CW4: =CX6-20 -> 2691.2841 | DH4: =DH6/DG6-1 -> 0.028666971
CW5: =CW4/CW6-1 -> 0.020856548 | CX5: =CX6/CW6-1 -> 0.028442938 | CY5: =CY6/CX6-1 -> 0.038182567 | CZ5: =CZ6/CY6-1 -> 0.019225772
C6: Revenue | F6: =HY!O271 -> 1274.5 | G6: =HY!P271 -> 1159.9 | H6: =HY!Q271 -> 1209.6 | I6: =HY!R271 -> 1129.3 | J6: =HY!S271 -> 1331.3 | K6: =HY!T271 -> 1283.3 | L6: =HY!U271 -> 1344.9 | M6: =HY!V271 -> 1291.4 | ... O6: =HY!X271 -> 1345.9846 | Q6: =J6 -> 1331.3 | R6: 1344.9 | S6: =R6/Q6-1 -> 0.010215579 | T6: =L6 -> 1344.9 | U6: =$R6/T6-1 -> 0 | V6: =Z6 -> 1325.1042 | W6: =$R6/V6-1 -> 0.014939085 | Z6: =AZ6 -> 1325.1042 | AB6: TAH_AU | AC6: Total revenue | AD6: consensus.vaactuals | AE6: =_xll.VAData($AB6,AE$3,$AC6,$AD6) -> 1152.3 | AF6: =_xll.VAData($AB6,AF$3,$AC6,$AD6) -> 1225 | AG6: =_xll.VAData($AB6,AG$3,$AC6,$AD6) -> 1274.5 | AH6: =_xll.VAData($AB6,AH$3,$AC6,$AD6) -> 1159.9 | AI6: =_xll.VAData($AB6,AI$3,$AC6,$AD6) -> 1209.6 | AJ6: =_xll.VAData($AB6,AJ$3,$AC6,$AD6) -> 1129.3 | AK6: =_xll.VAData($AB6,AK$3,$AC6,$AD6) -> 1331.3 | AL6: =_xll.VAData($AB6,AL$3,$AC6,$AD6) -> 1283.3 | ... AP6: =_xll.VAData($AB6,AP$3,$AC6,$AD6) -> 1320.0772 | AR6: 1152.3 | AS6: 1225 | AT6: 1274.5 | AU6: 1159.9 | AV6: 1209.6 | AW6: 1129.3 | AX6: 1331.3 | AY6: 1283.3 | AZ6: 1325.1042 | BA6: 1299.1995 | BB6: 1403.9844 | BC6: 1330.4886 | BE6: =D6-AR6 -> -1152.3 | BF6: =E6-AS6 -> -1225 | BG6: =F6-AT6 -> 0 | BH6: =G6-AU6 -> 0 | BI6: =H6-AV6 -> 0 | BJ6: =I6-AW6 -> 0 | BK6: =J6-AX6 -> 0 | BL6: =K6-AY6 -> 0 | ... BP6: =O6-BC6 -> 15.495959 | BT6: Revenue | BV6: =FY!D63 -> 2434.4 | BW6: =FY!E63 -> 2338.9 | BX6: =FY!F63 -> 2614.6 | BY6: =FY!G63 -> 2636.3 | BZ6: =FY!H63 -> 2746.9683 | CA6: =FY!I63 -> 2846.8577 | CB6: =FY!J63 -> 2878.0067 | CC6: =FY!K63 -> 2944.2614 | CE6: =BX6 -> 2614.6 | CF6: 2636.3 | CG6: =CF6/CE6-1 -> 0.0082995487 | CH6: =BY6 -> 2636.3 | CI6: =$CF6/CH6-1 -> 0 | CJ6: =CN6 -> 2648.8625 | CK6: =$CF6/CJ6-1 -> -0.0047426056 | CN6: =DG6 -> 2648.8625 | CP6: TAH_AU | CQ6: Total revenue | CR6: consensus.vaactuals | CS6: =_xll.VAData($AB6,CS$3,$AC6,$AD6) -> 2377.3 | CT6: =_xll.VAData($AB6,CT$3,$AC6,$AD6) -> 2434.4 | CU6: =_xll.VAData($AB6,CU$3,$AC6,$AD6) -> 2338.9 | CV6: =_xll.VAData($AB6,CV$3,$AC6,$AD6) -> 2614.6 | CW6: =_xll.VAData($AB6,CW$3,$AC6,$AD6) -> 2636.3 | CX6: =_xll.VAData($AB6,CX$3,$AC6,$AD6) -> 2711.2841 | CY6: =_xll.VAData($AB6,CY$3,$AC6,$AD6) -> 2814.8079 | CZ6: =_xll.VAData($AB6,CZ$3,$AC6,$AD6) -> 2868.9248 | DA6: =_xll.VAData($AB6,DA$3,$AC6,$AD6) -> 2923.4937 | DC6: 2377.3 | DD6: 2434.4 | DE6: 2338.9 | DF6: 2614.6 | DG6: 2648.8625 | DH6: 2724.7974 | DI6: 2805.8885 | DJ6: 2866.3854 | DK6: 2926.7643 | DN6: =BV6-DD6 -> 0 | DO6: =BW6-DE6 -> 0 | DP6: =BX6-DF6 -> 0 | DQ6: =BY6-DG6 -> -12.56251 | DR6: =BZ6-DH6 -> 22.170942 | DS6: =CA6-DI6 -> 40.969186 | DT6: =CB6-DJ6 -> 11.621313 | DU6: =CC6-DK6 -> 17.497128
C7: EBITDA | F7: =HY!O295 -> 196.6 | G7: =HY!P295 -> 194.4 | H7: =HY!Q295 -> 169.8 | I7: =HY!R295 -> 147.9 | J7: =HY!S295 -> 190.2 | K7: =HY!T295 -> 201.3 | L7: =HY!U295 -> 217.4 | M7: =HY!V295 -> 214.3 | ... O7: =HY!X295 -> 220.50641 | Q7: =J7 -> 190.2 | R7: 217.4 | S7: =R7/Q7-1 -> 0.14300736 | T7: =L7 -> 217.4 | U7: =$R7/T7-1 -> 0 | V7: =Z7 -> 195.97401 | W7: =$R7/V7-1 -> 0.10933079 | Z7: =AZ7 -> 195.97401 | AB7: TAH_AU | AC7: EBITDA - Operating | AD7: consensus.vaactuals | AE7: =_xll.VAData($AB7,AE$3,$AC7,$AD7) -> 159 | AF7: =_xll.VAData($AB7,AF$3,$AC7,$AD7) -> 201.6 | AG7: =_xll.VAData($AB7,AG$3,$AC7,$AD7) -> 196.6 | AH7: =_xll.VAData($AB7,AH$3,$AC7,$AD7) -> 194.4 | AI7: =_xll.VAData($AB7,AI$3,$AC7,$AD7) -> 169.8 | AJ7: =_xll.VAData($AB7,AJ$3,$AC7,$AD7) -> 147.9 | AK7: =_xll.VAData($AB7,AK$3,$AC7,$AD7) -> 190.2 | AL7: =_xll.VAData($AB7,AL$3,$AC7,$AD7) -> 201.3 | ... AP7: =_xll.VAData($AB7,AP$3,$AC7,$AD7) -> 221.70116 | AR7: 159 | AS7: 201.6 | AT7: 196.6 | AU7: 194.4 | AV7: 169.8 | AW7: 147.9 | AX7: 190.2 | AY7: 201.3 | AZ7: 195.97401 | BA7: 205.36811 | BB7: 218.32381 | BC7: 211.06276 | BE7: =D7-AR7 -> -159 | BF7: =E7-AS7 -> -201.6 | BG7: =F7-AT7 -> 0 | BH7: =G7-AU7 -> 0 | BI7: =H7-AV7 -> 0 | BJ7: =I7-AW7 -> 0 | BK7: =J7-AX7 -> 0 | BL7: =K7-AY7 -> 0 | ... BP7: =O7-BC7 -> 9.4436556 | BT7: EBITDA | BV7: =FY!D67 -> 391 | BW7: =FY!E67 -> 317.7 | BX7: =FY!F67 -> 391.5 | BY7: =FY!G67 -> 431.7 | BZ7: =FY!H67 -> 466.42006 | CA7: =FY!I67 -> 485.64577 | CB7: =FY!J67 -> 494.36371 | CC7: =FY!K67 -> 501.26086 | CE7: =BX7 -> 391.5 | CF7: 431.7 | CG7: =CF7/CE7-1 -> 0.10268199 | CH7: =BY7 -> 431.7 | CI7: =$CF7/CH7-1 -> 0 | CJ7: =CN7 -> 423.04047 | CK7: =$CF7/CJ7-1 -> 0.020469743 | CN7: =DG7 -> 423.04047 | CP7: TAH_AU | CQ7: EBITDA - Operating | CR7: consensus.vaactuals | CS7: =_xll.VAData($AB7,CS$3,$AC7,$AD7) -> 381.6 | CT7: =_xll.VAData($AB7,CT$3,$AC7,$AD7) -> 391 | CU7: =_xll.VAData($AB7,CU$3,$AC7,$AD7) -> 317.7 | CV7: =_xll.VAData($AB7,CV$3,$AC7,$AD7) -> 391.5 | CW7: =_xll.VAData($AB7,CW$3,$AC7,$AD7) -> 431.7 | CX7: =_xll.VAData($AB7,CX$3,$AC7,$AD7) -> 466.54104 | CY7: =_xll.VAData($AB7,CY$3,$AC7,$AD7) -> 489.5737 | CZ7: =_xll.VAData($AB7,CZ$3,$AC7,$AD7) -> 505.18115 | DA7: =_xll.VAData($AB7,DA$3,$AC7,$AD7) -> 518.4063 | DC7: 381.6 | DD7: 391 | DE7: 317.7 | DF7: 391.5 | DG7: 423.04047 | DH7: 440.67815 | DI7: 458.80963 | DJ7: 470.63364 | DK7: 483.28422 | DN7: =BV7-DD7 -> 0 | DO7: =BW7-DE7 -> 0 | DP7: =BX7-DF7 -> 0 | DQ7: =BY7-DG7 -> 8.6595296 | DR7: =BZ7-DH7 -> 25.741919 | DS7: =CA7-DI7 -> 26.836143 | DT7: =CB7-DJ7 -> 23.730071 | DU7: =CC7-DK7 -> 17.976638
C8: EBIT | F8: =HY!O311 -> 73.2 | G8: =HY!P311 -> 77.3 | H8: =HY!Q311 -> 50 | I8: =HY!R311 -> 47.4 | J8: =HY!S311 -> 92.7 | K8: =HY!T311 -> 96 | L8: =HY!U311 -> 110.2 | M8: =HY!V311 -> 108.5 | ... O8: =HY!X311 -> 106.30641 | Q8: =J8 -> 92.7 | R8: 110.2 | S8: =R8/Q8-1 -> 0.18878101 | T8: =L8 -> 110.2 | U8: =$R8/T8-1 -> 0 | V8: =Z8 -> 86.31809 | W8: =$R8/V8-1 -> 0.27667329 | Z8: =AZ8 -> 86.31809 | AB8: TAH_AU | AC8: Operating income/(loss) - Operating | AD8: consensus.vaactuals | AE8: =_xll.VAData($AB8,AE$3,$AC8,$AD8) -> 16.3 | AF8: =_xll.VAData($AB8,AF$3,$AC8,$AD8) -> 57.9 | AG8: =_xll.VAData($AB8,AG$3,$AC8,$AD8) -> 73.2 | AH8: =_xll.VAData($AB8,AH$3,$AC8,$AD8) -> 77.297995 | AI8: =_xll.VAData($AB8,AI$3,$AC8,$AD8) -> 50 | AJ8: =_xll.VAData($AB8,AJ$3,$AC8,$AD8) -> 47.4 | AK8: =_xll.VAData($AB8,AK$3,$AC8,$AD8) -> 92.7 | AL8: =_xll.VAData($AB8,AL$3,$AC8,$AD8) -> 96 | ... AP8: =_xll.VAData($AB8,AP$3,$AC8,$AD8) -> 105.43671 | AR8: 16.3 | AS8: 57.9 | AT8: 73.2 | AU8: 77.297995 | AV8: 50 | AW8: 47.4 | AX8: 92.7 | AY8: 96 | AZ8: 86.31809 | BA8: 95.631743 | BB8: 109.43267 | BC8: 101.31928 | BE8: =D8-AR8 -> -16.3 | BF8: =E8-AS8 -> -57.9 | BG8: =F8-AT8 -> 0 | BH8: =G8-AU8 -> 0.0020049496 | BI8: =H8-AV8 -> 0 | BJ8: =I8-AW8 -> 0 | BK8: =J8-AX8 -> 0 | BL8: =K8-AY8 -> 0 | ... BP8: =O8-BC8 -> 4.9871263 | BT8: EBIT | BV8: =FY!D71 -> 150.5 | BW8: =FY!E71 -> 97.4 | BX8: =FY!F71 -> 188.7 | BY8: =FY!G71 -> 218.7 | BZ8: =FY!H71 -> 238.02006 | CA8: =FY!I71 -> 262.24577 | CB8: =FY!J71 -> 269.16774 | CC8: =FY!K71 -> 285.90615 | CE8: =BX8 -> 188.7 | CF8: 218.7 | CG8: =CF8/CE8-1 -> 0.15898251 | CH8: =BY8 -> 218.7 | CI8: =$CF8/CH8-1 -> 0 | CJ8: =CN8 -> 207.08996 | CK8: =$CF8/CJ8-1 -> 0.056062785 | CN8: =DG8 -> 207.08996 | CP8: TAH_AU | CQ8: Operating income/(loss) - Operating | CR8: consensus.vaactuals | CS8: =_xll.VAData($AB8,CS$3,$AC8,$AD8) -> 95.2 | CT8: =_xll.VAData($AB8,CT$3,$AC8,$AD8) -> 150.5 | CU8: =_xll.VAData($AB8,CU$3,$AC8,$AD8) -> 97.4 | CV8: =_xll.VAData($AB8,CV$3,$AC8,$AD8) -> 188.7 | CW8: =_xll.VAData($AB8,CW$3,$AC8,$AD8) -> 218.7 | CX8: =_xll.VAData($AB8,CX$3,$AC8,$AD8) -> 235.01687 | CY8: =_xll.VAData($AB8,CY$3,$AC8,$AD8) -> 251.24654 | CZ8: =_xll.VAData($AB8,CZ$3,$AC8,$AD8) -> 264.73724 | DA8: =_xll.VAData($AB8,DA$3,$AC8,$AD8) -> 276.76132 | DC8: 95.2 | DD8: 150.5 | DE8: 97.4 | DF8: 188.7 | DG8: 207.08996 | DH8: 223.84775 | DI8: 237.84596 | DJ8: 248.86053 | DK8: 261.04487 | DN8: =BV8-DD8 -> 0 | DO8: =BW8-DE8 -> 0 | DP8: =BX8-DF8 -> 0 | DQ8: =BY8-DG8 -> 11.61004 | DR8: =BZ8-DH8 -> 14.172312 | DS8: =CA8-DI8 -> 24.399815 | DT8: =CB8-DJ8 -> 20.307201 | DU8: =CC8-DK8 -> 24.861272
C9: NPAT - before significant items | F9: =HY!O328 -> 47.3 | G9: =HY!P328 -> 37 | H9: =HY!Q328 -> 17.6 | I9: =HY!R328 -> 10.4 | J9: =HY!S328 -> 22.1 | K9: =HY!T328 -> 27.4 | L9: =HY!U328 -> 35.7 | M9: =HY!V328 -> 35.4 | ... O9: =HY!X328 -> 35.903642 | Q9: =J9 -> 22.1 | R9: 35.7 | S9: =R9/Q9-1 -> 0.61538462 | T9: =L9 -> 35.7 | U9: =$R9/T9-1 -> 0 | V9: =Z9 -> 25.068204 | W9: =$R9/V9-1 -> 0.42411477 | Z9: =AZ9 -> 25.068204 | AB9: TAH_AU | AC9: Net income/(loss) - Operating | AD9: consensus.vaactuals | AE9: =_xll.VAData($AB9,AE$3,$AC9,$AD9) -> 186.5 | AF9: =_xll.VAData($AB9,AF$3,$AC9,$AD9) -> 175.4 | AG9: =_xll.VAData($AB9,AG$3,$AC9,$AD9) -> 47.3 | AH9: =_xll.VAData($AB9,AH$3,$AC9,$AD9) -> 37 | AI9: =_xll.VAData($AB9,AI$3,$AC9,$AD9) -> 17.6 | AJ9: =_xll.VAData($AB9,AJ$3,$AC9,$AD9) -> 10.4 | AK9: =_xll.VAData($AB9,AK$3,$AC9,$AD9) -> 22.1 | AL9: =_xll.VAData($AB9,AL$3,$AC9,$AD9) -> 27.4 | ... AP9: =_xll.VAData($AB9,AP$3,$AC9,$AD9) -> 36.058029 | AR9: 186.5 | AS9: 175.4 | AT9: 47.3 | AU9: 37 | AV9: 17.6 | AW9: 10.4 | AX9: 22.1 | AY9: 27.4 | AZ9: 25.068204 | BA9: 33.062236 | BB9: 42.946837 | BC9: 39.784283 | BE9: =D9-AR9 -> -186.5 | BF9: =E9-AS9 -> -175.4 | BG9: =F9-AT9 -> 0 | BH9: =G9-AU9 -> 0 | BI9: =H9-AV9 -> 0 | BJ9: =I9-AW9 -> 0 | BK9: =J9-AX9 -> 0 | BL9: =K9-AY9 -> 0 | ... BP9: =O9-BC9 -> -3.8806414 | BT9: NPAT - before significant items | BV9: =FY!D81 -> 84.3 | BW9: =FY!E81 -> 28 | BX9: =FY!F81 -> 49.5 | BY9: =FY!G81 -> 71.1 | BZ9: =FY!H81 -> 89.710264 | CA9: =FY!I81 -> 110.08763 | CB9: =FY!J81 -> 120.65763 | CC9: =FY!K81 -> 137.49126 | CE9: =BX9 -> 49.5 | CF9: 71.1 | CG9: =CF9/CE9-1 -> 0.43636364 | CH9: =BY9 -> 71.1 | CI9: =$CF9/CH9-1 -> 0 | CJ9: =CN9 -> 67.058659 | CK9: =$CF9/CJ9-1 -> 0.060265757 | CN9: =DG9 -> 67.058659 | CP9: TAH_AU | CQ9: Net income/(loss) - Operating | CR9: consensus.vaactuals | CS9: =_xll.VAData($AB9,CS$3,$AC9,$AD9) -> 362.4 | CT9: =_xll.VAData($AB9,CT$3,$AC9,$AD9) -> 84.3 | CU9: =_xll.VAData($AB9,CU$3,$AC9,$AD9) -> 28 | CV9: =_xll.VAData($AB9,CV$3,$AC9,$AD9) -> 49.5 | CW9: =_xll.VAData($AB9,CW$3,$AC9,$AD9) -> 71.1 | CX9: =_xll.VAData($AB9,CX$3,$AC9,$AD9) -> 88.264785 | CY9: =_xll.VAData($AB9,CY$3,$AC9,$AD9) -> 101.01483 | CZ9: =_xll.VAData($AB9,CZ$3,$AC9,$AD9) -> 115.33058 | DA9: =_xll.VAData($AB9,DA$3,$AC9,$AD9) -> 129.83598 | DC9: 362.4 | DD9: 84.3 | DE9: 28 | DF9: 49.5 | DG9: 67.058659 | DH9: 85.12683 | DI9: 99.249123 | DJ9: 113.29612 | DK9: 126.2911 | DN9: =BV9-DD9 -> 0 | DO9: =BW9-DE9 -> 0 | DP9: =BX9-DF9 -> 0 | DQ9: =BY9-DG9 -> 4.0413409 | DR9: =BZ9-DH9 -> 4.5834341 | DS9: =CA9-DI9 -> 10.838511 | DT9: =CB9-DJ9 -> 7.3615068 | DU9: =CC9-DK9 -> 11.200154
C10: EPS (cps) | F10: =HY!O621 -> 2.2 | G10: =HY!P621 -> 1.6 | H10: =HY!Q621 -> 0.9 | I10: =HY!R621 -> 0.5 | J10: =HY!S621 -> 1.9 | K10: =HY!T621 -> 2 | L10: =HY!U621 -> 2.7 | M10: =HY!V621 -> 2.5 | ... O10: =HY!X621 -> 2.4776953 | Q10: =J10 -> 1.9 | R10: 2.7 | S10: =R10/Q10-1 -> 0.42105263 | T10: =L10 -> 2.7 | U10: =$R10/T10-1 -> 0 | V10: =Z10 -> 1.0951553 | W10: =$R10/V10-1 -> 1.4654038 | Z10: =AZ10 -> 1.0951553 | AB10: TAH_AU | AC10: EPS - Diluted - Operating | AD10: consensus.vaactuals | AE10: =_xll.VAData($AB10,AE$3,$AC10,$AD10) -> 8.3845126 | AF10: =_xll.VAData($AB10,AF$3,$AC10,$AD10) -> 2.1536655 | AG10: =_xll.VAData($AB10,AG$3,$AC10,$AD10) -> 2.0998424 | AH10: =_xll.VAData($AB10,AH$3,$AC10,$AD10) -> 1.620781 | AI10: =_xll.VAData($AB10,AI$3,$AC10,$AD10) -> 0.77139693 | AJ10: =_xll.VAData($AB10,AJ$3,$AC10,$AD10) -> 0.45554786 | AK10: =_xll.VAData($AB10,AK$3,$AC10,$AD10) -> 0.96750946 | AL10: =_xll.VAData($AB10,AL$3,$AC10,$AD10) -> 1.1988543 | ... AP10: =_xll.VAData($AB10,AP$3,$AC10,$AD10) -> 1.5514494 | AR10: 8.3845126 | AS10: 2.0859562 | AT10: 2.0998424 | AU10: 1.620781 | AV10: 0.77139693 | AW10: 0.45554786 | AX10: 0.96750946 | AY10: 1.1988543 | AZ10: 1.0951553 | BA10: 1.4429444 | BB10: 1.8759807 | BC10: 1.7358624 | BE10: =D10-AR10 -> -8.3845126 | BF10: =E10-AS10 -> -2.0859562 | BG10: =F10-AT10 -> 0.1001576 | BH10: =G10-AU10 -> -0.020781041 | BI10: =H10-AV10 -> 0.12860307 | BJ10: =I10-AW10 -> 0.044452138 | BK10: =J10-AX10 -> 0.93249054 | BL10: =K10-AY10 -> 0.80114568 | ... BP10: =O10-BC10 -> 0.74183284 | BT10: EPS (cps) - before significant items | BV10: =FY!D183 -> 3.8 | BW10: =FY!E183 -> 1.4 | BX10: =FY!F183 -> 3.9 | BY10: =FY!G183 -> 5.2 | BZ10: =FY!H183 -> 5.7799121 | CA10: =FY!I183 -> 6.1889398 | CB10: =FY!J183 -> 6.2138022 | CC10: =FY!K183 -> 6.5991127 | CE10: =BX10 -> 3.9 | CG10: =CF10/CE10-1 -> -1 | CH10: =BY10 -> 5.2 | CI10: =$CF10/CH10-1 -> -1 | CJ10: =CN10 -> 2.9258618 | CK10: =$CF10/CJ10-1 -> -1 | CN10: =DG10 -> 2.9258618 | CP10: TAH_AU | CQ10: EPS - Diluted - Operating | CR10: consensus.vaactuals | CS10: =_xll.VAData($AB10,CS$3,$AC10,$AD10) -> 16.288373 | CT10: =_xll.VAData($AB10,CT$3,$AC10,$AD10) -> 3.7174229 | CU10: =_xll.VAData($AB10,CU$3,$AC10,$AD10) -> 1.2266713 | CV10: =_xll.VAData($AB10,CV$3,$AC10,$AD10) -> 2.1570507 | CW10: =_xll.VAData($AB10,CW$3,$AC10,$AD10) -> 3.0560928 | CX10: =_xll.VAData($AB10,CX$3,$AC10,$AD10) -> 3.8066274 | CY10: =_xll.VAData($AB10,CY$3,$AC10,$AD10) -> 4.3149056 | CZ10: =_xll.VAData($AB10,CZ$3,$AC10,$AD10) -> 4.924777 | DA10: =_xll.VAData($AB10,DA$3,$AC10,$AD10) -> 5.5418836 | DC10: 16.288373 | DD10: 3.7174229 | DE10: 1.2266713 | DF10: 2.1570507 | DG10: 2.9258618 | DH10: 3.7081348 | DI10: 4.3047675 | DJ10: 4.9130597 | DK10: 5.4737282 | DN10: =BV10-DD10 -> 0.08257706 | DO10: =BW10-DE10 -> 0.17332866 | DP10: =BX10-DF10 -> 1.7429493 | DQ10: =BY10-DG10 -> 2.2741382 | DR10: =BZ10-DH10 -> 2.0717773 | DS10: =CA10-DI10 -> 1.8841723 | DT10: =CB10-DJ10 -> 1.3007424 | DU10: =CC10-DK10 -> 1.1253845
C11: DPS (cps) | F11: =HY!O527 -> 1.3 | G11: =HY!P527 -> 1 | H11: =HY!Q527 -> 1 | I11: =HY!R527 -> 0.3 | J11: =HY!S527 -> 1 | K11: =HY!T527 -> 1 | L11: =HY!U527 -> 1.5 | M11: =HY!V527 -> 1.5 | ... O11: =HY!X527 -> 1.6 | Q11: =J11 -> 1 | R11: 1.5 | S11: =R11/Q11-1 -> 0.5 | T11: =L11 -> 1.5 | U11: =$R11/T11-1 -> 0 | V11: =Z11 -> 0.8345962 | W11: =$R11/V11-1 -> 0.79727635 | Z11: =AZ11 -> 0.8345962 | AB11: TAH_AU | AC11: Dividend per share | AD11: consensus.vaactuals | AE11: =_xll.VAData($AB11,AE$3,$AC11,$AD11) -> 6.5 | AF11: =_xll.VAData($AB11,AF$3,$AC11,$AD11) -> 6.5 | AG11: =_xll.VAData($AB11,AG$3,$AC11,$AD11) -> 1.3 | AH11: =_xll.VAData($AB11,AH$3,$AC11,$AD11) -> 1 | AI11: =_xll.VAData($AB11,AI$3,$AC11,$AD11) -> 1 | AJ11: =_xll.VAData($AB11,AJ$3,$AC11,$AD11) -> 0.3 | AK11: =_xll.VAData($AB11,AK$3,$AC11,$AD11) -> 1 | AL11: =_xll.VAData($AB11,AL$3,$AC11,$AD11) -> 1 | ... AP11: =_xll.VAData($AB11,AP$3,$AC11,$AD11) -> 1.4208592 | AR11: 6.5 | AS11: 6.5 | AT11: 1.3 | AU11: 1 | AV11: 1 | AW11: 0.3 | AX11: 1 | AY11: 1 | AZ11: 0.8345962 | BA11: 1.0175185 | BB11: 1.3304097 | BC11: 1.2327437 | BE11: =D11-AR11 -> -6.5 | BF11: =E11-AS11 -> -6.5 | BG11: =F11-AT11 -> 0 | BH11: =G11-AU11 -> 0 | BI11: =H11-AV11 -> 0 | BJ11: =I11-AW11 -> 0 | BK11: =J11-AX11 -> 0 | BL11: =K11-AY11 -> 0 | ... BP11: =O11-BC11 -> 0.3672563 | BT11: DPS (cps) | BV11: =FY!D186 -> 2.3 | BW11: =FY!E186 -> 1.3 | BX11: =FY!F186 -> 2 | BY11: =FY!G186 -> 3 | BZ11: =FY!H186 -> 3.2 | CA11: =FY!I186 -> 3.2 | CB11: =FY!J186 -> 3.7282813 | CC11: =FY!K186 -> 3.2995563 | CE11: =BX11 -> 2 | CF11: 3 | CG11: =CF11/CE11-1 -> 0.5 | CH11: =BY11 -> 3 | CI11: =$CF11/CH11-1 -> 0 | CJ11: =CN11 -> 2.6905373 | CK11: =$CF11/CJ11-1 -> 0.11501894 | CN11: =DG11 -> 2.6905373 | CP11: TAH_AU | CQ11: Dividend per share | CR11: consensus.vaactuals | CS11: =_xll.VAData($AB11,CS$3,$AC11,$AD11) -> 13 | CT11: =_xll.VAData($AB11,CT$3,$AC11,$AD11) -> 2.3 | CU11: =_xll.VAData($AB11,CU$3,$AC11,$AD11) -> 1.3 | CV11: =_xll.VAData($AB11,CV$3,$AC11,$AD11) -> 2 | CW11: =_xll.VAData($AB11,CW$3,$AC11,$AD11) -> 3 | CX11: =_xll.VAData($AB11,CX$3,$AC11,$AD11) -> 3.3014117 | CY11: =_xll.VAData($AB11,CY$3,$AC11,$AD11) -> 3.5969058 | CZ11: =_xll.VAData($AB11,CZ$3,$AC11,$AD11) -> 4.0664096 | DA11: =_xll.VAData($AB11,DA$3,$AC11,$AD11) -> 4.4596903 | DC11: 13 | DD11: 2.3 | DE11: 1.3 | DF11: 2 | DG11: 2.6905373 | DH11: 3.0778477 | DI11: 3.2810497 | DJ11: 3.6919246 | DK11: 4.0219095 | DN11: =BV11-DD11 -> 0 | DO11: =BW11-DE11 -> 0 | DP11: =BX11-DF11 -> 0 | DQ11: =BY11-DG11 -> 0.30946274 | DR11: =BZ11-DH11 -> 0.12215228 | DS11: =CA11-DI11 -> -0.081049718 | DT11: =CB11-DJ11 -> 0.036356734 | DU11: =CC11-DK11 -> -0.72235321
C13: Tabcorp 1H26 Result - Segments | BT13: Tabcorp FY26 Result - Segments
D14: =D$3 -> 1H22A | E14: =E$3 -> 2H22A | F14: =F$3 -> 1H23A | G14: =G$3 -> 2H23A | H14: =H$3 -> 1H24A | I14: =I$3 -> 2H24E | J14: =J$3 -> 1H25E | K14: =K$3 -> 2H25E | ... O14: =O$3 -> 2H27E | Q14: =Q$3 -> 1H25A | R14: =R$3 -> 1H26A | S14: =S$3 -> % change | T14: =T$3 -> E&Pe 1H26E | U14: =U$3 -> % diff | V14: =V$3 -> VA Cons. 1H26E | W14: =W$3 -> % diff | Z14: 1H25 | AE14: 1H22 | AF14: 2H22 | AG14: 1H23 | AH14: 2H23 | AI14: 1H24 | AJ14: 2H24 | AK14: 1H25 | AL14: 2H25 | AM14: 1H26 | AN14: 2H26 | AO14: 1H27 | AP14: 2H27 | AR14: 1H22 | AS14: 2H22 | AT14: 1H23 | AU14: 2H23 | AV14: 1H24 | AW14: 2H24 | AX14: 1H25 | AY14: 2H25 | AZ14: 1H26 | BA14: 2H26 | BB14: 1H27 | BC14: 2H27 | BE14: 1H22 | BF14: 2H22 | BG14: 1H23 | BH14: 2H23 | BI14: 1H24 | BJ14: 2H24 | BK14: 1H25 | BL14: 2H25 | BM14: 1H26 | BN14: 2H26 | BO14: 1H27 | BP14: 2H27 | BU14: =BU$3 -> FY22A | BV14: =BV$3 -> FY23A | BW14: =BW$3 -> FY24A | BX14: =BX$3 -> FY25E | BY14: =BY$3 -> FY26E | BZ14: =BZ$3 -> FY27E | CA14: =CA$3 -> FY28E | CB14: =CB$3 -> FY29E | CC14: =CC$3 -> FY30E | CE14: =CE$3 -> FY25A | CF14: =CF$3 -> FY26A | CG14: =CG$3 -> % change | CH14: =CH$3 -> E&Pe FY26E | CI14: =CI$3 -> % diff | CJ14: =CJ$3 -> VA Cons. FY26E | CK14: =CK$3 -> % diff | CN14: =DG14 -> FY26 | CS14: FY22 | CT14: FY23 | CU14: FY24 | CV14: FY25 | CW14: FY26 | CX14: FY27 | CY14: FY27 | CZ14: FY27 | DA14: FY27 | DC14: FY22 | DD14: FY23 | DE14: FY24 | DF14: FY25 | DG14: FY26 | DH14: FY27 | DI14: FY27 | DJ14: FY27 | DK14: FY27 | DM14: FY22 | DN14: FY23 | DO14: FY24 | DP14: FY25 | DQ14: FY26 | DR14: FY27 | DS14: FY28 | DT14: FY29 | DU14: FY30
CW15: =CX17-20 -> 2500.6753
C16: Segments | BT16: Segments | CW16: =CW15/CW17-1 -> 0.018729488 | CX16: =CX17/CW17-1 -> 0.026877123 | CY16: =CY17/CX17-1 -> 0.025503622 | CZ16: =CZ17/CY17-1 -> 0.018435089 | DH16: 0.02790958 | DI16: 0.024634795 | DJ16: 0.021579666
C17: Wagering & Media | D17: =HY!M268 -> 1073.4 | E17: =HY!N268 -> 1108.5 | F17: =HY!O268 -> 1165.7 | G17: =HY!P268 -> 1065.1 | H17: =HY!Q268 -> 1116.6 | I17: =HY!R268 -> 1046.2 | J17: =HY!S268 -> 1243.2 | K17: =HY!T268 -> 1195.6 | ... O17: =HY!X268 -> 1228.5871 | Q17: =J17 -> 1243.2 | R17: 1253.2 | S17: =R17/Q17-1 -> 0.008043758 | T17: =L17 -> 1253.2 | U17: =$R17/T17-1 -> 0 | V17: =Z17 -> 1235.4444 | W17: =$R17/V17-1 -> 0.01437181 | Z17: =AZ17 -> 1235.4444 | AB17: TAH_AU | AC17: Total revenue - Wagering & media | AD17: consensus.vaactuals | AE17: =_xll.VAData($AB17,AE$3,$AC17,$AD17) -> 1073.4 | AF17: =_xll.VAData($AB17,AF$3,$AC17,$AD17) -> 1108.5 | AG17: =_xll.VAData($AB17,AG$3,$AC17,$AD17) -> 1165.7 | AH17: =_xll.VAData($AB17,AH$3,$AC17,$AD17) -> 1065.1 | AI17: =_xll.VAData($AB17,AI$3,$AC17,$AD17) -> 1116.7 | AJ17: =_xll.VAData($AB17,AJ$3,$AC17,$AD17) -> 1045.4 | AK17: =_xll.VAData($AB17,AK$3,$AC17,$AD17) -> 1243.2 | AL17: =_xll.VAData($AB17,AL$3,$AC17,$AD17) -> 1195.6 | ... AP17: =_xll.VAData($AB17,AP$3,$AC17,$AD17) -> 1223.8215 | AR17: 1073.4 | AS17: 1108.5 | AT17: 1165.7 | AU17: 1065.1 | AV17: 1116.7 | AW17: 1046.2 | AX17: 1243.2 | AY17: 1195.6 | AZ17: 1235.4444 | BA17: 1212.0123 | BB17: 1309.3178 | BC17: 1239.4595 | BE17: =D17-AR17 -> 0 | BF17: =E17-AS17 -> 0 | BG17: =F17-AT17 -> 0 | BH17: =G17-AU17 -> 0 | BI17: =H17-AV17 -> -0.1 | BJ17: =I17-AW17 -> 0 | BK17: =J17-AX17 -> 0 | BL17: =K17-AY17 -> 0 | ... BP17: =O17-BC17 -> -10.87241 | BT17: Wagering & Media | BU17: =FY!C8 -> 2181.9 | BV17: =FY!D8 -> 2230.8 | BW17: =FY!E8 -> 2162.8 | BX17: =FY!F8 -> 2438.8 | BY17: =FY!G8 -> 2454.7 | BZ17: =FY!H8 -> 2535.5783 | CA17: =FY!I8 -> 2553.5792 | CB17: =FY!J8 -> 2575.9298 | CC17: =FY!K8 -> 2633.1222 | CE17: =BX17 -> 2438.8 | CF17: 2454.7 | CG17: =CF17/CE17-1 -> 0.0065195998 | CH17: =BY17 -> 2454.7 | CI17: =$CF17/CH17-1 -> 0 | CJ17: =CN17 -> 2468.3065 | CK17: =$CF17/CJ17-1 -> -0.0055124919 | CN17: =DG17 -> 2468.3065 | CP17: TAH_AU | CQ17: Total revenue - Wagering & media | CR17: consensus.vaactuals | CS17: =_xll.VAData($AB17,CS$3,$AC17,$AD17) -> 2181.9 | CT17: =_xll.VAData($AB17,CT$3,$AC17,$AD17) -> 2230.8 | CU17: =_xll.VAData($AB17,CU$3,$AC17,$AD17) -> 2162.8 | CV17: =_xll.VAData($AB17,CV$3,$AC17,$AD17) -> 2438.8 | CW17: =_xll.VAData($AB17,CW$3,$AC17,$AD17) -> 2454.7 | CX17: =_xll.VAData($AB17,CX$3,$AC17,$AD17) -> 2520.6753 | CY17: =_xll.VAData($AB17,CY$3,$AC17,$AD17) -> 2584.9616 | CZ17: =_xll.VAData($AB17,CZ$3,$AC17,$AD17) -> 2632.6156 | DA17: =_xll.VAData($AB17,DA$3,$AC17,$AD17) -> 2680.5293 | DC17: 2181.9 | DD17: 2230.8 | DE17: 2162.8 | DF17: 2438.8 | DG17: 2468.3065 | DH17: 2537.1959 | DI17: 2599.6992 | DJ17: 2655.7999 | DK17: 2711.6151 | DM17: =BU17-DC17 -> 0 | DN17: =BV17-DD17 -> 0 | DO17: =BW17-DE17 -> 0 | DP17: =BX17-DF17 -> 0 | DQ17: =BY17-DG17 -> -13.60652 | DR17: =BZ17-DH17 -> -1.6176013 | DS17: =CA17-DI17 -> -46.119982 | DT17: =CB17-DJ17 -> -79.870041 | DU17: =CC17-DK17 -> -78.492871
C18: Integrity Services | D18: =HY!M269 -> 79.6 | E18: =HY!N269 -> 117.3 | F18: =HY!O269 -> 108.8 | G18: =HY!P269 -> 94.8 | H18: =HY!Q269 -> 80.3 | I18: =HY!R269 -> 83.1 | J18: =HY!S269 -> 88.1 | K18: =HY!T269 -> 87.7 | ... O18: =HY!X269 -> 92.1475 | Q18: =J18 -> 88.1 | R18: 91.7 | S18: =R18/Q18-1 -> 0.040862656 | T18: =L18 -> 91.7 | U18: =$R18/T18-1 -> 0 | V18: =Z18 -> 90.096278 | W18: =$R18/V18-1 -> 0.017800093 | Z18: =AZ18 -> 90.096278 | AB18: TAH_AU | AC18: Total revenue - Gaming services | AD18: consensus.vaactuals | AE18: =_xll.VAData($AB18,AE$3,$AC18,$AD18) -> 79.6 | AF18: =_xll.VAData($AB18,AF$3,$AC18,$AD18) -> 117.3 | AG18: =_xll.VAData($AB18,AG$3,$AC18,$AD18) -> 108.8 | AH18: =_xll.VAData($AB18,AH$3,$AC18,$AD18) -> 94.8 | AI18: =_xll.VAData($AB18,AI$3,$AC18,$AD18) -> 80.3 | AJ18: =_xll.VAData($AB18,AJ$3,$AC18,$AD18) -> 83.1 | AK18: =_xll.VAData($AB18,AK$3,$AC18,$AD18) -> 88.1 | AL18: =_xll.VAData($AB18,AL$3,$AC18,$AD18) -> 87.7 | ... AP18: =_xll.VAData($AB18,AP$3,$AC18,$AD18) -> 91.723117 | AR18: 79.6 | AS18: 117.3 | AT18: 108.8 | AU18: 94.8 | AV18: 93 | AW18: 83.1 | AX18: 88.1 | AY18: 87.7 | AZ18: 90.096278 | BA18: 89.817969 | BB18: 92.612824 | BC18: 92.312926 | BE18: =D18-AR18 -> 0 | BF18: =E18-AS18 -> 0 | BG18: =F18-AT18 -> 0 | BH18: =G18-AU18 -> 0 | BI18: =H18-AV18 -> -12.7 | BJ18: =I18-AW18 -> 0 | BK18: =J18-AX18 -> 0 | BL18: =K18-AY18 -> 0 | ... BP18: =O18-BC18 -> -0.16542612 | BT18: Integrity Services | BU18: =FY!C9 -> 196.9 | BV18: =FY!D9 -> 203.6 | BW18: =FY!E9 -> 163.4 | BX18: =FY!F9 -> 175.8 | BY18: =FY!G9 -> 181.6 | BZ18: =FY!H9 -> 186.14 | CA18: =FY!I9 -> 190.7935 | CB18: =FY!J9 -> 196.5173 | CC18: =FY!K9 -> 202.41282 | CE18: =BX18 -> 175.8 | CF18: 181.6 | CG18: =CF18/CE18-1 -> 0.032992036 | CH18: =BY18 -> 181.6 | CI18: =$CF18/CH18-1 -> 0 | CJ18: =CN18 -> 182.14801 | CK18: =$CF18/CJ18-1 -> -0.0030085891 | CN18: =DG18 -> 182.14801 | CP18: TAH_AU | CQ18: Total revenue - Gaming services | CR18: consensus.vaactuals | CS18: =_xll.VAData($AB18,CS$3,$AC18,$AD18) -> 196.9 | CT18: =_xll.VAData($AB18,CT$3,$AC18,$AD18) -> 203.6 | CU18: =_xll.VAData($AB18,CU$3,$AC18,$AD18) -> 163.4 | CV18: =_xll.VAData($AB18,CV$3,$AC18,$AD18) -> 175.8 | CW18: =_xll.VAData($AB18,CW$3,$AC18,$AD18) -> 181.6 | CX18: =_xll.VAData($AB18,CX$3,$AC18,$AD18) -> 185.16618 | CY18: =_xll.VAData($AB18,CY$3,$AC18,$AD18) -> 189.8524 | CZ18: =_xll.VAData($AB18,CZ$3,$AC18,$AD18) -> 194.58353 | DA18: =_xll.VAData($AB18,DA$3,$AC18,$AD18) -> 199.53644 | DC18: 196.9 | DD18: 203.6 | DE18: 163.4 | DF18: 175.8 | DG18: 182.14801 | DH18: 187.60247 | DI18: 192.69029 | DJ18: 197.68489 | DK18: 202.94352 | DM18: =BU18-DC18 -> 0 | DN18: =BV18-DD18 -> 0 | DO18: =BW18-DE18 -> 0 | DP18: =BX18-DF18 -> 0 | DQ18: =BY18-DG18 -> -0.54800851 | DR18: =BZ18-DH18 -> -1.4624651 | DS18: =CA18-DI18 -> -1.8967865 | DT18: =CB18-DJ18 -> -1.1675843 | DU18: =CC18-DK18 -> -0.53069124
